{
  "xsize": 16,
    "zsize": 16,
    "slices": [
      [
        "a$$a$$a$$a$$a$$a",
        "$bddddddddbdddb$",
        "$caaaaaaaaiaaac$",
        "aca$$$$aaaiaaaca",
        "$ca$1$$aa$iaaac$",
        "$ca$$1$aa$iaaac$",
        "aca$$$$aa$iaaaca",
        "$caaaaaaaaiaaac$",
        "$caaaaaaaaiaaac$",
        "acaaaa$l$aiaaaca",
        "$c$$$aaaaaiaaac$",
        "$bjjjjjjjjbaaac$",
        "acaaaaaaaaaaaaca",
        "$caaaaaaaaaaaac$",
        "$bddddddddddddb$",
        "a$$a$$a$$a$$a$$a"
      ],
      [
        "aaaaaaaaaaaaaaaa",
        "aFF      a    Fa",
        "aF F    Fa  F Fa",
        "aFFF    Fa   FFa",
        "a F F       FFFa",
        "a             Fa",
        "a              a",
        "a        a     a",
        "a        a     a",
        "a      l a     a",
        "aa   aaaaa     a",
        "a              a",
        "a      FF   F  a",
        "a   FFFF1F F1FFa",
        "a  FFFFFFF  FFFa",
        "aaaaaaaaaaaaaaaa"
      ],
      [
        "a44a44a44a44a44a",
        "4F k     a  k  4",
        "4F       a    F4",
        "a       ma   mFa",
        "4             F4",
        "4             m4",
        "an            oa",
        "4        a     4",
        "4        a     4",
        "a      l a     a",
        "4a   aaaaa     4",
        "4              4",
        "a             oa",
        "4    m  Fm  F  4",
        "4  TFFF FT   F 4",
        "a44a44a44a44a44a"
      ],
      [
        "a44a44a44a44a44a",
        "4F       a     4",
        "4m       a     4",
        "a        a     a",
        "4        a    F4",
        "4       oaf    4",
        "a        a     a",
        "4        a     4",
        "4        a     4",
        "a  T   l a     a",
        "4aaaaaaaaa     4",
        "4  r           4",
        "a              a",
        "4              4",
        "4   F        m 4",
        "a44a44a44a44a44a"
      ],
      [
        "aaaaaaaaaaaaaaaa",
        "abddddddddddddba",
        "acaaaaaaaaaaaaca",
        "acaaaaaaaaaaaaca",
        "acaaaaaaaaaaaaca",
        "acaaaaaaaaaaaaca",
        "acaaaaaaaaaaaaca",
        "acaaaaaaaaaaaaca",
        "acaaaaaaaaaaaaca",
        "acaaaa$l$aaaaaca",
        "acaaaaaaaaaaaaca",
        "acaaaaaaaaaaaaca",
        "acaaaaaaaaaaaaca",
        "acaaaaaaaaaaaaca",
        "acaaaaaaaaaaaaca",
        "abddddddddddddba"
      ],
      [
        "aaaaaaaaaaaaaaaa",
        "abddddddddddddba",
        "acaaaaaaaaaaaaca",
        "acaaaaaaaaaaaaca",
        "acaaaaaaaaaaaaca",
        "acaaaaaaaaaaaaca",
        "acaaaaaaaaaaaaca",
        "acaaaaaaaaaaaaca",
        "acaaaaaaaaaaaaca",
        "acaaaa$l$aaaaaca",
        "acaaaaaaaaaaaaca",
        "acaaaaaaaaaaaaca",
        "acaaaaaaaaaaaaca",
        "acaaaaaaaaaaaaca",
        "acaaaaaaaaaaaaca",
        "abddddddddddddba"
      ]
    ]
}