{
  "xsize": 16,
  "zsize": 16,
  "slices": [
    [
      "################",
      "#bddddddddddddb#",
      "#c############c#",
      "#c############c#",
      "#c############c#",
      "#c############c#",
      "#c############c#",
      "#c############c#",
      "#c############c#",
      "#c####$l$#####c#",
      "#c############c#",
      "#c############c#",
      "#c############c#",
      "#c############c#",
      "#bddddddddddddb#",
      "################"
    ],
    [
      "#aa@aaaaaaaa@aa#",
      "a              a",
      "a              a",
      "@              @",
      "a              a",
      "a              a",
      "a    ## ##     a",
      "a    #   #     a",
      "a    #   #     a",
      "a    # l #     a",
      "a# ############a",
      "a     FFF      a",
      "@              @",
      "a              a",
      "a              a",
      "#aa@aaaaaaaa@aa#"
    ],
    [
      "#aa@aaaaaaaa@aa#",
      "a              a",
      "a              a",
      "@              @",
      "a              a",
      "a              a",
      "a    ## ##     a",
      "a    #  T#     a",
      "a    #   #     a",
      "a    # l #     a",
      "a# ########aaa#a",
      "a              a",
      "@              @",
      "a              a",
      "a              a",
      "#aa@aaaaaaaa@aa#"
    ],
    [
      "#aa@aaaaaaaa@aa#",
      "a              a",
      "a              a",
      "@              @",
      "a              a",
      "a              a",
      "a    #####     a",
      "a    #   #     a",
      "a    #   #     a",
      "a    # l #     a",
      "a##############a",
      "a              a",
      "@              @",
      "a              a",
      "a              a",
      "#aa@aaaaaaaa@aa#"
    ],
    [
      "################",
      "################",
      "###1############",
      "################",
      "############1###",
      "################",
      "################",
      "################",
      "################",
      "######$l$#######",
      "################",
      "################",
      "################",
      "################",
      "################",
      "################"
    ],
    [
      "################",
      "#bddddddddddddb#",
      "#c############c#",
      "#c############c#",
      "#c############c#",
      "#c############c#",
      "#c############c#",
      "#c############c#",
      "#c############c#",
      "#c####$l$#####c#",
      "#c############c#",
      "#c############c#",
      "#c############c#",
      "#c############c#",
      "#c############c#",
      "#bddddddddddddb#"
    ]
  ]
}