{
  "xsize": 16,
  "zsize": 16,
  "slices": [
    [
      "aaaaaaaaaaaaaaaa",
      "abddbddddddbddba",
      "acaaIaaaaaacaaca",
      "acaaIaaaalacaaca",
      "acaaIaaaaaacaaca",
      "acaaIaaaaaacaaca",
      "acaaIaaaaaacaaca",
      "acaaIaaaaaacaaca",
      "acaaIaaaaaacaaca",
      "acaabdiyiddbaaca",
      "acaaaaaaaalaaaca",
      "acaaaaaaaaaaaaca",
      "acalaaalaaalaaca",
      "acaaaaaaaaaaaaca",
      "abddddddddddddba",
      "aaaaaaaaaaaaaaaa"
    ],
    [
      "ahhahhhhhhhhahha",
      "h  ajj   jjja  h",
      "h  ajjj  jjja  h",
      "a  ajj   jjja  a",
      "h  aj   j  ja  h",
      "h  a        a  h",
      "h              h",
      "h  a        a  h",
      "h  a        a  h",
      "h  a   y    a  h",
      "h  aaaaaaaaaa  h",
      "h  jjjjjj      h",
      "a  jjjjj       a",
      "h     j        h",
      "h     j        h",
      "ahhahhhhhhhhahha"
    ],
    [
      "ahhahhhhhhhhahha",
      "h  a       ja  h",
      "h  ajk    jja  h",
      "aq aj      ja sa",
      "h  ak      ja  h",
      "h  a        a  h",
      "h              h",
      "h  a        a  h",
      "h  a        a  h",
      "h  a   y    a  h",
      "h  aaaaaaaaaa  h",
      "h  kjjj k      h",
      "aq  k         sa",
      "h              h",
      "h  p        p  h",
      "ahhahhhhhhhhahha"
    ],
    [
      "ahhahhhhhhhhahha",
      "h  a       ja  h",
      "h  aj     k a  h",
      "a  a        a  a",
      "h  a        a  h",
      "h  a        a  h",
      "h  a        a  h",
      "h  a        a  h",
      "h  a        a  h",
      "h  a   y    a  h",
      "h  aaaaaaaaaa  h",
      "h    j         h",
      "a              a",
      "h              h",
      "h              h",
      "ahhahhhhhhhhahha"
    ],
    [
      "aaaaaaaaaaaaaaaa",
      "abddpddddddpddba",
      "acaaIaaaaaaIaaca",
      "acaaIaaaaaaIaaca",
      "acaaIaaaaaaIaaca",
      "acaaIaaaaaaIaaca",
      "acaaIaaaaaacaaca",
      "acaaIaaaaaacaaca",
      "acaaIaaaaaacaaca",
      "acaapKiyiddpaaca",
      "acaaaaaaaaaaaaca",
      "acaaaaaaaaaaaaca",
      "acaaaaaaaaaaaaca",
      "acaaaaaaaaaaaaca",
      "apKpa",
      "abddddddddddddba"
    ],
    [
      "aaaaaaaaaaaaaaaa",
      "abddpdddddddddba",
      "acaaaaaaaaaaaaca",
      "acaaaaaaaaaaaaca",
      "acaaaaaaaaaaaaca",
      "acaaaaaaaaaaaaca",
      "acaaaaaaaaaaaaca",
      "acaaaaaaaaaaaaca",
      "acaaaaaaaaaaaaca",
      "acaaaaiyiaaaaaca",
      "acaaaaaaaaaaaaca",
      "acaaaaaaaaaaaaca",
      "acaaaaaaaaaaaaca",
      "acaaaaaaaaaaaaca",
      "acaaaaaaaaaaaaca",
      "abddddddddddddba"
    ]
  ]
}