{
  "xsize": 16,
  "zsize": 16,
  "slices": [
    [
    "aaaaaaaaaaaaaaaa",
    "abddddddddddddba",
    "acaaaaaaaaaaaaca",
    "acaaaaaaaaaaaaca",
    "acaaaaaaaaaaaaca",
    "acaaalaaaalaaaca",
    "acaaaaaaaaaaaaca",
    "acaaaaaaaaaaaaca",
    "acaaaaaaaaaaaaca",
    "acaaaaiyiaaaaaca",
    "acaaaaaaaaaaaaca",
    "acaaaaaaaaaaaaca",
    "acaalaaalaaalaca",
    "acaaaaaaaaaaaaca",
    "abddddddddddddba",
    "aaaaaaaaaaaaaaaa"
    ],
    [
    "aaGGGaaaaaaGGGaa",
    "aaaaaa    aaaaaa",
    "Gajjj         aG",
    "Gajj     jjj jaG",
    "Gajj j   jjjjjaG",
    "aa jjj    jj  aa",
    "a j  jjj       a",
    "ajj  j         a",
    "ajjj     jj    a",
    "ajj    y       a",
    "aaj   aaa   j aa",
    "Gajj   j   jjjaG",
    "Ga jj  jj jjj aG",
    "Ga  j   j  j  aG",
    "aaaaaa  j aaaaaa",
    "aaGGGaaaaaaGGGaa"
    ],
    [
    "aa   aaaaaa   aa",
    "aahhha    ahhhaa",
    " h j          h ",
    " h        k   h ",
    " h k       j  h ",
    "aa         j  aa",
    "a      j       a",
    "ajj            a",
    "aj             a",
    "a      y       a",
    "aa    aaa   j aa",
    " hk         k h ",
    " h      k     h ",
    " h            h ",
    "aahhha    ahhhaa",
    "aa   aaaaaa   aa"
    ],
    [
    "aa   aaaaaa   aa",
    "aahhha    ahhhaa",
    " h   r    r   h ",
    " h            h ",
    " h            h ",
    "aaq          saa",
    "a              a",
    "ajk            a",
    "aj             a",
    "a      y       a",
    "aaq   aaa    saa",
    " h            h ",
    " h            h ",
    " h   p    p   h ",
    "aahhha    ahhhaa",
    "aa   aaaaaa   aa"
    ],
    [
    "aa   aaaaaa   aa",
    "aahhha    ahhhaa",
    " h            h ",
    " h            h ",
    " h            h ",
    "aa            aa",
    "a              a",
    "a              a",
    "a              a",
    "a      y       a",
    "aa    aaa     aa",
    " h            h ",
    " h            h ",
    " h            h ",
    "aahhha    ahhhaa",
    "aa   aaaaaa   aa"
    ],
    [
    "aaGGGaaaaaaGGGaa",
    "aaaaaaaaaaaaaaaa",
    "GaaaaaaaaaaaaaaG",
    "GaaaaaaaaaaaaaaG",
    "GaaaaaaaaaaaaaaG",
    "aaaaaaaaaaaaaaaa",
    "aaaaaaaaaaaaaaaa",
    "aaaaaaaaaaaaaaaa",
    "aaaaaaaaaaaaaaaa",
    "aaaaaaiyiaaaaaaa",
    "aaaaaaaaaaaaaaaa",
    "GaaaaaaaaaaaaaaG",
    "GaaaaaaaaaaaaaaG",
    "GaaaaaaaaaaaaaaG",
    "aaaaaaaaaaaaaaaa",
    "aaGGGaaaaaaGGGaa"
    ]
  ]
}