{
  "xsize": 16,
  "zsize": 16,
  "slices": [
    [
      "aaaaaaaaaaaaaaaa",
      "abddddddddddddba",
      "acaaaaaaaaaaaaca",
      "acaaaaaaaaaaaaca",
      "acaaaaaaaaaaaaca",
      "acaaaaaaaaaaaaca",
      "acaaaaaaaaaaaaca",
      "acaaaaaaaaaaaaca",
      "acaaaaaaaaaaaaca",
      "acaaa1$l$1aaaaca",
      "acaaaaaaaaaaaaca",
      "acaaaaaaaaaaaaca",
      "acaaaaaaaaaaaaca",
      "acaaaaaaaaaaaaca",
      "abddddddddddddba",
      "aaaaaaaaaaaaaaaa"
    ],
    [
      "a44@44444444@44a",
      "4   LL         4",
      "4              4",
      "@              @",
      "4              4",
      "4              4",
      "4    aa aa     4",
      "4    a   a     4",
      "4    a   a     4",
      "4    a l a     4",
      "4  QQaaaaaQQ   4",
      "4      CF      4",
      "@              @",
      "4              4",
      "4              4",
      "a44@44444444@44a"
    ],
    [
      "a44@44444444@44a",
      "4   LL         4",
      "4              4",
      "@              @",
      "4              4",
      "4              4",
      "4    aa aa     4",
      "4    a  Ta     4",
      "4    a   a     4",
      "4    a l a     4",
      "4  QQaaaaaQQ   4",
      "4              4",
      "@              @",
      "4              4",
      "4              4",
      "a44@44444444@44a"
    ],
    [
      "a44@44444444@44a",
      "4              4",
      "4              4",
      "@              @",
      "4              4",
      "4              4",
      "4    aaaaa     4",
      "4    a   a     4",
      "4    a   a     4",
      "4    a l a     4",
      "4  QQaaaaaQQ   4",
      "4              4",
      "@              @",
      "4              4",
      "4              4",
      "a44@44444444@44a"
    ],
    [
      "aaaaaaaaaaaaaaaa",
      "abddddddddddddba",
      "acaaaaaaaaaaaaca",
      "acaaaaaaaaaaaaca",
      "acaaaaaaaaaaaaca",
      "acaaaaaaaaaaaaca",
      "acaaaaaaaaaaaaca",
      "acaaaaaaaaaaaaca",
      "acaaaaaaaaaaaaca",
      "acaaaa$l$aaaaaca",
      "acaaaaaaaaaaaaca",
      "acaaaaaaaaaaaaca",
      "acaaaaaaaaaaaaca",
      "acaaaaaaaaaaaaca",
      "acaaaaaaaaaaaaca",
      "abddddddddddddba"
    ],
    [
      "aaaaaaaaaaaaaaaa",
      "abddddddddddddba",
      "acaaaaaaaaaaaaca",
      "acaaaaaaaaaaaaca",
      "acaaaaaaaaaaaaca",
      "acaaaaaaaaaaaaca",
      "acaaaaaaaaaaaaca",
      "acaaaaaaaaaaaaca",
      "acaaaaaaaaaaaaca",
      "acaaaa$l$aaaaaca",
      "acaaaaaaaaaaaaca",
      "acaaaaaaaaaaaaca",
      "acaaaaaaaaaaaaca",
      "acaaaaaaaaaaaaca",
      "acaaaaaaaaaaaaca",
      "abddddddddddddba"
    ]
  ]
}