{
  "xsize": 16,
  "zsize": 16,
  "slices": [
    [
      "aaaaaaaaaaaaaaaa",
      "abddddddddddddba",
      "acaaaaaaaaaaaaca",
      "acaaaaaaaaaaaaca",
      "acaaaaaaaaaaaaca",
      "acaaaaaaaaaaaaca",
      "acaaaaaaaaaaaaca",
      "acaaaaaaaaaaaaca",
      "acaaaaaaaaaaaaca",
      "acaaaailiaaaaaca",
      "acaaaaaaaaaaaaca",
      "acaaaaaaaaaaaaca",
      "acaaaaaaaaaaaaca",
      "acaaaaaaaaaaaaca",
      "abddddddddddddba",
      "aaaaaaaaaaaaaaaa"
    ],
    [
      "aa___aaaaaa___aa",
      "aaaaaa    aaaaaa",
      "_aDa        aDa_",
      "_aDa        aDa_",
      "_aDa        aDa_",
      "aaaa        aaaa",
      "a              a",
      "aj            ja",
      "aj            ja",
      "a      l       a",
      "aa    aaa     aa",
      "_a            a_",
      "_a    . .     a_",
      "_a            a_",
      "aaaaaa    aaaaaa",
      "aa___aaaaaa___aa"
    ],
    [
      "aa   aaaaaa   aa",
      "aahhha    ahhhaa",
      " hk          kh ",
      " hk          kh ",
      " hk          kh ",
      "aa            aa",
      "a              a",
      "a             ja",
      "a             ja",
      "a      l       a",
      "aa    aaa     aa",
      " h            h ",
      " h    - -     h ",
      " h            h ",
      "aahhha    ahhhaa",
      "aa   aaaaaa   aa"
    ],
    [
      "aa   aaaaaa   aa",
      "aahhha    ahhhaa",
      " h            h ",
      " h            h ",
      " h            h ",
      "aak          kaa",
      "a              a",
      "a              a",
      "a              a",
      "a      l       a",
      "aak   aaa    kaa",
      " h            h ",
      " h            h ",
      " h            h ",
      "aahhha    ahhhaa",
      "aa   aaaaaa   aa"
    ],
    [
      "aa   aaaaaa   aa",
      "aahhha    ahhhaa",
      " h            h ",
      " h            h ",
      " h            h ",
      "aa            aa",
      "a              a",
      "a              a",
      "a              a",
      "a      l       a",
      "aa    aaa     aa",
      " h            h ",
      " h            h ",
      " h            h ",
      "aahhha    ahhhaa",
      "aa   aaaaaa   aa"
    ],
    [
      "aa===aaaaaa===aa",
      "aaaaaaaaaaaaaaaa",
      "=aaaaaaaaaaaaaa=",
      "=aaaaaaaaaaaaaa=",
      "=aaaaaaaaaaaaaa=",
      "aaaaaaaaaaaaaaaa",
      "aaaaaaaaaaaaaaaa",
      "aaaaaaaaaaaaaaaa",
      "aaaaaaaaaaaaaaaa",
      "aaaaaailiaaaaaaa",
      "aaaaaaaaaaaaaaaa",
      "=aaaaaaaaaaaaaa=",
      "=aaaaaaaaaaaaaa=",
      "=aaaaaaaaaaaaaa=",
      "aaaaaaaaaaaaaaaa",
      "aa===aaaaaa===aa"
    ]
  ]
}