{
  "xsize": 16,
  "zsize": 16,
  "slices": [
    [
      "#$$#$$#$$#$$#$$#",
      "$bddddddddddddb$",
      "$c##1#########c$",
      "#c############c#",
      "$c####1#######c$",
      "$c############c$",
      "#c############c#",
      "$c############c$",
      "$c############c$",
      "#c####$l$#####c#",
      "$c############c$",
      "$c############c$",
      "#c############c#",
      "$c############c$",
      "$bddddddddddddb$",
      "#$$#$$#$$#$$#$$#"
    ],
    [
      "################",
      "#        #  FFF#",
      "#   FF F #   FF#",
      "#    F   #   FF#",
      "# F  FF  #   F #",
      "#  F  FF #     #",
      "##########     #",
      "#FF   FFF      #",
      "#F             #",
      "#F     l      F#",
      "#     ###    FF#",
      "#     FF     FF#",
      "#      F    FFF#",
      "#           FFF#",
      "#FF          FF#",
      "################"
    ],
    [
      "#aa#aa#aa#aa#aa#",
      "a     i     i Fa",
      "a            *Fa",
      "#j   F        F#",
      "a     F        a",
      "a     F        a",
      "#     F  #     #",
      "aF*     F      a",
      "aF             a",
      "#      l      k#",
      "a     ###     *a",
      "a      F      Fa",
      "#j     F     FF#",
      "a            FFa",
      "a *   T     T Fa",
      "#aa#aa#aa#aa#aa#"
    ],
    [
      "#aa#aa#aa#aa#aa#",
      "a             Fa",
      "a              a",
      "#              #",
      "a     F        a",
      "a              a",
      "#     *  #     #",
      "a              a",
      "a              a",
      "#      l       #",
      "a     ###      a",
      "a      *       a",
      "#              #",
      "a            *Fa",
      "a             Fa",
      "#aa#aa#aa#aa#aa#"
    ],
    [
      "################",
      "#bddddddddddddb#",
      "#c############c#",
      "#c############c#",
      "#c############c#",
      "#c############c#",
      "#c############c#",
      "#c############c#",
      "#c############c#",
      "#c####$l$#####c#",
      "#c############c#",
      "#c############c#",
      "#c############c#",
      "#c############c#",
      "#c############c#",
      "#bddddddddddddb#"
    ],
    [
      "################",
      "#bddddddddddddb#",
      "#c############c#",
      "#c############c#",
      "#c############c#",
      "#c############c#",
      "#c############c#",
      "#c############c#",
      "#c############c#",
      "#c####$l$#####c#",
      "#c############c#",
      "#c############c#",
      "#c############c#",
      "#c############c#",
      "#c############c#",
      "#bddddddddddddb#"
    ]
  ]
}