{
  "xsize": 16,
  "zsize": 16,
  "slices": [
    [
      "aaaaaaaaaaaaaaaa",
      "abddddddddddddba",
      "acaaaaaaaaaaaaca",
      "acaaaaaaaaaaaaca",
      "acaaaaaaaaaaaaca",
      "acaaaaaaaaaaaaca",
      "acaaaaaaaaaaaaca",
      "acaaaaaaaaaaaaca",
      "acaaaaaaaaaaaaca",
      "acaaaa$l$aaaaaca",
      "acaaaaaaaaaaaaca",
      "acaaaaaaaaaaaaca",
      "acaaaaaaaaaaaaca",
      "acaaaaaaaaaaaaca",
      "abddddddddddddba",
      "aaaaaaaaaaaaaaaa"
    ],
    [
      "a44@44444444@44a",
      "4              4",
      "4              4",
      "@              @",
      "4              4",
      "4              4",
      "4    aa aa     4",
      "4    a   a     4",
      "4    a   a     4",
      "4    a l a     4",
      "4a aaaaaaaaaaaa4",
      "4     FFF      4",
      "@              @",
      "4              4",
      "4              4",
      "a44@44444444@44a"
    ],
    [
      "a44@44444444@44a",
      "4              4",
      "4              4",
      "@              @",
      "4              4",
      "4              4",
      "4    aa aa     4",
      "4    a  Ta     4",
      "4    a   a     4",
      "4    a l a     4",
      "4a aaaaaaaa444a4",
      "4              4",
      "@              @",
      "4              4",
      "4              4",
      "a44@44444444@44a"
    ],
    [
      "a44@44444444@44a",
      "4              4",
      "4              4",
      "@              @",
      "4              4",
      "4              4",
      "4    aaaaa     4",
      "4    a   a     4",
      "4    a   a     4",
      "4    a l a     4",
      "4aaaaaaaaaaaaaa4",
      "4              4",
      "@              @",
      "4              4",
      "4              4",
      "a44@44444444@44a"
    ],
    [
      "aaaaaaaaaaaaaaaa",
      "aaaaaaaaaaaaaaaa",
      "aaa1aaaaaaaaaaaa",
      "aaaaaaaaaaaaaaaa",
      "aaaaaaaaaaaa1aaa",
      "aaaaaaaaaaaaaaaa",
      "aaaaaaaaaaaaaaaa",
      "aaaaaaaaaaaaaaaa",
      "aaaaaaaaaaaaaaaa",
      "aaaaaa$l$aaaaaaa",
      "aaaaaaaaaaaaaaaa",
      "aaaaaaaaaaaaaaaa",
      "aaaaaaaaaaaaaaaa",
      "aaaaaaaaaaaaaaaa",
      "aaaaaaaaaaaaaaaa",
      "aaaaaaaaaaaaaaaa"
    ],
    [
      "aaaaaaaaaaaaaaaa",
      "abddddddddddddba",
      "acaaaaaaaaaaaaca",
      "acaaaaaaaaaaaaca",
      "acaaaaaaaaaaaaca",
      "acaaaaaaaaaaaaca",
      "acaaaaaaaaaaaaca",
      "acaaaaaaaaaaaaca",
      "acaaaaaaaaaaaaca",
      "acaaaa$l$aaaaaca",
      "acaaaaaaaaaaaaca",
      "acaaaaaaaaaaaaca",
      "acaaaaaaaaaaaaca",
      "acaaaaaaaaaaaaca",
      "acaaaaaaaaaaaaca",
      "abddddddddddddba"
    ]
  ]
}