{
    "xsize": 16,
    "zsize": 16,
    "slices": [
      [
        "aaaaaaaaaaaaaaaa",
        "abddddddddddddba",
        "acaaaaaaaaaaaaca",
        "acaaaaaaaaaaaaca",
        "acaalaalaaalaaca",
        "acaaaaaaaaaaaaca",
        "acaaaaaaaaaaaaca",
        "acaaaaaaaaaaaaca",
        "acaaaaaaaaaaaaca",
        "abddbbiyibddddba",
        "acaalaaaaaaiiica",
        "abKdddddddddddba",
        "acaaaaaaaaaaaaca",
        "acaaaaaaaaaaaaca",
        "abddddddddddddba",
        "aaaaaaaaaaaaaaaa"
      ],
      [
        "ahhahhhhhhhhahha",
        "hjjj      jjjjjh",
        "hjjj       jjjjh",
        "ajjj       j jja",
        "hjjjj  jj  j  jh",
        "hj    jj      jh",
        "h              h",
        "h              h",
        "h              h",
        "h      y       h",
        "haaaaaaaaaa   ah",
        "h  jjj         h",
        "a   j          a",
        "h              h",
        "hjj            h",
        "ahhahhhhhhhhahha"
      ],
      [
        "ahhahhhhhhhhahha",
        "hj r      kkjjjh",
        "hjj         jjjh",
        "ajj          kja",
        "h              h",
        "hk     j       h",
        "h              h",
        "h              h",
        "h              h",
        "h    p y p     h",
        "hahhaaaaaaa   ah",
        "h   jk  r      h",
        "aq            sa",
        "h              h",
        "hj             h",
        "ahhahhhhhhhhahha"
      ],
      [
        "ahhahhhhhhhhahha",
        "hj           jjh",
        "hj           kjh",
        "a k            a",
        "h              h",
        "h              h",
        "h              h",
        "h              h",
        "h              h",
        "h      y       h",
        "haaaaaaaaaaaaaah",
        "h              h",
        "a              a",
        "h              h",
        "h              h",
        "ahhahhhhhhhhahha"
      ],
      [
        "aaaaaaaaaaaaaaaa",
        "abddddddddddddba",
        "acaaaaaaaaaaaaca",
        "acaaaaaaaaaaaaca",
        "acaaaaaaaaaaaaca",
        "acaaaaaaaaaaaaca",
        "acaaaaaaaaaaaaca",
        "acaaaaaaaaaaaaca",
        "acaaaaaaaaaaaaca",
        "acaaaaiyiaaaaaca",
        "acaaaaaaaaaaaaca",
        "acaaaaaaaaaaaaca",
        "acaaaaaaaaaaaaca",
        "acaaaaaaaaaaaaca",
        "acaaaaaaaaaaaaca",
        "abddddddddddddba"
      ],
      [
        "aaaaaaaaaaaaaaaa",
        "abddddddddddddba",
        "acaaaaaaaaaaaaca",
        "acaaaaaaaaaaaaca",
        "acaaaaaaaaaaaaca",
        "acaaaaaaaaaaaaca",
        "acaaaaaaaaaaaaca",
        "acaaaaaaaaaaaaca",
        "acaaaaaaaaaaaaca",
        "acaaaaiyiaaaaaca",
        "acaaaaaaaaaaaaca",
        "acaaaaaaaaaaaaca",
        "acaaaaaaaaaaaaca",
        "acaaaaaaaaaaaaca",
        "acaaaaaaaaaaaaca",
        "abddddddddddddba"
      ]
    ]
  }