{
  "xsize": 16,
  "zsize": 16,
  "slices": [
    [
      "aSSSSSSSSSSSSSSa",
      "SbddddddddddddbS",
      "ScaaaaaaaaaaaacS",
      "ScaaaaaaaaaaaacS",
      "ScaaaaaaaaaaaacS",
      "ScaaaaaaaaaaaacS",
      "ScaaaaaaaaaaaacS",
      "ScaaaaaaaaaaaacS",
      "ScaaaaaaaaaaaacS",
      "ScaaaaaaaaaaaacS",
      "Scaaaaaaaa  aacS",
      "Scaaaaaaaa  aacS",
      "Scaaaaaaaa  aacS",
      "ScaaaaaaaaccaacS",
      "SbddddddddddddbS",
      "aSSSSSSSSSSSSSSa"
    ],
    [
      "ahhahhahhahhahha",
      "h  j  H        h",
      "h     H        h",
      "aj k  a        a",
      "h     H        h",
      "h     H        h",
      "aHHa  a        a",
      "h              h",
      "h         cc   h",
      "a     a  HddH  a",
      "h     H  H  H  h",
      "h     H  H  H  h",
      "a     a  H  H  a",
      "h     H        h",
      "h     H        h",
      "ahhahhahhahhahha"
    ],
    [
      "ahhahhahhahhahha",
      "h     H        h",
      "h     H        h",
      "a     a        a",
      "h     H        h",
      "h     H        h",
      "aHHa  a        a",
      "h              h",
      "h              h",
      "a     a   cc   a",
      "h     H   dd   h",
      "h     H        h",
      "a     a        a",
      "h     H        h",
      "h     H        h",
      "ahhahhahhahhahha"
    ],
    [
      "ahhahhahhahhahha",
      "h     H        h",
      "h     H        h",
      "a     a        a",
      "h     H        h",
      "h     H        h",
      "aHHa  a        a",
      "h              h",
      "h              h",
      "a     a        a",
      "h     H   cc   h",
      "h     H   dd   h",
      "a     a        a",
      "h     H        h",
      "h     H        h",
      "ahhahhahhahhahha"
    ],
    [
      "aSSSSSSSSSSSSSSa",
      "SaaaaaaaaaaaaaaS",
      "SaaaaaaaaaaaaaaS",
      "SaaaaaaaaaaaaaaS",
      "SaaaaaaaaaaaaaaS",
      "SaaaaaaaaaaaaaaS",
      "SaaaaaaaaaaaaaaS",
      "SaaaaaaaaaaaaaaS",
      "Saaaaaaaaa  aaaS",
      "Saaaaaaaaa  aaaS",
      "Saaaaaaaaa  aaaS",
      "SaaaaaaaaaccaaaS",
      "SaaaaaaaaaaaaaaS",
      "SaaaaaaaaaaaaaaS",
      "SaaaaaaaaaaaaaaS",
      "aSSSSSSSSSSSSSSa"
    ],
    [
      "aaaaaaaaaaaaaaaa",
      "aaaaaaaaaaaaaaaa",
      "aaaaaaaaaaaaaaaa",
      "aaaaaaaaaaaaaaaa",
      "aaaaaaaaaaaaaaaa",
      "aaaaaaaaaaaaaaaa",
      "aaaaaaaaaaaaaaaa",
      "aaaaaaaaaaaaaaaa",
      "aaaaaaaaaaaaaaaa",
      "aaaaaaaaaa  aaaa",
      "aaaaaaaaaa  aaaa",
      "aaaaaaaaaa  aaaa",
      "aaaaaaaaaaccaaaa",
      "aaaaaaaaaaaaaaaa",
      "aaaaaaaaaaaaaaaa",
      "aaaaaaaaaaaaaaaa"
    ]
  ]
}