{
  "xsize": 16,
  "zsize": 16,
  "slices": [
    [
      "aSSSSSSSSSSSSSSa",
      "SbddddddddddddbS",
      "ScaaaaaaaaaaaacS",
      "ScaaaaaaaaaaaacS",
      "ScaaaaaaaaaaaacS",
      "ScaaaaaaaaaaaacS",
      "ScaalaaaaaaaaacS",
      "ScaaaaaaaaaaaacS",
      "ScaaaaaaaaaaaacS",
      "ScaaaaaaaaaaaacS",
      "Scaaaaaaaa  aacS",
      "Scaaaaaaaa  aacS",
      "Scaaaaaaaa  aacS",
      "ScaaaaaaaaccaacS",
      "SbddddddddddddbS",
      "aSSSSSSSSSSSSSSa"
    ],
    [
      "ahhahhahhahhahha",
      "h              h",
      "h              h",
      "a             ja",
      "h              h",
      "h  Cjj         h",
      "aaaaaaaaaa  aaaa",
      "h              h",
      "h         cc   h",
      "a        :dd:  a",
      "h        :  :  h",
      "h        :  :  h",
      "a        :  :  a",
      "h              h",
      "h  j           h",
      "ahhahhahhahhahha"
    ],
    [
      "ahhahhahhahhahha",
      "h              h",
      "h              h",
      "a              a",
      "h              h",
      "h    k         h",
      "aaaaaaahha  ahha",
      "h    k         h",
      "h              h",
      "a         cc   a",
      "h         dd   h",
      "h              h",
      "a              a",
      "h              h",
      "h              h",
      "ahhahhahhahhahha"
    ],
    [
      "ahhahhahhahhahha",
      "h              h",
      "h              h",
      "a              a",
      "h              h",
      "h              h",
      "aaaaaaahha  ahha",
      "h              h",
      "h              h",
      "a              a",
      "h         cc   h",
      "h         dd   h",
      "a              a",
      "h              h",
      "h              h",
      "ahhahhahhahhahha"
    ],
    [
      "aSSSSSSSSSSSSSSa",
      "SaaaaaaaaaaaaaaS",
      "SaaaaaaaaaaaaaaS",
      "SaaaaaaaaaaaaaaS",
      "SaaaaaaaaaaaaaaS",
      "SaaaaaaaaaaaaaaS",
      "SaaaaaaaaaaaaaaS",
      "SaaaaaaaaaaaaaaS",
      "Saaaaaaaaa  aaaS",
      "Saaaaaaaaa  aaaS",
      "Saaaaaaaaa  aaaS",
      "SaaaaaaaaaccaaaS",
      "SaaaaaaaaaaaaaaS",
      "SaaaaaaaaaaaaaaS",
      "SaaaaaaaaaaaaaaS",
      "aSSSSSSSSSSSSSSa"
    ],
    [
      "aaaaaaaaaaaaaaaa",
      "aaaaaaaaaaaaaaaa",
      "aaaaaaaaaaaaaaaa",
      "aaaaaaaaaaaaaaaa",
      "aaaaaaaaaaaaaaaa",
      "aaaaaaaaaaaaaaaa",
      "aaaaaaaaaaaaaaaa",
      "aaaaaaaaaaaaaaaa",
      "aaaaaaaaaaaaaaaa",
      "aaaaaaaaaa  aaaa",
      "aaaaaaaaaa  aaaa",
      "aaaaaaaaaa  aaaa",
      "aaaaaaaaaaccaaaa",
      "aaaaaaaaaaaaaaaa",
      "aaaaaaaaaaaaaaaa",
      "aaaaaaaaaaaaaaaa"
    ]
  ]
}