{
  "xsize": 16,
  "zsize": 16,
  "slices": [
    [
      "################",
      "#bddddddddddddb#",
      "#c############c#",
      "#c############c#",
      "#c############c#",
      "#c############c#",
      "#c############c#",
      "#c############c#",
      "#c############c#",
      "#c####$l$#####c#",
      "#c############c#",
      "#c############c#",
      "#c############c#",
      "#c############c#",
      "#bddddddddddddb#",
      "################"
    ],
    [
      "#aa@aaaaaaaa@aa#",
      "aWWWWWWWWWWWWWWa",
      "aWWWWWWWWWWWWWWa",
      "@WWWWWWWWWWWWWW@",
      "aWWWWWWWWWWWWWWa",
      "aaaaaaaaaaaaaaaa",
      "a              a",
      "a              a",
      "aL             a",
      "aF     l       a",
      "aF    ###::::::a",
      "a      :       a",
      "@      :   T   @",
      "a      :       a",
      "a      :       a",
      "#aa@aaaaaaaa@aa#"
    ],
    [
      "#aa@aaaaaaaa@aa#",
      "aWWWWWWWWWWWWWWa",
      "aWWWWWWWWWWWWWWa",
      "@WWWWWWWWWWWWWW@",
      "aWWWWWWWWWWWWWWa",
      "aaaaaaaaaaaaaaaa",
      "a              a",
      "a              a",
      "aL             a",
      "a      l       a",
      "a     ###::::::a",
      "a      :       a",
      "@      :       @",
      "a      :       a",
      "a      :       a",
      "#aa@aaaaaaaa@aa#"
    ],
    [
      "#aa@aaaaaaaa@aa#",
      "aWWWWWWWWWWWWWWa",
      "aWWWWWWWWWWWWWWa",
      "@WWWWWWWWWWWWWW@",
      "aWWWWWWWWWWWWWWa",
      "aaaaaaaaaaaaaaaa",
      "a              a",
      "a              a",
      "aL             a",
      "a      l       a",
      "a     ###::::::a",
      "a      :       a",
      "@      :       @",
      "a      :       a",
      "a      :       a",
      "#aa@aaaaaaaa@aa#"
    ],
    [
      "################",
      "################",
      "################",
      "################",
      "################",
      "################",
      "################",
      "################",
      "################",
      "######$l$#######",
      "################",
      "################",
      "##1#1###########",
      "################",
      "################",
      "################"
    ],
    [
      "################",
      "#bddddddddddddb#",
      "#c############c#",
      "#c############c#",
      "#c############c#",
      "#c############c#",
      "#c############c#",
      "#c############c#",
      "#c############c#",
      "#c####$l$#####c#",
      "#c############c#",
      "#c############c#",
      "#c############c#",
      "#c############c#",
      "#c############c#",
      "#bddddddddddddb#"
    ]
  ]
}