{
  "xsize": 16,
  "zsize": 16,
  "slices": [
    [
      "aaaaaaaaaaaaaaaa",
      "abddddddddddddba",
      "acaaaaaaaaaaaaca",
      "acaaaaaaaaaaaaca",
      "acaaaaaaaaaaaaca",
      "acaaaaaaaaaaaaca",
      "acaaaaaaaaaaaaca",
      "acaaaaaaaaaaaaca",
      "acaaaaaaaaaaaaca",
      "acaaaa$l$aaaaaca",
      "acaaaaaaaaaaaaca",
      "acaaaaaaaaaaaaca",
      "acaaaaaaaaaaaaca",
      "acaaaaaaaaaaaaca",
      "abddddddddddddba",
      "aaaaaaaaaaaaaaaa"
    ],
    [
      "a44@44444444@44a",
      "4WWWWWWWWWWWWWW4",
      "4WWWWWWWWWWWWWW4",
      "@WWWWWWWWWWWWWW@",
      "4WWWWWWWWWWWWWW4",
      "4444444444444444",
      "4              4",
      "4              4",
      "4L             4",
      "4F     l       4",
      "4F    aaa::::::4",
      "4      :       4",
      "@      :   T   @",
      "4      :       4",
      "4      :       4",
      "a44@44444444@44a"
    ],
    [
      "a44@44444444@44a",
      "4WWWWWWWWWWWWWW4",
      "4WWWWWWWWWWWWWW4",
      "@WWWWWWWWWWWWWW@",
      "4WWWWWWWWWWWWWW4",
      "4444444444444444",
      "4              4",
      "4              4",
      "4L             4",
      "4      l       4",
      "4     aaa::::::4",
      "4      :       4",
      "@      :       @",
      "4      :       4",
      "4      :       4",
      "a44@44444444@44a"
    ],
    [
      "a44@44444444@44a",
      "4WWWWWWWWWWWWWW4",
      "4WWWWWWWWWWWWWW4",
      "@WWWWWWWWWWWWWW@",
      "4WWWWWWWWWWWWWW4",
      "4444444444444444",
      "4              4",
      "4              4",
      "4L             4",
      "4      l       4",
      "4     aaa::::::4",
      "4      :       4",
      "@      :       @",
      "4      :       4",
      "4      :       4",
      "a44@44444444@44a"
    ],
    [
      "aaaaaaaaaaaaaaaa",
      "aaaaaaaaaaaaaaaa",
      "aaaaaaaaaaaaaaaa",
      "aaaaaaaaaaaaaaaa",
      "aaaaaaaaaaaaaaaa",
      "aaaaaaaaaaaaaaaa",
      "aaaaaaaaaaaaaaaa",
      "aaaaaaaaaaaaaaaa",
      "aaaaaaaaaaaaaaaa",
      "aaaaaa$l$aaaaaaa",
      "aaaaaaaaaaaaaaaa",
      "aaaaaaaaaaaaaaaa",
      "aa1a1aaaaaaaaaaa",
      "aaaaaaaaaaaaaaaa",
      "aaaaaaaaaaaaaaaa",
      "aaaaaaaaaaaaaaaa"
    ],
    [
      "aaaaaaaaaaaaaaaa",
      "abddddddddddddba",
      "acaaaaaaaaaaaaca",
      "acaaaaaaaaaaaaca",
      "acaaaaaaaaaaaaca",
      "acaaaaaaaaaaaaca",
      "acaaaaaaaaaaaaca",
      "acaaaaaaaaaaaaca",
      "acaaaaaaaaaaaaca",
      "acaaaa$l$aaaaaca",
      "acaaaaaaaaaaaaca",
      "acaaaaaaaaaaaaca",
      "acaaaaaaaaaaaaca",
      "acaaaaaaaaaaaaca",
      "acaaaaaaaaaaaaca",
      "abddddddddddddba"
    ]
  ]
}