{
  "xsize": 16,
  "zsize": 16,
  "slices": [
    [
      "#$$#$$#$$#$$#$$#",
      "$bddddddddddddb$",
      "$c##1#########c$",
      "#c############c#",
      "$c####1#######c$",
      "$bddddddddb###c$",
      "#c########c###c#",
      "$bddddddb#c###c$",
      "$c######c#c###c$",
      "#bdddd$l$#c###c#",
      "$c########c###c$",
      "$biiiiiiiib###c$",
      "#c############c#",
      "$c############c$",
      "$bddddddddddddb$",
      "#$$#$$#$$#$$#$$#"
    ],
    [
      "################",
      "#           LLL#",
      "#   bjb      LL#",
      "#   j#j      LL#",
      "#   bjb       L#",
      "#              #",
      "##########     #",
      "#LL      #LL   #",
      "#L       #L    #",
      "#      l #L    #",
      "#  #######    L#",
      "#    LLLL     L#",
      "#      L      L#",
      "#              #",
      "#LL            #",
      "################"
    ],
    [
      "#aa#aa#aa#aa#aa#",
      "a             La",
      "a   bkb       La",
      "#m  kCk        #",
      "a   bkb        a",
      "a       T      a",
      "####aaa###    n#",
      "aL      T#     a",
      "a        #L    a",
      "#      l #     #",
      "a  #######     a",
      "a      LL      a",
      "#m            L#",
      "a              a",
      "a L   T     T  a",
      "#aa#aa#aa#aa#aa#"
    ],
    [
      "#aa#aa#aa#aa#aa#",
      "a             La",
      "a   bob        a",
      "#   o of       #",
      "a   bob        a",
      "a              a",
      "##########     #",
      "a        #     a",
      "a        #     a",
      "#      l #     #",
      "a  #######     a",
      "a              a",
      "#             L#",
      "a              a",
      "a              a",
      "#aa#aa#aa#aa#aa#"
    ],
    [
      "################",
      "#bddddddddddddb#",
      "#c############c#",
      "#c############c#",
      "#c############c#",
      "#c############c#",
      "#c############c#",
      "#c############c#",
      "#c############c#",
      "#c####$l$#####c#",
      "#c############c#",
      "#c############c#",
      "#c############c#",
      "#c############c#",
      "#c############c#",
      "#bddddddddddddb#"
    ],
    [
      "################",
      "#bddddddddddddb#",
      "#c############c#",
      "#c############c#",
      "#c############c#",
      "#c############c#",
      "#c############c#",
      "#c############c#",
      "#c############c#",
      "#c####$l$#####c#",
      "#c############c#",
      "#c############c#",
      "#c############c#",
      "#c############c#",
      "#c############c#",
      "#bddddddddddddb#"
    ]
  ]
}