{
  "xsize": 16,
  "zsize": 16,
  "slices": [
    [
      "aaaaaaaaaaaaaaaa",
      "abddddddddddddba",
      "acaaaaaaaaaaaaca",
      "acaaaaaaaaaaaaca",
      "acaaaaaaaaaaaaca",
      "acaaaaaaaaaaaaca",
      "acaaaaaaaaaaaaca",
      "acaaaaaaaaaaaaca",
      "acaaaaaaaaaaaaca",
      "acaaaaiyiaaaaaca",
      "acaaaaaaaaaaaaca",
      "acaaaaaaaaaaaaca",
      "acaaaaaaaaaaaaca",
      "acaaaaaaaaaaaaca",
      "abddddddddddddba",
      "aaaaaaaaaaaaaaaa"
    ],
    [
      "ahhkhhhhhhhhkhha",
      "h              h",
      "h              h",
      "k              k",
      "h              h",
      "h              h",
      "h    jjjjjHHHHHh",
      "h    j   j     h",
      "h    j   j     h",
      "h      y       h",
      "h    jjjjj     h",
      "h              h",
      "k              k",
      "h              h",
      "h              h",
      "ahhkhhhhhhhhkhha"
    ],
    [
      "ahhkhhhhhhhhkhha",
      "h              h",
      "h              h",
      "k              k",
      "h              h",
      "h              h",
      "h    jjjjjHHHHHh",
      "h    j   j     h",
      "h    j   j     h",
      "h      y       h",
      "h    jjjjj     h",
      "h              h",
      "k              k",
      "h              h",
      "h              h",
      "ahhkhhhhhhhhkhha"
    ],
    [
      "ahhkhhhhhhhhkhha",
      "h              h",
      "h              h",
      "k              k",
      "h              h",
      "h              h",
      "h    jjjjjHHHHHh",
      "h    j   j     h",
      "h    j   j     h",
      "h    j y j     h",
      "h    jjjjj     h",
      "h              h",
      "k              k",
      "h              h",
      "h              h",
      "ahhkhhhhhhhhkhha"
    ],
    [
      "aaaaaaaaaaaaaaaa",
      "abddddddddddddba",
      "acaaaaaaaaaaaaca",
      "acaaaaaaaaaaaaca",
      "acaaaaaaaaaaaaca",
      "acaaaaaaaaaaaaca",
      "acaaaaaaaaaaaaca",
      "acaaaaaaaaaaaaca",
      "acaaaaaaaaaaaaca",
      "acaaaaiyiaaaaaca",
      "acaaaaaaaaaaaaca",
      "acaaaaaaaaaaaaca",
      "acaaaaaaaaaaaaca",
      "acaaaaaaaaaaaaca",
      "acaaaaaaaaaaaaca",
      "abddddddddddddba"
    ],
    [
      "aaaaaaaaaaaaaaaa",
      "abddddddddddddba",
      "acaaaaaaaaaaaaca",
      "acaaaaaaaaaaaaca",
      "acaaaaaaaaaaaaca",
      "acaaaaaaaaaaaaca",
      "acaaaaaaaaaaaaca",
      "acaaaaaaaaaaaaca",
      "acaaaaaaaaaaaaca",
      "acaaaaiyiaaaaaca",
      "acaaaaaaaaaaaaca",
      "acaaaaaaaaaaaaca",
      "acaaaaaaaaaaaaca",
      "acaaaaaaaaaaaaca",
      "acaaaaaaaaaaaaca",
      "abddddddddddddba"
    ]
  ]
}