{
  "xsize": 16,
  "zsize": 16,
  "slices": [
    [
      "aa   aaaaaa   aa",
      "abddddddddddddba",
      " aaaaaaaaaaaaaa ",
      " aaaaaaaaaaaaaa ",
      " aaaaaaaaaaaaaa ",
      "aaaaaaaaaaaaaaaa",
      "aaaaaaaaaaaaaaaa",
      "aaaaaaaaaaaaaaaa",
      "aaaaaaaaaaaaaaaa",
      "aaaaaa$l$aaaaaaa",
      "aaaaaaaaaaaaaaaa",
      " aaaaaaaaaaaaaa ",
      " aaaaaaaaaaaaaa ",
      " aaaaaaaaaaaaaa ",
      "abddddddddddddba",
      "aa   aaaaaa   aa"
    ],
    [
      "aa   aaaaaa   aa",
      "aa444a    a444aa",
      " 4  Fa        4 ",
      " 4  Fa        4 ",
      " 4   aF       4 ",
      "aa   aF       aa",
      "a    a        La",
      "a    a         a",
      "a    a         a",
      "a    a l       a",
      "aa   aaaaa aaaaa",
      " 4            4 ",
      " 4            4 ",
      " 4            4 ",
      "aa444a    a444aa",
      "aa   aaaaaa   aa"
    ],
    [
      "aa   aaaaaa   aa",
      "aa444a    a444aa",
      " 4   a        4 ",
      " 4   a        4 ",
      " 4   4        4 ",
      "aa   4        aa",
      "a    4         a",
      "a    4         a",
      "a   Ta         a",
      "a    a l       a",
      "aa   aaaaa aaaaa",
      " 4     T      4 ",
      " 4            4 ",
      " 4            4 ",
      "aa444a    a444aa",
      "aa   aaaaaa   aa"
    ],
    [
      "aa   aaaaaa   aa",
      "aa444a    a444aa",
      " 4   a        4 ",
      " 4   a        4 ",
      " 4   a        4 ",
      "aa   a        aa",
      "a    a         a",
      "a    a         a",
      "a    a         a",
      "a    a l       a",
      "aa   aaaaaaaaaaa",
      " 4            4 ",
      " 4            4 ",
      " 4            4 ",
      "aa444a    a444aa",
      "aa   aaaaaa   aa"
    ],
    [
      "aa   aaaaaa   aa",
      "aaaaaaaaaaaaaaaa",
      " aaaaaaaaaaaaaa ",
      " aaaaaaaaaaaaaa ",
      " aaaaaaaaaaaaaa ",
      "aaaaaaaaaaaaaaaa",
      "aaaaaaaaaaaaaaaa",
      "aaaaaaaaaaaaaaaa",
      "aaaaaaaaaaaaaaaa",
      "aaaaaa$l$aaaaaaa",
      "aaaaaaaaaaaaaaaa",
      " aaaaaaaaaaaaaa ",
      " aaaaaaaaaaaaaa ",
      " aaaaaaaaaaaaaa ",
      "aaaaaaaaaaaaaaaa",
      "aa   aaaaaa   aa"
    ],
    [
      "aa   aaaaaa   aa",
      "aaaaaaaaaaaaaaaa",
      " aaaaaaaaaaaaaa ",
      " aaaaaaaaaaaaaa ",
      " aaaaaaaaaaaaaa ",
      "aaaaaaaaaaaaaaaa",
      "aaaaaaaaaaaaaaaa",
      "aaaaaaaaaaaaaaaa",
      "aaaaaaaaaaaaaaaa",
      "aaaaaa$l$aaaaaaa",
      "aaaaaaaaaaaaaaaa",
      " aaaaaaaaaaaaaa ",
      " aaaaaaaaaaaaaa ",
      " aaaaaaaaaaaaaa ",
      "aaaaaaaaaaaaaaaa",
      "aa   aaaaaa   aa"
    ]
  ]
}