{
  "xsize": 16,
  "zsize": 16,
  "slices": [
    [
      "aSSSSSSSSSSSSSSa",
      "SbddddddddddddbS",
      "ScaaaaaaaaaaaacS",
      "ScaaaaaaaaaaaacS",
      "ScaaaaaaaaaaaacS",
      "ScaaaaaaaaaaaacS",
      "ScaaaalaaaaaaacS",
      "ScaaaaaaaaaaaacS",
      "ScaaaaaaaaaaaacS",
      "ScaaaaaaaaaaaacS",
      "Scaaaaaaaa  aacS",
      "Scaaaaaaaa  aacS",
      "Scaaaaaaaa  aacS",
      "ScaaaaaaaaccaacS",
      "SbddddddddddddbS",
      "aSSSSSSSSSSSSSSa"
    ],
    [
      "ahhahhahhahhahha",
      "h     a        h",
      "h     a        h",
      "ax             a",
      "h     a        h",
      "h     a        h",
      "aaaaaaa        a",
      "h    Sa        h",
      "h    Sa   cc   h",
      "a    Sa  HddH  a",
      "h     a  H  H  h",
      "h        H  H  h",
      "a    ja  H  H  a",
      "h    ja        h",
      "h     a        h",
      "ahhahhahhahhahha"
    ],
    [
      "ahhahhahhahhahha",
      "h     a        h",
      "h     a        h",
      "a              a",
      "h     a        h",
      "h     a        h",
      "aaHHHaak       a",
      "h     a        h",
      "h    ka        h",
      "a    ka   cc   a",
      "h     a   dd   h",
      "h              h",
      "a     a        a",
      "h     a        h",
      "h     a        h",
      "ahhahhahhahhahha"
    ],
    [
      "ahhahhahhahhahha",
      "h     a        h",
      "h     a        h",
      "a     a        a",
      "h     a        h",
      "h     a        h",
      "aaaaaaa        a",
      "h     a        h",
      "h     a        h",
      "a     a        a",
      "h     a   cc   h",
      "h     a   dd   h",
      "a     a        a",
      "h     a        h",
      "h     a        h",
      "ahhahhahhahhahha"
    ],
    [
      "aSSSSSSSSSSSSSSa",
      "SaaaaaaaaaaaaaaS",
      "SaaaaaaaaaaaaaaS",
      "SaaaaaaaaaaaaaaS",
      "SaaaaaaaaaaaaaaS",
      "SaaaaaaaaaaaaaaS",
      "SaaaaaaaaaaaaaaS",
      "SaaaaaaaaaaaaaaS",
      "Saaaaaaaaa  aaaS",
      "Saaaaaaaaa  aaaS",
      "Saaaaaaaaa  aaaS",
      "SaaaaaaaaaccaaaS",
      "SaaaaaaaaaaaaaaS",
      "SaaaaaaaaaaaaaaS",
      "SaaaaaaaaaaaaaaS",
      "aSSSSSSSSSSSSSSa"
    ],
    [
      "aaaaaaaaaaaaaaaa",
      "aaaaaaaaaaaaaaaa",
      "aaaaaaaaaaaaaaaa",
      "aaaaaaaaaaaaaaaa",
      "aaaaaaaaaaaaaaaa",
      "aaaaaaaaaaaaaaaa",
      "aaaaaaaaaaaaaaaa",
      "aaaaaaaaaaaaaaaa",
      "aaaaaaaaaaaaaaaa",
      "aaaaaaaaaa  aaaa",
      "aaaaaaaaaa  aaaa",
      "aaaaaaaaaa  aaaa",
      "aaaaaaaaaaccaaaa",
      "aaaaaaaaaaaaaaaa",
      "aaaaaaaaaaaaaaaa",
      "aaaaaaaaaaaaaaaa"
    ]
  ]
}