{
  "xsize": 16,
  "zsize": 16,
  "slices": [
    [
      "aSSSSSSSSSSSSSSa",
      "SbddddddddddddbS",
      "ScaaaaaaaaaaaacS",
      "ScaaaaaaaaaalacS",
      "ScaaaaaaaaaaaacS",
      "ScalaaaaaaaaaacS",
      "ScaaaaaaaaaaaacS",
      "ScaaaaiaaaaaaacS",
      "ScalaaiaaaaaaacS",
      "Scaaaaaaaa  aacS",
      "Scaaaaaaaa  aacS",
      "Scalaaaaaa  aacS",
      "ScaaaaaaaaaQaacS",
      "ScaaaaaaaaaaaacS",
      "SbddddddddddddbS",
      "aSSSSSSSSSSSSSSa"
    ],
    [
      "ahhahhahhahhahha",
      "h     a    jjjjh",
      "h j   a   jjjjjh",
      "ajj   a  jjjjjja",
      "hjjj  a        h",
      "hjjjj a     jj h",
      "a jj  a        a",
      "h  j       Q   h",
      "h jjj     aa   h",
      "ajj   a  NaaM  a",
      "h     a  H  H  h",
      "h  jj a  H  H  h",
      "a   jja  H  H  a",
      "h jjjjaj       h",
      "hjjxjjajj      h",
      "ahhahhahhahhahha"
    ],
    [
      "ahhahhahhahhahha",
      "h  r  a  r  jjjh",
      "h     a    jjk h",
      "aj    a    k  sa",
      "hjj   a        h",
      "h j   a      j h",
      "aq    aq       a",
      "h              h",
      "h          Q   h",
      "a     aq  aa  sa",
      "h     a   aa   h",
      "h     a        h",
      "aq  k a        a",
      "h     ak       h",
      "hk jj aj    p  h",
      "ahhahhahhahhahha"
    ],
    [
      "ahhahhahhahhahha",
      "h     a     jj h",
      "h     a        h",
      "a     a        a",
      "hjk   a        h",
      "h     a        h",
      "a     a        a",
      "h     a        h",
      "h     a        h",
      "a     a    Q   a",
      "h     a   aa   h",
      "h     a   aa   h",
      "a     a        a",
      "h     a        h",
      "h  j  a        h",
      "ahhahhahhahhahha"
    ],
    [
      "aSSSSSSSSSSSSSSa",
      "SaaaaaaaaaaaaaaS",
      "SaaaaaaaaaaaaaaS",
      "SaaaaaaaaaaaaaaS",
      "SaaaaaaaaaaaaaaS",
      "SaaaaaaaaaaaaaaS",
      "SaaaaaaaaaaaaaaS",
      "Saaaaaaaaa  aaaS",
      "Saaaaaaaaa  aaaS",
      "Saaaaaaaaa  aaaS",
      "SaaaaaaaaaaQaaaS",
      "SaaaaaaaaaaaaaaS",
      "SaaaaaaaaaaaaaaS",
      "SaaaaaaaaaaaaaaS",
      "SaaaaaaaaaaaaaaS",
      "aSSSSSSSSSSSSSSa"
    ],
    [
      "aaaaaaaaaaaaaaaa",
      "aaaaaaaaaaaaaaaa",
      "aaaaaaaaaaaaaaaa",
      "aaaaaaaaaaaaaaaa",
      "aaaaaaaaaaaaaaaa",
      "aaaaaaaaaaaaaaaa",
      "aaaaaaaaaaaaaaaa",
      "aaaaaaaaaaaaaaaa",
      "aaaaaaaaaa  aaaa",
      "aaaaaaaaaa  aaaa",
      "aaaaaaaaaa  aaaa",
      "aaaaaaaaaaaQaaaa",
      "aaaaaaaaaaaaaaaa",
      "aaaaaaaaaaaaaaaa",
      "aaaaaaaaaaaaaaaa",
      "aaaaaaaaaaaaaaaa"
    ]
  ]
}