{
  "xsize": 16,
  "zsize": 16,
  "slices": [
    [
      "aaaaaaaaaaaaaaaa",
      "abddddddddddddba",
      "acaaaaaaaaaaaaca",
      "acaaaaaaaaaaaaca",
      "acaaaaaaaaaaaaca",
      "acaaaaaaaaaaaaca",
      "acaaaaaaaaaaaaca",
      "acaaaaaaaaaaaaca",
      "acaaaaaaaaaaaaca",
      "acaaaaiyiaaaaaca",
      "acaaaaaaaaaaaaca",
      "acaaaaaaaaaaaaca",
      "acaaaaaaaaaaaaca",
      "acaaaaaaaaaaaaca",
      "abddddddddddddba",
      "aaaaaaaaaaaaaaaa"
    ],
    [
      "aaGGGaaaaaaGGGaa",
      "aaaaaa    aaaaaa",
      "Gaza        azaG",
      "Gaza        azaG",
      "Gaza        azaG",
      "aaaa        aaaa",
      "a              a",
      "aj            ja",
      "aj            ja",
      "a      y       a",
      "aa    aaa     aa",
      "Ga            aG",
      "Ga    E E     aG",
      "Ga            aG",
      "aaaaaa    aaaaaa",
      "aaGGGaaaaaaGGGaa"
    ],
    [
      "aa   aaaaaa   aa",
      "aahhha    ahhhaa",
      " hk          kh ",
      " hk          kh ",
      " hk          kh ",
      "aa            aa",
      "a              a",
      "a             ja",
      "a             ja",
      "a      y       a",
      "aa    aaa     aa",
      " h            h ",
      " h    z z     h ",
      " h            h ",
      "aahhha    ahhhaa",
      "aa   aaaaaa   aa"
    ],
    [
      "aa   aaaaaa   aa",
      "aahhha    ahhhaa",
      " h            h ",
      " h            h ",
      " h            h ",
      "aak          kaa",
      "a              a",
      "a              a",
      "a              a",
      "a      y       a",
      "aak   aaa    kaa",
      " h            h ",
      " h            h ",
      " h            h ",
      "aahhha    ahhhaa",
      "aa   aaaaaa   aa"
    ],
    [
      "aa   aaaaaa   aa",
      "aahhha    ahhhaa",
      " h            h ",
      " h            h ",
      " h            h ",
      "aa            aa",
      "a              a",
      "a              a",
      "a              a",
      "a      y       a",
      "aa    aaa     aa",
      " h            h ",
      " h            h ",
      " h            h ",
      "aahhha    ahhhaa",
      "aa   aaaaaa   aa"
    ],
    [
      "aaGGGaaaaaaGGGaa",
      "aaaaaaaaaaaaaaaa",
      "GaaaaaaaaaaaaaaG",
      "GaaaaaaaaaaaaaaG",
      "GaaaaaaaaaaaaaaG",
      "aaaaaaaaaaaaaaaa",
      "aaaaaaaaaaaaaaaa",
      "aaaaaaaaaaaaaaaa",
      "aaaaaaaaaaaaaaaa",
      "aaaaaaiyiaaaaaaa",
      "aaaaaaaaaaaaaaaa",
      "GaaaaaaaaaaaaaaG",
      "GaaaaaaaaaaaaaaG",
      "GaaaaaaaaaaaaaaG",
      "aaaaaaaaaaaaaaaa",
      "aaGGGaaaaaaGGGaa"
    ]
  ]
}