{
  "xsize": 16,
  "zsize": 16,
  "slices": [
    [
      "################",
      "#bddddddddddddb#",
      "#c############c#",
      "#c############c#",
      "#c############c#",
      "#c############c#",
      "#c############c#",
      "#c############c#",
      "#c############c#",
      "#c####$l$#####c#",
      "#c############c#",
      "#c############c#",
      "#c############c#",
      "#c############c#",
      "#bddddddddddddb#",
      "################"
    ],
    [
      "##___######___##",
      "######    ######",
      "_#            #_",
      "_#            #_",
      "_#            #_",
      "##            ##",
      "#              #",
      "#              #",
      "#              #",
      "#      l       #",
      "##    ###     ##",
      "_#            #_",
      "_#            #_",
      "_#            #_",
      "######    ######",
      "##___######___##"
    ],
    [
      "##   ######   ##",
      "##aaa#    #aaa##",
      " a            a ",
      " a            a ",
      " a            a ",
      "##            ##",
      "#              #",
      "#              #",
      "#              #",
      "#      l       #",
      "##    ###     ##",
      " a            a ",
      " a            a ",
      " a            a ",
      "##aaa#    #aaa##",
      "##   ######   ##"
    ],
    [
      "##   ######   ##",
      "##aaa#    #aaa##",
      " a            a ",
      " a            a ",
      " a            a ",
      "##T          T##",
      "#              #",
      "#              #",
      "#              #",
      "#      l       #",
      "##T   ###    T##",
      " a            a ",
      " a            a ",
      " a            a ",
      "##aaa#    #aaa##",
      "##   ######   ##"
    ],
    [
      "##   ######   ##",
      "##aaa#    #aaa##",
      " a            a ",
      " a            a ",
      " a            a ",
      "##            ##",
      "#              #",
      "#              #",
      "#              #",
      "#      l       #",
      "##    ###     ##",
      " a            a ",
      " a            a ",
      " a            a ",
      "##aaa#    #aaa##",
      "##   ######   ##"
    ],
    [
      "##===######===##",
      "################",
      "=##############=",
      "=##############=",
      "=##############=",
      "################",
      "################",
      "################",
      "################",
      "######$l$#######",
      "################",
      "=##############=",
      "=##############=",
      "=##############=",
      "################",
      "##===######===##"
    ]
  ]
}