{
  "xsize": 16,
  "zsize": 16,
  "slices": [
    [
      "#$$#$$#$$#$$#$$#",
      "$bddddddddddddb$",
      "$c############c$",
      "#c############c#",
      "$c##e######e##c$",
      "$c############c$",
      "#c############c#",
      "$c############c$",
      "$c############c$",
      "#c####$l$#####c#",
      "$c############c$",
      "$c##e######e##c$",
      "#c############c#",
      "$c############c$",
      "$bddddddddddddb$",
      "#$$#$$#$$#$$#$$#"
    ],
    [
      "################",
      "# iii          #",
      "#  ii  i  ii   #",
      "#  i    ii i   #",
      "# iiiii  i ii  #",
      "#iiii iiii i   #",
      "#   i i        #",
      "#  ii         i#",
      "#  ii        ii#",
      "#      l      i#",
      "#     ### i    #",
      "# i i    iiii  #",
      "#  ii     ii   #",
      "#              #",
      "#              #",
      "################"
    ],
    [
      "#aa#aa#aa#aa#aa#",
      "a iii j     j  a",
      "a ii      k    a",
      "#m i     i i   #",
      "a i  k      i  a",
      "a     i        a",
      "#             n#",
      "a             ia",
      "a  i          ia",
      "#m     l       #",
      "a     ### k    a",
      "a         i    a",
      "#   k         n#",
      "a              a",
      "a  o     o     a",
      "#aa#aa#aa#aa#aa#"
    ],
    [
      "#aa#aa#aa#aa#aa#",
      "a ik           a",
      "a              a",
      "#  i           #",
      "a              a",
      "a              a",
      "#              #",
      "a              a",
      "a  k          ka",
      "#      l       #",
      "a     ###      a",
      "a              a",
      "#              #",
      "a              a",
      "a              a",
      "#aa#aa#aa#aa#aa#"
    ],
    [
      "################",
      "#bddddddddddddb#",
      "#c############c#",
      "#c############c#",
      "#c############c#",
      "#c############c#",
      "#c############c#",
      "#c############c#",
      "#c############c#",
      "#c####$l$#####c#",
      "#c############c#",
      "#c############c#",
      "#c############c#",
      "#c############c#",
      "#c############c#",
      "#bddddddddddddb#"
    ],
    [
      "################",
      "#bddddddddddddb#",
      "#c############c#",
      "#c############c#",
      "#c############c#",
      "#c############c#",
      "#c############c#",
      "#c############c#",
      "#c############c#",
      "#c####$l$#####c#",
      "#c############c#",
      "#c############c#",
      "#c############c#",
      "#c############c#",
      "#c############c#",
      "#bddddddddddddb#"
    ]
  ]
}