{
  "xsize": 16,
  "zsize": 16,
  "slices": [
    [
      "aSSSSSSSSSSSSSSa",
      "SbddddddddddddbS",
      "ScaaaaaaaaaaaacS",
      "ScaaaaaaaaaaaacS",
      "ScaaaaaaaaaaaacS",
      "ScaaaaaaaaaaaacS",
      "ScaaaaaaaaaaaacS",
      "ScaaaaaaaaaaaacS",
      "ScaaaaaaaaaaaacS",
      "ScaaaaaaaaaaaacS",
      "Scaaaaaaaa  aacS",
      "Scaaaaaaaa  aacS",
      "Scaaaaaaaa  aacS",
      "ScaaaaaaaaccaacS",
      "SbddddddddddddbS",
      "aSSSSSSSSSSSSSSa"
    ],
    [
      "ahhahhahhahhahha",
      "h     a  j     h",
      "h     j        h",
      "aj    j        a",
      "h     j        h",
      "h     j        h",
      "aj    a        a",
      "h              h",
      "h         cc   h",
      "aj    a  HddH  a",
      "h     j  H  H  h",
      "h     j  H  H  h",
      "a     j  H  H  a",
      "h     j        h",
      "h     a        h",
      "ahhahhahhahhahha"
    ],
    [
      "ahhahhahhahhahha",
      "h     a        h",
      "h     j        h",
      "a     j        a",
      "h     j        h",
      "h     j        h",
      "a     a        a",
      "h              h",
      "h              h",
      "a     a   cc   a",
      "h     j   dd   h",
      "h     j        h",
      "a     j        a",
      "h     j        h",
      "h     a        h",
      "ahhahhahhahhahha"
    ],
    [
      "ahhahhahhahhahha",
      "h     a        h",
      "h     j        h",
      "a     j        a",
      "h     j        h",
      "h     j        h",
      "a     a        a",
      "h     a        h",
      "h     a        h",
      "a     a        a",
      "h     j   cc   h",
      "h     j   dd   h",
      "a     j        a",
      "h     j        h",
      "h     a        h",
      "ahhahhahhahhahha"
    ],
    [
      "aSSSSSSSSSSSSSSa",
      "SaaaaaaaaaaaaaaS",
      "SaaaaaaaaaaaaaaS",
      "SaaaaaaaaaaaaaaS",
      "SaaaaaaaaaaaaaaS",
      "SaaaaaaaaaaaaaaS",
      "SaaaaaaaaaaaaaaS",
      "SaaaaaaaaaaaaaaS",
      "Saaaaaaaaa  aaaS",
      "Saaaaaaaaa  aaaS",
      "Saaaaaaaaa  aaaS",
      "SaaaaaaaaaccaaaS",
      "SaaaaaaaaaaaaaaS",
      "SaaaaaaaaaaaaaaS",
      "SaaaaaaaaaaaaaaS",
      "aSSSSSSSSSSSSSSa"
    ],
    [
      "aaaaaaaaaaaaaaaa",
      "aaaaaaaaaaaaaaaa",
      "aaaaaaaaaaaaaaaa",
      "aaaaaaaaaaaaaaaa",
      "aaaaaaaaaaaaaaaa",
      "aaaaaaaaaaaaaaaa",
      "aaaaaaaaaaaaaaaa",
      "aaaaaaaaaaaaaaaa",
      "aaaaaaaaaaaaaaaa",
      "aaaaaaaaaa  aaaa",
      "aaaaaaaaaa  aaaa",
      "aaaaaaaaaa  aaaa",
      "aaaaaaaaaaccaaaa",
      "aaaaaaaaaaaaaaaa",
      "aaaaaaaaaaaaaaaa",
      "aaaaaaaaaaaaaaaa"
    ]
  ]
}