{
  "xsize": 16,
  "zsize": 16,
  "slices": [
    [
      "aaaaaaaaaaaaaaaa",
      "abddddddddddddba",
      "acaaaaaaaaaaaaca",
      "acaaaaaaaaaaaaca",
      "acaaaaaaaaaaaaca",
      "acaaaaaaaaaaaaca",
      "acaaaaaaaaaaaaca",
      "acaaaaaaaaaaaaca",
      "acaaaaaaaaaaaaca",
      "acaaaliyilaaaaca",
      "acaaaaaaaaaaaaca",
      "acaaaaaaaaaaaaca",
      "acaaaaaaaaaaaaca",
      "acaaaaaaaaaaaaca",
      "abddddddddddddba",
      "aaaaaaaaaaaaaaaa"
    ],
    [
      "ahhahhhhhhhhahha",
      "h   jj         h",
      "h              h",
      "a              a",
      "h              h",
      "h              h",
      "h    aa aa     h",
      "h    a   a     h",
      "h    a   a     h",
      "h    a y a     h",
      "h  jjaaaaajj   h",
      "h      xj      h",
      "a              a",
      "h              h",
      "h              h",
      "ahhahhhhhhhhahha"
    ],
    [
      "ahhahhhhhhhhahha",
      "h   jj         h",
      "h              h",
      "a              a",
      "h              h",
      "h              h",
      "h    aa aa     h",
      "h    a  ka     h",
      "h    a   a     h",
      "h    a y a     h",
      "h  jjaaaaajj   h",
      "h              h",
      "a              a",
      "h              h",
      "h              h",
      "ahhahhhhhhhhahha"
    ],
    [
      "ahhahhhhhhhhahha",
      "h              h",
      "h              h",
      "a              a",
      "h              h",
      "h              h",
      "h    aaaaa     h",
      "h    a   a     h",
      "h    a   a     h",
      "h    a y a     h",
      "h  jjaaaaajj   h",
      "h              h",
      "a              a",
      "h              h",
      "h              h",
      "ahhahhhhhhhhahha"
    ],
    [
      "aaaaaaaaaaaaaaaa",
      "abddddddddddddba",
      "acaaaaaaaaaaaaca",
      "acaaaaaaaaaaaaca",
      "acaaaaaaaaaaaaca",
      "acaaaaaaaaaaaaca",
      "acaaaaaaaaaaaaca",
      "acaaaaaaaaaaaaca",
      "acaaaaaaaaaaaaca",
      "acaaaaiyiaaaaaca",
      "acaaaaaaaaaaaaca",
      "acaaaaaaaaaaaaca",
      "acaaaaaaaaaaaaca",
      "acaaaaaaaaaaaaca",
      "acaaaaaaaaaaaaca",
      "abddddddddddddba"
    ],
    [
      "aaaaaaaaaaaaaaaa",
      "abddddddddddddba",
      "acaaaaaaaaaaaaca",
      "acaaaaaaaaaaaaca",
      "acaaaaaaaaaaaaca",
      "acaaaaaaaaaaaaca",
      "acaaaaaaaaaaaaca",
      "acaaaaaaaaaaaaca",
      "acaaaaaaaaaaaaca",
      "acaaaaiyiaaaaaca",
      "acaaaaaaaaaaaaca",
      "acaaaaaaaaaaaaca",
      "acaaaaaaaaaaaaca",
      "acaaaaaaaaaaaaca",
      "acaaaaaaaaaaaaca",
      "abddddddddddddba"
    ]
  ]
}