{
  "xsize": 16,
  "zsize": 16,
  "slices": [
    [
      "aSSSSSSSSSSSSSSa",
      "SbddddddddddddbS",
      "ScaaaaaaaaaaaacS",
      "ScaaaaaaaaaaaacS",
      "ScaaaaaaaaaaaacS",
      "ScaaaaaaaaaaaacS",
      "ScaaaaaaaaaaaacS",
      "ScaaaaaaaaaaaacS",
      "ScaaaaaaaaaaaacS",
      "ScaaaaaaaaaaaacS",
      "Scaaaaaaaa  aacS",
      "Scaaaaaaaa  aacS",
      "Scaaaaaaaa  aacS",
      "ScaaaaaaaaccaacS",
      "SbddddddddddddbS",
      "aSSSSSSSSSSSSSSa"
    ],
    [
      "ahhahhahhahhahha",
      "h     a  j     h",
      "h     Q        h",
      "aj    Q        a",
      "h     Q        h",
      "h     Q        h",
      "aj    a        a",
      "h              h",
      "h         cc   h",
      "aj    a  :dd:  a",
      "h     Q  :  :  h",
      "h     Q  :  :  h",
      "a     Q  :  :  a",
      "h     Q        h",
      "h     a        h",
      "ahhahhahhahhahha"
    ],
    [
      "ahhahhahhahhahha",
      "h     a        h",
      "h     Q        h",
      "a     Q        a",
      "h     Q        h",
      "h     Q        h",
      "a     a        a",
      "h              h",
      "h              h",
      "a     a   cc   a",
      "h     Q   dd   h",
      "h     Q        h",
      "a     Q        a",
      "h     Q        h",
      "h     a        h",
      "ahhahhahhahhahha"
    ],
    [
      "ahhahhahhahhahha",
      "h     a        h",
      "h     Q        h",
      "a     Q        a",
      "h     Q        h",
      "h     Q        h",
      "a     a        a",
      "h     a        h",
      "h     a        h",
      "a     a        a",
      "h     Q   cc   h",
      "h     Q   dd   h",
      "a     Q        a",
      "h     Q        h",
      "h     a        h",
      "ahhahhahhahhahha"
    ],
    [
      "aSSSSSSSSSSSSSSa",
      "SaaaaaaaaaaaaaaS",
      "SaaaaaaaaaaaaaaS",
      "SaaaaaaaaaaaaaaS",
      "SaaaaaaaaaaaaaaS",
      "SaaaaaaaaaaaaaaS",
      "SaaaaaaaaaaaaaaS",
      "SaaaaaaaaaaaaaaS",
      "Saaaaaaaaa  aaaS",
      "Saaaaaaaaa  aaaS",
      "Saaaaaaaaa  aaaS",
      "SaaaaaaaaaccaaaS",
      "SaaaaaaaaaaaaaaS",
      "SaaaaaaaaaaaaaaS",
      "SaaaaaaaaaaaaaaS",
      "aSSSSSSSSSSSSSSa"
    ],
    [
      "aaaaaaaaaaaaaaaa",
      "aaaaaaaaaaaaaaaa",
      "aaaaaaaaaaaaaaaa",
      "aaaaaaaaaaaaaaaa",
      "aaaaaaaaaaaaaaaa",
      "aaaaaaaaaaaaaaaa",
      "aaaaaaaaaaaaaaaa",
      "aaaaaaaaaaaaaaaa",
      "aaaaaaaaaaaaaaaa",
      "aaaaaaaaaa  aaaa",
      "aaaaaaaaaa  aaaa",
      "aaaaaaaaaa  aaaa",
      "aaaaaaaaaaccaaaa",
      "aaaaaaaaaaaaaaaa",
      "aaaaaaaaaaaaaaaa",
      "aaaaaaaaaaaaaaaa"
    ]
  ]
}