{
  "xsize": 16,
  "zsize": 16,
  "slices": [
    [
      "aaaaaaaaaaaaaaaa",
      "abddddddddddddba",
      "acaaaaaaaaaaaaca",
      "acaaaaaaaaaaaaca",
      "acaaaaaaaaaaaaca",
      "acaaaaaaaaaaaaca",
      "acaaaaaaaaaaaaca",
      "acaaaaaaaaaaaaca",
      "acaaaaaaaaaaaaca",
      "acaaaaiyiaaaaaca",
      "acaaaaaaaaaaaaca",
      "acaaaaaaaaaaaaca",
      "acaaaaaaaaaaaaca",
      "acaaaaaaaaaaaaca",
      "abddddddddddddba",
      "aaaaaaaaaaaaaaaa"
    ],
    [
      "ahhahhhhhhhhahha",
      "hFFFFFFFFFFFFFFh",
      "hFFFFFFFFFFFFFFh",
      "aFFFFFFFFFFFFFFa",
      "hFFFFFFFFFFFFFFh",
      "hhhhhhhhhhhhhhhh",
      "h              h",
      "h              h",
      "hj             h",
      "hj     y       h",
      "hj    aaaHHHHHHh",
      "h      H       h",
      "a      H   k   a",
      "h      H       h",
      "h      H       h",
      "ahhahhhhhhhhahha"
    ],
    [
      "ahhahhhhhhhhahha",
      "hFFFFFFFFFFFFFFh",
      "hFFFFFFFFFFFFFFh",
      "aFFFFFFFFFFFFFFa",
      "hFFFFFFFFFFFFFFh",
      "hhhhhhhhhhhhhhhh",
      "h              h",
      "h              h",
      "hj             h",
      "h      y       h",
      "h     aaaHHHHHHh",
      "h      H       h",
      "a      H       a",
      "h      H       h",
      "h      H       h",
      "ahhahhhhhhhhahha"
    ],
    [
      "ahhahhhhhhhhahha",
      "hFFFFFFFFFFFFFFh",
      "hFFFFFFFFFFFFFFh",
      "aFFFFFFFFFFFFFFa",
      "hFFFFFFFFFFFFFFh",
      "hhhhhhhhhhhhhhhh",
      "h              h",
      "h              h",
      "hj             h",
      "h      y       h",
      "h     aaaHHHHHHh",
      "h      H       h",
      "a      H       a",
      "h      H       h",
      "h      H       h",
      "ahhahhhhhhhhahha"
    ],
    [
      "aaaaaaaaaaaaaaaa",
      "aaaaaaaaaaaaaaaa",
      "aaaaaaaaaaaaaaaa",
      "aaaaaaaaaaaaaaaa",
      "aaaaaaaaaaaaaaaa",
      "aaaaaaaaaaaaaaaa",
      "aaaaaaaaaaaaaaaa",
      "aaaaaaaaaaaaaaaa",
      "aaaaaaaaaaaaaaaa",
      "aaaaaaiyiaaaaaaa",
      "aaaaaaaaaaaaaaaa",
      "aaaaaaaaaaaaaaaa",
      "aalalaaaaaaaaaaa",
      "aaaaaaaaaaaaaaaa",
      "aaaaaaaaaaaaaaaa",
      "aaaaaaaaaaaaaaaa"
    ],
    [
      "aaaaaaaaaaaaaaaa",
      "abddddddddddddba",
      "acaaaaaaaaaaaaca",
      "acaaaaaaaaaaaaca",
      "acaaaaaaaaaaaaca",
      "acaaaaaaaaaaaaca",
      "acaaaaaaaaaaaaca",
      "acaaaaaaaaaaaaca",
      "acaaaaaaaaaaaaca",
      "acaaaaiyiaaaaaca",
      "acaaaaaaaaaaaaca",
      "acaaaaaaaaaaaaca",
      "acaaaaaaaaaaaaca",
      "acaaaaaaaaaaaaca",
      "acaaaaaaaaaaaaca",
      "abddddddddddddba"
    ]
  ]
}