{
  "xsize": 16,
  "zsize": 16,
  "slices": [
    [
      "aaaaaaaaaaaaaaaa",
      "abddddddddddddba",
      "acaaaaaaaaaaaaca",
      "acaaaaaaaaaaaaca",
      "acaaaaaaaaaaaaca",
      "acaaaaaaaaaaaaca",
      "acaaaaaaaaaaaaca",
      "acaaaaaaaaaaaaca",
      "acaaaaaaaaaaaaca",
      "acaaaa$l$aaaaaca",
      "acaaaaaaaaaaaaca",
      "acaaaaaaaaaaaaca",
      "acaaaaaaaaaaaaca",
      "acaaaaaaaaaaaaca",
      "abddddddddddddba",
      "aaaaaaaaaaaaaaaa"
    ],
    [
      "aa___aaaaaa___aa",
      "aaaaaa    aaaaaa",
      "_aF          Fa_",
      "_a            a_",
      "_aF          Fa_",
      "aaaaaaa  aaaaaaa",
      "a              a",
      "a .          . a",
      "a .          . a",
      "a      l       a",
      "aa    aaa     aa",
      "_a            a_",
      "_a            a_",
      "_a            a_",
      "aaaaaa    aaaaaa",
      "aa___aaaaaa___aa"
    ],
    [
      "aa   aaaaaa   aa",
      "aa444a    a444aa",
      " 4            4 ",
      " 4            4 ",
      " 4            4 ",
      "aa4444a  a4444aa",
      "a              a",
      "a -          - a",
      "a -          - a",
      "a      l       a",
      "aa    aaa     aa",
      " 4            4 ",
      " 4            4 ",
      " 4            4 ",
      "aa444a    a444aa",
      "aa   aaaaaa   aa"
    ],
    [
      "aa   aaaaaa   aa",
      "aa444a    a444aa",
      " 4            4 ",
      " 4            4 ",
      " 4    T  T    4 ",
      "aa4444aaaa4444aa",
      "a              a",
      "a              a",
      "a              a",
      "a      l       a",
      "aaT   aaa    Taa",
      " 4            4 ",
      " 4            4 ",
      " 4            4 ",
      "aa444a    a444aa",
      "aa   aaaaaa   aa"
    ],
    [
      "aa   aaaaaa   aa",
      "aa444a    a444aa",
      " 4            4 ",
      " 4            4 ",
      " 4            4 ",
      "aaaaaaaaaaaaaaaa",
      "a              a",
      "a              a",
      "a              a",
      "a      l       a",
      "aa    aaa     aa",
      " 4            4 ",
      " 4            4 ",
      " 4            4 ",
      "aa444a    a444aa",
      "aa   aaaaaa   aa"
    ],
    [
      "aa===aaaaaa===aa",
      "aaaaaaaaaaaaaaaa",
      "=aaaaaaaaaaaaaa=",
      "=aaaaaaaaaaaaaa=",
      "=aaaaaaaaaaaaaa=",
      "aaaaaaaaaaaaaaaa",
      "aaaaaaaaaaaaaaaa",
      "aaaaaaaaaaaaaaaa",
      "aaaaaaaaaaaaaaaa",
      "aaaaaa$l$aaaaaaa",
      "aaaaaaaaaaaaaaaa",
      "=aaaaaaaaaaaaaa=",
      "=aaaaaaaaaaaaaa=",
      "=aaaaaaaaaaaaaa=",
      "aaaaaaaaaaaaaaaa",
      "aa===aaaaaa===aa"
    ]
  ]
}