{
  "xsize": 16,
  "zsize": 16,
  "slices": [
    [
      "################",
      "#bddddddddddddb#",
      "#c############c#",
      "#c############c#",
      "#c############c#",
      "#c############c#",
      "#c############c#",
      "#c############c#",
      "#c############c#",
      "#c####$l$#####c#",
      "#c########1###c#",
      "#c############c#",
      "#c############c#",
      "#c############c#",
      "#bddddddddddddb#",
      "################"
    ],
    [
      "#aa@aaaaaaaa@aa#",
      "a  #        #  a",
      "a  #F       #  a",
      "@  #F      L#  @",
      "a  #D      L#  a",
      "a  #        #  a",
      "a              a",
      "a  #        #  a",
      "a  #        #  a",
      "a  #   l    #  a",
      "a  ##########  a",
      "a              a",
      "@              @",
      "a              a",
      "a     F        a",
      "#aa@aaaaaaaa@aa#"
    ],
    [
      "#aa@aaaaaaaa@aa#",
      "a  #        #  a",
      "a  #        #  a",
      "@  #       L#  @",
      "a  #*      L#  a",
      "a  #        #  a",
      "a              a",
      "a  #        #  a",
      "a  #        #  a",
      "a  #   l    #  a",
      "a  ##########  a",
      "a       T      a",
      "@              @",
      "a              a",
      "a              a",
      "#aa@aaaaaaaa@aa#"
    ],
    [
      "#aa@aaaaaaaa@aa#",
      "a  #        #  a",
      "a  #        #  a",
      "@  #        #  @",
      "a  #        #  a",
      "a  #        #  a",
      "a  #        #  a",
      "a  #        #  a",
      "a  #        #  a",
      "a  #   l    #  a",
      "a  ##########  a",
      "a              a",
      "@              @",
      "a              a",
      "a              a",
      "#aa@aaaaaaaa@aa#"
    ],
    [
      "################",
      "#bddddddddddddb#",
      "#c############c#",
      "#c############c#",
      "#c############c#",
      "#c############c#",
      "#c############c#",
      "#c############c#",
      "#c############c#",
      "#c####$l$#####c#",
      "#c############c#",
      "#c############c#",
      "#c############c#",
      "#c############c#",
      "#c############c#",
      "#bddddddddddddb#"
    ],
    [
      "################",
      "#bddddddddddddb#",
      "#c############c#",
      "#c############c#",
      "#c############c#",
      "#c############c#",
      "#c############c#",
      "#c############c#",
      "#c############c#",
      "#c####$l$#####c#",
      "#c############c#",
      "#c############c#",
      "#c############c#",
      "#c############c#",
      "#c############c#",
      "#bddddddddddddb#"
    ]
  ]
}