{
  "xsize": 16,
  "zsize": 16,
  "slices": [
    [
      "##   ######   ##",
      "#bddddddddddddb#",
      " ############## ",
      " ############## ",
      " ############## ",
      "#######1########",
      "################",
      "################",
      "################",
      "######$l$#######",
      "#####1##########",
      " ############## ",
      " ############## ",
      " ############## ",
      "#bddddddddddddb#",
      "##   ######   ##"
    ],
    [
      "##   ######   ##",
      "##aaa#F   #aaa##",
      " a            a ",
      " a            a ",
      " a            a ",
      "##  #######   ##",
      "#   :     :    #",
      "#   :          #",
      "#   :          #",
      "#   :  l  :    #",
      "##  #######   ##",
      " a            a ",
      " a            a ",
      " a            a ",
      "##aaa#    #aaa##",
      "##   ######   ##"
    ],
    [
      "##   ######   ##",
      "##aaa#    #aaa##",
      " a            a ",
      " a            a ",
      " a            a ",
      "##  #######   ##",
      "#   :  T  :    #",
      "#   :          #",
      "#   :          #",
      "#   :  l  :    #",
      "##  #######   ##",
      " a            a ",
      " a            a ",
      " a            a ",
      "##aaa#    #aaa##",
      "##   ######   ##"
    ],
    [
      "##   ######   ##",
      "##aaa#    #aaa##",
      " a            a ",
      " a            a ",
      " a            a ",
      "##  #######   ##",
      "#   :     :    #",
      "#   :          #",
      "#   :          #",
      "#   :  l  :    #",
      "##  #######   ##",
      " a            a ",
      " a            a ",
      " a            a ",
      "##aaa#    #aaa##",
      "##   ######   ##"
    ],
    [
      "##   ######   ##",
      "################",
      " ############## ",
      " ############## ",
      " ############## ",
      "################",
      "################",
      "################",
      "################",
      "######$l$#######",
      "################",
      " ############## ",
      " ############## ",
      " ############## ",
      "################",
      "##   ######   ##"
    ],
    [
      "##   ######   ##",
      "################",
      " ############## ",
      " ############## ",
      " ############## ",
      "################",
      "################",
      "################",
      "################",
      "######$l$#######",
      "################",
      " ############## ",
      " ############## ",
      " ############## ",
      "################",
      "##   ######   ##"
    ]
  ]
}