{
  "xsize": 16,
    "zsize": 16,
    "slices": [
      [
        "aiiaiiaiiaiiaiia",
        "ibddddddddbdddbi",
        "icaaaaaaaabaaaci",
        "acaiiiiaaabaaaca",
        "icailiiaaibaaaci",
        "icaiiliaaibaaaci",
        "acaiiiiaaibaaaca",
        "icaaaaaaaabaaaci",
        "icaaaaaaaabaaaci",
        "acaaaailiabaaaca",
        "iciiiaaaaabaaaci",
        "ibddddddddbaaaci",
        "acaaaaaaaaaaaaca",
        "icaaaaaaaaaaaaci",
        "ibddddddddddddbi",
        "aiiaiiaiiaiiaiia"
      ],
      [
        "aaaaaaaaaaaaaaaa",
        "ajj      a    ja",
        "aj j    ja  j ja",
        "ajjj    ja   jja",
        "a j j       jjja",
        "a             ja",
        "a              a",
        "a        a     a",
        "a        a     a",
        "a      l a     a",
        "aa   aaaaa     a",
        "a              a",
        "a      jj   j  a",
        "a   jjjjlj jljja",
        "a  jjjjjjj  jjja",
        "aaaaaaaaaaaaaaaa"
      ],
      [
        "ahhahhahhahhahha",
        "hj b     a  b  h",
        "hj       a    jh",
        "a       ka   kja",
        "h             jh",
        "h             kh",
        "as            ca",
        "h        a     h",
        "h        a     h",
        "a      l a     a",
        "ha   aaaaa     h",
        "h              h",
        "a             ca",
        "h    k  jk  j  h",
        "h  kjjj jk   j h",
        "ahhahhahhahhahha"
      ],
      [
        "ahhahhahhahhahha",
        "hj       a     h",
        "hk       a     h",
        "a        a     a",
        "h        a    jh",
        "h       caf    h",
        "a        a     a",
        "h        a     h",
        "h        a     h",
        "a  k   l a     a",
        "haaaaaaaaa     h",
        "h  c           h",
        "a              a",
        "h              h",
        "h   j        k h",
        "ahhahhahhahhahha"
      ],
      [
        "aaaaaaaaaaaaaaaa",
        "abddddddddddddba",
        "acaaaaaaaaaaaaca",
        "acaaaaaaaaaaaaca",
        "acaaaaaaaaaaaaca",
        "acaaaaaaaaaaaaca",
        "acaaaaaaaaaaaaca",
        "acaaaaaaaaaaaaca",
        "acaaaaaaaaaaaaca",
        "acaaaailiaaaaaca",
        "acaaaaaaaaaaaaca",
        "acaaaaaaaaaaaaca",
        "acaaaaaaaaaaaaca",
        "acaaaaaaaaaaaaca",
        "acaaaaaaaaaaaaca",
        "abddddddddddddba"
      ],
      [
        "aaaaaaaaaaaaaaaa",
        "abddddddddddddba",
        "acaaaaaaaaaaaaca",
        "acaaaaaaaaaaaaca",
        "acaaaaaaaaaaaaca",
        "acaaaaaaaaaaaaca",
        "acaaaaaaaaaaaaca",
        "acaaaaaaaaaaaaca",
        "acaaaaaaaaaaaaca",
        "acaaaailiaaaaaca",
        "acaaaaaaaaaaaaca",
        "acaaaaaaaaaaaaca",
        "acaaaaaaaaaaaaca",
        "acaaaaaaaaaaaaca",
        "acaaaaaaaaaaaaca",
        "abddddddddddddba"
      ]
    ]
}