{
  "xsize": 16,
  "zsize": 16,
  "slices": [
    [
      "aa   aaaaaa   aa",
      "abddddddddddddba",
      " aaaaaaaaaaaaaa ",
      " aaaaaaaaaaaaaa ",
      " aaaaaaaaaaaaaa ",
      "aaaaaaaaaaaaaaaa",
      "aaaaaaaaaaaaaaaa",
      "aaaaaaaaaaaaaaaa",
      "aaaaaaaaaaaaaaaa",
      "aaaaaaiyiaaaaaaa",
      "aaaaaaaaaaaaaaaa",
      " aaaaaaaaaaaaaa ",
      " aaaaaaaaaaaaaa ",
      " aaaaaaaaaaaaaa ",
      "abddddddddddddba",
      "aa   aaaaaa   aa"
    ],
    [
      "aa   aaaaaa   aa",
      "aahhha    ahhhaa",
      " h            h ",
      " h            h ",
      " h            h ",
      "aa            aa",
      "a              a",
      "a              a",
      "a              a",
      "a      y       a",
      "aa    aaa     aa",
      " h            h ",
      " h            h ",
      " h            h ",
      "aahhha    ahhhaa",
      "aa   aaaaaa   aa"
    ],
    [
      "aa   aaaaaa   aa",
      "aahhha    ahhhaa",
      " h            h ",
      " h            h ",
      " h            h ",
      "aa            aa",
      "a              a",
      "a              a",
      "a              a",
      "a      y       a",
      "aa    aaa     aa",
      " h     k      h ",
      " h            h ",
      " h            h ",
      "aahhha    ahhhaa",
      "aa   aaaaaa   aa"
    ],
    [
      "aa   aaaaaa   aa",
      "aahhha    ahhhaa",
      " h            h ",
      " h            h ",
      " h            h ",
      "aa            aa",
      "a              a",
      "a              a",
      "a              a",
      "a      y       a",
      "aa    aaa     aa",
      " h            h ",
      " h            h ",
      " h            h ",
      "aahhha    ahhhaa",
      "aa   aaaaaa   aa"
    ],
    [
      "aa   aaaaaa   aa",
      "aaaaaaaaaaaaaaaa",
      " aaaaaaaaaaaaaa ",
      " aaaaaaaaaaaaaa ",
      " aaaaaaaaaaaaaa ",
      "aaaaaaaaaaaaaaaa",
      "aaaaaaaaaaaaaaaa",
      "aaaaaaaaaaaaaaaa",
      "aaaaaaaaaaaaaaaa",
      "aaaaaaiyiaaaaaaa",
      "aaaaaaaaaaaaaaaa",
      " aaaaaaaaaaaaaa ",
      " aaaaaaaaaaaaaa ",
      " aaaaaaaaaaaaaa ",
      "aaaaaaaaaaaaaaaa",
      "aa   aaaaaa   aa"
    ],
    [
      "aa   aaaaaa   aa",
      "aaaaaaaaaaaaaaaa",
      " aaaaaaaaaaaaaa ",
      " aaaaaaaaaaaaaa ",
      " aaaaaaaaaaaaaa ",
      "aaaaaaaaaaaaaaaa",
      "aaaaaaaaaaaaaaaa",
      "aaaaaaaaaaaaaaaa",
      "aaaaaaaaaaaaaaaa",
      "aaaaaaiyiaaaaaaa",
      "aaaaaaaaaaaaaaaa",
      " aaaaaaaaaaaaaa ",
      " aaaaaaaaaaaaaa ",
      " aaaaaaaaaaaaaa ",
      "aaaaaaaaaaaaaaaa",
      "aa   aaaaaa   aa"
    ]
  ]
}