{
  "xsize": 16,
  "zsize": 16,
  "slices": [
    [
      "aaaaaaaaaaaaaaaa",
      "abddddddddddddba",
      "acaaaaaaaaaaaaca",
      "acaaaaaaaaaaaaca",
      "acaaaaaaaaaaaaca",
      "acaaaaaaaaaaaaca",
      "acaaaaaaaaaaaaca",
      "acaaaaaaaaaaaaca",
      "acaaaaaaaaaaaaca",
      "acaaaa$l$aaaaaca",
      "acaaaaaaaaaaaaca",
      "acaaaaaaaaaaaaca",
      "acaaaaaaaaaaaaca",
      "acaaaaaaaaaaaaca",
      "abddddddddddddba",
      "aaaaaaaaaaaaaaaa"
    ],
    [
      "aa___aaaaaa___aa",
      "aaaaaa    aaaaaa",
      "_a            a_",
      "_a            a_",
      "_a            a_",
      "aa            aa",
      "a              a",
      "a              a",
      "a              a",
      "a      l       a",
      "aaaaaaaaaaa aaaa",
      "_a   FFFF     a_",
      "_a            a_",
      "_a            a_",
      "aaaaaa    aaaaaa",
      "aa___aaaaaa___aa"
    ],
    [
      "aa   aaaaaa   aa",
      "aa444a    a444aa",
      " 4            4 ",
      " 4            4 ",
      " 4            4 ",
      "aa            aa",
      "a              a",
      "a              a",
      "a              a",
      "a     $l$      a",
      "aaaaaaaaaaa aaaa",
      " 4            4 ",
      " 4            4 ",
      " 4            4 ",
      "aa444a    a444aa",
      "aa   aaaaaa   aa"
    ],
    [
      "aa   aaaaaa   aa",
      "aa444a    a444aa",
      " 4            4 ",
      " 4            4 ",
      " 4            4 ",
      "aaT          Taa",
      "a              a",
      "a              a",
      "a              a",
      "a      l       a",
      "aaaaaaaaaaaaaaaa",
      " 4     T      4 ",
      " 4            4 ",
      " 4            4 ",
      "aa444a    a444aa",
      "aa   aaaaaa   aa"
    ],
    [
      "aa   aaaaaa   aa",
      "aa444a    a444aa",
      " 4            4 ",
      " 4            4 ",
      " 4            4 ",
      "aa            aa",
      "a              a",
      "a              a",
      "a              a",
      "a      l       a",
      "aaaaaaaaaaaaaaaa",
      " 4            4 ",
      " 4            4 ",
      " 4            4 ",
      "aa444a    a444aa",
      "aa   aaaaaa   aa"
    ],
    [
      "aa===aaaaaa===aa",
      "aaaaaaaaaaaaaaaa",
      "=aaaaaaaaaaaaaa=",
      "=aaaaaaaaaaaaaa=",
      "=aaaaaaaaaaaaaa=",
      "aaaaaaaaaaaaaaaa",
      "aaaaaaaaaaaaaaaa",
      "aaaaaaaaaaaaaaaa",
      "aaaaaaaaaaaaaaaa",
      "aaaaaa$l$aaaaaaa",
      "aaaaaaaaaaaaaaaa",
      "=aaaaaaaaaaaaaa=",
      "=aaaaaaaaaaaaaa=",
      "=aaaaaaaaaaaaaa=",
      "aaaaaaaaaaaaaaaa",
      "aa===aaaaaa===aa"
    ]
  ]
}