{
  "xsize": 16,
  "zsize": 16,
  "slices": [
    [
      "aaaaaaaaaaaaaaaa",
      "abddddddddddddba",
      "acaaaaaaaaaaaaca",
      "acaaaaaaaaaaaaca",
      "acaaaaaaaaaaaaca",
      "acaaaaaaaaaaaaca",
      "acaaaaaaaaaaaaca",
      "acaaaaaaaaaaaaca",
      "acaaaaaaaaaaaaca",
      "acaaaa$l$aaaaaca",
      "acaaa1aaa1aaaaca",
      "acaaaaaaaaaaaaca",
      "acaaaaaaaaaaaaca",
      "acaaaaaaaaaaaaca",
      "abddddddddddddba",
      "aaaaaaaaaaaaaaaa"
    ],
    [
      "a44@44444444@44a",
      "4      a       4",
      "4      aF      4",
      "@              @",
      "4      a       4",
      "4     La       4",
      "4    aaaaa     4",
      "4    a   a     4",
      "4    a   aF    4",
      "4      l a     4",
      "4aaaaaaaaa     4",
      "4       :      4",
      "@       :      @",
      "4   C          4",
      "4              4",
      "a44@44444444@44a"
    ],
    [
      "a44@44444444@44a",
      "4      a       4",
      "4      a       4",
      "@              @",
      "4      a       4",
      "4     La       4",
      "4    aaaaa     4",
      "4    a   a     4",
      "4    a   aT    4",
      "4      l a     4",
      "4aaaaaaaaa     4",
      "4    T  :      4",
      "@       :      @",
      "4              4",
      "4              4",
      "a44@44444444@44a"
    ],
    [
      "a44@44444444@44a",
      "4      a       4",
      "4      a       4",
      "@      a       @",
      "4      a       4",
      "4     La       4",
      "4    aaaaa     4",
      "4    a   a     4",
      "4    a   a     4",
      "4    a l a     4",
      "4aaaaaaaaa     4",
      "4       :      4",
      "@       :      @",
      "4              4",
      "4              4",
      "a44@44444444@44a"
    ],
    [
      "aaaaaaaaaaaaaaaa",
      "abddddddddddddba",
      "acaaaaaaaaaaaaca",
      "acaaaaaaaaaaaaca",
      "acaaaaaaaaaaaaca",
      "acaaaaaaaaaaaaca",
      "acaaaaaaaaaaaaca",
      "acaaaaaaaaaaaaca",
      "acaaaaaaaaaaaaca",
      "acaaaa$l$aaaaaca",
      "acaaaaaaaaaaaaca",
      "acaaaaaaaaaaaaca",
      "acaaaaaaaaaaaaca",
      "acaaaaaaaaaaaaca",
      "acaaaaaaaaaaaaca",
      "abddddddddddddba"
    ],
    [
      "aaaaaaaaaaaaaaaa",
      "abddddddddddddba",
      "acaaaaaaaaaaaaca",
      "acaaaaaaaaaaaaca",
      "acaaaaaaaaaaaaca",
      "acaaaaaaaaaaaaca",
      "acaaaaaaaaaaaaca",
      "acaaaaaaaaaaaaca",
      "acaaaaaaaaaaaaca",
      "acaaaa$l$aaaaaca",
      "acaaaaaaaaaaaaca",
      "acaaaaaaaaaaaaca",
      "acaaaaaaaaaaaaca",
      "acaaaaaaaaaaaaca",
      "acaaaaaaaaaaaaca",
      "abddddddddddddba"
    ]
  ]
}