{
  "xsize": 16,
  "zsize": 16,
  "slices": [
    [
      "aaaaaaaaaaaaaaaa",
      "abddddbddbddddba",
      "acbdddbaabdddbca",
      "accaaaaaaaaaaIca",
      "accamaanaaamaIca",
      "accaaaaaaaaaaIca",
      "abbaaaaaaaaaabba",
      "acaaaaaaaaaaaaca",
      "acaaaaaaaaaaaaca",
      "abddddiyidddddba",
      "acaaaaaaaaaiaaca",
      "acbaaaaKaaaaabca",
      "accaaaaaaaaaaIca",
      "acbdddbaaaabKbca",
      "abddddbddbddddba",
      "aaaaaaaaaaaaaaaa"
    ],
    [
      "aaGGGaaaaaaGGGaa",
      "aaaaaa    aaaaaa",
      "Gajjjjj     jjaG",
      "Gajjjjj   jjjjaG",
      "Gajjj jjj jjj aG",
      "aa j  j     jjaa",
      "a            j a",
      "a              a",
      "ajj            a",
      "ajjj   y       a",
      "aaaaaaaaaaa aaaa",
      "Gajjj        jaG",
      "Gaj         jjaG",
      "Ga     j j   jaG",
      "aaaaaajjjjaaaaaa",
      "aaGGGaaaaaaGGGaa"
    ],
    [
      "aa   aaaaaa   aa",
      "aahhha    ahhhaa",
      " h          jjh ",
      " h jj      k  h ",
      " hj k   k   j h ",
      "aa            aa",
      "a            k a",
      "a              a",
      "a              a",
      "a k    y       a",
      "aaaaaaaaaaa aaaa",
      " hjk         jh ",
      " h          k h ",
      " h            h ",
      "aahhhakj jahhhaa",
      "aa   aaaaaa   aa"
    ],
    [
      "aa   aaaaaa   aa",
      "aahhha    ahhhaa",
      " h   r    r   h ",
      " h            h ",
      " h            h ",
      "aaq          saa",
      "a              a",
      "a              a",
      "a              a",
      "a      y   v   a",
      "aaaaaaaaaaaaaaaa",
      " h            h ",
      " h            h ",
      " h   p    p   h ",
      "aahhha   jahhhaa",
      "aa   aaaaaa   aa"
    ],
    [
      "aa   aaaaaa   aa",
      "aahhha    ahhhaa",
      " h            h ",
      " h            h ",
      " h            h ",
      "aa            aa",
      "a              a",
      "a              a",
      "a              a",
      "a      y       a",
      "aaaaaaaaaaaaaaaa",
      " h            h ",
      " h            h ",
      " h            h ",
      "aahhha    ahhhaa",
      "aa   aaaaaa   aa"
    ],
    [
      "aaGGGaaaaaaGGGaa",
      "aaaaaaJddJaaaaaa",
      "GaJdddJaaJdddJaG",
      "GacaaaaaaaaaaIaG",
      "GacaaaaaaaaaaIaG",
      "aacaaaaaaaaaaIaa",
      "aJaaaaaaaaaaaaJa",
      "acaaaaaaaaaaaaIa",
      "acaaaaaaaaaaaaIa",
      "aJKiyiaaaaaaaKJa",
      "aaaaaaaaaaaaaaaa",
      "GaJddddddddddJaG",
      "GacaaaaaaaaaaIaG",
      "GaJKJaaaaaaJKJaG",
      "aaaaaaJKJaaaaaaa",
      "aaGGGaaaaaaGGGaa"
    ]
  ]
}