{
  "xsize": 16,
  "zsize": 16,
  "slices": [
    [
      "aSSSSSSSSSSSSSSa",
      "SbddddddddddddbS",
      "ScaaaaaaaaaaaacS",
      "ScaaaaaaaaaaaacS",
      "ScaaaaaaaaaaaacS",
      "ScaaaaaaaaaaaacS",
      "Scaaaa1aaaaaaacS",
      "ScaaaaaaaaaaaacS",
      "ScaaaaaaaaaaaacS",
      "ScaaaaaaaaaaaacS",
      "Scaaaaaaaa  aacS",
      "Scaaaaaaaa  aacS",
      "Scaaaaaaaa  aacS",
      "ScaaaaaaaaccaacS",
      "SbddddddddddddbS",
      "aSSSSSSSSSSSSSSa"
    ],
    [
      "a44a44a44a44a44a",
      "4     a        4",
      "4     a        4",
      "aC             a",
      "4     a        4",
      "4     a        4",
      "aaaaaaa        a",
      "4    Sa        4",
      "4    Sa   cc   4",
      "a    Sa  :dd:  a",
      "4     a  :  :  4",
      "4        :  :  4",
      "a    Fa  :  :  a",
      "4    Fa        4",
      "4     a        4",
      "a44a44a44a44a44a"
    ],
    [
      "a44a44a44a44a44a",
      "4     a        4",
      "4     a        4",
      "a              a",
      "4     a        4",
      "4     a        4",
      "aa:::aaT       a",
      "4     a        4",
      "4    *a        4",
      "a    *a   cc   a",
      "4     a   dd   4",
      "4              4",
      "a     a        a",
      "4     a        4",
      "4     a        4",
      "a44a44a44a44a44a"
    ],
    [
      "a44a44a44a44a44a",
      "4     a        4",
      "4     a        4",
      "a     a        a",
      "4     a        4",
      "4     a        4",
      "aaaaaaa        a",
      "4     a        4",
      "4     a        4",
      "a     a        a",
      "4     a   cc   4",
      "4     a   dd   4",
      "a     a        a",
      "4     a        4",
      "4     a        4",
      "a44a44a44a44a44a"
    ],
    [
      "aSSSSSSSSSSSSSSa",
      "SaaaaaaaaaaaaaaS",
      "SaaaaaaaaaaaaaaS",
      "SaaaaaaaaaaaaaaS",
      "SaaaaaaaaaaaaaaS",
      "SaaaaaaaaaaaaaaS",
      "SaaaaaaaaaaaaaaS",
      "SaaaaaaaaaaaaaaS",
      "Saaaaaaaaa  aaaS",
      "Saaaaaaaaa  aaaS",
      "Saaaaaaaaa  aaaS",
      "SaaaaaaaaaccaaaS",
      "SaaaaaaaaaaaaaaS",
      "SaaaaaaaaaaaaaaS",
      "SaaaaaaaaaaaaaaS",
      "aSSSSSSSSSSSSSSa"
    ],
    [
      "aaaaaaaaaaaaaaaa",
      "aaaaaaaaaaaaaaaa",
      "aaaaaaaaaaaaaaaa",
      "aaaaaaaaaaaaaaaa",
      "aaaaaaaaaaaaaaaa",
      "aaaaaaaaaaaaaaaa",
      "aaaaaaaaaaaaaaaa",
      "aaaaaaaaaaaaaaaa",
      "aaaaaaaaaaaaaaaa",
      "aaaaaaaaaa  aaaa",
      "aaaaaaaaaa  aaaa",
      "aaaaaaaaaa  aaaa",
      "aaaaaaaaaaccaaaa",
      "aaaaaaaaaaaaaaaa",
      "aaaaaaaaaaaaaaaa",
      "aaaaaaaaaaaaaaaa"
    ]
  ]
}