{
  "xsize": 16,
  "zsize": 16,
  "slices": [
    [
      "aaaaaaaaaaaaaaaa",
      "abddddddddddddba",
      "acaaaaaaaaaaaaca",
      "acaaaaaaaaaaaaca",
      "acaaaaaaaaaaaaca",
      "acaaaaaaaaaaaaca",
      "acaaaaaaaaaaaaca",
      "acaaaaaaaaaaaaca",
      "acaaaaaaaaaaaaca",
      "acaaaailiaaaaaca",
      "acaaaaaaaaaaaaca",
      "acaaaaaaaaaaaaca",
      "acaaaaaaaaaaaaca",
      "acaaaaaaaaaaaaca",
      "abddddddddddddba",
      "aaaaaaaaaaaaaaaa"
    ],
    [
      "ahh@hhhhhhhh@hha",
      "hWWWWWWWWWWWWWWh",
      "hWWWWWWWWWWWWWWh",
      "@WWWWWWWWWWWWWW@",
      "hWWWWWWWWWWWWWWh",
      "hhhhhhhhhhhhhhhh",
      "h              h",
      "h              h",
      "hj             h",
      "hj     l       h",
      "hj    aaa::::::h",
      "h      :       h",
      "@      :   k   @",
      "h      :       h",
      "h      :       h",
      "ahh@hhhhhhhh@hha"
    ],
    [
      "ahh@hhhhhhhh@hha",
      "hWWWWWWWWWWWWWWh",
      "hWWWWWWWWWWWWWWh",
      "@WWWWWWWWWWWWWW@",
      "hWWWWWWWWWWWWWWh",
      "hhhhhhhhhhhhhhhh",
      "h              h",
      "h              h",
      "hj             h",
      "h      l       h",
      "h     aaa::::::h",
      "h      :       h",
      "@      :       @",
      "h      :       h",
      "h      :       h",
      "ahh@hhhhhhhh@hha"
    ],
    [
      "ahh@hhhhhhhh@hha",
      "hWWWWWWWWWWWWWWh",
      "hWWWWWWWWWWWWWWh",
      "@WWWWWWWWWWWWWW@",
      "hWWWWWWWWWWWWWWh",
      "hhhhhhhhhhhhhhhh",
      "h              h",
      "h              h",
      "hj             h",
      "h      l       h",
      "h     aaa::::::h",
      "h      :       h",
      "@      :       @",
      "h      :       h",
      "h      :       h",
      "ahh@hhhhhhhh@hha"
    ],
    [
      "aaaaaaaaaaaaaaaa",
      "aaaaaaaaaaaaaaaa",
      "aaaaaaaaaaaaaaaa",
      "aaaaaaaaaaaaaaaa",
      "aaaaaaaaaaaaaaaa",
      "aaaaaaaaaaaaaaaa",
      "aaaaaaaaaaaaaaaa",
      "aaaaaaaaaaaaaaaa",
      "aaaaaaaaaaaaaaaa",
      "aaaaaailiaaaaaaa",
      "aaaaaaaaaaaaaaaa",
      "aaaaaaaaaaaaaaaa",
      "aalalaaaaaaaaaaa",
      "aaaaaaaaaaaaaaaa",
      "aaaaaaaaaaaaaaaa",
      "aaaaaaaaaaaaaaaa"
    ],
    [
      "aaaaaaaaaaaaaaaa",
      "abddddddddddddba",
      "acaaaaaaaaaaaaca",
      "acaaaaaaaaaaaaca",
      "acaaaaaaaaaaaaca",
      "acaaaaaaaaaaaaca",
      "acaaaaaaaaaaaaca",
      "acaaaaaaaaaaaaca",
      "acaaaaaaaaaaaaca",
      "acaaaailiaaaaaca",
      "acaaaaaaaaaaaaca",
      "acaaaaaaaaaaaaca",
      "acaaaaaaaaaaaaca",
      "acaaaaaaaaaaaaca",
      "acaaaaaaaaaaaaca",
      "abddddddddddddba"
    ]
  ]
}