{
  "xsize": 16,
  "zsize": 16,
  "slices": [
    [
      "aiiaiiaiiaiiaiia",
      "ibddddddddddddbi",
      "icaaaaaaaaaaaaci",
      "acaaaaaaaaaaaaca",
      "icaamaaaaaamaaci",
      "icaaaaaaaaaaaaci",
      "acaaaaaaaaaaaaca",
      "icaaaaaaaaaaaaci",
      "icaaaaaaaaaaaaci",
      "acaaaailiaaaaaca",
      "icaaaaaaaaaaaaci",
      "icaamaaaaaamaaci",
      "acaaaaaaaaaaaaca",
      "icaaaaaaaaaaaaci",
      "ibddddddddddddbi",
      "aiiaiiaiiaiiaiia"
    ],
    [
      "aaaaaaaaaaaaaaaa",
      "a bbb          a",
      "a  bb  b  bb   a",
      "a  b    bb b   a",
      "a bbbbb  b bb  a",
      "abbbb bbbb b   a",
      "a   b b        a",
      "a  bb         ba",
      "a  bb        bba",
      "a      l      ba",
      "a     aaa b    a",
      "a b b    bbbb  a",
      "a  bb     bb   a",
      "a              a",
      "a              a",
      "aaaaaaaaaaaaaaaa"
    ],
    [
      "ahhahhahhahhahha",
      "h bbb d     d  h",
      "h bb      b    h",
      "ak b     b b   a",
      "h b  b      b  h",
      "h     b        h",
      "a             qa",
      "h             bh",
      "h  b          bh",
      "ak     l       a",
      "h     aaa b    h",
      "h         b    h",
      "a   b         qa",
      "h              h",
      "h  c     c     h",
      "ahhahhahhahhahha"
    ],
    [
      "ahhahhahhahhahha",
      "h bb           h",
      "h              h",
      "a  b           a",
      "h              h",
      "h              h",
      "a              a",
      "h              h",
      "h  b          bh",
      "a      l       a",
      "h     aaa      h",
      "h              h",
      "a              a",
      "h              h",
      "h              h",
      "ahhahhahhahhahha"
    ],
    [
      "aaaaaaaaaaaaaaaa",
      "abddddddddddddba",
      "acaaaaaaaaaaaaca",
      "acaaaaaaaaaaaaca",
      "acaaaaaaaaaaaaca",
      "acaaaaaaaaaaaaca",
      "acaaaaaaaaaaaaca",
      "acaaaaaaaaaaaaca",
      "acaaaaaaaaaaaaca",
      "acaaaailiaaaaaca",
      "acaaaaaaaaaaaaca",
      "acaaaaaaaaaaaaca",
      "acaaaaaaaaaaaaca",
      "acaaaaaaaaaaaaca",
      "acaaaaaaaaaaaaca",
      "abddddddddddddba"
    ],
    [
      "aaaaaaaaaaaaaaaa",
      "abddddddddddddba",
      "acaaaaaaaaaaaaca",
      "acaaaaaaaaaaaaca",
      "acaaaaaaaaaaaaca",
      "acaaaaaaaaaaaaca",
      "acaaaaaaaaaaaaca",
      "acaaaaaaaaaaaaca",
      "acaaaaaaaaaaaaca",
      "acaaaailiaaaaaca",
      "acaaaaaaaaaaaaca",
      "acaaaaaaaaaaaaca",
      "acaaaaaaaaaaaaca",
      "acaaaaaaaaaaaaca",
      "acaaaaaaaaaaaaca",
      "abddddddddddddba"
    ]
  ]
}