{
  "xsize": 16,
  "zsize": 16,
  "slices": [
    [
      "aSSSSSSSSSSSSSSa",
      "SbddddddddddddbS",
      "ScaaaaaaaaaaaacS",
      "ScaaaaaaaaaaaacS",
      "ScaaaaaaaaaaaacS",
      "ScaaaaaaaaaaaacS",
      "ScaaaaaaaaaaaacS",
      "ScaaaaaaaaaaaacS",
      "ScaaaaaaaaaaaacS",
      "ScaaaaaaaaaaaacS",
      "Scaaaaaaaa  aacS",
      "Scaaaaaaaa  aacS",
      "Scaaaaaaaa  aacS",
      "ScaaaaaaaaccaacS",
      "SbddddddddddddbS",
      "aSSSSSSSSSSSSSSa"
    ],
    [
      "a44a44a44a44a44a",
      "4     a  F     4",
      "4     Q        4",
      "aF    Q        a",
      "4     Q        4",
      "4     Q        4",
      "aF    a        a",
      "4              4",
      "4         cc   4",
      "aF    a  :dd:  a",
      "4     Q  :  :  4",
      "4     Q  :  :  4",
      "a     Q  :  :  a",
      "4     Q        4",
      "4     a        4",
      "a44a44a44a44a44a"
    ],
    [
      "a44a44a44a44a44a",
      "4     a        4",
      "4     Q        4",
      "a     Q        a",
      "4     Q        4",
      "4     Q        4",
      "a     a        a",
      "4              4",
      "4              4",
      "a     a   cc   a",
      "4     Q   dd   4",
      "4     Q        4",
      "a     Q        a",
      "4     Q        4",
      "4     a        4",
      "a44a44a44a44a44a"
    ],
    [
      "a44a44a44a44a44a",
      "4     a        4",
      "4     Q        4",
      "a     Q        a",
      "4     Q        4",
      "4     Q        4",
      "a     a        a",
      "4     a        4",
      "4     a        4",
      "a     a        a",
      "4     Q   cc   4",
      "4     Q   dd   4",
      "a     Q        a",
      "4     Q        4",
      "4     a        4",
      "a44a44a44a44a44a"
    ],
    [
      "aSSSSSSSSSSSSSSa",
      "SaaaaaaaaaaaaaaS",
      "SaaaaaaaaaaaaaaS",
      "SaaaaaaaaaaaaaaS",
      "SaaaaaaaaaaaaaaS",
      "SaaaaaaaaaaaaaaS",
      "SaaaaaaaaaaaaaaS",
      "SaaaaaaaaaaaaaaS",
      "Saaaaaaaaa  aaaS",
      "Saaaaaaaaa  aaaS",
      "Saaaaaaaaa  aaaS",
      "SaaaaaaaaaccaaaS",
      "SaaaaaaaaaaaaaaS",
      "SaaaaaaaaaaaaaaS",
      "SaaaaaaaaaaaaaaS",
      "aSSSSSSSSSSSSSSa"
    ],
    [
      "aaaaaaaaaaaaaaaa",
      "aaaaaaaaaaaaaaaa",
      "aaaaaaaaaaaaaaaa",
      "aaaaaaaaaaaaaaaa",
      "aaaaaaaaaaaaaaaa",
      "aaaaaaaaaaaaaaaa",
      "aaaaaaaaaaaaaaaa",
      "aaaaaaaaaaaaaaaa",
      "aaaaaaaaaaaaaaaa",
      "aaaaaaaaaa  aaaa",
      "aaaaaaaaaa  aaaa",
      "aaaaaaaaaa  aaaa",
      "aaaaaaaaaaccaaaa",
      "aaaaaaaaaaaaaaaa",
      "aaaaaaaaaaaaaaaa",
      "aaaaaaaaaaaaaaaa"
    ]
  ]
}