{
  "xsize": 16,
  "zsize": 16,
  "slices": [
    [
      "aa   aaaaaa   aa",
      "abddddddddddddba",
      " aaaaaaaaaaaaaa ",
      " aaaaaaaaaaaaaa ",
      " aaaaaaaaaaaaaa ",
      "aaaaaaaaaaaaaaaa",
      "aaaaaaaaaaaaaaaa",
      "aaaaaaaaaaaaaaaa",
      "aaaaaaaaaaaaaaaa",
      "aaaaaailiaaaaaaa",
      "aaaaaaaaaaaaaaaa",
      " aaaaaaaaaaaaaa ",
      " aaaaaaaaaaaaaa ",
      " aaaaaaaaaaaaaa ",
      "abddddddddddddba",
      "aa   aaaaaa   aa"
    ],
    [
      "aa   aaaaaa   aa",
      "aahhha    ahhhaa",
      " h  ja        h ",
      " h  ja        h ",
      " h   aj       h ",
      "aa   aj       aa",
      "a    a        ja",
      "a    a         a",
      "a    a         a",
      "a    a l       a",
      "aa   aaaaa aaaaa",
      " h            h ",
      " h            h ",
      " h            h ",
      "aahhha    ahhhaa",
      "aa   aaaaaa   aa"
    ],
    [
      "aa   aaaaaa   aa",
      "aahhha    ahhhaa",
      " h   a        h ",
      " h   a        h ",
      " h   h        h ",
      "aa   h        aa",
      "a    h         a",
      "a    h         a",
      "a   ka         a",
      "a    a l       a",
      "aa   aaaaa aaaaa",
      " h     k      h ",
      " h            h ",
      " h            h ",
      "aahhha    ahhhaa",
      "aa   aaaaaa   aa"
    ],
    [
      "aa   aaaaaa   aa",
      "aahhha    ahhhaa",
      " h   a        h ",
      " h   a        h ",
      " h   a        h ",
      "aa   a        aa",
      "a    a         a",
      "a    a         a",
      "a    a         a",
      "a    a l       a",
      "aa   aaaaaaaaaaa",
      " h            h ",
      " h            h ",
      " h            h ",
      "aahhha    ahhhaa",
      "aa   aaaaaa   aa"
    ],
    [
      "aa   aaaaaa   aa",
      "aaaaaaaaaaaaaaaa",
      " aaaaaaaaaaaaaa ",
      " aaaaaaaaaaaaaa ",
      " aaaaaaaaaaaaaa ",
      "aaaaaaaaaaaaaaaa",
      "aaaaaaaaaaaaaaaa",
      "aaaaaaaaaaaaaaaa",
      "aaaaaaaaaaaaaaaa",
      "aaaaaailiaaaaaaa",
      "aaaaaaaaaaaaaaaa",
      " aaaaaaaaaaaaaa ",
      " aaaaaaaaaaaaaa ",
      " aaaaaaaaaaaaaa ",
      "aaaaaaaaaaaaaaaa",
      "aa   aaaaaa   aa"
    ],
    [
      "aa   aaaaaa   aa",
      "aaaaaaaaaaaaaaaa",
      " aaaaaaaaaaaaaa ",
      " aaaaaaaaaaaaaa ",
      " aaaaaaaaaaaaaa ",
      "aaaaaaaaaaaaaaaa",
      "aaaaaaaaaaaaaaaa",
      "aaaaaaaaaaaaaaaa",
      "aaaaaaaaaaaaaaaa",
      "aaaaaailiaaaaaaa",
      "aaaaaaaaaaaaaaaa",
      " aaaaaaaaaaaaaa ",
      " aaaaaaaaaaaaaa ",
      " aaaaaaaaaaaaaa ",
      "aaaaaaaaaaaaaaaa",
      "aa   aaaaaa   aa"
    ]
  ]
}