{
  "xsize": 16,
  "zsize": 16,
  "slices": [
    [
      "a$$a$$a$$a$$a$$a",
      "$bddddddddddddb$",
      "$caa1aaaaaaaaac$",
      "acaaaaaaaaaaaaca",
      "$caaaa1aaaaaaac$",
      "$bddddddddbaaac$",
      "acaaaaaaaacaaaca",
      "$bddddddbacaaac$",
      "$caaaaaacacaaac$",
      "abdddd$l$acaaaca",
      "$caaaaaaaacaaac$",
      "$bbbbbbbbbbaaac$",
      "acaaaaaaaaaaaaca",
      "$caaaaaaaaaaaac$",
      "$bddddddddddddb$",
      "a$$a$$a$$a$$a$$a"
    ],
    [
      "aaaaaaaaaaaaaaaa",
      "a           LLLa",
      "a   bjb      LLa",
      "a   jaj      LLa",
      "a   bjb       La",
      "a              a",
      "aaaaaaaaaa     a",
      "aLL      aLL   a",
      "aL       aL    a",
      "a      l aL    a",
      "a  aaaaaaa    La",
      "a    LLLL     La",
      "a      L      La",
      "a              a",
      "aLL            a",
      "aaaaaaaaaaaaaaaa"
    ],
    [
      "a44a44a44a44a44a",
      "4             L4",
      "4   bkb       L4",
      "am  kCk        a",
      "4   bkb        4",
      "4       T      4",
      "aaaa444aaa    na",
      "4L      Ta     4",
      "4        aL    4",
      "a      l a     a",
      "4  aaaaaaa     4",
      "4      LL      4",
      "am            La",
      "4              4",
      "4 L   T     T  4",
      "a44a44a44a44a44a"
    ],
    [
      "a44a44a44a44a44a",
      "4             L4",
      "4   bcb        4",
      "a   c cf       a",
      "4   bcb        4",
      "4              4",
      "aaaaaaaaaa     a",
      "4        a     4",
      "4        a     4",
      "a      l a     a",
      "4  aaaaaaa     4",
      "4              4",
      "a             La",
      "4              4",
      "4              4",
      "a44a44a44a44a44a"
    ],
    [
      "aaaaaaaaaaaaaaaa",
      "abddddddddddddba",
      "acaaaaaaaaaaaaca",
      "acaaaaaaaaaaaaca",
      "acaaaaaaaaaaaaca",
      "acaaaaaaaaaaaaca",
      "acaaaaaaaaaaaaca",
      "acaaaaaaaaaaaaca",
      "acaaaaaaaaaaaaca",
      "acaaaa$l$aaaaaca",
      "acaaaaaaaaaaaaca",
      "acaaaaaaaaaaaaca",
      "acaaaaaaaaaaaaca",
      "acaaaaaaaaaaaaca",
      "acaaaaaaaaaaaaca",
      "abddddddddddddba"
    ],
    [
      "aaaaaaaaaaaaaaaa",
      "abddddddddddddba",
      "acaaaaaaaaaaaaca",
      "acaaaaaaaaaaaaca",
      "acaaaaaaaaaaaaca",
      "acaaaaaaaaaaaaca",
      "acaaaaaaaaaaaaca",
      "acaaaaaaaaaaaaca",
      "acaaaaaaaaaaaaca",
      "acaaaa$l$aaaaaca",
      "acaaaaaaaaaaaaca",
      "acaaaaaaaaaaaaca",
      "acaaaaaaaaaaaaca",
      "acaaaaaaaaaaaaca",
      "acaaaaaaaaaaaaca",
      "abddddddddddddba"
    ]
  ]
}