{
  "xsize": 16,
  "zsize": 16,
  "slices": [
    [
      "aiiaiiaiiaiiaiia",
      "ibddddddddddddbi",
      "icaalaaaaaaaaaci",
      "acaaaaaaaaaaaaca",
      "icaaaalaaaaaaaci",
      "ibddddddddbaaaci",
      "acaaaaaaaacaaaca",
      "ibddddddbacaaaci",
      "icaaaaaacacaaaci",
      "abddddiyiacaaaca",
      "icaaaaaaaacaaaci",
      "ibddKdddbaaaci",
      "acaaaaaaaaaaaaca",
      "icaaaaaaaaaaaaci",
      "ibddddddddddddbi",
      "aiiaiiaiiaiiaiia"
    ],
    [
      "aaaaaaaaaaaaaaaa",
      "a           LLLa",
      "a   bfb      LLa",
      "a   faf      LLa",
      "a   bfb       La",
      "a              a",
      "aaaaaaaaaa     a",
      "aLL      aLL   a",
      "aL       aL    a",
      "a      y aL    a",
      "a  aaaaaaa    La",
      "a    LLLL     La",
      "aL     L     LLa",
      "aL           LLa",
      "aLL            a",
      "aaaaaaaaaaaaaaaa"
    ],
    [
      "ahhahhahhahhahha",
      "h        r    Lh",
      "h   bfb       Lh",
      "aq  fxf        a",
      "h   bfb        h",
      "h       T      h",
      "aaaahhhaaa    sa",
      "hL       a     h",
      "h       saL    h",
      "a      y a     a",
      "h  aaaaaaa     h",
      "h     kLL     kh",
      "ak            La",
      "h              h",
      "h L   T     T  h",
      "ahhahhahhahhahha"
    ],
    [
      "ahhahhahhahhahha",
      "h             Lh",
      "h   bgb       kh",
      "a   g g        a",
      "h   bgb        h",
      "h              h",
      "aaaaaaaaaa     a",
      "h        a     h",
      "h        ak    h",
      "a      y a     a",
      "h  aaaaaaa     h",
      "h              h",
      "a             La",
      "h              h",
      "h              h",
      "ahhahhahhahhahha"
    ],
    [
      "aaaaaaaaaaaaaaaa",
      "abddddddddddddba",
      "acaaaaaaaaaaaaca",
      "acaaaaaaaaaaaaca",
      "acaaaaaaaaaaaaca",
      "acaaaaaaaaaaaaca",
      "acaaaaaaaaaaaaca",
      "acaaaaaaaaaaaaca",
      "acaaaaaaaaaaaaca",
      "acaaaaiyiaaaaaca",
      "acaaaaaaaaaaaaca",
      "acaaaaaaaaaaaaca",
      "acaaaaaaaaaaaaca",
      "acaaaaaaaaaaaaca",
      "acaaaaaaaaaaaaca",
      "abddddddddddddba"
    ],
    [
      "aaaaaaaaaaaaaaaa",
      "abddddddddddddba",
      "acaaaaaaaaaaaaca",
      "acaaaaaaaaaaaaca",
      "acaaaaaaaaaaaaca",
      "acaaaaaaaaaaaaca",
      "acaaaaaaaaaaaaca",
      "acaaaaaaaaaaaaca",
      "acaaaaaaaaaaaaca",
      "acaaaaiyiaaaaaca",
      "acaaaaaaaaaaaaca",
      "acaaaaaaaaaaaaca",
      "acaaaaaaaaaaaaca",
      "acaaaaaaaaaaaaca",
      "acaaaaaaaaaaaaca",
      "abddddddddddddba"
    ]
  ]
}