{
  "xsize": 16,
  "zsize": 16,
  "slices": [
    [
      "aaaaaaaaaaaaaaaa",
      "abddddbdbdddddba",
      "acaaaacaraaaaaca",
      "acalaaciraaalaca",
      "acaaaacacaaaaaca",
      "acaabKbabdbaaaca",
      "acaacaaaaaraaaca",
      "acaacaaaaaraaaca",
      "acaacaaaaaraaaca",
      "abKbiiyiaraaaaca",
      "acaaalaaalraaaca",
      "abddddddddbaaaca",
      "acaaaaaaaaaalaca",
      "acaaaaaaaaaaaaca",
      "abddddddddddddba",
      "aaaaaaaaaaaaaaaa"
    ],
    [
      "ahhahhhhhhhhahha",
      "h      ajj   jjh",
      "h      aj    j h",
      "a              a",
      "h      a       h",
      "hj    ja       h",
      "hjj  aaaaaj    h",
      "hjjj ajj ajj   h",
      "hjj  aj  aj    h",
      "hjj    y aj    h",
      "haaaaaaaaa     h",
      "hjjjjj         h",
      "ajjj           a",
      "h   x     j    h",
      "h        jjjj  h",
      "ahhahhhhhhhhahha"
    ],
    [
      "ahhahhhhhhhhahha",
      "h  r   a    rjjh",
      "h      aj    k h",
      "aq            sa",
      "h      a       h",
      "h     ja       h",
      "hj   aaaaa     h",
      "hjk  ajk aj    h",
      "h    a   ak    h",
      "hj     y a     h",
      "haaaaaaaaa     h",
      "h jjjk         h",
      "aqkj          sa",
      "h         k    h",
      "h  p      j p  h",
      "ahhahhhhhhhhahha"
    ],
    [
      "ahhahhhhhhhhahha",
      "h      a       h",
      "h      a       h",
      "a      a       a",
      "h      a       h",
      "h     ja       h",
      "h    aaaaa     h",
      "h    a   a     h",
      "h    a   a     h",
      "hk   a y a     h",
      "haaaaaaaaa     h",
      "h  j           h",
      "a              a",
      "h              h",
      "h              h",
      "ahhahhhhhhhhahha"
    ],
    [
      "aaaaaaaaaaaaaaaa",
      "abddddddkdddddba",
      "acaaaaaacaaaaaca",
      "acaaaaaacaaaaaca",
      "acaaaaaacaaaaaca",
      "acaaaaaakdkaaaca",
      "acaaaaaaaacaaaca",
      "acaaaaaaaacaaaca",
      "acaaaaaaaacaaaca",
      "acaaaaiyiacaaaca",
      "acaaaaaaaacaaaca",
      "akddddddddkaaaca",
      "acaaaaaaaaaaaaca",
      "acaaaaaaaaaaaaca",
      "akdddddddddddKka",
      "abddddddddddddba"
    ],
    [
      "aaaaaaaaaaaaaaaa",
      "abddddddddddddba",
      "acaaaaaaaaaaaaca",
      "acaaaaaaaaaaaaca",
      "acaaaaaaaaaaaaca",
      "acaaaaaaaaaaaaca",
      "acaaaaaaaaaaaaca",
      "acaaaaaaaaaaaaca",
      "acaaaaaaaaaaaaca",
      "acaaaaiyiaaaaaca",
      "acaaaaaaaaaaaaca",
      "acaaaaaaaaaaaaca",
      "acaaaaaaaaaaaaca",
      "acaaaaaaaaaaaaca",
      "acaaaaaaaaaaaaca",
      "abddddddddddddba"
    ]
  ]
}