{
  "xsize": 16,
  "zsize": 16,
  "slices": [
    [
      "a$$a$$a$$a$$a$$a",
      "$bddddddddddddb$",
      "$caaaaaaaaaaaac$",
      "acaaaaaaaaaaaaca",
      "$caaeaaaaaaeaac$",
      "$caaaaaaaaaaaac$",
      "acaaaaaaaaaaaaca",
      "$caaaaaaaaaaaac$",
      "$caaaaaaaaaaaac$",
      "acaaaa$l$aaaaaca",
      "$caaaaaaaaaaaac$",
      "$caaeaaaaaaeaac$",
      "acaaaaaaaaaaaaca",
      "$caaaaaaaaaaaac$",
      "$bddddddddddddb$",
      "a$$a$$a$$a$$a$$a"
    ],
    [
      "aaaaaaaaaaaaaaaa",
      "a bbb          a",
      "a  bb  b  bb   a",
      "a  b    bb b   a",
      "a bbbbb  b bb  a",
      "abbbb bbbb b   a",
      "a   b b        a",
      "a  bb         ba",
      "a  bb        bba",
      "a      l      ba",
      "a     aaa b    a",
      "a b b    bbbb  a",
      "a  bb     bb   a",
      "a              a",
      "a              a",
      "aaaaaaaaaaaaaaaa"
    ],
    [
      "a44a44a44a44a44a",
      "4 bbb j     j  4",
      "4 bb      k    4",
      "am b     b b   a",
      "4 b  k      b  4",
      "4     b        4",
      "a             na",
      "4             b4",
      "4  b          b4",
      "am     l       a",
      "4     aaa k    4",
      "4         b    4",
      "a   k         na",
      "4              4",
      "4  c     c     4",
      "a44a44a44a44a44a"
    ],
    [
      "a44a44a44a44a44a",
      "4 bk           4",
      "4              4",
      "a  b           a",
      "4              4",
      "4              4",
      "a              a",
      "4              4",
      "4  k          k4",
      "a      l       a",
      "4     aaa      4",
      "4              4",
      "a              a",
      "4              4",
      "4              4",
      "a44a44a44a44a44a"
    ],
    [
      "aaaaaaaaaaaaaaaa",
      "abddddddddddddba",
      "acaaaaaaaaaaaaca",
      "acaaaaaaaaaaaaca",
      "acaaaaaaaaaaaaca",
      "acaaaaaaaaaaaaca",
      "acaaaaaaaaaaaaca",
      "acaaaaaaaaaaaaca",
      "acaaaaaaaaaaaaca",
      "acaaaa$l$aaaaaca",
      "acaaaaaaaaaaaaca",
      "acaaaaaaaaaaaaca",
      "acaaaaaaaaaaaaca",
      "acaaaaaaaaaaaaca",
      "acaaaaaaaaaaaaca",
      "abddddddddddddba"
    ],
    [
      "aaaaaaaaaaaaaaaa",
      "abddddddddddddba",
      "acaaaaaaaaaaaaca",
      "acaaaaaaaaaaaaca",
      "acaaaaaaaaaaaaca",
      "acaaaaaaaaaaaaca",
      "acaaaaaaaaaaaaca",
      "acaaaaaaaaaaaaca",
      "acaaaaaaaaaaaaca",
      "acaaaa$l$aaaaaca",
      "acaaaaaaaaaaaaca",
      "acaaaaaaaaaaaaca",
      "acaaaaaaaaaaaaca",
      "acaaaaaaaaaaaaca",
      "acaaaaaaaaaaaaca",
      "abddddddddddddba"
    ]
  ]
}