{
  "xsize": 16,
  "zsize": 16,
  "slices": [
    [
      "aaaaaaaaaaaaaaaa",
      "abddddddddddddba",
      "acaaaaaaaaaaaaca",
      "acaaaaaaaaaaaaca",
      "acaaaaaaaaaaaaca",
      "acaaaaaaaaaaaaca",
      "acaaaaaaaaaaaaca",
      "acaaaaaaaaaaaaca",
      "acaaaaaaaaaaaaca",
      "acaaaliyilaaaaca",
      "acaaaaaaaaaaaaca",
      "acaaaaaaaaaaaaca",
      "acaaaaaaaaaaaaca",
      "acaaaaaaaaaaaaca",
      "abddddddddddddba",
      "aaaaaaaaaaaaaaaa"
    ],
    [
      "ahh@hhhhhhhh@hha",
      "h   jj         h",
      "h              h",
      "@              @",
      "h              h",
      "h              h",
      "h    aa aa     h",
      "h    a   a     h",
      "h    a   a     h",
      "h    a y a     h",
      "h  jjaaaaajj   h",
      "h      xj      h",
      "@              @",
      "h              h",
      "h              h",
      "ahh@hhhhhhhh@hha"
    ],
    [
      "ahh@hhhhhhhh@hha",
      "h   jj         h",
      "h              h",
      "@              @",
      "h              h",
      "h              h",
      "h    aa aa     h",
      "h    a  ka     h",
      "h    a   a     h",
      "h    a y a     h",
      "h  jjaaaaajj   h",
      "h              h",
      "@              @",
      "h              h",
      "h              h",
      "ahh@hhhhhhhh@hha"
    ],
    [
      "ahh@hhhhhhhh@hha",
      "h              h",
      "h              h",
      "@              @",
      "h              h",
      "h              h",
      "h    aaaaa     h",
      "h    a   a     h",
      "h    a   a     h",
      "h    a y a     h",
      "h  jjaaaaajj   h",
      "h              h",
      "@              @",
      "h              h",
      "h              h",
      "ahh@hhhhhhhh@hha"
    ],
    [
      "aaaaaaaaaaaaaaaa",
      "abddddddddddddba",
      "acaaaaaaaaaaaaca",
      "acaaaaaaaaaaaaca",
      "acaaaaaaaaaaaaca",
      "acaaaaaaaaaaaaca",
      "acaaaaaaaaaaaaca",
      "acaaaaaaaaaaaaca",
      "acaaaaaaaaaaaaca",
      "acaaaaiyiaaaaaca",
      "acaaaaaaaaaaaaca",
      "acaaaaaaaaaaaaca",
      "acaaaaaaaaaaaaca",
      "acaaaaaaaaaaaaca",
      "acaaaaaaaaaaaaca",
      "abddddddddddddba"
    ],
    [
      "aaaaaaaaaaaaaaaa",
      "abddddddddddddba",
      "acaaaaaaaaaaaaca",
      "acaaaaaaaaaaaaca",
      "acaaaaaaaaaaaaca",
      "acaaaaaaaaaaaaca",
      "acaaaaaaaaaaaaca",
      "acaaaaaaaaaaaaca",
      "acaaaaaaaaaaaaca",
      "acaaaaiyiaaaaaca",
      "acaaaaaaaaaaaaca",
      "acaaaaaaaaaaaaca",
      "acaaaaaaaaaaaaca",
      "acaaaaaaaaaaaaca",
      "acaaaaaaaaaaaaca",
      "abddddddddddddba"
    ]
  ]
}