{
  "xsize": 16,
  "zsize": 16,
  "slices": [
    [
      "#SSSSSSSSSSSSSS#",
      "SbddddddddddddbS",
      "Sc############cS",
      "Sc############cS",
      "Sc############cS",
      "Sc############cS",
      "Sc############cS",
      "Sc############cS",
      "Sc############cS",
      "Sc############cS",
      "Sc########  ##cS",
      "Sc########  ##cS",
      "Sc########  ##cS",
      "Sc########cc##cS",
      "SbddddddddddddbS",
      "#SSSSSSSSSSSSSS#"
    ],
    [
      "#aa#aa#aa#aa#aa#",
      "a     #  F     a",
      "a     Q        a",
      "#F    Q        #",
      "a     Q        a",
      "a     Q        a",
      "#F    #        #",
      "a              a",
      "a         cc   a",
      "#F    #  :dd:  #",
      "a     Q  :  :  a",
      "a     Q  :  :  a",
      "#     Q  :  :  #",
      "a     Q        a",
      "a     #        a",
      "#aa#aa#aa#aa#aa#"
    ],
    [
      "#aa#aa#aa#aa#aa#",
      "a     #        a",
      "a     Q        a",
      "#     Q        #",
      "a     Q        a",
      "a     Q        a",
      "#     #        #",
      "a              a",
      "a              a",
      "#     #   cc   #",
      "a     Q   dd   a",
      "a     Q        a",
      "#     Q        #",
      "a     Q        a",
      "a     #        a",
      "#aa#aa#aa#aa#aa#"
    ],
    [
      "#aa#aa#aa#aa#aa#",
      "a     #        a",
      "a     Q        a",
      "#     Q        #",
      "a     Q        a",
      "a     Q        a",
      "#     #        #",
      "a     #        a",
      "a     #        a",
      "#     #        #",
      "a     Q   cc   a",
      "a     Q   dd   a",
      "#     Q        #",
      "a     Q        a",
      "a     #        a",
      "#aa#aa#aa#aa#aa#"
    ],
    [
      "#SSSSSSSSSSSSSS#",
      "S##############S",
      "S##############S",
      "S##############S",
      "S##############S",
      "S##############S",
      "S##############S",
      "S##############S",
      "S#########  ###S",
      "S#########  ###S",
      "S#########  ###S",
      "S#########cc###S",
      "S##############S",
      "S##############S",
      "S##############S",
      "#SSSSSSSSSSSSSS#"
    ],
    [
      "################",
      "################",
      "################",
      "################",
      "################",
      "################",
      "################",
      "################",
      "################",
      "##########  ####",
      "##########  ####",
      "##########  ####",
      "##########cc####",
      "################",
      "################",
      "################"
    ]
  ]
}