{
  "xsize": 16,
  "zsize": 16,
  "slices": [
    [
      "aaaaaaaaaaaaaaaa",
      "abddddddddddddba",
      "acaaaaaaaaaaaaca",
      "acaaaaaaaaaaaaca",
      "acaaaaaaaaaaaaca",
      "acaaaaaaaaaaaaca",
      "acaaaaaaaaaaaaca",
      "acaaaaaaaaaaaaca",
      "acaaaaaaaaaaaaca",
      "acaaaaiyiaaaaaca",
      "acaaaaaaaaaaaaca",
      "acaaaaaaaaaaaaca",
      "acaaaaaaaaaaaaca",
      "acaaaaaaaaaaaaca",
      "abddddddddddddba",
      "aaaaaaaaaaaaaaaa"
    ],
    [
      "ahhkhhhhhhhhkhha",
      "h              h",
      "h              h",
      "k              k",
      "h              h",
      "h              h",
      "h    aa aa     h",
      "h    a   aaaaaah",
      "h              h",
      "h    a y a     h",
      "h    aaaaa     h",
      "h      ja      h",
      "k       a      k",
      "h              h",
      "h       a      h",
      "ahhkhhhhhhhhkhha"
    ],
    [
      "ahhkhhhhhhhhkhha",
      "h              h",
      "h              h",
      "k              k",
      "h              h",
      "h              h",
      "h    aa aa     h",
      "h    a   aaa:aah",
      "h          k k h",
      "h    a y a     h",
      "h    aaaaa     h",
      "h       a      h",
      "k       a      k",
      "h              h",
      "h       a      h",
      "ahhkhhhhhhhhkhha"
    ],
    [
      "ahhkhhhhhhhhkhha",
      "h              h",
      "h              h",
      "k              k",
      "h              h",
      "h              h",
      "h    aaaaa     h",
      "h    a   aaaaaah",
      "h    a   a     h",
      "h    a y a     h",
      "h    aaaaa     h",
      "h       a      h",
      "k       a      k",
      "h       a      h",
      "h       a      h",
      "ahhkhhhhhhhhkhha"
    ],
    [
      "aaaaaaaaaaaaaaaa",
      "abddddddddddddba",
      "acaaaaaaaaaaaaca",
      "acaaaaaaaaaaaaca",
      "acaaaaaaaaaaaaca",
      "acaaaaaaaaaaaaca",
      "acaaaaaaaaaaaaca",
      "acaaaaaaaaaaaaca",
      "acaaaaaaaaaaaaca",
      "acaaaaiyiaaaaaca",
      "acaaaaaaaaaaaaca",
      "acaaaaaaaaaaaaca",
      "acaaaaaaaaaaaaca",
      "acaaaaaaaaaaaaca",
      "acaaaaaaaaaaaaca",
      "abddddddddddddba"
    ],
    [
      "aaaaaaaaaaaaaaaa",
      "abddddddddddddba",
      "acaaaaaaaaaaaaca",
      "acaaaaaaaaaaaaca",
      "acaaaaaaaaaaaaca",
      "acaaaaaaaaaaaaca",
      "acaaaaaaaaaaaaca",
      "acaaaaaaaaaaaaca",
      "acaaaaaaaaaaaaca",
      "acaaaaiyiaaaaaca",
      "acaaaaaaaaaaaaca",
      "acaaaaaaaaaaaaca",
      "acaaaaaaaaaaaaca",
      "acaaaaaaaaaaaaca",
      "acaaaaaaaaaaaaca",
      "abddddddddddddba"
    ]
  ]
}