{
  "xsize": 16,
  "zsize": 16,
  "slices": [
    [
      "aa   aaaaaa   aa",
      "abddddddddddddba",
      " aaaaaaaaaaaaaa ",
      " aaaaaaaaaaaaaa ",
      " aaaaaaaaaaaaaa ",
      "aaaaaaalaaaaaaaa",
      "aaaaaaaaaaaaaaaa",
      "aaaaaaaaaaaaaaaa",
      "aaaaaaaaaaaaaaaa",
      "aaaaaaiyiaaaaaaa",
      "aaaaalaaaaaaaaaa",
      " aaaaaaaaaaaaaa ",
      " aaaaaaaaaaaaaa ",
      " aaaaaaaaaaaaaa ",
      "abddddddddddddba",
      "aa   aaaaaa   aa"
    ],
    [
      "aa   aaaaaa   aa",
      "aahhhaj   ahhhaa",
      " h            h ",
      " h            h ",
      " h            h ",
      "aa  aaaaaaa   aa",
      "a   H     H    a",
      "a   H          a",
      "a   H          a",
      "a   H  y  H    a",
      "aa  aaaaaaa   aa",
      " h            h ",
      " h            h ",
      " h            h ",
      "aahhha    ahhhaa",
      "aa   aaaaaa   aa"
    ],
    [
      "aa   aaaaaa   aa",
      "aahhha    ahhhaa",
      " h            h ",
      " h            h ",
      " h            h ",
      "aa  aaaaaaa   aa",
      "a   H  k  H    a",
      "a   H          a",
      "a   H          a",
      "a   H  y  H    a",
      "aa  aaaaaaa   aa",
      " h            h ",
      " h            h ",
      " h            h ",
      "aahhha    ahhhaa",
      "aa   aaaaaa   aa"
    ],
    [
      "aa   aaaaaa   aa",
      "aahhha    ahhhaa",
      " h            h ",
      " h            h ",
      " h            h ",
      "aa  aaaaaaa   aa",
      "a   H     H    a",
      "a   H          a",
      "a   H          a",
      "a   H  y  H    a",
      "aa  aaaaaaa   aa",
      " h            h ",
      " h            h ",
      " h            h ",
      "aahhha    ahhhaa",
      "aa   aaaaaa   aa"
    ],
    [
      "aa   aaaaaa   aa",
      "aaaaaaaaaaaaaaaa",
      " aaaaaaaaaaaaaa ",
      " aaaaaaaaaaaaaa ",
      " aaaaaaaaaaaaaa ",
      "aaaaaaaaaaaaaaaa",
      "aaaaaaaaaaaaaaaa",
      "aaaaaaaaaaaaaaaa",
      "aaaaaaaaaaaaaaaa",
      "aaaaaaiyiaaaaaaa",
      "aaaaaaaaaaaaaaaa",
      " aaaaaaaaaaaaaa ",
      " aaaaaaaaaaaaaa ",
      " aaaaaaaaaaaaaa ",
      "aaaaaaaaaaaaaaaa",
      "aa   aaaaaa   aa"
    ],
    [
      "aa   aaaaaa   aa",
      "aaaaaaaaaaaaaaaa",
      " aaaaaaaaaaaaaa ",
      " aaaaaaaaaaaaaa ",
      " aaaaaaaaaaaaaa ",
      "aaaaaaaaaaaaaaaa",
      "aaaaaaaaaaaaaaaa",
      "aaaaaaaaaaaaaaaa",
      "aaaaaaaaaaaaaaaa",
      "aaaaaaiyiaaaaaaa",
      "aaaaaaaaaaaaaaaa",
      " aaaaaaaaaaaaaa ",
      " aaaaaaaaaaaaaa ",
      " aaaaaaaaaaaaaa ",
      "aaaaaaaaaaaaaaaa",
      "aa   aaaaaa   aa"
    ]
  ]
}