{
  "xsize": 16,
  "zsize": 16,
  "slices": [
    [
      "aa   aaaaaa   aa",
      "abddddddddddddba",
      " aaaaaaaaaaaaaa ",
      " aaaaaaaaaaaaaa ",
      " aaaaaaaaaaaaaa ",
      "aaaaaaaaaaaalaaa",
      "aaaaaaaaaaaaaaaa",
      "aaaaaaaaaaaaaaaa",
      "aaaaaaaaaaaaaaaa",
      "aaaaaaiyiaaaaaaa",
      "aaaalaaaaaaaaaaa",
      " aaaaaaaaaaaaaa ",
      " aaaaaaaaaaaaaa ",
      " aaaaaaaaaaaaaa ",
      "abddddddddddddba",
      "aa   aaaaaa   aa"
    ],
    [
      "aa   aaaaaa   aa",
      "aahhha    ahhhaa",
      " h            h ",
      " h            h ",
      " h            h ",
      "aaaa aaaaaaaaaaa",
      "a       jj     a",
      "a              a",
      "a              a",
      "a      y      xa",
      "aaaaaaaaaaa aaaa",
      " h            h ",
      " h            h ",
      " h            h ",
      "aahhha    ahhhaa",
      "aa   aaaaaa   aa"
    ],
    [
      "aa   aaaaaa   aa",
      "aahhha    ahhhaa",
      " h            h ",
      " h            h ",
      " h     k      h ",
      "aaaa aaaaaaaaaaa",
      "a      k       a",
      "a              a",
      "a              a",
      "a      y       a",
      "aaaaaaaaaaa aaaa",
      " h            h ",
      " h            h ",
      " h            h ",
      "aahhha    ahhhaa",
      "aa   aaaaaa   aa"
    ],
    [
      "aa   aaaaaa   aa",
      "aahhha    ahhhaa",
      " h            h ",
      " h            h ",
      " h            h ",
      "aaaaaaaaaaaaaaaa",
      "a            jja",
      "a              a",
      "a              a",
      "aj     y      ja",
      "aaaaaaaaaaaaaaaa",
      " h            h ",
      " h            h ",
      " h            h ",
      "aahhha    ahhhaa",
      "aa   aaaaaa   aa"
    ],
    [
      "aa   aaaaaa   aa",
      "aaaaaaaaaaaaaaaa",
      " aaaaaaaaaaaaaa ",
      " aaaaaaaaaaaaaa ",
      " aaaaaaaaaaaaaa ",
      "aaaaaaaaaaaaaaaa",
      "aaaaaaaaaaaaaaaa",
      "aaaaaaaaaaaaaaaa",
      "aaaaaaaaaaaaaaaa",
      "aaaaaaiyiaaaaaaa",
      "aaaaaaaaaaaaaaaa",
      " aaaaaaaaaaaaaa ",
      " aaaaaaaaaaaaaa ",
      " aaaaaaaaaaaaaa ",
      "aaaaaaaaaaaaaaaa",
      "aa   aaaaaa   aa"
    ],
    [
      "aa   aaaaaa   aa",
      "aaaaaaaaaaaaaaaa",
      " aaaaaaaaaaaaaa ",
      " aaaaaaaaaaaaaa ",
      " aaaaaaaaaaaaaa ",
      "aaaaaaaaaaaaaaaa",
      "aaaaaaaaaaaaaaaa",
      "aaaaaaaaaaaaaaaa",
      "aaaaaaaaaaaaaaaa",
      "aaaaaaiyiaaaaaaa",
      "aaaaaaaaaaaaaaaa",
      " aaaaaaaaaaaaaa ",
      " aaaaaaaaaaaaaa ",
      " aaaaaaaaaaaaaa ",
      "aaaaaaaaaaaaaaaa",
      "aa   aaaaaa   aa"
    ]
  ]
}