{
  "xsize": 16,
  "zsize": 16,
  "slices": [
    [
      "aSSSSSSSSSSSSSSa",
      "SbddddddddddddbS",
      "ScaaaaaaaaaaaacS",
      "ScaaaaaaaaaaaacS",
      "ScaaaaaaaaaaaacS",
      "ScaaaaaaaaaaaacS",
      "ScaaaaaaaaaaaacS",
      "ScaaaaaaaaaaaacS",
      "ScaaaaaaaaaaaacS",
      "ScaaaaaaaaaaaacS",
      "Scaaaaaaaa  aacS",
      "Scaaaaaaaa  aacS",
      "Scaaaaaaaa  aacS",
      "ScaaaaaaaaccaacS",
      "SbddddddddddddbS",
      "aSSSSSSSSSSSSSSa"
    ],
    [
      "ahhahhahhahhahha",
      "h  j  :        h",
      "h     :        h",
      "aj k  a        a",
      "h     :        h",
      "h     :        h",
      "a::a  a        a",
      "h              h",
      "h         cc   h",
      "a     a  :dd:  a",
      "h     :  :  :  h",
      "h     :  :  :  h",
      "a     a  :  :  a",
      "h     :        h",
      "h     :        h",
      "ahhahhahhahhahha"
    ],
    [
      "ahhahhahhahhahha",
      "h     :        h",
      "h     :        h",
      "a     a        a",
      "h     :        h",
      "h     :        h",
      "a::a  a        a",
      "h              h",
      "h              h",
      "a     a   cc   a",
      "h     :   dd   h",
      "h     :        h",
      "a     a        a",
      "h     :        h",
      "h     :        h",
      "ahhahhahhahhahha"
    ],
    [
      "ahhahhahhahhahha",
      "h     :        h",
      "h     :        h",
      "a     a        a",
      "h     :        h",
      "h     :        h",
      "a::a  a        a",
      "h              h",
      "h              h",
      "a     a        a",
      "h     :   cc   h",
      "h     :   dd   h",
      "a     a        a",
      "h     :        h",
      "h     :        h",
      "ahhahhahhahhahha"
    ],
    [
      "aSSSSSSSSSSSSSSa",
      "SaaaaaaaaaaaaaaS",
      "SaaaaaaaaaaaaaaS",
      "SaaaaaaaaaaaaaaS",
      "SaaaaaaaaaaaaaaS",
      "SaaaaaaaaaaaaaaS",
      "SaaaaaaaaaaaaaaS",
      "SaaaaaaaaaaaaaaS",
      "Saaaaaaaaa  aaaS",
      "Saaaaaaaaa  aaaS",
      "Saaaaaaaaa  aaaS",
      "SaaaaaaaaaccaaaS",
      "SaaaaaaaaaaaaaaS",
      "SaaaaaaaaaaaaaaS",
      "SaaaaaaaaaaaaaaS",
      "aSSSSSSSSSSSSSSa"
    ],
    [
      "aaaaaaaaaaaaaaaa",
      "aaaaaaaaaaaaaaaa",
      "aaaaaaaaaaaaaaaa",
      "aaaaaaaaaaaaaaaa",
      "aaaaaaaaaaaaaaaa",
      "aaaaaaaaaaaaaaaa",
      "aaaaaaaaaaaaaaaa",
      "aaaaaaaaaaaaaaaa",
      "aaaaaaaaaaaaaaaa",
      "aaaaaaaaaa  aaaa",
      "aaaaaaaaaa  aaaa",
      "aaaaaaaaaa  aaaa",
      "aaaaaaaaaaccaaaa",
      "aaaaaaaaaaaaaaaa",
      "aaaaaaaaaaaaaaaa",
      "aaaaaaaaaaaaaaaa"
    ]
  ]
}