{
  "xsize": 16,
  "zsize": 16,
  "slices": [
    [
      "aiiaiiaiiaiiaiia",
      "ibddddddddddddbi",
      "icaalaaaaaaaaaci",
      "acaaaaaaaaaaaaca",
      "icaaaalaaaaaaaci",
      "ibddddddddbaaaci",
      "acaaaaaaaacaaaca",
      "ibddddddbacaaaci",
      "icaaaaaacacaaaci",
      "abddddiyiacaaaca",
      "icaaaaaaaacaaaci",
      "ibddddddddbaaaci",
      "acaaaaaaaaaaaaca",
      "icaaaaaaaaaaaaci",
      "ibddddddddddddbi",
      "aiiaiiaiiaiiaiia"
    ],
    [
      "aaaaaaaaaaaaaaaa",
      "a           jjja",
      "a   beb      jja",
      "a   eae      jja",
      "a   beb       ja",
      "a              a",
      "aaaaaaaaaa     a",
      "ajj      ajj   a",
      "aj       aj    a",
      "a      y aj    a",
      "a  aaaaaaa    ja",
      "a    jjjj     ja",
      "aj     j     jja",
      "aj           jja",
      "ajj            a",
      "aaaaaaaaaaaaaaaa"
    ],
    [
      "ahhahhahhahhahha",
      "h        r    jh",
      "h   bfb       jh",
      "aq  fxf        a",
      "h   bfb        h",
      "h       k      h",
      "aaaahhhaaa    sa",
      "hj       a     h",
      "h       saj    h",
      "a      y a     a",
      "h  aaaaaaa     h",
      "h     kjj     kh",
      "ak            ja",
      "h              h",
      "h j   k     k  h",
      "ahhahhahhahhahha"
    ],
    [
      "ahhahhahhahhahha",
      "h             jh",
      "h   bgb       kh",
      "a   g g        a",
      "h   bgb        h",
      "h              h",
      "aaaaaaaaaa     a",
      "h        a     h",
      "h        ak    h",
      "a      y a     a",
      "h  aaaaaaa     h",
      "h              h",
      "a             ja",
      "h              h",
      "h              h",
      "ahhahhahhahhahha"
    ],
    [
      "aaaaaaaaaaaaaaaa",
      "abddddddddddddba",
      "acaaaaaaaaaaaaca",
      "acaaaaaaaaaaaaca",
      "acaaaaaaaaaaaaca",
      "acaaaaaaaaaaaaca",
      "acaaaaaaaaaaaaca",
      "acaaaaaaaaaaaaca",
      "acaaaaaaaaaaaaca",
      "acaaaaiyiaaaaaca",
      "acaaaaaaaaaaaaca",
      "acaaaaaaaaaaaaca",
      "acaaaaaaaaaaaaca",
      "acaaaaaaaaaaaaca",
      "acaaaaaaaaaaaaca",
      "abddddddddddddba"
    ],
    [
      "aaaaaaaaaaaaaaaa",
      "abddddddddddddba",
      "acaaaaaaaaaaaaca",
      "acaaaaaaaaaaaaca",
      "acaaaaaaaaaaaaca",
      "acaaaaaaaaaaaaca",
      "acaaaaaaaaaaaaca",
      "acaaaaaaaaaaaaca",
      "acaaaaaaaaaaaaca",
      "acaaaaiyiaaaaaca",
      "acaaaaaaaaaaaaca",
      "acaaaaaaaaaaaaca",
      "acaaaaaaaaaaaaca",
      "acaaaaaaaaaaaaca",
      "acaaaaaaaaaaaaca",
      "abddddddddddddba"
    ]
  ]
}