{
  "xsize": 16,
  "zsize": 16,
  "slices": [
    [
      "aaaaaaaaaaaaaaaa",
      "abddddddddddddba",
      "acaaaaaaaaaaaaca",
      "acaaaaaaaaaaaaca",
      "acaaaaaaaaaaaaca",
      "acaaaaaaaaaaaaca",
      "acaaaaaaaaaaaaca",
      "acaaaaaaaaaaaaca",
      "acaaaaaaaaaaaaca",
      "acaaaa$l$aaaaaca",
      "acaaaaaaaaaaaaca",
      "acaaaaaaaaaaaaca",
      "acaaaaaaaaaaaaca",
      "acaaaaaaaaaaaaca",
      "abddddddddddddba",
      "aaaaaaaaaaaaaaaa"
    ],
    [
      "a44@44444444@44a",
      "4              4",
      "4              4",
      "@              @",
      "4              4",
      "4              4",
      "4    aa aa     4",
      "4    a   aaaaaa4",
      "4              4",
      "4    a l a     4",
      "4    aaaaa     4",
      "4      Fa      4",
      "@       a      @",
      "4              4",
      "4       a      4",
      "a44@44444444@44a"
    ],
    [
      "a44@44444444@44a",
      "4              4",
      "4              4",
      "@              @",
      "4              4",
      "4              4",
      "4    aa aa     4",
      "4    a   aaa:aa4",
      "4          T T 4",
      "4    a l a     4",
      "4    aaaaa     4",
      "4       a      4",
      "@       a      @",
      "4              4",
      "4       a      4",
      "a44@44444444@44a"
    ],
    [
      "a44@44444444@44a",
      "4              4",
      "4              4",
      "@              @",
      "4              4",
      "4              4",
      "4    aaaaa     4",
      "4    a   aaaaaa4",
      "4    a   a     4",
      "4    a l a     4",
      "4    aaaaa     4",
      "4       a      4",
      "@       a      @",
      "4       a      4",
      "4       a      4",
      "a44@44444444@44a"
    ],
    [
      "aaaaaaaaaaaaaaaa",
      "abddddddddddddba",
      "acaaaaaaaaaaaaca",
      "acaaaaaaaaaaaaca",
      "acaaaaaaaaaaaaca",
      "acaaaaaaaaaaaaca",
      "acaaaaaaaaaaaaca",
      "acaaaaaaaaaaaaca",
      "acaaaaaaaaaaaaca",
      "acaaaa$l$aaaaaca",
      "acaaaaaaaaaaaaca",
      "acaaaaaaaaaaaaca",
      "acaaaaaaaaaaaaca",
      "acaaaaaaaaaaaaca",
      "acaaaaaaaaaaaaca",
      "abddddddddddddba"
    ],
    [
      "aaaaaaaaaaaaaaaa",
      "abddddddddddddba",
      "acaaaaaaaaaaaaca",
      "acaaaaaaaaaaaaca",
      "acaaaaaaaaaaaaca",
      "acaaaaaaaaaaaaca",
      "acaaaaaaaaaaaaca",
      "acaaaaaaaaaaaaca",
      "acaaaaaaaaaaaaca",
      "acaaaa$l$aaaaaca",
      "acaaaaaaaaaaaaca",
      "acaaaaaaaaaaaaca",
      "acaaaaaaaaaaaaca",
      "acaaaaaaaaaaaaca",
      "acaaaaaaaaaaaaca",
      "abddddddddddddba"
    ]
  ]
}