{
  "xsize": 16,
  "zsize": 16,
  "slices": [
    [
      "aSSSSSSSSSSSSSSa",
      "SbddddddddddddbS",
      "ScaaaaaaaaaaaacS",
      "ScalaaiaaaaalacS",
      "ScaaaaaaaaaaaacS",
      "ScaaaaaaaaaaaacS",
      "ScaaaalaaaaaaacS",
      "ScaaaaaaaaaaaacS",
      "ScaaaaaaaaaaaacS",
      "ScaaaaaaaaaaaacS",
      "Scaaaaaaaa  aacS",
      "Scaaaaiaaa  aacS",
      "Scalaaaaaa  aacS",
      "ScaaaaaaaaaQaacS",
      "SbddddddddddddbS",
      "aSSSSSSSSSSSSSSa"
    ],
    [
      "ahhahhahhahhahha",
      "hxjjj a        h",
      "hjj   a    jj  h",
      "ajjj      jjj  a",
      "hjj   a    j   h",
      "hj    a   j    h",
      "aaaaaaaj       a",
      "hjjj aaj       h",
      "hj   aaj   Q   h",
      "a    aa  NaaM  a",
      "h     a  H  H  h",
      "h        H  H  h",
      "a  j ja  H  H  a",
      "h   jja        h",
      "h   jja        h",
      "ahhahhahhahhahha"
    ],
    [
      "ahhahhahhahhahha",
      "hjj   a  r     h",
      "hj    a    jj  h",
      "ajk           sa",
      "h     aq   k   h",
      "h     a        h",
      "aaHHHaak       a",
      "hj    aj       h",
      "h    ka        h",
      "aq    a    Q  sa",
      "h     a   aa   h",
      "h              h",
      "a     aq       a",
      "h   kja        h",
      "h  p ja     p  h",
      "ahhahhahhahhahha"
    ],
    [
      "ahhahhahhahhahha",
      "hj    a        h",
      "h     a        h",
      "ak    a        a",
      "h     a        h",
      "h     a        h",
      "aaaaaaa        a",
      "h     a        h",
      "h     a        h",
      "a     a        a",
      "h     a    Q   h",
      "h     a   aa   h",
      "a     a        a",
      "h     a        h",
      "h    ja        h",
      "ahhahhahhahhahha"
    ],
    [
      "aSSSSSSSSSSSSSSa",
      "SaaaaaaaaaaaaaaS",
      "SaaaaaaaaaaaaaaS",
      "SaaaaaaaaaaaaaaS",
      "SaaaaaaaaaaaaaaS",
      "SaaaaaaaaaaaaaaS",
      "SaaaaaaaaaaaaaaS",
      "SaaaaaaaaaaaaaaS",
      "Saaaaaaaaa  aaaS",
      "Saaaaaaaaa  aaaS",
      "Saaaaaaaaa  aaaS",
      "SaaaaaaaaaaQaaaS",
      "SaaaaaaaaaaaaaaS",
      "SaaaaaaaaaaaaaaS",
      "SaaaaaaaaaaaaaaS",
      "aSSSSSSSSSSSSSSa"
    ],
    [
      "aaaaaaaaaaaaaaaa",
      "aaaaaaaaaaaaaaaa",
      "aaaaaaaaaaaaaaaa",
      "aaaaaaaaaaaaaaaa",
      "aaaaaaaaaaaaaaaa",
      "aaaaaaaaaaaaaaaa",
      "aaaaaaaaaaaaaaaa",
      "aaaaaaaaaaaaaaaa",
      "aaaaaaaaaaaaaaaa",
      "aaaaaaaaaa  aaaa",
      "aaaaaaaaaa  aaaa",
      "aaaaaaaaaa  aaaa",
      "aaaaaaaaaaaQaaaa",
      "aaaaaaaaaaaaaaaa",
      "aaaaaaaaaaaaaaaa",
      "aaaaaaaaaaaaaaaa"
    ]
  ]
}