{
  "xsize": 16,
  "zsize": 16,
  "slices": [
    [
      "aaaaaaaaaaaaaaaa",
      "abddddddddddddba",
      "acaaaaaaaaaaaaca",
      "acaaaaaaaaaaaaca",
      "acaaaaaaaaaaaaca",
      "acaaaaaaaaaaaaca",
      "acaaaaaaaaaaaaca",
      "acaaaaaaaaaaaaca",
      "acaaaaaaaaaaaaca",
      "acaaaa$l$aaaaaca",
      "acaaaaaaaaaaaaca",
      "acaaaaaaaaaaaaca",
      "acaaaaaaaaaaaaca",
      "acaaaaaaaaaaaaca",
      "abddddddddddddba",
      "aaaaaaaaaaaaaaaa"
    ],
    [
      "aa___aaaaaa___aa",
      "aaaaaa    aaaaaa",
      "_aDa        aDa_",
      "_aDa        aDa_",
      "_aDa        aDa_",
      "aaaa        aaaa",
      "a              a",
      "aF            La",
      "aF            La",
      "a      l       a",
      "aa    aaa     aa",
      "_a            a_",
      "_a    . .     a_",
      "_a            a_",
      "aaaaaa    aaaaaa",
      "aa___aaaaaa___aa"
    ],
    [
      "aa   aaaaaa   aa",
      "aa444a    a444aa",
      " 4K          K4 ",
      " 4K          K4 ",
      " 4K          K4 ",
      "aa            aa",
      "a              a",
      "a             La",
      "a             La",
      "a      l       a",
      "aa    aaa     aa",
      " 4            4 ",
      " 4    - -     4 ",
      " 4            4 ",
      "aa444a    a444aa",
      "aa   aaaaaa   aa"
    ],
    [
      "aa   aaaaaa   aa",
      "aa444a    a444aa",
      " 4            4 ",
      " 4            4 ",
      " 4            4 ",
      "aaT          Taa",
      "a              a",
      "a              a",
      "a              a",
      "a      l       a",
      "aaT   aaa    Taa",
      " 4            4 ",
      " 4            4 ",
      " 4            4 ",
      "aa444a    a444aa",
      "aa   aaaaaa   aa"
    ],
    [
      "aa   aaaaaa   aa",
      "aa444a    a444aa",
      " 4            4 ",
      " 4            4 ",
      " 4            4 ",
      "aa            aa",
      "a              a",
      "a              a",
      "a              a",
      "a      l       a",
      "aa    aaa     aa",
      " 4            4 ",
      " 4            4 ",
      " 4            4 ",
      "aa444a    a444aa",
      "aa   aaaaaa   aa"
    ],
    [
      "aa===aaaaaa===aa",
      "aaaaaaaaaaaaaaaa",
      "=aaaaaaaaaaaaaa=",
      "=aaaaaaaaaaaaaa=",
      "=aaaaaaaaaaaaaa=",
      "aaaaaaaaaaaaaaaa",
      "aaaaaaaaaaaaaaaa",
      "aaaaaaaaaaaaaaaa",
      "aaaaaaaaaaaaaaaa",
      "aaaaaa$l$aaaaaaa",
      "aaaaaaaaaaaaaaaa",
      "=aaaaaaaaaaaaaa=",
      "=aaaaaaaaaaaaaa=",
      "=aaaaaaaaaaaaaa=",
      "aaaaaaaaaaaaaaaa",
      "aa===aaaaaa===aa"
    ]
  ]
}