{
  "xsize": 16,
  "zsize": 16,
  "slices": [
    [
      "aaaaaaaaaaaaaaaa",
      "abddddddddddddba",
      "acaaaaaaaaaaaaca",
      "acaaaaaaaaaaaaca",
      "acaaaaaaaaaaaaca",
      "acaaaaaaaaaaaaca",
      "acaaaaaaaaaaaaca",
      "acaaaaaaaaaaaaca",
      "acaaaaaaaaaaaaca",
      "acaaaa$l$aaaaaca",
      "acaaaaaaaaaaaaca",
      "acaaaaaaaaaaaaca",
      "acaaaaaaaaaaaaca",
      "acaaaaaaaaaaaaca",
      "abddddddddddddba",
      "aaaaaaaaaaaaaaaa"
    ],
    [
      "a44@44444444@44a",
      "4      a       4",
      "4      a       4",
      "@              @",
      "4      a       4",
      "4      a       4",
      "4    aaaaa     4",
      "4    a   a     4",
      "4    a   aL    4",
      "4      l aL    4",
      "4aaaaaaaaa     4",
      "4    F         4",
      "@              @",
      "4              4",
      "4              4",
      "a44@44444444@44a"
    ],
    [
      "a44@44444444@44a",
      "4      a       4",
      "4      a       4",
      "@              @",
      "4      a       4",
      "4      a       4",
      "4    aaaaa     4",
      "4    a T a     4",
      "4    a   aL    4",
      "4      l aL    4",
      "4aaaaaaaaa     4",
      "4              4",
      "@              @",
      "4              4",
      "4              4",
      "a44@44444444@44a"
    ],
    [
      "a44@44444444@44a",
      "4      a       4",
      "4      a       4",
      "@      a       @",
      "4      a       4",
      "4      a       4",
      "4    aaaaa     4",
      "4    a   a     4",
      "4    a   a     4",
      "4    a l a     4",
      "4aaaaaaaaa     4",
      "4              4",
      "@              @",
      "4              4",
      "4              4",
      "a44@44444444@44a"
    ],
    [
      "aaaaaaaaaaaaaaaa",
      "abddddddddddddba",
      "acaaaaaaaaaaaaca",
      "acaaaaaaaaaaaaca",
      "acaaaaaaaaaaaaca",
      "acaaaaaaaaaaaaca",
      "acaaaaaaaaaaaaca",
      "acaaaaaaaaaaaaca",
      "acaaaaaaaaaaaaca",
      "acaaaa$l$aaaaaca",
      "acaaaaaaaaaaaaca",
      "acaaaaaaaaaaaaca",
      "acaaaaaaaaaaaaca",
      "acaaaaaaaaaaaaca",
      "acaaaaaaaaaaaaca",
      "abddddddddddddba"
    ],
    [
      "aaaaaaaaaaaaaaaa",
      "abddddddddddddba",
      "acaaaaaaaaaaaaca",
      "acaaaaaaaaaaaaca",
      "acaaaaaaaaaaaaca",
      "acaaaaaaaaaaaaca",
      "acaaaaaaaaaaaaca",
      "acaaaaaaaaaaaaca",
      "acaaaaaaaaaaaaca",
      "acaaaa$l$aaaaaca",
      "acaaaaaaaaaaaaca",
      "acaaaaaaaaaaaaca",
      "acaaaaaaaaaaaaca",
      "acaaaaaaaaaaaaca",
      "acaaaaaaaaaaaaca",
      "abddddddddddddba"
    ]
  ]
}