{
  "xsize": 16,
  "zsize": 16,
  "slices": [
    [
      "##   ######   ##",
      "#bddddddddddddb#",
      " ############## ",
      " ############## ",
      " ############## ",
      "################",
      "################",
      "################",
      "################",
      "######$l$#######",
      "################",
      " ############## ",
      " ############## ",
      " ############## ",
      "#bddddddddddddb#",
      "##   ######   ##"
    ],
    [
      "##   ######   ##",
      "##aaa#    #aaa##",
      " a            a ",
      " a            a ",
      " a            a ",
      "##            ##",
      "#              #",
      "#              #",
      "#              #",
      "#      l       #",
      "##    ###     ##",
      " a            a ",
      " a            a ",
      " a            a ",
      "##aaa#    #aaa##",
      "##   ######   ##"
    ],
    [
      "##   ######   ##",
      "##aaa#    #aaa##",
      " a            a ",
      " a            a ",
      " a            a ",
      "##            ##",
      "#              #",
      "#              #",
      "#              #",
      "#      l       #",
      "##    ###     ##",
      " a     T      a ",
      " a            a ",
      " a            a ",
      "##aaa#    #aaa##",
      "##   ######   ##"
    ],
    [
      "##   ######   ##",
      "##aaa#    #aaa##",
      " a            a ",
      " a            a ",
      " a            a ",
      "##            ##",
      "#              #",
      "#              #",
      "#              #",
      "#      l       #",
      "##    ###     ##",
      " a            a ",
      " a            a ",
      " a            a ",
      "##aaa#    #aaa##",
      "##   ######   ##"
    ],
    [
      "##   ######   ##",
      "################",
      " ############## ",
      " ############## ",
      " ############## ",
      "################",
      "################",
      "################",
      "################",
      "######$l$#######",
      "################",
      " ############## ",
      " ############## ",
      " ############## ",
      "################",
      "##   ######   ##"
    ],
    [
      "##   ######   ##",
      "################",
      " ############## ",
      " ############## ",
      " ############## ",
      "################",
      "################",
      "################",
      "################",
      "######$l$#######",
      "################",
      " ############## ",
      " ############## ",
      " ############## ",
      "################",
      "##   ######   ##"
    ]
  ]
}