{
  "xsize": 16,
  "zsize": 16,
  "slices": [
    [
      "aaaaaaaaaaaaaaaa",
      "abddddbddbddddba",
      "acaabdbaabdbaaca",
      "acaacaaaaaaIaaca",
      "acaacaaaaaaIaaca",
      "acaacamaamaIaaca",
      "abddbaaaaaaabKba",
      "acaaaaaaaaaaaaca",
      "acaaaaaaaaaaaaca",
      "abbaaaiyiaaaabba",
      "accaaaaaaaaaacca",
      "accaaaaaaaaaacca",
      "accmaaanaaaamcca",
      "accdddbaaaabKbca",
      "abbdddbddbddddba",
      "aaaaaaaaaaaaaaaa"
    ],
    [
      "aaGGGaaaaaaGGGaa",
      "aaaaaa    aaaaaa",
      "Gaza        azaG",
      "Gaza   j    azaG",
      "Gaza j jj   azaG",
      "aaaa jjjjj  aaaa",
      "a      j j     a",
      "aj   j    j   ja",
      "aj         j  ja",
      "a      y       a",
      "aa    aaa    jaa",
      "Gaj   j     jjaG",
      "Gajj   j   jjjaG",
      "Gajjjj     jjjaG",
      "aaaaaa    aaaaaa",
      "aaGGGaaaaaaGGGaa"
    ],
    [
      "aa   aaaaaa   aa",
      "aahhha    ahhhaa",
      " hk          kh ",
      " hk          kh ",
      " hk          kh ",
      "aa    jjj     aa",
      "a      j       a",
      "a             ja",
      "ak            ja",
      "a      y       a",
      "aa    aaa     aa",
      " h    j       h ",
      " hj    k    k h ",
      " hjjj       jjh ",
      "aahhha    ahhhaa",
      "aa   aaaaaa   aa"
    ],
    [
      "aa   aaaaaa   aa",
      "aahhha    ahhhaa",
      " h   r    r   h ",
      " h            h ",
      " h            h ",
      "aaq   kj     saa",
      "a              a",
      "a             ka",
      "a              a",
      "a      y       a",
      "aaq   aaa    saa",
      " h            h ",
      " h            h ",
      " h jkp    p  jh ",
      "aahhha    ahhhaa",
      "aa   aaaaaa   aa"
    ],
    [
      "aa   aaaaaa   aa",
      "aahhha    ahhhaa",
      " h            h ",
      " h            h ",
      " h            h ",
      "aa            aa",
      "a              a",
      "a              a",
      "a              a",
      "a      y       a",
      "aa    aaa     aa",
      " h            h ",
      " h            h ",
      " h            h ",
      "aahhha    ahhhaa",
      "aa   aaaaaa   aa"
    ],
    [
      "aaGGGaaaaaaGGGaa",
      "aaaaaaaaaaaaaaaa",
      "GaaaaaaaaaaaaaaG",
      "GaaaaaaaaaaaaaaG",
      "GaaaaaaaaaaaaaaG",
      "aaaaaaaaaaaaaaaa",
      "aaaaaaaaaaaaaaaa",
      "aaaaaaaaaaaaaaaa",
      "aaaaaaaaaaaaaaaa",
      "aaaaaaiyiaaaaaaa",
      "aaaaaaaaaaaaaaaa",
      "GaaaaaaaaaaaaaaG",
      "GaaaaaaaaaaaaaaG",
      "GaaaaaaaaaaaaaaG",
      "aaaaaaaaaaaaaaaa",
      "aaGGGaaaaaaGGGaa"
    ]
  ]
}