{
  "xsize": 16,
  "zsize": 16,
  "slices": [
    [
      "aaaaaaaaaaaaaaaa",
      "abddddddddddddba",
      "acaaaaaaaaaaaaca",
      "acaaaaaaaaaaaaca",
      "acaaaaaaaaaaaaca",
      "acaaaaaaaaaaaaca",
      "acaaaaaaaaaaaaca",
      "acaaaaaaaaaaaaca",
      "acaaaaaaaaaaaaca",
      "acaaaaiyiaaaaaca",
      "acaaaaaaaaaaaaca",
      "acaaaaaaaaaaaaca",
      "acaaaaaaaaaaaaca",
      "acaaaaaaaaaaaaca",
      "abddddddddddddba",
      "aaaaaaaaaaaaaaaa"
    ],
    [
      "ahhahhhhhhhhahha",
      "h              h",
      "h              h",
      "a              a",
      "h              h",
      "h              h",
      "h    aa aa     h",
      "h    a   a     h",
      "h    a   a     h",
      "h    a y a     h",
      "ha aaaaaaaaaaaah",
      "h     jjj      h",
      "a              a",
      "h              h",
      "h              h",
      "ahhahhhhhhhhahha"
    ],
    [
      "ahhahhhhhhhhahha",
      "h              h",
      "h              h",
      "a              a",
      "h              h",
      "h              h",
      "h    aa aa     h",
      "h    a  ka     h",
      "h    a   a     h",
      "h    a y a     h",
      "ha aaaaaaaahhhah",
      "h              h",
      "a              a",
      "h              h",
      "h              h",
      "ahhahhhhhhhhahha"
    ],
    [
      "ahhahhhhhhhhahha",
      "h              h",
      "h              h",
      "a              a",
      "h              h",
      "h              h",
      "h    aaaaa     h",
      "h    a   a     h",
      "h    a   a     h",
      "h    a y a     h",
      "haaaaaaaaaaaaaah",
      "h              h",
      "a              a",
      "h              h",
      "h              h",
      "ahhahhhhhhhhahha"
    ],
    [
      "aaaaaaaaaaaaaaaa",
      "aaaaaaaaaaaaaaaa",
      "aaalaaaaaaaaaaaa",
      "aaaaaaaaaaaaaaaa",
      "aaaaaaaaaaaalaaa",
      "aaaaaaaaaaaaaaaa",
      "aaaaaaaaaaaaaaaa",
      "aaaaaaaaaaaaaaaa",
      "aaaaaaaaaaaaaaaa",
      "aaaaaaiyiaaaaaaa",
      "aaaaaaaaaaaaaaaa",
      "aaaaaaaaaaaaaaaa",
      "aaaaaaaaaaaaaaaa",
      "aaaaaaaaaaaaaaaa",
      "aaaaaaaaaaaaaaaa",
      "aaaaaaaaaaaaaaaa"
    ],
    [
      "aaaaaaaaaaaaaaaa",
      "abddddddddddddba",
      "acaaaaaaaaaaaaca",
      "acaaaaaaaaaaaaca",
      "acaaaaaaaaaaaaca",
      "acaaaaaaaaaaaaca",
      "acaaaaaaaaaaaaca",
      "acaaaaaaaaaaaaca",
      "acaaaaaaaaaaaaca",
      "acaaaaiyiaaaaaca",
      "acaaaaaaaaaaaaca",
      "acaaaaaaaaaaaaca",
      "acaaaaaaaaaaaaca",
      "acaaaaaaaaaaaaca",
      "acaaaaaaaaaaaaca",
      "abddddddddddddba"
    ]
  ]
}