{
  "xsize": 16,
  "zsize": 16,
  "slices": [
    [
      "aaaaaaaaaaaaaaaa",
      "abddddddddddddba",
      "acaaaaaaaaaaaaca",
      "acamaaaaaaaamaca",
      "acaaaaaaaaaaaaca",
      "acaaaaaiiaaaaaca",
      "acaaaaaaaaaaaaca",
      "acamaaaaaaaamaca",
      "acaaaaaaaaaaaaca",
      "acaaaaiyiaaaaaca",
      "acaaaaaaaaaaaaca",
      "acaaaaaaaaaaaaca",
      "acaaaaaaaaaaaaca",
      "acaaaaaaaaaaaaca",
      "abddddddddddddba",
      "aaaaaaaaaaaaaaaa"
    ],
    [
      "aaGGGaaaaaaGGGaa",
      "aaaaaa jjjaaaaaa",
      "Gajj    j   jjaG",
      "Gajjjj      jjaG",
      "Gajjj        jaG",
      "aaaaaaa  aaaaaaa",
      "ajjj        jj a",
      "ajjjj       j  a",
      "aj j           a",
      "a  jj  y       a",
      "aa    aaa  j  aa",
      "Ga          jjaG",
      "Ga         jjjaG",
      "Ga   jjj     jaG",
      "aaaaaajjj aaaaaa",
      "aaGGGaaaaaaGGGaa"
    ],
    [
      "aa   aaaaaa   aa",
      "aahhha  jjahhhaa",
      " hj          jh ",
      " hjk        k h ",
      " h j          h ",
      "aahhhha  ahhhhaa",
      "a kj        j  a",
      "aj  j       k  a",
      "a              a",
      "a  j   y       a",
      "aa    aaa     aa",
      " h           jh ",
      " h          k h ",
      " h    k      jh ",
      "aahhha j  ahhhaa",
      "aa   aaaaaa   aa"
    ],
    [
      "aa   aaaaaa   aa",
      "aahhha  kjahhhaa",
      " h   r    r   h ",
      " h            h ",
      " h    p  p    h ",
      "aahhhhaaaahhhhaa",
      "a     r  r     a",
      "a              a",
      "a              a",
      "a      y       a",
      "aaq   aaa    saa",
      " h            h ",
      " h            h ",
      " h   p    p   h ",
      "aahhha    ahhhaa",
      "aa   aaaaaa   aa"
    ],
    [
      "aa   aaaaaa   aa",
      "aahhha    ahhhaa",
      " h            h ",
      " h            h ",
      " h            h ",
      "aaaaaaaaaaaaaaaa",
      "a              a",
      "a              a",
      "a              a",
      "a      y       a",
      "aa    aaa     aa",
      " h            h ",
      " h            h ",
      " h            h ",
      "aahhha    ahhhaa",
      "aa   aaaaaa   aa"
    ],
    [
      "aaGGGaaaaaaGGGaa",
      "aaaaaaaaaaaaaaaa",
      "GaaaaaaaaaaaaaaG",
      "GaaaaaaaaaaaaaaG",
      "GaaaaaaaaaaaaaaG",
      "aaaaaaaaaaaaaaaa",
      "aaaaaaaaaaaaaaaa",
      "aaaaaaaaaaaaaaaa",
      "aaaaaaaaaaaaaaaa",
      "aaaaaaiyiaaaaaaa",
      "aaaaaaaaaaaaaaaa",
      "GaaaaaaaaaaaaaaG",
      "GaaaaaaaaaaaaaaG",
      "GaaaaaaaaaaaaaaG",
      "aaaaaaaaaaaaaaaa",
      "aaGGGaaaaaaGGGaa"
    ]
  ]
}