{
  "xsize": 16,
  "zsize": 16,
  "slices": [
    [
      "a$$a$$a$$a$$a$$a",
      "$bddddddddddddb$",
      "$caaaaaaaaaaaac$",
      "acaaaaaaaaaaaaca",
      "$caaeaaaaaaeaac$",
      "$caaaaaaaaaaaac$",
      "acaaaaaaaaaaaaca",
      "$caaaaaaaaaaaac$",
      "$caaaaaaaaaaaac$",
      "acaaaa$l$aaaaaca",
      "$caaaaaaaaaaaac$",
      "$caaeaaaaaaeaac$",
      "acaaaaaaaaaaaaca",
      "$caaaaaaaaaaaac$",
      "$bddddddddddddb$",
      "a$$a$$a$$a$$a$$a"
    ],
    [
      "aaaaaaaaaaaaaaaa",
      "a iii          a",
      "a  ii  i  ii   a",
      "a  i    ii i   a",
      "a iiiii  i ii  a",
      "aiiii iiii i   a",
      "a   i i        a",
      "a  ii         ia",
      "a  ii        iia",
      "a      l      ia",
      "a     aaa i    a",
      "a i i    iiii  a",
      "a  ii     ii   a",
      "a              a",
      "a              a",
      "aaaaaaaaaaaaaaaa"
    ],
    [
      "a44a44a44a44a44a",
      "4 iii j     j  4",
      "4 ii      k    4",
      "am i     i i   a",
      "4 i  k      i  4",
      "4     i        4",
      "a             na",
      "4             i4",
      "4  i          i4",
      "am     l       a",
      "4     aaa k    4",
      "4         i    4",
      "a   k         na",
      "4              4",
      "4  o     o     4",
      "a44a44a44a44a44a"
    ],
    [
      "a44a44a44a44a44a",
      "4 ik           4",
      "4              4",
      "a  i           a",
      "4              4",
      "4              4",
      "a              a",
      "4              4",
      "4  k          k4",
      "a      l       a",
      "4     aaa      4",
      "4              4",
      "a              a",
      "4              4",
      "4              4",
      "a44a44a44a44a44a"
    ],
    [
      "aaaaaaaaaaaaaaaa",
      "abddddddddddddba",
      "acaaaaaaaaaaaaca",
      "acaaaaaaaaaaaaca",
      "acaaaaaaaaaaaaca",
      "acaaaaaaaaaaaaca",
      "acaaaaaaaaaaaaca",
      "acaaaaaaaaaaaaca",
      "acaaaaaaaaaaaaca",
      "acaaaa$l$aaaaaca",
      "acaaaaaaaaaaaaca",
      "acaaaaaaaaaaaaca",
      "acaaaaaaaaaaaaca",
      "acaaaaaaaaaaaaca",
      "acaaaaaaaaaaaaca",
      "abddddddddddddba"
    ],
    [
      "aaaaaaaaaaaaaaaa",
      "abddddddddddddba",
      "acaaaaaaaaaaaaca",
      "acaaaaaaaaaaaaca",
      "acaaaaaaaaaaaaca",
      "acaaaaaaaaaaaaca",
      "acaaaaaaaaaaaaca",
      "acaaaaaaaaaaaaca",
      "acaaaaaaaaaaaaca",
      "acaaaa$l$aaaaaca",
      "acaaaaaaaaaaaaca",
      "acaaaaaaaaaaaaca",
      "acaaaaaaaaaaaaca",
      "acaaaaaaaaaaaaca",
      "acaaaaaaaaaaaaca",
      "abddddddddddddba"
    ]
  ]
}