{
  "xsize": 16,
  "zsize": 16,
  "slices": [
    [
      "aaaaaaaaaaaaaaaa",
      "abddddddddddddba",
      "acaaaaaaaaaaaaca",
      "acaaaaaaaaaaaaca",
      "acaaaaaaaaaaaaca",
      "acaaaaaaaaaaaaca",
      "acaaaaaaaaaaaaca",
      "acaaaaaaaaaaaaca",
      "acaaaaaaaaaaaaca",
      "acaaaailiaaaaaca",
      "acaaaaaaaaaaaaca",
      "acaaaaaaaaaaaaca",
      "acaaaaaaaaaaaaca",
      "acaaaaaaaaaaaaca",
      "abddddddddddddba",
      "aaaaaaaaaaaaaaaa"
    ],
    [
      "ahh@hhhhhhhh@hha",
      "h      a       h",
      "h      a       h",
      "@              @",
      "h      a       h",
      "h      a       h",
      "h    aaaaa     h",
      "h    a   a     h",
      "h    a   aj    h",
      "h      l aj    h",
      "haaaaaaaaa     h",
      "h    j         h",
      "@              @",
      "h              h",
      "h              h",
      "ahh@hhhhhhhh@hha"
    ],
    [
      "ahh@hhhhhhhh@hha",
      "h      a       h",
      "h      a       h",
      "@              @",
      "h      a       h",
      "h      a       h",
      "h    aaaaa     h",
      "h    a k a     h",
      "h    a   aj    h",
      "h      l aj    h",
      "haaaaaaaaa     h",
      "h              h",
      "@              @",
      "h              h",
      "h              h",
      "ahh@hhhhhhhh@hha"
    ],
    [
      "ahh@hhhhhhhh@hha",
      "h      a       h",
      "h      a       h",
      "@      a       @",
      "h      a       h",
      "h      a       h",
      "h    aaaaa     h",
      "h    a   a     h",
      "h    a   a     h",
      "h    a l a     h",
      "haaaaaaaaa     h",
      "h              h",
      "@              @",
      "h              h",
      "h              h",
      "ahh@hhhhhhhh@hha"
    ],
    [
      "aaaaaaaaaaaaaaaa",
      "abddddddddddddba",
      "acaaaaaaaaaaaaca",
      "acaaaaaaaaaaaaca",
      "acaaaaaaaaaaaaca",
      "acaaaaaaaaaaaaca",
      "acaaaaaaaaaaaaca",
      "acaaaaaaaaaaaaca",
      "acaaaaaaaaaaaaca",
      "acaaaailiaaaaaca",
      "acaaaaaaaaaaaaca",
      "acaaaaaaaaaaaaca",
      "acaaaaaaaaaaaaca",
      "acaaaaaaaaaaaaca",
      "acaaaaaaaaaaaaca",
      "abddddddddddddba"
    ],
    [
      "aaaaaaaaaaaaaaaa",
      "abddddddddddddba",
      "acaaaaaaaaaaaaca",
      "acaaaaaaaaaaaaca",
      "acaaaaaaaaaaaaca",
      "acaaaaaaaaaaaaca",
      "acaaaaaaaaaaaaca",
      "acaaaaaaaaaaaaca",
      "acaaaaaaaaaaaaca",
      "acaaaailiaaaaaca",
      "acaaaaaaaaaaaaca",
      "acaaaaaaaaaaaaca",
      "acaaaaaaaaaaaaca",
      "acaaaaaaaaaaaaca",
      "acaaaaaaaaaaaaca",
      "abddddddddddddba"
    ]
  ]
}