{
  "xsize": 16,
  "zsize": 16,
  "slices": [
    [
      "aSSSSSSSSSSSSSSa",
      "SbddddddddddddbS",
      "ScaaaaaaaaaaaacS",
      "ScalaaalaaaalacS",
      "ScaaaaaaaaaaaacS",
      "ScaaaaaaaaaaaacS",
      "ScaalaaaaaaaaacS",
      "ScaaaaaaaaaaaacS",
      "ScaaaaaaaaaaaacS",
      "Scaaaaaaaa  aacS",
      "Scaaaaaaaa  aacS",
      "Scaaaaaaaa  aacS",
      "ScalaaaaaaaQaacS",
      "ScaaaaaaaaaaaacS",
      "SbddddddddddddbS",
      "aSSSSSSSSSSSSSSa"
    ],
    [
      "ahhahhahhahhahha",
      "h  j     jj    h",
      "h  j     jjjj  h",
      "ajjjj jjjj  j ja",
      "h      jj  jj  h",
      "h  xjj      j  h",
      "aaaaaaaaaa  aaaa",
      "h            jjh",
      "h          Q jjh",
      "a  jjj   NaaM ja",
      "h    j  jO  H  h",
      "h j j j jO  H  h",
      "a jjj    H  H  a",
      "hjjj         jjh",
      "hjjj        jjjh",
      "ahhahhahhahhahha"
    ],
    [
      "ahhahhahhahhahha",
      "h  k  r  j  r  h",
      "h        jj k  h",
      "aq  j  j k     a",
      "h          jj  h",
      "h    k   p  p  h",
      "aaaaaaahha  ahha",
      "h    r      rjjh",
      "h             jh",
      "aq k       Q   a",
      "h       j aa   h",
      "h j            h",
      "a             sa",
      "hj j         k h",
      "hj p     p   jjh",
      "ahhahhahhahhahha"
    ],
    [
      "ahhahhahhahhahha",
      "h              h",
      "h              h",
      "a      j       a",
      "h              h",
      "h              h",
      "aaaaaaahha  ahha",
      "h            jkh",
      "h              h",
      "a              a",
      "h          Q   h",
      "h         aa   h",
      "a              a",
      "h  k           h",
      "h              h",
      "ahhahhahhahhahha"
    ],
    [
      "aSSSSSSSSSSSSSSa",
      "SaaaaaaaaaaaaaaS",
      "SaaaaaaaaaaaaaaS",
      "SaaaaaaaaaaaaaaS",
      "SaaaaaaaaaaaaaaS",
      "SaaaaaaaaaaaaaaS",
      "SaaaaaaaaaaaaaaS",
      "SaaaaaaaaaaaaaaS",
      "Saaaaaaaaa  aaaS",
      "Saaaaaaaaa  aaaS",
      "Saaaaaaaaa  aaaS",
      "SaaaaaaaaaaQaaaS",
      "SaaaaaaaaaaaaaaS",
      "SaaaaaaaaaaaaaaS",
      "SaaaaaaaaaaaaaaS",
      "aSSSSSSSSSSSSSSa"
    ],
    [
      "aaaaaaaaaaaaaaaa",
      "aaaaaaaaaaaaaaaa",
      "aaaaaaaaaaaaaaaa",
      "aaaaaaaaaaaaaaaa",
      "aaaaaaaaaaaaaaaa",
      "aaaaaaaaaaaaaaaa",
      "aaaaaaaaaaaaaaaa",
      "aaaaaaaaaaaaaaaa",
      "aaaaaaaaaaaaaaaa",
      "aaaaaaaaaa  aaaa",
      "aaaaaaaaaa  aaaa",
      "aaaaaaaaaa  aaaa",
      "aaaaaaaaaaaQaaaa",
      "aaaaaaaaaaaaaaaa",
      "aaaaaaaaaaaaaaaa",
      "aaaaaaaaaaaaaaaa"
    ]
  ]
}