{
  "xsize": 16,
  "zsize": 16,
  "slices": [
    [
      "aa   aaaaaa   aa",
      "abddddddddddddba",
      " aaaaaaaaaaaaaa ",
      " aaaaaaaaaaaaaa ",
      " aaaaaaaaaaaaaa ",
      "aaaaaaa1aaaaaaaa",
      "aaaaaaaaaaaaaaaa",
      "aaaaaaaaaaaaaaaa",
      "aaaaaaaaaaaaaaaa",
      "aaaaaa$l$aaaaaaa",
      "aaaaa1aaaaaaaaaa",
      " aaaaaaaaaaaaaa ",
      " aaaaaaaaaaaaaa ",
      " aaaaaaaaaaaaaa ",
      "abddddddddddddba",
      "aa   aaaaaa   aa"
    ],
    [
      "aa   aaaaaa   aa",
      "aa444aF   a444aa",
      " 4            4 ",
      " 4            4 ",
      " 4            4 ",
      "aa  aaaaaaa   aa",
      "a   :     :    a",
      "a   :          a",
      "a   :          a",
      "a   :  l  :    a",
      "aa  aaaaaaa   aa",
      " 4            4 ",
      " 4            4 ",
      " 4            4 ",
      "aa444a    a444aa",
      "aa   aaaaaa   aa"
    ],
    [
      "aa   aaaaaa   aa",
      "aa444a    a444aa",
      " 4            4 ",
      " 4            4 ",
      " 4            4 ",
      "aa  aaaaaaa   aa",
      "a   :  T  :    a",
      "a   :          a",
      "a   :          a",
      "a   :  l  :    a",
      "aa  aaaaaaa   aa",
      " 4            4 ",
      " 4            4 ",
      " 4            4 ",
      "aa444a    a444aa",
      "aa   aaaaaa   aa"
    ],
    [
      "aa   aaaaaa   aa",
      "aa444a    a444aa",
      " 4            4 ",
      " 4            4 ",
      " 4            4 ",
      "aa  aaaaaaa   aa",
      "a   :     :    a",
      "a   :          a",
      "a   :          a",
      "a   :  l  :    a",
      "aa  aaaaaaa   aa",
      " 4            4 ",
      " 4            4 ",
      " 4            4 ",
      "aa444a    a444aa",
      "aa   aaaaaa   aa"
    ],
    [
      "aa   aaaaaa   aa",
      "aaaaaaaaaaaaaaaa",
      " aaaaaaaaaaaaaa ",
      " aaaaaaaaaaaaaa ",
      " aaaaaaaaaaaaaa ",
      "aaaaaaaaaaaaaaaa",
      "aaaaaaaaaaaaaaaa",
      "aaaaaaaaaaaaaaaa",
      "aaaaaaaaaaaaaaaa",
      "aaaaaa$l$aaaaaaa",
      "aaaaaaaaaaaaaaaa",
      " aaaaaaaaaaaaaa ",
      " aaaaaaaaaaaaaa ",
      " aaaaaaaaaaaaaa ",
      "aaaaaaaaaaaaaaaa",
      "aa   aaaaaa   aa"
    ],
    [
      "aa   aaaaaa   aa",
      "aaaaaaaaaaaaaaaa",
      " aaaaaaaaaaaaaa ",
      " aaaaaaaaaaaaaa ",
      " aaaaaaaaaaaaaa ",
      "aaaaaaaaaaaaaaaa",
      "aaaaaaaaaaaaaaaa",
      "aaaaaaaaaaaaaaaa",
      "aaaaaaaaaaaaaaaa",
      "aaaaaa$l$aaaaaaa",
      "aaaaaaaaaaaaaaaa",
      " aaaaaaaaaaaaaa ",
      " aaaaaaaaaaaaaa ",
      " aaaaaaaaaaaaaa ",
      "aaaaaaaaaaaaaaaa",
      "aa   aaaaaa   aa"
    ]
  ]
}