{
  "xsize": 16,
    "zsize": 16,
    "slices": [
      [
        "#$$#$$#$$#$$#$$#",
        "$bddddddddbdddb$",
        "$c########i###c$",
        "#c#$$$$###i###c#",
        "$c#$1$$##$i###c$",
        "$c#$$1$##$i###c$",
        "#c#$$$$##$i###c#",
        "$c########i###c$",
        "$c########i###c$",
        "#c####$l$#i###c#",
        "$c$$$#####i###c$",
        "$bjjjjjjjjb###c$",
        "#c############c#",
        "$c############c$",
        "$bddddddddddddb$",
        "#$$#$$#$$#$$#$$#"
      ],
      [
        "################",
        "#FF      #    F#",
        "#F F    F#  F F#",
        "#FFF    F#   FF#",
        "# F F       FFF#",
        "#             F#",
        "#              #",
        "#        #     #",
        "#        #     #",
        "#      l #     #",
        "##   #####     #",
        "#              #",
        "#      FF   F  #",
        "#   FFFF1F F1FF#",
        "#  FFFFFFF  FFF#",
        "################"
      ],
      [
        "#aa#aa#aa#aa#aa#",
        "aF k     #  k  a",
        "aF       #    Fa",
        "#       m#   mF#",
        "a             Fa",
        "a             ma",
        "#n            o#",
        "a        #     a",
        "a        #     a",
        "#      l #     #",
        "a#   #####     a",
        "a              a",
        "#             o#",
        "a    m  Fm  F  a",
        "a  TFFF FT   F a",
        "#aa#aa#aa#aa#aa#"
      ],
      [
        "#aa#aa#aa#aa#aa#",
        "aF       #     a",
        "am       #     a",
        "#        #     #",
        "a        #    Fa",
        "a       o#f    a",
        "#        #     #",
        "a        #     a",
        "a        #     a",
        "#  T   l #     #",
        "a#########     a",
        "a  r           a",
        "#              #",
        "a              a",
        "a   F        m a",
        "#aa#aa#aa#aa#aa#"
      ],
      [
        "################",
        "#bddddddddddddb#",
        "#c############c#",
        "#c############c#",
        "#c############c#",
        "#c############c#",
        "#c############c#",
        "#c############c#",
        "#c############c#",
        "#c####$l$#####c#",
        "#c############c#",
        "#c############c#",
        "#c############c#",
        "#c############c#",
        "#c############c#",
        "#bddddddddddddb#"
      ],
      [
        "################",
        "#bddddddddddddb#",
        "#c############c#",
        "#c############c#",
        "#c############c#",
        "#c############c#",
        "#c############c#",
        "#c############c#",
        "#c############c#",
        "#c####$l$#####c#",
        "#c############c#",
        "#c############c#",
        "#c############c#",
        "#c############c#",
        "#c############c#",
        "#bddddddddddddb#"
      ]
    ]
}