{
  "xsize": 16,
  "zsize": 16,
  "slices": [
    [
      "a$$a$$a$$a$$a$$a",
      "$bddddddddddddb$",
      "$caa1aaaaaaaaac$",
      "acaaaaaaaaaaaaca",
      "$caaaa1aaaaaaac$",
      "$caaaaaaaaaaaac$",
      "acaaaaaaaaaaaaca",
      "$caaaaaaaaaaaac$",
      "$caaaaaaaaaaaac$",
      "acaaaa$l$aaaaaca",
      "$caaaaaaaaaaaac$",
      "$caaaaaaaaaaaac$",
      "acaaaaaaaaaaaaca",
      "$caaaaaaaaaaaac$",
      "$bddddddddddddb$",
      "a$$a$$a$$a$$a$$a"
    ],
    [
      "aaaaaaaaaaaaaaaa",
      "a        a  FFFa",
      "a   FF F a   FFa",
      "a    F   a   FFa",
      "a F  FF  a   F a",
      "a  F  FF a     a",
      "aaaaaaaaaa     a",
      "aFF   FFF      a",
      "aF             a",
      "aF     l      Fa",
      "a     aaa    FFa",
      "a     FF     FFa",
      "a      F    FFFa",
      "a           FFFa",
      "aFF          FFa",
      "aaaaaaaaaaaaaaaa"
    ],
    [
      "a44a44a44a44a44a",
      "4     b     b F4",
      "4            *F4",
      "aj   F        Fa",
      "4     F        4",
      "4     F        4",
      "a     F  a     a",
      "4F*     F      4",
      "4F             4",
      "a      l      ka",
      "4     aaa     *4",
      "4      F      F4",
      "aj     F     FFa",
      "4            FF4",
      "4 *   T     T F4",
      "a44a44a44a44a44a"
    ],
    [
      "a44a44a44a44a44a",
      "4             F4",
      "4              4",
      "a              a",
      "4     F        4",
      "4              4",
      "a     *  a     a",
      "4              4",
      "4              4",
      "a      l       a",
      "4     aaa      4",
      "4      *       4",
      "a              a",
      "4            *F4",
      "4             F4",
      "a44a44a44a44a44a"
    ],
    [
      "aaaaaaaaaaaaaaaa",
      "abddddddddddddba",
      "acaaaaaaaaaaaaca",
      "acaaaaaaaaaaaaca",
      "acaaaaaaaaaaaaca",
      "acaaaaaaaaaaaaca",
      "acaaaaaaaaaaaaca",
      "acaaaaaaaaaaaaca",
      "acaaaaaaaaaaaaca",
      "acaaaa$l$aaaaaca",
      "acaaaaaaaaaaaaca",
      "acaaaaaaaaaaaaca",
      "acaaaaaaaaaaaaca",
      "acaaaaaaaaaaaaca",
      "acaaaaaaaaaaaaca",
      "abddddddddddddba"
    ],
    [
      "aaaaaaaaaaaaaaaa",
      "abddddddddddddba",
      "acaaaaaaaaaaaaca",
      "acaaaaaaaaaaaaca",
      "acaaaaaaaaaaaaca",
      "acaaaaaaaaaaaaca",
      "acaaaaaaaaaaaaca",
      "acaaaaaaaaaaaaca",
      "acaaaaaaaaaaaaca",
      "acaaaa$l$aaaaaca",
      "acaaaaaaaaaaaaca",
      "acaaaaaaaaaaaaca",
      "acaaaaaaaaaaaaca",
      "acaaaaaaaaaaaaca",
      "acaaaaaaaaaaaaca",
      "abddddddddddddba"
    ]
  ]
}