{
  "xsize": 16,
  "zsize": 16,
  "slices": [
    [
      "aaaaaaaaaaaaaaaa",
      "abddddddddddddba",
      "acaaaaaaaaaaaaca",
      "acaaaaaaaaaaaaca",
      "acaaaaaaaaaaaaca",
      "acaaaaaaaaaaaaca",
      "acaaaaaaaaaaaaca",
      "acaaaaaaaaaaaaca",
      "acaaaaaaaaaaaaca",
      "acaaaa$l$aaaaaca",
      "acaa1aaaaaaaaaca",
      "acaaaaaaaaaaaaca",
      "acaaaaaaaaaaaaca",
      "acaaaaaaaaaaaaca",
      "abddddddddddddba",
      "aaaaaaaaaaaaaaaa"
    ],
    [
      "a44@44444444@44a",
      "4  F      QQQ  4",
      "4              4",
      "@              @",
      "4              4",
      "4             F4",
      "4              4",
      "4              4",
      "4              4",
      "4      l       4",
      "4aaaaaaaaaaa  a4",
      "4              4",
      "@              @",
      "4              4",
      "4              4",
      "a44@44444444@44a"
    ],
    [
      "a44@44444444@44a",
      "4         **   4",
      "4              4",
      "@              @",
      "4              4",
      "4              4",
      "4              4",
      "4              4",
      "4              4",
      "4    T l       4",
      "4a::aaaaaaaa  a4",
      "4    T         4",
      "@              @",
      "4              4",
      "4              4",
      "a44@44444444@44a"
    ],
    [
      "a44@44444444@44a",
      "4              4",
      "4              4",
      "@              @",
      "4              4",
      "4              4",
      "4              4",
      "4              4",
      "4              4",
      "4      l       4",
      "4aaaaaaaaaaaaaa4",
      "4              4",
      "@              @",
      "4              4",
      "4              4",
      "a44@44444444@44a"
    ],
    [
      "aaaaaaaaaaaaaaaa",
      "abddddddddddddba",
      "acaaaaaaaaaaaaca",
      "acaaaaaaaaaaaaca",
      "acaaaaaaaaaaaaca",
      "acaaaaaaaaaaaaca",
      "acaaaaaaaaaaaaca",
      "acaaaaaaaaaaaaca",
      "acaaaaaaaaaaaaca",
      "acaaaa$l$aaaaaca",
      "acaaaaaaaaaaaaca",
      "acaaaaaaaaaaaaca",
      "acaaaaaaaaaaaaca",
      "acaaaaaaaaaaaaca",
      "acaaaaaaaaaaaaca",
      "abddddddddddddba"
    ],
    [
      "aaaaaaaaaaaaaaaa",
      "abddddddddddddba",
      "acaaaaaaaaaaaaca",
      "acaaaaaaaaaaaaca",
      "acaaaaaaaaaaaaca",
      "acaaaaaaaaaaaaca",
      "acaaaaaaaaaaaaca",
      "acaaaaaaaaaaaaca",
      "acaaaaaaaaaaaaca",
      "acaaaa$l$aaaaaca",
      "acaaaaaaaaaaaaca",
      "acaaaaaaaaaaaaca",
      "acaaaaaaaaaaaaca",
      "acaaaaaaaaaaaaca",
      "acaaaaaaaaaaaaca",
      "abddddddddddddba"
    ]
  ]
}