{
  "xsize": 16,
  "zsize": 16,
  "slices": [
    [
      "##   ######   ##",
      "#bddddddddddddb#",
      " ############## ",
      " ############## ",
      " ############## ",
      "############1###",
      "################",
      "################",
      "################",
      "######$l$#######",
      "####1###########",
      " ############## ",
      " ############## ",
      " ############## ",
      "#bddddddddddddb#",
      "##   ######   ##"
    ],
    [
      "##   ######   ##",
      "##aaa#    #aaa##",
      " a            a ",
      " a            a ",
      " a            a ",
      "#### ###########",
      "#       FF     #",
      "#              #",
      "#              #",
      "#      l      C#",
      "########### ####",
      " a            a ",
      " a            a ",
      " a            a ",
      "##aaa#    #aaa##",
      "##   ######   ##"
    ],
    [
      "##   ######   ##",
      "##aaa#    #aaa##",
      " a            a ",
      " a            a ",
      " a     T      a ",
      "#### ###########",
      "#      T       #",
      "#              #",
      "#              #",
      "#      l       #",
      "########### ####",
      " a            a ",
      " a            a ",
      " a            a ",
      "##aaa#    #aaa##",
      "##   ######   ##"
    ],
    [
      "##   ######   ##",
      "##aaa#    #aaa##",
      " a            a ",
      " a            a ",
      " a            a ",
      "################",
      "#            %%#",
      "#              #",
      "#              #",
      "#%     l      %#",
      "################",
      " a            a ",
      " a            a ",
      " a            a ",
      "##aaa#    #aaa##",
      "##   ######   ##"
    ],
    [
      "##   ######   ##",
      "################",
      " ############## ",
      " ############## ",
      " ############## ",
      "################",
      "################",
      "################",
      "################",
      "######$l$#######",
      "################",
      " ############## ",
      " ############## ",
      " ############## ",
      "################",
      "##   ######   ##"
    ],
    [
      "##   ######   ##",
      "################",
      " ############## ",
      " ############## ",
      " ############## ",
      "################",
      "################",
      "################",
      "################",
      "######$l$#######",
      "################",
      " ############## ",
      " ############## ",
      " ############## ",
      "################",
      "##   ######   ##"
    ]
  ]
}