{
  "xsize": 16,
  "zsize": 16,
  "slices": [
    [
      "aaaaaaaaaaaaaaaa",
      "abddddddddddddba",
      "acaaaaaaaaaaaaca",
      "acaaaaaaaaaaaaca",
      "acaaaaaaaaaaaaca",
      "acaaaaaaaaaaaaca",
      "acaaaaaaaaaaaaca",
      "acaaaaaaaaaaaaca",
      "acaaaaaaaaaaaaca",
      "acaaaaiyiaaaaaca",
      "acaaaaaaaaaaaaca",
      "acaaaaaaaaaaaaca",
      "acaaaaaaaaaaaaca",
      "acaaaaaaaaaaaaca",
      "abddddddddddddba",
      "aaaaaaaaaaaaaaaa"
    ],
    [
      "ahhkhhhhhhhhkhha",
      "h      a       h",
      "h      a       h",
      "k              k",
      "h      a       h",
      "h      a       h",
      "h    aaaaa     h",
      "h    a   a     h",
      "h    a   aj    h",
      "h      y aj    h",
      "haaaaaaaaa     h",
      "h    j         h",
      "k              k",
      "h              h",
      "h              h",
      "ahhkhhhhhhhhkhha"
    ],
    [
      "ahhkhhhhhhhhkhha",
      "h      a       h",
      "h      a       h",
      "k              k",
      "h      a       h",
      "h      a       h",
      "h    aaaaa     h",
      "h    a k a     h",
      "h    a   aj    h",
      "h      y aj    h",
      "haaaaaaaaa     h",
      "h              h",
      "k              k",
      "h              h",
      "h              h",
      "ahhkhhhhhhhhkhha"
    ],
    [
      "ahhkhhhhhhhhkhha",
      "h      a       h",
      "h      a       h",
      "k      a       k",
      "h      a       h",
      "h      a       h",
      "h    aaaaa     h",
      "h    a   a     h",
      "h    a   a     h",
      "h    a y a     h",
      "haaaaaaaaa     h",
      "h              h",
      "k              k",
      "h              h",
      "h              h",
      "ahhkhhhhhhhhkhha"
    ],
    [
      "aaaaaaaaaaaaaaaa",
      "abddddddddddddba",
      "acaaaaaaaaaaaaca",
      "acaaaaaaaaaaaaca",
      "acaaaaaaaaaaaaca",
      "acaaaaaaaaaaaaca",
      "acaaaaaaaaaaaaca",
      "acaaaaaaaaaaaaca",
      "acaaaaaaaaaaaaca",
      "acaaaaiyiaaaaaca",
      "acaaaaaaaaaaaaca",
      "acaaaaaaaaaaaaca",
      "acaaaaaaaaaaaaca",
      "acaaaaaaaaaaaaca",
      "acaaaaaaaaaaaaca",
      "abddddddddddddba"
    ],
    [
      "aaaaaaaaaaaaaaaa",
      "abddddddddddddba",
      "acaaaaaaaaaaaaca",
      "acaaaaaaaaaaaaca",
      "acaaaaaaaaaaaaca",
      "acaaaaaaaaaaaaca",
      "acaaaaaaaaaaaaca",
      "acaaaaaaaaaaaaca",
      "acaaaaaaaaaaaaca",
      "acaaaaiyiaaaaaca",
      "acaaaaaaaaaaaaca",
      "acaaaaaaaaaaaaca",
      "acaaaaaaaaaaaaca",
      "acaaaaaaaaaaaaca",
      "acaaaaaaaaaaaaca",
      "abddddddddddddba"
    ]
  ]
}