{
  "xsize": 16,
  "zsize": 16,
  "slices": [
    [
      "aaaaaaaaaaaaaaaa",
      "abddddddddddddba",
      "acaaaaaaaaaaaaca",
      "acaaaaaaaaaaaaca",
      "acaaaaaaaaaaaaca",
      "acaaaaaaaaaaaaca",
      "acaaaaaaaaaaaaca",
      "acaaaaaaaaaaaaca",
      "acaaaaaaaaaaaaca",
      "acaaaaiyiaaaaaca",
      "acaaaaaaaaaaaaca",
      "acaaaaaaaaaaaaca",
      "acaaaaaaaaaaaaca",
      "acaaaaaaaaaaaaca",
      "abddddddddddddba",
      "aaaaaaaaaaaaaaaa"
    ],
    [
      "ahh@hhhhhhhh@hha",
      "hFFFFFFFFFFFFFFh",
      "hFFFFFFFFFFFFFFh",
      "@FFFFFFFFFFFFFF@",
      "hFFFFFFFFFFFFFFh",
      "hhhhhhhhhhhhhhhh",
      "h              h",
      "h              h",
      "hj             h",
      "hj     y       h",
      "hj    aaaHHHHHHh",
      "h      H       h",
      "@      H   k   @",
      "h      H       h",
      "h      H       h",
      "ahh@hhhhhhhh@hha"
    ],
    [
      "ahh@hhhhhhhh@hha",
      "hFFFFFFFFFFFFFFh",
      "hFFFFFFFFFFFFFFh",
      "@FFFFFFFFFFFFFF@",
      "hFFFFFFFFFFFFFFh",
      "hhhhhhhhhhhhhhhh",
      "h              h",
      "h              h",
      "hj             h",
      "h      y       h",
      "h     aaaHHHHHHh",
      "h      H       h",
      "@      H       @",
      "h      H       h",
      "h      H       h",
      "ahh@hhhhhhhh@hha"
    ],
    [
      "ahh@hhhhhhhh@hha",
      "hFFFFFFFFFFFFFFh",
      "hFFFFFFFFFFFFFFh",
      "@FFFFFFFFFFFFFF@",
      "hFFFFFFFFFFFFFFh",
      "hhhhhhhhhhhhhhhh",
      "h              h",
      "h              h",
      "hj             h",
      "h      y       h",
      "h     aaaHHHHHHh",
      "h      H       h",
      "@      H       @",
      "h      H       h",
      "h      H       h",
      "ahh@hhhhhhhh@hha"
    ],
    [
      "aaaaaaaaaaaaaaaa",
      "aaaaaaaaaaaaaaaa",
      "aaaaaaaaaaaaaaaa",
      "aaaaaaaaaaaaaaaa",
      "aaaaaaaaaaaaaaaa",
      "aaaaaaaaaaaaaaaa",
      "aaaaaaaaaaaaaaaa",
      "aaaaaaaaaaaaaaaa",
      "aaaaaaaaaaaaaaaa",
      "aaaaaaiyiaaaaaaa",
      "aaaaaaaaaaaaaaaa",
      "aaaaaaaaaaaaaaaa",
      "aalalaaaaaaaaaaa",
      "aaaaaaaaaaaaaaaa",
      "aaaaaaaaaaaaaaaa",
      "aaaaaaaaaaaaaaaa"
    ],
    [
      "aaaaaaaaaaaaaaaa",
      "abddddddddddddba",
      "acaaaaaaaaaaaaca",
      "acaaaaaaaaaaaaca",
      "acaaaaaaaaaaaaca",
      "acaaaaaaaaaaaaca",
      "acaaaaaaaaaaaaca",
      "acaaaaaaaaaaaaca",
      "acaaaaaaaaaaaaca",
      "acaaaaiyiaaaaaca",
      "acaaaaaaaaaaaaca",
      "acaaaaaaaaaaaaca",
      "acaaaaaaaaaaaaca",
      "acaaaaaaaaaaaaca",
      "acaaaaaaaaaaaaca",
      "abddddddddddddba"
    ]
  ]
}