{
  "xsize": 16,
  "zsize": 16,
  "slices": [
    [
      "aSSSSSSSSSSSSSSa",
      "SbddddddddddddbS",
      "ScaaaaaaaaaaaacS",
      "ScaaaaaaaaaaaacS",
      "ScaaaaaaaaamaacS",
      "ScaaaaaaaaaaaacS",
      "ScaaaaaaaaaaaacS",
      "ScaaaaaaaaaaaacS",
      "ScaaaaaaaaaaaacS",
      "ScaaaaaaaaaaaacS",
      "Scaaaaaaaa  aacS",
      "Scamaaaaaa  aacS",
      "Scaaaaaaaa  aacS",
      "ScaaaaaaaaaQaacS",
      "SbddddddddddddbS",
      "aSSSSSSSSSSSSSSa"
    ],
    [
      "ahhahhahhahhahha",
      "hjjjj H      j h",
      "hjjj  H    j   h",
      "ajj   a   jjjj a",
      "hj    H   jjj  h",
      "h     H    j   h",
      "aPa  a         a",
      "h              h",
      "h          Q   h",
      "a     a  NaaM  a",
      "h     H  H  H  h",
      "h  j  H  H  H  h",
      "a  jj a  H  H  a",
      "h jjjjO        h",
      "hjjjjjO        h",
      "ahhahhahhahhahha"
    ],
    [
      "ahhahhahhahhahha",
      "hjj k H     r  h",
      "hjx   H        h",
      "a    sa    jk  a",
      "h     H    jj  h",
      "h     H        h",
      "aPa  aq       sa",
      "h  r           h",
      "h              h",
      "a     aq   Q   a",
      "h     H   aa   h",
      "h     H        h",
      "aq  k a       sa",
      "h  j  H        h",
      "hk jjjO  p     h",
      "ahhahhahhahhahha"
    ],
    [
      "ahhahhahhahhahha",
      "hj    H        h",
      "h     H        h",
      "a     a        a",
      "h     H        h",
      "h     H        h",
      "aPa  a         a",
      "h              h",
      "h              h",
      "a     a        a",
      "h     H    Q   h",
      "h     H   aa   h",
      "a     a        a",
      "h     H        h",
      "h   j H        h",
      "ahhahhahhahhahha"
    ],
    [
      "aSSSSSSSSSSSSSSa",
      "SaaaaaaaaaaaaaaS",
      "SaaaaaaaaaaaaaaS",
      "SaaaaaaaaaaaaaaS",
      "SaaaaaaaaaaaaaaS",
      "SaaaaaaaaaaaaaaS",
      "SaaaaaaaaaaaaaaS",
      "SaaaaaaaaaaaaaaS",
      "Saaaaaaaaa  aaaS",
      "Saaaaaaaaa  aaaS",
      "Saaaaaaaaa  aaaS",
      "SaaaaaaaaaaQaaaS",
      "SaaaaaaaaaaaaaaS",
      "SaaaaaaaaaaaaaaS",
      "SaaaaaaaaaaaaaaS",
      "aSSSSSSSSSSSSSSa"
    ],
    [
      "aaaaaaaaaaaaaaaa",
      "aaaaaaaaaaaaaaaa",
      "aaaaaaaaaaaaaaaa",
      "aaaaaaaaaaaaaaaa",
      "aaaaaaaaaaaaaaaa",
      "aaaaaaaaaaaaaaaa",
      "aaaaaaaaaaaaaaaa",
      "aaaaaaaaaaaaaaaa",
      "aaaaaaaaaaaaaaaa",
      "aaaaaaaaaa  aaaa",
      "aaaaaaaaaa  aaaa",
      "aaaaaaaaaa  aaaa",
      "aaaaaaaaaaaQaaaa",
      "aaaaaaaaaaaaaaaa",
      "aaaaaaaaaaaaaaaa",
      "aaaaaaaaaaaaaaaa"
    ]
  ]
}