{
  "xsize": 16,
  "zsize": 16,
  "slices": [
    [
      "aaaaaaaaaaaaaaaa",
      "abddddddddddddba",
      "acaaaaaaaaaaaaca",
      "acaaaaaaaaaaaaca",
      "acaaaaaaaaaaaaca",
      "acaaaaaaaaaaaaca",
      "acaaaaaaaaaaaaca",
      "acaaaaaaaaaaaaca",
      "acaaaaaaaaaaaaca",
      "acaaaaiyiaaaaaca",
      "acaaaaaaaaaaaaca",
      "acaaaaaaaaaaaaca",
      "acaaaaaaaaaaaaca",
      "acaaaaaaaaaaaaca",
      "abddddddddddddba",
      "aaaaaaaaaaaaaaaa"
    ],
    [
      "ahh@hhhhhhhh@hha",
      "h              h",
      "h              h",
      "@              @",
      "h              h",
      "h              h",
      "h    jjjjjHHHHHh",
      "h    j   j     h",
      "h    j   j     h",
      "h      y       h",
      "h    jjjjj     h",
      "h              h",
      "@              @",
      "h              h",
      "h              h",
      "ahh@hhhhhhhh@hha"
    ],
    [
      "ahh@hhhhhhhh@hha",
      "h              h",
      "h              h",
      "@              @",
      "h              h",
      "h              h",
      "h    jjjjjHHHHHh",
      "h    j   j     h",
      "h    j   j     h",
      "h      y       h",
      "h    jjjjj     h",
      "h              h",
      "@              @",
      "h              h",
      "h              h",
      "ahh@hhhhhhhh@hha"
    ],
    [
      "ahh@hhhhhhhh@hha",
      "h              h",
      "h              h",
      "@              @",
      "h              h",
      "h              h",
      "h    jjjjjHHHHHh",
      "h    j   j     h",
      "h    j   j     h",
      "h    j y j     h",
      "h    jjjjj     h",
      "h              h",
      "@              @",
      "h              h",
      "h              h",
      "ahh@hhhhhhhh@hha"
    ],
    [
      "aaaaaaaaaaaaaaaa",
      "abddddddddddddba",
      "acaaaaaaaaaaaaca",
      "acaaaaaaaaaaaaca",
      "acaaaaaaaaaaaaca",
      "acaaaaaaaaaaaaca",
      "acaaaaaaaaaaaaca",
      "acaaaaaaaaaaaaca",
      "acaaaaaaaaaaaaca",
      "acaaaaiyiaaaaaca",
      "acaaaaaaaaaaaaca",
      "acaaaaaaaaaaaaca",
      "acaaaaaaaaaaaaca",
      "acaaaaaaaaaaaaca",
      "acaaaaaaaaaaaaca",
      "abddddddddddddba"
    ],
    [
      "aaaaaaaaaaaaaaaa",
      "abddddddddddddba",
      "acaaaaaaaaaaaaca",
      "acaaaaaaaaaaaaca",
      "acaaaaaaaaaaaaca",
      "acaaaaaaaaaaaaca",
      "acaaaaaaaaaaaaca",
      "acaaaaaaaaaaaaca",
      "acaaaaaaaaaaaaca",
      "acaaaaiyiaaaaaca",
      "acaaaaaaaaaaaaca",
      "acaaaaaaaaaaaaca",
      "acaaaaaaaaaaaaca",
      "acaaaaaaaaaaaaca",
      "acaaaaaaaaaaaaca",
      "abddddddddddddba"
    ]
  ]
}