{
  "xsize": 16,
  "zsize": 16,
  "slices": [
    [
      "aiiaiiaiiaiiaiia",
      "ibddddddddddddbi",
      "icaalaaaaaaaaaci",
      "acaaaaaaaaaaaaca",
      "icaaaalaaaaaaaci",
      "icaaaaaaaaaaaaci",
      "acaaaaaaaaaaaaca",
      "icaaaaaaaaaaaaci",
      "icaaaaaaaaaaaaci",
      "acaaaaiyiaaaaaca",
      "icaaaaaaaaaaaaci",
      "icaaaaaaaaaaaaci",
      "acaaaaaaaaaaaaca",
      "icaaaaaaaaaaaaci",
      "ibddddddddddddbi",
      "aiiaiiaiiaiiaiia"
    ],
    [
      "aaaaaaaaaaaaaaaa",
      "a        a  jjja",
      "a   jj j a   jja",
      "a    j   a   jja",
      "a j  jj  a   j a",
      "a  j  jj a     a",
      "aaaaaaaaaa     a",
      "ajj   jjj      a",
      "aj             a",
      "aj     y      ja",
      "a     aaa    jja",
      "a     jj     jja",
      "a      j    jjja",
      "a           jjja",
      "ajj          jja",
      "aaaaaaaaaaaaaaaa"
    ],
    [
      "ahhahhahhahhahha",
      "h     b     b jh",
      "h            kjh",
      "ad   j        ja",
      "h     j        h",
      "h     j        h",
      "a     j  a     a",
      "hjk     j      h",
      "hj             h",
      "a      y      ba",
      "h     aaa     kh",
      "h      j      jh",
      "ad     j     jja",
      "h            jjh",
      "h k   k     k jh",
      "ahhahhahhahhahha"
    ],
    [
      "ahhahhahhahhahha",
      "h             jh",
      "h              h",
      "a              a",
      "h     j        h",
      "h              h",
      "a     k  a     a",
      "h              h",
      "h              h",
      "a      y       a",
      "h     aaa      h",
      "h      k       h",
      "a              a",
      "h            kjh",
      "h             jh",
      "ahhahhahhahhahha"
    ],
    [
      "aaaaaaaaaaaaaaaa",
      "abddddddddddddba",
      "acaaaaaaaaaaaaca",
      "acaaaaaaaaaaaaca",
      "acaaaaaaaaaaaaca",
      "acaaaaaaaaaaaaca",
      "acaaaaaaaaaaaaca",
      "acaaaaaaaaaaaaca",
      "acaaaaaaaaaaaaca",
      "acaaaaiyiaaaaaca",
      "acaaaaaaaaaaaaca",
      "acaaaaaaaaaaaaca",
      "acaaaaaaaaaaaaca",
      "acaaaaaaaaaaaaca",
      "acaaaaaaaaaaaaca",
      "abddddddddddddba"
    ],
    [
      "aaaaaaaaaaaaaaaa",
      "abddddddddddddba",
      "acaaaaaaaaaaaaca",
      "acaaaaaaaaaaaaca",
      "acaaaaaaaaaaaaca",
      "acaaaaaaaaaaaaca",
      "acaaaaaaaaaaaaca",
      "acaaaaaaaaaaaaca",
      "acaaaaaaaaaaaaca",
      "acaaaaiyiaaaaaca",
      "acaaaaaaaaaaaaca",
      "acaaaaaaaaaaaaca",
      "acaaaaaaaaaaaaca",
      "acaaaaaaaaaaaaca",
      "acaaaaaaaaaaaaca",
      "abddddddddddddba"
    ]
  ]
}