{
  "xsize": 16,
  "zsize": 16,
  "palette": {
    "palette": [
      {
        "char": "D",
        "block": "minecraft:iron_door[half=lower]"
      },
      {
        "char": "d",
        "block": "minecraft:iron_door[half=upper]"
      },
      {
        "char": "P",
        "block": "minecraft:quartz_block"
      },
      {
        "char": "B",
        "block": "minecraft:barrel[facing=north]"
      },
      {
        "char": "c",
        "block": "minecraft:exposed_copper"
      },
      {
        "char": "1",
        "block": "minecraft:exposed_cut_copper_stairs[facing=north]"
      },
      {
        "char": "2",
        "block": "minecraft:exposed_cut_copper_stairs[facing=west]"
      },
      {
        "char": "3",
        "block": "minecraft:exposed_cut_copper_stairs[facing=south]"
      },
      {
        "char": "4",
        "block": "minecraft:exposed_cut_copper_stairs[facing=east]"
      }
    ]
  },
  "slices": [
    [
      "                ",
      "                ",
      "                ",
      "   aaaaaaaaaaaa ",
      "   aaaaaaaaaaaa ",
      "   aaaaaaaaaaaa ",
      "   aaaaaaaaaa   ",
      "   aaaaaaaaaa   ",
      "   aaaaaaaaaa   ",
      "   aaaaaaaaaa   ",
      "   aaaaaaaaaa   ",
      "   aaaaaaaaaa   ",
      "   aaaaaaaaaa   ",
      "                ",
      "                ",
      "                "
    ],
    [
      "                ",
      "                ",
      "                ",
      "   aaaaaaaaaaaa ",
      "   aaaaaaaaaaaa ",
      "   aaaaaaaaaaaa ",
      "   aaaaaaaaaa   ",
      "   aaaaaaaaaa   ",
      "   aaaaaaaaaa   ",
      "   aaaaaaaaaa   ",
      "   aaaaaaaaaa   ",
      "   aaaaaaaaaa   ",
      "   aaaaaaaaaa   ",
      "                ",
      "                ",
      "                "
    ],
    [
      "                ",
      "                ",
      "                ",
      "   aaaaaaaaaaaa ",
      "   aaaaaaaaaaaa ",
      "   aaaaaaaaaaaa ",
      "   aaaaaaaaaa   ",
      "   aaaaaaaaaa   ",
      "   aaaaaaaaaa   ",
      "   aaaaaaaaaa   ",
      "   aaaaaaaaaa   ",
      "   aaaaaaaaaa   ",
      "   aaaaaaaaaa   ",
      "                ",
      "                ",
      "                "
    ],
    [
      "                ",
      "                ",
      "                ",
      "   cPPPPPPPPc   ",
      "   P    B   P:  ",
      "   P        P   ",
      "   P        P   ",
      "   PC       P   ",
      "   P        P   ",
      "   P        P   ",
      "   P        P   ",
      "   P        P   ",
      "   cPDPPPPPPc   ",
      "                ",
      "                ",
      "                "
    ],
    [
      "                ",
      "                ",
      "                ",
      "   cPPPPPPPPc   ",
      "   P        P:  ",
      "   P        P   ",
      "   P        P   ",
      "   P        P   ",
      "   P        :   ",
      "   P        :   ",
      "   P        P   ",
      "   P        P   ",
      "   cPdPPP:PPc   ",
      "                ",
      "                ",
      "                "
    ],
    [
      "                ",
      "                ",
      "                ",
      "   cPPPPPPPPc   ",
      "   P        P:  ",
      "   P        P   ",
      "   P        P   ",
      "   P        P   ",
      "   P        P   ",
      "   P        P   ",
      "   P        P   ",
      "   P        P   ",
      "   cPPPPPPPPc   ",
      "                ",
      "                ",
      "                "
    ],
    [
      "                ",
      "                ",
      "                ",
      "   c11111111c   ",
      "   2aaaaaaaacc  ",
      "   2aaaaaaaa4   ",
      "   2aaaaaaaa4   ",
      "   2aaaaaaaa4   ",
      "   2aaaaaaaa4   ",
      "   2aaaaaaaa4   ",
      "   2aaaaaaaa4   ",
      "   2aaaaaaaa4   ",
      "   c33333333c   ",
      "                ",
      "                ",
      "                "
    ],
    [
      "                ",
      "                ",
      "                ",
      "                ",
      "                ",
      "     :    :     ",
      "                ",
      "                ",
      "                ",
      "                ",
      "     :    :     ",
      "                ",
      "                ",
      "                ",
      "                ",
      "                "
    ]
  ]
}