{
  "xsize": 16,
  "zsize": 16,
  "slices": [
    [
      "aaSQSQSQSQSQSQSQ",
      "aaQSQSQSQSQSQSQS",
      " aSQSQSQSQSQSQSQ",
      " aQSQSQSQSQSQSQS",
      " aSQSQSQSQSQSQSQ",
      "aaQSQSQSQSQSQSQS",
      "aQSQSQSQSQSQSQSQ",
      "aSQSQSQSQSQSQSQS",
      "aQSQSQSQSQSQSQSQ",
      "aSQSQSQSQSQSQSQS",
      "aaSQSQSQSQSQSQSQ",
      " aQSQSQSQSQSQSQS",
      " aSQSQSQSQSQSQSQ",
      " aQSQSQSQSQSQSQS",
      "aaaaaaSQSQaaaaaa",
      "aa   aaaaaa   aa"
    ],
    [
      "aa              ",
      "aa    a+:+:+:+a ",
      " a    aaaaaaaaa ",
      " a    a+:+:+:+a ",
      " a              ",
      "aa    a+:+:+:+a ",
      "a     aaaaaaaaa ",
      "a     a+:+:+:+a ",
      "a               ",
      "a     a+:+:+:+a ",
      "aa    aaaaaaaaa ",
      " a    a+:+:+:+a ",
      " a              ",
      " a              ",
      "aaaaaa    aaaaaa",
      "aa   aaaaaa   aa"
    ],
    [
      "aa              ",
      "aa    a+:+:+:+a ",
      " a   aaaaaaaaaa ",
      " a    a+:+:+:+a ",
      " a              ",
      "aa    a+:+:+:+a ",
      "a    aaaaaaaaaa ",
      "a     a+:+:+:+a ",
      "a               ",
      "a     a+:+:+:+a ",
      "aa   aaaaaaaaaa ",
      " a    a+:+:+:+a ",
      " a              ",
      " a              ",
      "aaaaaa    aaaaaa",
      "aa   aaaaaa   aa"
    ],
    [
      "aa              ",
      "aa    a+:+:+:+a ",
      " a    aaaaaaaaa ",
      " a    a+:+:+:+a ",
      " a              ",
      "aa    a+:+:+:+a ",
      "a     aaaaaaaaa ",
      "a     a+:+:+:+a ",
      "a               ",
      "a     a+:+:+:+a ",
      "aa    aaaaaaaaa ",
      " a    a+:+:+:+a ",
      " a              ",
      " a              ",
      "aaaaaa    aaaaaa",
      "aa   aaaaaa   aa"
    ],
    [
      "aa              ",
      "aa    a+:+:+:+a ",
      " a    aaaaaaaaa ",
      " a    a+:+:+:+a ",
      " a              ",
      "aa    a+:+:+:+a ",
      "a     aaaaaaaaa ",
      "a     a+:+:+:+a ",
      "a               ",
      "a     a+:+:+:+a ",
      "aa    aaaaaaaaa ",
      " a    a+:+:+:+a ",
      " a              ",
      " a              ",
      "aaaaaa    aaaaaa",
      "aa   aaaaaa   aa"
    ],
    [
      "aaaaaaaaaaaaaaaa",
      "aaaaaaaaaaaaaaaa",
      " aaaaaaaaaaaaaaa",
      " aaaaaaaaaaaaaaa",
      " aaaaaaaaaaaaaaa",
      "aaaaaaaaaaaaaaaa",
      "aaaaaaaaaaaaaaaa",
      "aaaaaaaaaaaaaaaa",
      "aaaaaaaaaaaaaaaa",
      "aaaaaaaaaaaaaaaa",
      "aaaaaaaaaaaaaaaa",
      " aaaaaaaaaaaaaaa",
      " aaaaaaaaaaaaaaa",
      " aaaaaaaaaaaaaaa",
      "aaaaaaaaaaaaaaaa",
      "aa   aaaaaa   aa"
    ]
  ]
}