{
  "xsize": 16,
  "zsize": 16,
  "slices": [
    [
      "aa   aaaaaa   aa",
      "aaaaaaQSQSaaaaaa",
      "SQSQSQSQSQSQSQa ",
      "QSQSQSQSQSQSQSa ",
      "SQSQSQSQSQSQSQa ",
      "QSQSQSQSQSQSQSaa",
      "SQSQSQSQSQSQSQSa",
      "QSQSQSQSQSQSQSQa",
      "SQSQSQSQSQSQSQSa",
      "QSQSQSQSQSQSQSQa",
      "SQSQSQSQSQSQSQaa",
      "QSQSQSQSQSQSQSa ",
      "SQSQSQSQSQSQSQa ",
      "QSQSQSQSQSQSQSa ",
      "SQSQSQSQSQSQSQaa",
      "QSQSQSQSQSQSQSaa"
    ],
    [
      "aa   aaaaaa   aa",
      "aaaaaa    aaaaaa",
      "              a ",
      "              a ",
      "              a ",
      "   +++++++    aa",
      "   +QQQQQ+     a",
      "   +Q1QQQ+     a",
      "   +QQQ1Q+     a",
      "   +QQQQQ+     a",
      "   +++++++    aa",
      "              a ",
      "              a ",
      "              a ",
      "              aa",
      "              aa"
    ],
    [
      "aa   aaaaaa   aa",
      "aaaaaa    aaaaaa",
      "              a ",
      "              a ",
      "              a ",
      "   +++++++    aa",
      "   +QQQQQ+     a",
      "   +QQQQQ+     a",
      "   +QQQQQ+     a",
      "   +QQQQQ+     a",
      "   +++++++    aa",
      "              a ",
      "              a ",
      "              a ",
      "              aa",
      "              aa"
    ],
    [
      "aa   aaaaaa   aa",
      "aaaaaa    aaaaaa",
      "              a ",
      "              a ",
      "              a ",
      "   +++++++    aa",
      "   +QQQQQ+     a",
      "   +QQQQQ+     a",
      "   +QQQQQ+     a",
      "   +QQQQQ+     a",
      "   +++++++    aa",
      "              a ",
      "              a ",
      "              a ",
      "              aa",
      "              aa"
    ],
    [
      "aa   aaaaaa   aa",
      "aaaaaa    aaaaaa",
      "              a ",
      "              a ",
      "              a ",
      "   +++++++    aa",
      "   +QQQQQ+     a",
      "   +QQQQQ+     a",
      "   +QQQQQ+     a",
      "   +QQQQQ+     a",
      "   +++++++    aa",
      "              a ",
      "              a ",
      "              a ",
      "              aa",
      "              aa"
    ],
    [
      "aa   aaaaaa   aa",
      "aaaaaaaaaaaaaaaa",
      "aaaaaaaaaaaaaaa ",
      "aaaaaaaaaaaaaaa ",
      "aaaaaaaaaaaaaaa ",
      "aaaaaaaaaaaaaaaa",
      "aaaaaaaaaaaaaaaa",
      "aaaaaaaaaaaaaaaa",
      "aaaaaaaaaaaaaaaa",
      "aaaaaaaaaaaaaaaa",
      "aaaaaaaaaaaaaaaa",
      "aaaaaaaaaaaaaaa ",
      "aaaaaaaaaaaaaaa ",
      "aaaaaaaaaaaaaaa ",
      "aaaaaaaaaaaaaaaa",
      "aaaaaaaaaaaaaaaa"
    ]
  ]
}