{
  "xsize": 16,
  "zsize": 16,
  "slices": [
    [
      "aa   aaaaaa   aa",
      "aaaaaaQSQSaaaaaa",
      " aSQSQSQSQSQSQSQ",
      " aQSQSQSQSQSQSQS",
      " aSQSQSQSQSQSQSQ",
      "aaQSQSQSQSQSQSQS",
      "aQSQSQSQSQSQSQSQ",
      "aSQSQSQSQSQSQSQS",
      "aQSQSQSQSQSQSQSQ",
      "aSQSQSQSQSQSQSQS",
      "aaSQSQSQSQSQS  Q",
      " aQSQSQSQSQSQ  S",
      " aSQSQSQSQSQS  Q",
      " aQSQSQSQSQSQ  S",
      "aaSQSQSQSQSQS))Q",
      "aaQSQSQSQSQSQSQS"
    ],
    [
      "aa   aaaaaa   aa",
      "aaaaaa    aaaaaa",
      " a              ",
      " a              ",
      " a              ",
      "aa              ",
      "a               ",
      "a               ",
      "a               ",
      "a            )) ",
      "aa          Q  Q",
      " a          Q  Q",
      " a          Q  Q",
      " a          Q  Q",
      "aa          Q  Q",
      "aa              "
    ],
    [
      "aa   aaaaaa   aa",
      "aaaaaa    aaaaaa",
      " a              ",
      " a              ",
      " a              ",
      "aa              ",
      "a               ",
      "a               ",
      "a               ",
      "a               ",
      "aa          a))a",
      " a          a  a",
      " a          a  a",
      " a          a  a",
      "aa          a  a",
      "aa              "
    ],
    [
      "aa   aaaaaa   aa",
      "aaaaaa    aaaaaa",
      " a              ",
      " a              ",
      " a              ",
      "aa              ",
      "a               ",
      "a               ",
      "a               ",
      "a               ",
      "aa          a  a",
      " a          a))a",
      " a          a  a",
      " a          a  a",
      "aa          a  a",
      "aa              "
    ],
    [
      "aa   aaaaaa   aa",
      "aaaaaa    aaaaaa",
      " a              ",
      " a              ",
      " a              ",
      "aa              ",
      "a               ",
      "a               ",
      "a               ",
      "a               ",
      "aa          a  a",
      " a          a  a",
      " a          a))a",
      " a          a  a",
      "aa          a  a",
      "aa              "
    ],
    [
      "aa   aaaaaa   aa",
      "aaaaaaaaaaaaaaaa",
      " aaaaaaaaaaaaaaa",
      " aaaaaaaaaaaaaaa",
      " aaaaaaaaaaaaaaa",
      "aaaaaaaaaaaaaaaa",
      "aaaaaaaaaaaaaaaa",
      "aaaaaaaaaaaaaaaa",
      "aaaaaaaaaaaaaaaa",
      "aaaaaaaaaaaaaaaa",
      "aaaaaaaaaaaaa  a",
      " aaaaaaaaaaaa  a",
      " aaaaaaaaaaaa  a",
      " aaaaaaaaaaaa))a",
      "aaaaaaaaaaaaa  a",
      "aaaaaaaaaaaaaaaa"
    ]
  ]
}