{
  "xsize": 16,
  "zsize": 16,
  "slices": [
    [
      "aa   aaaaaa   aa",
      "aaaaaaQSQSaaaaaa",
      "SQSQSQSQSQSQSQa ",
      "QSQSQSQSQSQSQSa ",
      "SQSQSQSQSQSQSQa ",
      "QSQSQSQSQSQSQSaa",
      "SQSQSQSQSQSQSQSa",
      "QSQSQSQSQSQSQSQa",
      "SQSQSQSQSQSQSQSa",
      "QSQSQSQSQSQSQSQa",
      "SQSQSQSQSQSQSQaa",
      "QSQSQSQSQSQSQSa ",
      "SQSQSQSQSQSQSQa ",
      "QSQSQSQSQSQSQSa ",
      "SQSQSQSQSQSQSQaa",
      "QSQSQSQSQSQSQSaa"
    ],
    [
      "aa   aaaaaa   aa",
      "aaaaaa    aaaaaa",
      "              a ",
      "              a ",
      "              a ",
      "  aaa   aaa   aa",
      "  +a+   +a+    a",
      "  :a:   :a:    a",
      "  +a+   +a+    a",
      "  :a:   :a:    a",
      "  +a+   +a+   aa",
      "  :a:   :a:   a ",
      "  +a+   +a+   a ",
      "  :a:   :a:   a ",
      "  +a+   +a+   aa",
      "  aaa   aaa   aa"
    ],
    [
      "aa   aaaaaa   aa",
      "aaaaaa    aaaaaa",
      "              a ",
      "              a ",
      "   a     a    a ",
      "  aaa   aaa   aa",
      "  +a+   +a+    a",
      "  :a:   :a:    a",
      "  +a+   +a+    a",
      "  :a:   :a:    a",
      "  +a+   +a+   aa",
      "  :a:   :a:   a ",
      "  +a+   +a+   a ",
      "  :a:   :a:   a ",
      "  +a+   +a+   aa",
      "  aaa   aaa   aa"
    ],
    [
      "aa   aaaaaa   aa",
      "aaaaaa    aaaaaa",
      "              a ",
      "              a ",
      "              a ",
      "  aaa   aaa   aa",
      "  +a+   +a+    a",
      "  :a:   :a:    a",
      "  +a+   +a+    a",
      "  :a:   :a:    a",
      "  +a+   +a+   aa",
      "  :a:   :a:   a ",
      "  +a+   +a+   a ",
      "  :a:   :a:   a ",
      "  +a+   +a+   aa",
      "  aaa   aaa   aa"
    ],
    [
      "aa   aaaaaa   aa",
      "aaaaaa    aaaaaa",
      "              a ",
      "              a ",
      "              a ",
      "  aaa   aaa   aa",
      "  +a+   +a+    a",
      "  :a:   :a:    a",
      "  +a+   +a+    a",
      "  :a:   :a:    a",
      "  +a+   +a+   aa",
      "  :a:   :a:   a ",
      "  +a+   +a+   a ",
      "  :a:   :a:   a ",
      "  +a+   +a+   aa",
      "  aaa   aaa   aa"
    ],
    [
      "aa   aaaaaa   aa",
      "aaaaaaaaaaaaaaaa",
      "aaaaaaaaaaaaaaa ",
      "aaaaaaaaaaaaaaa ",
      "aaaaaaaaaaaaaaa ",
      "aaaaaaaaaaaaaaaa",
      "aaaaaaaaaaaaaaaa",
      "aaaaaaaaaaaaaaaa",
      "aaaaaaaaaaaaaaaa",
      "aaaaaaaaaaaaaaaa",
      "aaaaaaaaaaaaaaaa",
      "aaaaaaaaaaaaaaa ",
      "aaaaaaaaaaaaaaa ",
      "aaaaaaaaaaaaaaa ",
      "aaaaaaaaaaaaaaaa",
      "aaaaaaaaaaaaaaaa"
    ]
  ]
}