{
  "meta": [
    {
      "key": "support",
      "char": "U"
    }
  ],
  "xsize": 16,
  "zsize": 16,
  "slices": [
    [
      "UUUUUUUUUUUUUUUU",
      "TTTTTTTTTTTTTTTT",
      "TTTTTTTTTTTTTTTT",
      "TTTTTTTTTTTTTTTT",
      "TTTTTTTTTTTTTTTT",
      "TTTTTTTTTTTTTTTT",
      "TTTTTTTTTTTTTTTT",
      "BBBBBBBBBBBBBBBB",
      "BBBBBBBBBBBBBBBB",
      "TTTTTTTTTTTTTTTT",
      "TTTTTTTTTTTTTTTT",
      "TTTTTTTTTTTTTTTT",
      "TTTTTTTTTTTTTTTT",
      "TTTTTTTTTTTTTTTT",
      "TTTTTTTTTTTTTTTT",
      "UUUUUUUUUUUUUUUU"
    ],
    [
      "UHHHHHHHHHHHHHHH",
      "~~~~~~~~~~~~~~j~",
      "~j~j~~~~~~~~jjj~",
      "~jjjj~~~~~~~~j~~",
      "~~jj~~~~~~~~~~~~",
      "~~~~j~~~~~~~~~~~",
      "~~~~~~~~~~~~~~~~",
      "~~~~~~~~~~~~~~~~",
      "~~~~~~~~~~~~~~~~",
      "~~~jj~~~~j~~~~~~",
      "~~~~~~~jjj~~~~~~",
      "~~~~~~~~~~~~~j~~",
      "~~~~~~~~~~~jjj~~",
      "~~~~~~~~~~~~~~~~",
      "~~~~~~~~~~~~~~~~",
      "UHHHHHHHHHHHHHHH"
    ],
    [
      "A~~~~~~~~~~~~~~~",
      "~~~~~~~~~~~~~~~~",
      "~~~~~~~~~~~~~k~~",
      "~~~j~~~~~~~~~~~~",
      "~~~k~~~~~~~~~~~~",
      "~~~~~~~~~~~~~~~~",
      "~~~~~~~~~~~~~~~~",
      "~~~~~~~~~~~~~~~~",
      "~~~~~~~~~~~~~~~~",
      "~~~k~~~~~~~~~~~~",
      "~~~~~~~k~j~~~~~~",
      "~~~~~~~~~~~~~~~~",
      "~~~~~~~~~~~~kj~~",
      "~~~~~~~~~~~~~~~~",
      "~~~~~~~~~~~~~~~~",
      "A~~~~~~~~~~~~~~~"
    ],
    [
      "A~~~~~~~~~~~~~~~",
      "~~~~~~~~~~~~~~~~",
      "~~~~~~~~~~~~~~~~",
      "~~~~~~~~~~~~~~~~",
      "~~~~~~~~~~~~~~~~",
      "~~~~~~~~~~~~~~~~",
      "~~~~~~~~~~~~~~~~",
      "~~~~~~~~~~~~~~~~",
      "~~~~~~~~~~~~~~~~",
      "~~~~~~~~~~~~~~~~",
      "~~~~~~~~~~~~~~~",
      "~~~~~~~~~~~~~~~~",
      "~~~~~~~~~~~~~~~",
      "~~~~~~~~~~~~~~~~",
      "~~~~~~~~~~~~~~~~",
      "A~~~~~~~~~~~~~~~"
    ],
    [
      "A~~~~~~~~~~~~~~~",
      "~~~~~~~~~~~~~~~~",
      "~~~~~~~~~~~~~~~~",
      "~~~~~~~~~~~~~~~~",
      "~~~~~~~~~~~~~~~~",
      "~~~~~~~~~~~~~~~~",
      "~~~~~~~~~~~~~~~~",
      "~~~~~~~~~~~~~~~~",
      "~~~~~~~~~~~~~~~~",
      "~~~~~~~~~~~~~~~~",
      "~~~~~~~~~~~~~~~~",
      "~~~~~~~~~~~~~~~~",
      "~~~~~~~~~~~~~~~~",
      "~~~~~~~~~~~~~~~~",
      "~~~~~~~~~~~~~~~~",
      "A~~~~~~~~~~~~~~~"
    ],
    [
      "A~~~~~~~~~~~~~~~",
      "~~~~~~~~~~~~~~~~",
      "~~~~~~~~~~~~~~~~",
      "~~~~~~~~~~~~~~~~",
      "~~~~~~~~~~~~~~~~",
      "~~~~~~~~~~~~~~~~",
      "~~~~~~~~~~~~~~~~",
      "~~~~~~~~~~~~~~~~",
      "~~~~~~~~~~~~~~~~",
      "~~~~~~~~~~~~~~~~",
      "~~~~~~~~~~~~~~~~",
      "~~~~~~~~~~~~~~~~",
      "~~~~~~~~~~~~~~~~",
      "~~~~~~~~~~~~~~~~",
      "~~~~~~~~~~~~~~~~",
      "A~~~~~~~~~~~~~~~"
    ],
    [
      "A~~~~~~~~~~~~~~~",
      "~~~~~~~~~~~~~~~~",
      "~~~~~~~~~~~~~~~~",
      "~~~~~~~~~~~~~~~~",
      "~~~~~~~~~~~~~~~~",
      "~~~~~~~~~~~~~~~~",
      "~~~~~~~~~~~~~~~~",
      "~~~~~~~~~~~~~~~~",
      "~~~~~~~~~~~~~~~~",
      "~~~~~~~~~~~~~~~~",
      "~~~~~~~~~~~~~~~~",
      "~~~~~~~~~~~~~~~~",
      "~~~~~~~~~~~~~~~~",
      "~~~~~~~~~~~~~~~~",
      "~~~~~~~~~~~~~~~~",
      "A~~~~~~~~~~~~~~~"
    ],
    [
      "A~~~~~~~~~~~~~~~",
      "~~~~~~~~~~~~~~~~",
      "~~~~~~~~~~~~~~~~",
      "~~~~~~~~~~~~~~~~",
      "~~~~~~~~~~~~~~~~",
      "~~~~~~~~~~~~~~~~",
      "~~~~~~~~~~~~~~~~",
      "~~~~~~~~~~~~~~~~",
      "~~~~~~~~~~~~~~~~",
      "~~~~~~~~~~~~~~~~",
      "~~~~~~~~~~~~~~~~",
      "~~~~~~~~~~~~~~~~",
      "~~~~~~~~~~~~~~~~",
      "~~~~~~~~~~~~~~~~",
      "~~~~~~~~~~~~~~~~",
      "A~~~~~~~~~~~~~~~"
    ],
    [
      "A~~~~~~~~~~~~~~~",
      "A~~~~~~~~~~~~~~~",
      "A~~~~~~~~~~~~~~~",
      "A~~~~~~~~~~~~~~~",
      "A~~~~~~~~~~~~~~~",
      "A~~~~~~~~~~~~~~~",
      "A~~~~~~~~~~~~~~~",
      "A~~~~~~~~~~~~~~~",
      "A~~~~~~~~~~~~~~~",
      "A~~~~~~~~~~~~~~~",
      "A~~~~~~~~~~~~~~~",
      "A~~~~~~~~~~~~~~~",
      "A~~~~~~~~~~~~~~~",
      "A~~~~~~~~~~~~~~~",
      "A~~~~~~~~~~~~~~~",
      "A~~~~~~~~~~~~~~~"
    ]
  ]
}