{
  "meta": [
    {
      "key": "support",
      "char": "U"
    }
  ],
  "xsize": 16,
  "zsize": 16,
  "slices": [
    [
      "UUUUUUUUUUUUUUUU",
      "TTTTTTTTTTTTTTTT",
      "TTTTTTTTTTTTTTTT",
      "TTTTTTTTTTTTTTTT",
      "TTTTTTTTTTTTTTTT",
      "TTTTTTTTTTTTTTTT",
      "TTTTTTTTTTTTTTTT",
      "BBBBBBBBBBBBBBBB",
      "BBBBBBBBBBBBBBBB",
      "TTTTTTTTTTTTTTTT",
      "TTTTTTTTTTTTTTTT",
      "TTTTTTTTTTTTTTTT",
      "TTTTTTTTTTTTTTTT",
      "TTTTTTTTTTTTTTTT",
      "TTTTTTTTTTTTTTTT",
      "UUUUUUUUUUUUUUUU"
    ],
    [
      "UUUUUUUUUUUUUUUU",
      "~~~~~~~~~~~~~~~~",
      "~~~~~~~~~~~~~~~~",
      "~~~~~~~~~~~~~~~~",
      "~~~~~~~~~~~~~~~~",
      "~~~~~~~~~~~~~~~~",
      "~~~~~~~~~~~~~~~~",
      "~~~~~~~~~~~~~~~~",
      "~~~~~~~~~~~~~~~~",
      "~~~~~~~~~~~~~~~~",
      "~~~~~~~~~~~~~~~~",
      "~~~~~~~~~~~~~~~~",
      "~~~~~~~~~~~~~~~~",
      "~~~~~~~~~~~~~~~~",
      "~~~~~~~~~~~~~~~~",
      "UUUUUUUUUUUUUUUU"
    ],
    [
      "UUUUUUUUUUUUUUUU",
      "~~~~~~~~~~~~~~~~",
      "~~~~~~~~~~~~~~~~",
      "~~~~~~~~~~~~~~~~",
      "~~~~~~~~~~~~~~~~",
      "~~~~~~~~~~~~~~~~",
      "~~~~~~~~~~~~~~~~",
      "~~~~~~~~~~~~~~~~",
      "~~~~~~~~~~~~~~~~",
      "~~~~~~~~~~~~~~~~",
      "~~~~~~~~~~~~~~~~",
      "~~~~~~~~~~~~~~~~",
      "~~~~~~~~~~~~~~~~",
      "~~~~~~~~~~~~~~~~",
      "~~~~~~~~~~~~~~~~",
      "UUUUUUUUUUUUUUUU"
    ],
    [
      "UUUUUUUUUUUUUUUU",
      "~~~~~~~~U~~~~~~~",
      "~~~~~~~~~~~~~~~~",
      "~~~~~~~~~~~~~~~~",
      "~~~~~~~~~~~~~~~~",
      "~~~~~~~~~~~~~~~~",
      "~~~~~~~~~~~~~~~~",
      "~~~~~~~~~~~~~~~~",
      "~~~~~~~~~~~~~~~~",
      "~~~~~~~~~~~~~~~~",
      "~~~~~~~~~~~~~~~~",
      "~~~~~~~~~~~~~~~~",
      "~~~~~~~~~~~~~~~~",
      "~~~~~~~~~~~~~~~~",
      "~~~~~~~~U~~~~~~~",
      "UUUUUUUUUUUUUUUU"
    ],
    [
      "                ",
      "UUUUUUUUUUUUUUUU",
      "~~~~~~~~~~~~~~~~",
      "~~~~~~~~~~~~~~~~",
      "~~~~~~~~~~~~~~~~",
      "~~~~~~~~~~~~~~~~",
      "~~~~~~~~~~~~~~~~",
      "~~~~~~~~~~~~~~~~",
      "~~~~~~~~~~~~~~~~",
      "~~~~~~~~~~~~~~~~",
      "~~~~~~~~~~~~~~~~",
      "~~~~~~~~~~~~~~~~",
      "~~~~~~~~~~~~~~~~",
      "~~~~~~~~~~~~~~~~",
      "UUUUUUUUUUUUUUUU",
      "                "
    ],
    [
      "                ",
      "                ",
      "UUUUUUUUUUUUUUUU",
      "UUUUUUUUUUUUUUUU",
      "UUUUUUUUUUUUUUUU",
      "UUUUUUUUUUUUUUUU",
      "UUUUUUUUUUUUUUUU",
      "UUUUUUUUUUUUUUUU",
      "UUUUUUUUUUUUUUUU",
      "UUUUUUUUUUUUUUUU",
      "UUUUUUUUUUUUUUUU",
      "UUUUUUUUUUUUUUUU",
      "UUUUUUUUUUUUUUUU",
      "UUUUUUUUUUUUUUUU",
      "                ",
      "                "
    ]
  ]
}