{
  "meta": [
    {
      "key": "support",
      "char": "U"
    }
  ],
  "xsize": 16,
  "zsize": 16,
  "slices": [
    [
      "UTTTTTTBBTTTTTTU",
      "TTTTTTTBBTTTTTTT",
      "TTTTTTTBBTTTTTTT",
      "TTTTTTTBBTTTTTTT",
      "TTTTTTTBBTTTTTTT",
      "TTTTTTTBBTTTTTTT",
      "TTTTTTTBBTTTTTTT",
      "BBBBBBBBBBBBBBBB",
      "BBBBBBBBBBBBBBBB",
      "TTTTTTTBBTTTTTTT",
      "TTTTTTTBBTTTTTTT",
      "TTTTTTTBBTTTTTTT",
      "TTTTTTTBBTTTTTTT",
      "TTTTTTTBBTTTTTTT",
      "TTTTTTTBBTTTTTTT",
      "UTTTTTTBBTTTTTTU"
    ],
    [
      "U~~~~~~~~~~~~~~U",
      "~~~~~~~~~~~~~~~~",
      "~~~~~~~~~~~~~~~~",
      "~~~~~~~~~~~~~~~~",
      "~~~~~~~~~~~~~~~~",
      "~~~~~~~~~~~~~~~~",
      "~~~~~~~~~~~~~~~~",
      "~~~~~~~~~~~~~~~~",
      "~~~~~~~~~~~~~~~~",
      "~~~~~~~~~~~~~~~~",
      "~~~~~~~~~~~~~~~~",
      "~~~~~~~~~~~~~~~~",
      "~~~~~~~~~~~~~~~~",
      "~~~~~~~~~~~~~~~~",
      "~~~~~~~~~~~~~~~~",
      "U~~~~~~~~~~~~~~U"
    ],
    [
      "U~~~~~~~~~~~~~~U",
      "~~~~~~~~~~~~~~~~",
      "~~~~~~~~~~~~~~~~",
      "~~~~~~~~~~~~~~~~",
      "~~~~~~~~~~~~~~~~",
      "~~~~~~~~~~~~~~~~",
      "~~~~~~~~~~~~~~~~",
      "~~~~~~~~~~~~~~~~",
      "~~~~~~~~~~~~~~~~",
      "~~~~~~~~~~~~~~~~",
      "~~~~~~~~~~~~~~~~",
      "~~~~~~~~~~~~~~~~",
      "~~~~~~~~~~~~~~~~",
      "~~~~~~~~~~~~~~~~",
      "~~~~~~~~~~~~~~~~",
      "U~~~~~~~~~~~~~~U"
    ],
    [
      "U~~~~~~~~~~~~~~U",
      "~~~~~~~~~~~~~~~~",
      "~~~~~~~~~~~~~~~~",
      "~~~~~~~~~~~~~~~~",
      "~~~~~~~~~~~~~~~~",
      "~~~~~~~~~~~~~~~~",
      "~~~~~~~~~~~~~~~~",
      "~~~~~~~~~~~~~~~~",
      "~~~~~~~~~~~~~~~~",
      "~~~~~~~~~~~~~~~~",
      "~~~~~~~~~~~~~~~~",
      "~~~~~~~~~~~~~~~~",
      "~~~~~~~~~~~~~~~~",
      "~~~~~~~~~~~~~~~~",
      "~~~~~~~~~~~~~~~~",
      "U~~~~~~~~~~~~~~U"
    ],
    [
      " U~~~~~~~~~~~~U ",
      "U~~~~~~~~~~~~~~U",
      "~~~~~~~~~~~~~~~~",
      "~~~~~~~~~~~~~~~~",
      "~~~~~~~~~~~~~~~~",
      "~~~~~~~~~~~~~~~~",
      "~~~~~~~~~~~~~~~~",
      "~~~~~~~~~~~~~~~~",
      "~~~~~~~~~~~~~~~~",
      "~~~~~~~~~~~~~~~~",
      "~~~~~~~~~~~~~~~~",
      "~~~~~~~~~~~~~~~~",
      "~~~~~~~~~~~~~~~~",
      "~~~~~~~~~~~~~~~~",
      "U~~~~~~~~~~~~~~U",
      " U~~~~~~~~~~~~U "
    ],
    [
      "  UUUUUUUUUUUU  ",
      "  UUUUUUUUUUUU  ",
      "UUUUUUUUUUUUUUUU",
      "UUUUUUUUUUUUUUUU",
      "UUUUUUUUUUUUUUUU",
      "UUUUUUUUUUUUUUUU",
      "UUUUUUUUUUUUUUUU",
      "UUUUUUUUUUUUUUUU",
      "UUUUUUUUUUUUUUUU",
      "UUUUUUUUUUUUUUUU",
      "UUUUUUUUUUUUUUUU",
      "UUUUUUUUUUUUUUUU",
      "UUUUUUUUUUUUUUUU",
      "UUUUUUUUUUUUUUUU",
      "  UUUUUUUUUUUU  ",
      "  UUUUUUUUUUUU  "
    ]
  ]
}