{
  "xsize": 16,
  "zsize": 16,
  "slices": [
    [
      "aSSaQQQQQQQQQQQQ",
      "aSSaQQQQQQQQQQQQ",
      "aSSaQQQQQQQQQQQQ",
      "aSSaQQQQQQQQQQQQ",
      "aSSaQQQQQQQQQQQQ",
      "aSSaQQQQQQQQQQQQ",
      "aSSaQQQQQQQQQQQQ",
      "aSSaQQQQQQQQQQQQ",
      "aSSaQQQQQQQQQQQQ",
      "aSSaQQQQQQQQQQQQ",
      "aSSaQQQQQQQQQQQQ",
      "aSSaQQQQQQQQQQQQ",
      "aSSaaaaaaaaaaaaa",
      "aSSSSSSSSSSSSSSS",
      "aSSSSSSSSSSSSSSS",
      "aaaaaaaaaaaaaaaa"
    ],
    [
      "a               ",
      "a               ",
      "a               ",
      "a               ",
      "a      LLLL     ",
      "a     QQQQQQ    ",
      "a     QLLLLQ    ",
      "a     Q    Q    ",
      "a               ",
      "a     Q    Q    ",
      "a     QLLLLQ    ",
      "a     QQQQQQ    ",
      "a      LLLL     ",
      "a               ",
      "a               ",
      "aaaaaaaaaaaaaaaa"
    ],
    [
      "a               ",
      "a               ",
      "a               ",
      "a               ",
      "a               ",
      "a      **       ",
      "a               ",
      "a               ",
      "a               ",
      "a               ",
      "a               ",
      "a        * *    ",
      "a               ",
      "a               ",
      "a               ",
      "aaaaaaaaaaaaaaaa"
    ],
    [
      "a               ",
      "a               ",
      "a               ",
      "a               ",
      "a               ",
      "a               ",
      "a               ",
      "a               ",
      "a               ",
      "a               ",
      "a               ",
      "a               ",
      "a               ",
      "a               ",
      "a               ",
      "aaaaaaaaaaaaaaaa"
    ],
    [
      "a               ",
      "a               ",
      "a               ",
      "a               ",
      "a               ",
      "a               ",
      "a               ",
      "a               ",
      "a               ",
      "a               ",
      "a               ",
      "a               ",
      "a               ",
      "a               ",
      "a               ",
      "aaaaaaaaaaaaaaaa"
    ],
    [
      "aaaaaaaaaaaaaaaa",
      "aaaaaaaaaaaaaaaa",
      "aaaaaaaaaaaaaaaa",
      "aaaaaaaaaaaaaaaa",
      "aaaaaaaaaaaaaaaa",
      "aaaaaaaaaaaaaaaa",
      "aaaaaaaaaaaaaaaa",
      "aaaaaaaaaaaaaaaa",
      "aaaaaaaaaaaaaaaa",
      "aaaaaaaaaaaaaaaa",
      "aaaaaaaaaaaaaaaa",
      "aaaaaaaaaaaaaaaa",
      "aaaaaaaaaaaaaaaa",
      "aaaaaaaaaaaaaaaa",
      "aaaaaaaaaaaaaaaa",
      "aaaaaaaaaaaaaaaa"
    ]
  ]
}