{
  "xsize": 16,
  "zsize": 16,
  "slices": [
    [
      "aSSaQQQQQQQQQQQQ",
      "aSSaQQQQQQQQQQQQ",
      "aSSaQQQQQQQQQQQQ",
      "aSSaQQQQQQQQQQQQ",
      "aSSaQQQQQQQQQQQQ",
      "aSSaQQQQQQQQQQQQ",
      "aSSaQQQQQQQQQQQQ",
      "aSSaQQQQQQQQQQQQ",
      "aSSaQQQQQQQQQQQQ",
      "aSSaQQQQQQQQQQQQ",
      "aSSaQQQQQQQQQQQQ",
      "aSSaQQQQQQQQQQQQ",
      "aSSaaaaaaaaaaaaa",
      "aSSSSSSSSSSSSSSS",
      "aSSSSSSSSSSSSSSS",
      "aaaaaaaaaaaaaaaa"
    ],
    [
      "a               ",
      "a               ",
      "a               ",
      "a               ",
      "a               ",
      "a               ",
      "a               ",
      "a               ",
      "aaa:::::::aaa   ",
      "a               ",
      "a   LLL     a   ",
      "a           :   ",
      "a   LLL     :   ",
      "a           a   ",
      "a F         a   ",
      "aaaaaaaaaaaaaaaa"
    ],
    [
      "a               ",
      "a               ",
      "a               ",
      "a               ",
      "a               ",
      "a               ",
      "a               ",
      "a               ",
      "aaa:::::::aaa   ",
      "a               ",
      "a   LLL     a   ",
      "a           :   ",
      "a   LLLa    :   ",
      "a           a   ",
      "a           a   ",
      "aaaaaaaaaaaaaaaa"
    ],
    [
      "a               ",
      "a               ",
      "a               ",
      "a               ",
      "a               ",
      "a               ",
      "a               ",
      "a               ",
      "aaa:::::::aaa   ",
      "a           a   ",
      "a   LLL     a   ",
      "a           :   ",
      "a   LLL     :   ",
      "a           a   ",
      "a           a   ",
      "aaaaaaaaaaaaaaaa"
    ],
    [
      "a               ",
      "a               ",
      "a               ",
      "a               ",
      "a               ",
      "a               ",
      "a               ",
      "a               ",
      "aaa:::::::aaa   ",
      "a           a   ",
      "a           a   ",
      "a           :   ",
      "a           :   ",
      "a           a   ",
      "a           a   ",
      "aaaaaaaaaaaaaaaa"
    ],
    [
      "aaaaaaaaaaaaaaaa",
      "aaaaaaaaaaaaaaaa",
      "aaaaaaaaaaaaaaaa",
      "aaaaaaaaaaaaaaaa",
      "aaaaaaaaaaaaaaaa",
      "aaaaaaaaaaaaaaaa",
      "aaaaaaaaaaaaaaaa",
      "aaaaaaaaaaaaaaaa",
      "aaaaaaaaaaaaaaaa",
      "aaaaaaaaaaaaaaaa",
      "aaaaaaaaaaaaaaaa",
      "aaaaaaaaaaaaaaaa",
      "aaaaaaaaaaaaaaaa",
      "aaaaaaaaaaaaaaaa",
      "aaaaaaaaaaaaaaaa",
      "aaaaaaaaaaaaaaaa"
    ]
  ]
}