{
  "xsize": 16,
  "zsize": 16,
  "slices": [
    [
      "QQQQQQQQQQQQaSSa",
      "QQQQQQQQQQQQaSSa",
      "QQQQQQQQQQQQaSSa",
      "QQQQQQQQQQQQaSSa",
      "QQQQQQQQQQQQaSSa",
      "QQQQQQQQQQQQaSSa",
      "QQQQQQQQQQQQaSSa",
      "QQQQQQQQQQQQaSSa",
      "QQQQQQQQQQQQaSSa",
      "QQQQQQQQQQQQaSSa",
      "QQQQQQQQQQQQaSSa",
      "QQQQQQQQQQQQaSSa",
      "aaaaaaaaaaaaaSSa",
      "SSSSSSSSSSSSSSSa",
      "SSSSSSSSSSSSSSSa",
      "aaaaaaaaaaaaaaaa"
    ],
    [
      "               a",
      "               a",
      "               a",
      "               a",
      "      LLLL     a",
      "               a",
      "      LLLL     a",
      "               a",
      "      LLLL     a",
      "               a",
      "      LLLL     a",
      "               a",
      "               a",
      "               a",
      "               a",
      "aaaaaaaaaaaaaaaa"
    ],
    [
      "               a",
      "               a",
      "               a",
      "               a",
      "     aLLLL     a",
      "               a",
      "      LLLL     a",
      "               a",
      "      LLLL     a",
      "               a",
      "     aLLLL     a",
      "               a",
      "               a",
      "               a",
      "               a",
      "aaaaaaaaaaaaaaaa"
    ],
    [
      "               a",
      "               a",
      "               a",
      "               a",
      "      LLLL     a",
      "               a",
      "      LLLL     a",
      "               a",
      "      LLLL     a",
      "               a",
      "      LLLL     a",
      "               a",
      "               a",
      "               a",
      "               a",
      "aaaaaaaaaaaaaaaa"
    ],
    [
      "               a",
      "               a",
      "               a",
      "               a",
      "               a",
      "      %        a",
      "               a",
      "       %       a",
      "               a",
      "               a",
      "               a",
      "               a",
      "               a",
      "               a",
      "               a",
      "aaaaaaaaaaaaaaaa"
    ],
    [
      "aaaaaaaaaaaaaaaa",
      "aaaaaaaaaaaaaaaa",
      "aaaaaaaaaaaaaaaa",
      "aaaaaaaaaaaaaaaa",
      "aaaaaaaaaaaaaaaa",
      "aaaaaaaaaaaaaaaa",
      "aaaaaaaaaaaaaaaa",
      "aaaaaaaaaaaaaaaa",
      "aaaaaaaaaaaaaaaa",
      "aaaaaaaaaaaaaaaa",
      "aaaaaaaaaaaaaaaa",
      "aaaaaaaaaaaaaaaa",
      "aaaaaaaaaaaaaaaa",
      "aaaaaaaaaaaaaaaa",
      "aaaaaaaaaaaaaaaa",
      "aaaaaaaaaaaaaaaa"
    ]
  ]
}