{
  "xsize": 16,
  "zsize": 16,
  "slices": [
    [
      "aaaaaaaaaaaaaaaa",
      "aSSSSSSSSSSSSSSS",
      "aSSSSSSSSSSSSSSS",
      "aSSaaaaaaaaaaaaa",
      "aSSaQQQQQQQQQQQQ",
      "aSSaQQQQQQQQQQQQ",
      "aSSaQQQQQQQQQQQQ",
      "aSSaQQQQQQQQQQQQ",
      "aSSaQQQQQQQQQQQQ",
      "aSSaQQQQQQQQQQQQ",
      "aSSaQQQQQQQQQ  Q",
      "aSSaQQQQQQQQQ  Q",
      "aSSaQQQQQQQQQ  Q",
      "aSSaQQQQQQQQQ  Q",
      "aSSaQQQQQQQQQ))Q",
      "aSSaQQQQQQQQQQQQ"
    ],
    [
      "aaaaaaaaaaaaaaaa",
      "a               ",
      "a               ",
      "a               ",
      "a      LLLL     ",
      "a               ",
      "a      LLLL     ",
      "a               ",
      "a               ",
      "a            )) ",
      "a           w  w",
      "a           w  w",
      "a           w  w",
      "a           w  w",
      "a           w  w",
      "a               "
    ],
    [
      "aaaaaaaaaaaaaaaa",
      "a               ",
      "a               ",
      "a               ",
      "a      LLLLa    ",
      "a               ",
      "a      LLLLa    ",
      "a               ",
      "a               ",
      "a               ",
      "a           :)):",
      "a           :  :",
      "a           :  :",
      "a           :  :",
      "a           :  :",
      "a               "
    ],
    [
      "aaaaaaaaaaaaaaaa",
      "a               ",
      "a               ",
      "a               ",
      "a      LLLL     ",
      "a               ",
      "a      LLLL     ",
      "a               ",
      "a               ",
      "a               ",
      "a           :  :",
      "a           :)):",
      "a           :  :",
      "a           :  :",
      "a           :  :",
      "a               "
    ],
    [
      "aaaaaaaaaaaaaaaa",
      "a        %      ",
      "a               ",
      "a               ",
      "a               ",
      "a               ",
      "a               ",
      "a               ",
      "a               ",
      "a               ",
      "a          %:  :",
      "a           :  :",
      "a           :)):",
      "a          %:  :",
      "a           :  :",
      "a               "
    ],
    [
      "aaaaaaaaaaaaaaaa",
      "aaaaaaaaaaaaaaaa",
      "aaaaaaaaaaaaaaaa",
      "aaaaaaaaaaaaaaaa",
      "aaaaaaaaaaaaaaaa",
      "aaaaaaaaaaaaaaaa",
      "aaaaaaaaaaaaaaaa",
      "aaaaaaaaaaaaaaaa",
      "aaaaaaaaaaaaaaaa",
      "aaaaaaaaaaaaaaaa",
      "aaaaaaaaaaaaa  a",
      "aaaaaaaaaaaaa  a",
      "aaaaaaaaaaaaa  a",
      "aaaaaaaaaaaaa))a",
      "aaaaaaaaaaaaa  a",
      "aaaaaaaaaaaaaaaa"
    ]
  ]
}