{
  "xsize": 16,
  "zsize": 16,
  "slices": [
    [
      "################",
      "SSSSSSSSSSSSSSS#",
      "SSSSSSSSSSSSSSS#",
      "#############SS#",
      "QQQQQQQQQQQQ#SS#",
      "QQQQQQQQQQQQ#SS#",
      "QQQQQQQQQQQQ#SS#",
      "QQQQQQQQQQQQ#SS#",
      "QQQQQQQQQQQQ#SS#",
      "QQQQQQQQQQQQ#SS#",
      "QQQQQQQQQQQQ#SS#",
      "QQQQQQQQQQQQ#SS#",
      "QQQQQQQQQQQQ#SS#",
      "QQQQQQQQQQQQ#SS#",
      "QQQQQQQQQQQQ#SS#",
      "QQQQQQQQQQQQ#SS#"
    ],
    [
      "aaa#aaaa#aaaa#aa",
      "               a",
      "               #",
      "               a",
      "     LLLLLL    a",
      "               a",
      "     LLLLLL%   a",
      "               #",
      "     LLLLLLC   a",
      "               a",
      "    %LLLLLL    a",
      "               a",
      "     LLLLLL    #",
      "               a",
      "               a",
      "               a"
    ],
    [
      "aaa#aaaa#aaaa#aa",
      "               a",
      "               #",
      "               a",
      "    aLLLLLL    a",
      "               a",
      "     LLLLLL    a",
      "               #",
      "     LLLLLL    a",
      "               a",
      "     LLLLLL    a",
      "               a",
      "    aLLLLLL    #",
      "               a",
      "               a",
      "               a"
    ],
    [
      "aaa#aaaa#aaaa#aa",
      "               a",
      "               #",
      "               a",
      "     LLLLLL    a",
      "               a",
      "     LLLLLL    a",
      "               #",
      "     LLLLLL    a",
      "               a",
      "     LLLLLL    a",
      "               a",
      "               #",
      "               a",
      "               a",
      "               a"
    ],
    [
      "################",
      "               #",
      "               #",
      "               #",
      "     %         #",
      "               #",
      "        %      #",
      "               #",
      "               #",
      "               #",
      "               #",
      "               #",
      "               #",
      "               #",
      "               #",
      "               #"
    ],
    [
      "################",
      "################",
      "################",
      "################",
      "################",
      "################",
      "################",
      "################",
      "################",
      "################",
      "################",
      "################",
      "################",
      "################",
      "################",
      "################"
    ]
  ]
}