{
  "xsize": 16,
  "zsize": 16,
  "slices": [
    [
      "aaaaaaaaaaaaaaaa",
      "SSSSSSSSSSSSSSSa",
      "SSSSSSSSSSSSSSSa",
      "aaaaaaaaaaaaaSSa",
      "QQQQQQQQQQQQaSSa",
      "QQQQQQQQQQQQaSSa",
      "QQQQQQQQQQQQaSSa",
      "QQQQQQQQQQQQaSSa",
      "QQQQQQQQQQQQaSSa",
      "QQQQQQQQQQQQaSSa",
      "QQQQQQQQQQQQaSSa",
      "QQQQQQQQQQQQaSSa",
      "QQQQQQQQQQQQaSSa",
      "QQQQQQQQQQQQaSSa",
      "QQQQQQQQQQQQaSSa",
      "QQQQQQQQQQQQaSSa"
    ],
    [
      "aaaaaaaaaaaaaaaa",
      "               a",
      "               a",
      "               a",
      "     LLLLL     a",
      "               a",
      "               a",
      "     .  .  .   a",
      "               a",
      "               a",
      "     .  .  .   a",
      "               a",
      "               a",
      "     LLLLL     a",
      "               a",
      "               a"
    ],
    [
      "aaaaaaaaaaaaaaaa",
      "               a",
      "               a",
      "               a",
      "    aLLLLL     a",
      "               a",
      "               a",
      "     -  -  -   a",
      "               a",
      "               a",
      "     -  -  -   a",
      "               a",
      "               a",
      "    aLLLLL     a",
      "               a",
      "               a"
    ],
    [
      "aaaaaaaaaaaaaaaa",
      "               a",
      "               a",
      "               a",
      "     LLLLL     a",
      "               a",
      "               a",
      "               a",
      "               a",
      "               a",
      "               a",
      "               a",
      "               a",
      "     LLLLL     a",
      "               a",
      "               a"
    ],
    [
      "aaaaaaaaaaaaaaaa",
      "               a",
      "               a",
      "               a",
      "               a",
      "               a",
      "               a",
      "               a",
      "               a",
      "               a",
      "               a",
      "               a",
      "               a",
      "               a",
      "               a",
      "               a"
    ],
    [
      "aaaaaaaaaaaaaaaa",
      "aaaaaaaaaaaaaaaa",
      "aaaaaaaaaaaaaaaa",
      "aaaaaaaaaaaaaaaa",
      "aaaaaaaaaaaaaaaa",
      "aaaaaaaaaaaaaaaa",
      "aaaaaaaaaaaaaaaa",
      "aaaaaaaaaaaaaaaa",
      "aaaaaaaaaaaaaaaa",
      "aaaaaaaaaaaaaaaa",
      "aaaaaaaaaaaaaaaa",
      "aaaaaaaaaaaaaaaa",
      "aaaaaaaaaaaaaaaa",
      "aaaaaaaaaaaaaaaa",
      "aaaaaaaaaaaaaaaa",
      "aaaaaaaaaaaaaaaa"
    ]
  ]
}