{
  "xsize": 16,
  "zsize": 16,
  "slices": [
    [
      "aaaaaaaaaaaaaaaa",
      "SSSSSSSSSSSSSSSa",
      "SSSSSSSSSSSSSSSa",
      "aaaaaaaaaaaaaSSa",
      "QQQQQQQQQQQQaSSa",
      "QQQQQQQQQQQQaSSa",
      "QQQQQQQQQQQQaSSa",
      "QQQQQQQQQQQQaSSa",
      "QQQQQQQQQQQQaSSa",
      "QQQQQQQQQQQQaSSa",
      "QQQQQQQQQQQQaSSa",
      "QQQQQQQQQQQQaSSa",
      "QQQQQQQQQQQQaSSa",
      "QQQQQQQQQQQQaSSa",
      "QQQQQQQQQQQQaSSa",
      "QQQQQQQQQQQQaSSa"
    ],
    [
      "aaaaaaaaaaaaaaaa",
      "               a",
      "               a",
      "    FLLLLF     a",
      "  aaaaaaaaaa   a",
      "  a1aaaaaa1a   a",
      "  aaaaaaaaaa   a",
      "  aaaC C aaaF  a",
      "  aaa    aaaL  a",
      "  aaa  C aaaL  a",
      "         aaaL  a",
      "  aaa   CaaaF  a",
      "  aaaaaaaaaa   a",
      "  a4aaaaaa1a   a",
      "  aaaaaaaaaa   a",
      "    FLLLLF     a"
    ],
    [
      "aaaaaaaaaaaaaaaa",
      "               a",
      "               a",
      "   a LLLL      a",
      "  aaaaaaaaaa   a",
      "  aaaaaaaaaa   a",
      "  aaaaaaaaaa   a",
      "  aaa    aaa   a",
      "  aaa    aaaL  a",
      "  aaa    aaaL  a",
      "         aaaL  a",
      "  aaa    aaa   a",
      "  aaaaaaaaaa   a",
      "  aaaaaaaaaa   a",
      "  aaaaaaaaaa   a",
      "     LLLL      a"
    ],
    [
      "aaaaaaaaaaaaaaaa",
      "               a",
      "               a",
      "     LLLL      a",
      "  aaaaaaaaaa   a",
      "  aaaaaaaaaa   a",
      "  aaaaaaaaaa   a",
      "  aaa    aaa   a",
      "  aaa    aaaL  a",
      "  aaa    aaaL  a",
      "  aaa    aaaL  a",
      "  aaa    aaa   a",
      "  aaaaaaaaaa   a",
      "  aaaaaaaaaa   a",
      "  aaaaaaaaaa   a",
      "     LLLL      a"
    ],
    [
      "aaaaaaaaaaaaaaaa",
      "               a",
      "               a",
      "               a",
      "  aaaaaaaaaa   a",
      "  aaaaaaaaaa   a",
      "  aaaaaaaaaa   a",
      "  aaa%  %aaa   a",
      "  aaa    aaa   a",
      "  aaa    aaa   a",
      "  aaa    aaa   a",
      "  aaa%  %aaa   a",
      "  aaaaaaaaaa   a",
      "  aaaaaaaaaa   a",
      "  aaaaaaaaaa   a",
      "               a"
    ],
    [
      "aaaaaaaaaaaaaaaa",
      "aaaaaaaaaaaaaaaa",
      "aaaaaaaaaaaaaaaa",
      "aaaaaaaaaaaaaaaa",
      "aaaaaaaaaaaaaaaa",
      "aaaaaaaaaaaaaaaa",
      "aaaaaaaaaaaaaaaa",
      "aaaaaaaaaaaaaaaa",
      "aaaaaaaaaaaaaaaa",
      "aaaaaaaaaaaaaaaa",
      "aaaaaaaaaaaaaaaa",
      "aaaaaaaaaaaaaaaa",
      "aaaaaaaaaaaaaaaa",
      "aaaaaaaaaaaaaaaa",
      "aaaaaaaaaaaaaaaa",
      "aaaaaaaaaaaaaaaa"
    ]
  ]
}