{
  "xsize": 16,
  "zsize": 16,
  "slices": [
    [
      "aaaaaaaaaaaaaaaa",
      "SSSSSSSSSSSSSSSa",
      "SSSSSSSSSSSSSSSa",
      "aaaaaaaaaaaaaSSa",
      "QQQQQQQQQQQQaSSa",
      "QQQQQQQQQQQQaSSa",
      "QQQQQQQQQQQQaSSa",
      "QQQQQQQQQQQQaSSa",
      "QQQQQQQQQQQQaSSa",
      "QQQQQQQQQQQQaSSa",
      "QQQQQQQQQQQQaSSa",
      "QQQQQQQQQQQQaSSa",
      "QQQQQQQQQQQQaSSa",
      "QQQQQQQQQQQQaSSa",
      "QQQQQQQQQQQQaSSa",
      "QQQQQQQQQQQQaSSa"
    ],
    [
      "aaaaaaaaaaaaaaaa",
      "               a",
      "               a",
      "               a",
      "     LLLLLL    a",
      "               a",
      "     LLLLLL%   a",
      "               a",
      "     LLLLLLC   a",
      "               a",
      "    %LLLLLL    a",
      "               a",
      "     LLLLLL    a",
      "               a",
      "               a",
      "               a"
    ],
    [
      "aaaaaaaaaaaaaaaa",
      "               a",
      "               a",
      "               a",
      "    aLLLLLL    a",
      "               a",
      "     LLLLLL    a",
      "               a",
      "     LLLLLL    a",
      "               a",
      "     LLLLLL    a",
      "               a",
      "    aLLLLLL    a",
      "               a",
      "               a",
      "               a"
    ],
    [
      "aaaaaaaaaaaaaaaa",
      "               a",
      "               a",
      "               a",
      "     LLLLLL    a",
      "               a",
      "     LLLLLL    a",
      "               a",
      "     LLLLLL    a",
      "               a",
      "     LLLLLL    a",
      "               a",
      "               a",
      "               a",
      "               a",
      "               a"
    ],
    [
      "aaaaaaaaaaaaaaaa",
      "               a",
      "               a",
      "               a",
      "     %         a",
      "               a",
      "        %      a",
      "               a",
      "               a",
      "               a",
      "               a",
      "               a",
      "               a",
      "               a",
      "               a",
      "               a"
    ],
    [
      "aaaaaaaaaaaaaaaa",
      "aaaaaaaaaaaaaaaa",
      "aaaaaaaaaaaaaaaa",
      "aaaaaaaaaaaaaaaa",
      "aaaaaaaaaaaaaaaa",
      "aaaaaaaaaaaaaaaa",
      "aaaaaaaaaaaaaaaa",
      "aaaaaaaaaaaaaaaa",
      "aaaaaaaaaaaaaaaa",
      "aaaaaaaaaaaaaaaa",
      "aaaaaaaaaaaaaaaa",
      "aaaaaaaaaaaaaaaa",
      "aaaaaaaaaaaaaaaa",
      "aaaaaaaaaaaaaaaa",
      "aaaaaaaaaaaaaaaa",
      "aaaaaaaaaaaaaaaa"
    ]
  ]
}