{
  "xsize": 16,
  "zsize": 16,
  "slices": [
    [
      "aSSaQQQQQQQQQQQQ",
      "aSSaQQQQQQQQQQQQ",
      "aSSaQQQQQQQQQQQQ",
      "aSSaQQQQQQQQQQQQ",
      "aSSaQQQQQQQQQQQQ",
      "aSSaQQQQQQQQQQQQ",
      "aSSaQQQQQQQQQQQQ",
      "aSSaQQQQQQQQQQQQ",
      "aSSaQQQQQQQQQQQQ",
      "aSSaQQQQQQQQQQQQ",
      "aSSaQQQQQQQQQQQQ",
      "aSSaQQQQQQQQQQQQ",
      "aSSaaaaaaaaaaaaa",
      "aSSSSSSSSSSSSSSS",
      "aSSSSSSSSSSSSSSS",
      "aaaaaaaaaaaaaaaa"
    ],
    [
      "a               ",
      "a               ",
      "a               ",
      "a       %       ",
      "a      LLLL     ",
      "a               ",
      "a      LLLL     ",
      "a        %%     ",
      "a      LLLL     ",
      "a               ",
      "a      LLLL     ",
      "a      %%       ",
      "a               ",
      "a               ",
      "a               ",
      "aaaaaaaaaaaaaaaa"
    ],
    [
      "a               ",
      "a               ",
      "a               ",
      "a               ",
      "a      LLLLa    ",
      "a               ",
      "a      LLLL     ",
      "a               ",
      "a      LLLL     ",
      "a               ",
      "a      LLLLa    ",
      "a               ",
      "a               ",
      "a               ",
      "a               ",
      "aaaaaaaaaaaaaaaa"
    ],
    [
      "a               ",
      "a               ",
      "a               ",
      "a               ",
      "a      LLLL     ",
      "a               ",
      "a      LLLL     ",
      "a               ",
      "a      LLLL     ",
      "a               ",
      "a      LLLL     ",
      "a               ",
      "a               ",
      "a               ",
      "a               ",
      "aaaaaaaaaaaaaaaa"
    ],
    [
      "a               ",
      "a               ",
      "a               ",
      "a               ",
      "a               ",
      "a               ",
      "a               ",
      "a               ",
      "a               ",
      "a               ",
      "a               ",
      "a               ",
      "a               ",
      "a               ",
      "a               ",
      "aaaaaaaaaaaaaaaa"
    ],
    [
      "aaaaaaaaaaaaaaaa",
      "aaaaaaaaaaaaaaaa",
      "aaaaaaaaaaaaaaaa",
      "aaaaaaaaaaaaaaaa",
      "aaaaaaaaaaaaaaaa",
      "aaaaaaaaaaaaaaaa",
      "aaaaaaaaaaaaaaaa",
      "aaaaaaaaaaaaaaaa",
      "aaaaaaaaaaaaaaaa",
      "aaaaaaaaaaaaaaaa",
      "aaaaaaaaaaaaaaaa",
      "aaaaaaaaaaaaaaaa",
      "aaaaaaaaaaaaaaaa",
      "aaaaaaaaaaaaaaaa",
      "aaaaaaaaaaaaaaaa",
      "aaaaaaaaaaaaaaaa"
    ]
  ]
}