{
  "xsize": 16,
  "zsize": 16,
  "slices": [
    [
      "                ",
      " wwww      wwww ",
      " w     p p  p w ",
      " w   p        w ",
      " w           pw ",
      "           p    ",
      "  p    aaa      ",
      "      aFFFa p   ",
      "    p aFFFa     ",
      "      aFFFa     ",
      "  p    aaap     ",
      " w    p     p w ",
      " w            w ",
      " w p     p    w ",
      " wwwwp     wwww ",
      "                "
    ],
    [
      "                ",
      " w  w      w  w ",
      "                ",
      "                ",
      " w            w ",
      "                ",
      "       waw      ",
      "      w   w     ",
      "        F       ",
      "      w   w     ",
      "       waw      ",
      " w            w ",
      "                ",
      "                ",
      " w  w      w  w ",
      "                "
    ],
    [
      "                ",
      " w  w      w  w ",
      "                ",
      "                ",
      " w            w ",
      "                ",
      "                ",
      "                ",
      "        F       ",
      "                ",
      "                ",
      "  w           w ",
      "                ",
      "                ",
      " w  w      w  w ",
      "                "
    ],
    [
      "                ",
      " aaaa      aaaa ",
      " a            a ",
      " a            a ",
      " a            a ",
      "                ",
      "                ",
      "                ",
      "                ",
      "                ",
      "                ",
      " a            a ",
      " a            a ",
      " a            a ",
      " aaaa      aaaa ",
      "                "
    ]
  ]
}