{
  "xsize": 16,
  "zsize": 16,
  "slices": [
    [
      "                ",
      "      x  x      ",
      "                ",
      "   x        x   ",
      "                ",
      "                ",
      " x            x ",
      "                ",
      "                ",
      " x            x ",
      "                ",
      "                ",
      "   x        x   ",
      "                ",
      "      x  x      ",
      "                "
    ],
    [
      "                ",
      "      w  w      ",
      "      a  a      ",
      "   w        w   ",
      "                ",
      "                ",
      " wa          aw ",
      "                ",
      "                ",
      " wa          aw ",
      "                ",
      "                ",
      "   w        w   ",
      "      a  a      ",
      "      w  w      ",
      "                "
    ],
    [
      "                ",
      "      w  w      ",
      "                ",
      "   w        w   ",
      "                ",
      "                ",
      " w            w ",
      "                ",
      "                ",
      " w            w ",
      "                ",
      "                ",
      "   w        w   ",
      "                ",
      "      w  w      ",
      "                "
    ],
    [
      "                ",
      "      w  w      ",
      "                ",
      "   w        w   ",
      "                ",
      "                ",
      " w            w ",
      "                ",
      "                ",
      " w            w ",
      "                ",
      "                ",
      "   w        w   ",
      "                ",
      "      w  w      ",
      "                "
    ],
    [
      "                ",
      "      aaaa      ",
      "    aaaaaaaa    ",
      "   aaaaaaaaaa   ",
      "  aaaaaaaaaaaa  ",
      "  aaaaaaaaaaaa  ",
      " aaaaaaaaaaaaaa ",
      " aaaaaaaaaaaaaa ",
      " aaaaaaaaaaaaaa ",
      " aaaaaaaaaaaaaa ",
      "  aaaaaaaaaaaa  ",
      "  aaaaaaaaaaaa  ",
      "   aaaaaaaaaa   ",
      "    aaaaaaaa    ",
      "      aaaa      ",
      "                "
    ]
  ]
}