{
  "xsize": 16,
  "zsize": 16,
  "slices": [
    [
      "                ",
      "      x  x      ",
      "                ",
      "   x        x   ",
      "                ",
      "                ",
      " x            x ",
      "                ",
      "                ",
      " x            x ",
      "                ",
      "                ",
      "   x        x   ",
      "                ",
      "      x  x      ",
      "                "
    ],
    [
      "                ",
      "      w  w      ",
      "      a  a      ",
      "   w        w   ",
      "                ",
      "                ",
      " wa          aw ",
      "                ",
      "                ",
      " wa          aw ",
      "                ",
      "                ",
      "   w        w   ",
      "      a  a      ",
      "      w  w      ",
      "                "
    ],
    [
      "                ",
      "      w  w      ",
      "                ",
      "   w        w   ",
      "                ",
      "                ",
      " w            w ",
      "                ",
      "                ",
      " w            w ",
      "                ",
      "                ",
      "   w        w   ",
      "                ",
      "      w  w      ",
      "                "
    ],
    [
      "                ",
      "      w  w      ",
      "                ",
      "   w        w   ",
      "                ",
      "                ",
      " w            w ",
      "                ",
      "                ",
      " w            w ",
      "                ",
      "                ",
      "   w        w   ",
      "                ",
      "      w  w      ",
      "                "
    ],
    [
      "                ",
      "      aaaa      ",
      "    aaaaaaaa    ",
      "   aaauuuuaaa   ",
      "  aaauuuuuuaaa  ",
      "  aauuuuuuuuaa  ",
      " aauuuuuuuuuuaa ",
      " aauuuuuuuuuuaa ",
      " aauuuuuuuuuuaa ",
      " aauuuuuuuuuuaa ",
      "  aauuuuuuuuaa  ",
      "  aaauuuuuuaaa  ",
      "   aaauuuuaaa   ",
      "    aaaaaaaa    ",
      "      aaaa      ",
      "                "
    ],
    [
      "                ",
      "                ",
      "                ",
      "                ",
      "                ",
      "       aa       ",
      "      aaaa      ",
      "     aaaaaa     ",
      "     aaaaaa     ",
      "      aaaa      ",
      "       aa       ",
      "                ",
      "                ",
      "                ",
      "                ",
      "                "
    ]
  ]
}