{
  "xsize": 16,
  "zsize": 16,
  "slices": [
    [
      "SQQSSQQSSQQSSQQa",
      "QSSQQSSQQSSQQSSa",
      "QSSQQSSQQSSQQSSa",
      "SQQSSQQSSQQSSQQa",
      "SQQSSQQSSQQSSQQa",
      "QSSQQSSQQSSQQSSa",
      "QSSQQSSQQSSQQSSa",
      "SQQSSQQSSQQSSQQa",
      "SQQSSQQS  QSSQQa",
      "QSSQQSSQ  SQQSSa",
      "QSSQQSSQ  SQQSSa",
      "SQQSSQQS  QSSQQa",
      "SQQSSQQS  QSSQQa",
      "QSSQQSSQ))SQQSSa",
      "QSSQQSSQQSSQQSSa",
      "aaaaaaaaaaaaaaaa"
    ],
    [
      "               a",
      "               a",
      "               a",
      "               a",
      "               a",
      "               a",
      "               a",
      "               a",
      "       `))`    a",
      "       `  `    a",
      "       `  `    a",
      "       `  `    a",
      "       `  `    a",
      "       `  `    a",
      "               a",
      "aaaaaaaaaaaaaaaa"
    ],
    [
      "               a",
      "               a",
      "               a",
      "               a",
      "               a",
      "               a",
      "               a",
      "               a",
      "       `  `    a",
      "       `))`    a",
      "       `  `    a",
      "       `  `    a",
      "       `  `    a",
      "       `  `    a",
      "               a",
      "aaaaaaaaaaaaaaaa"
    ],
    [
      "               a",
      "               a",
      "               a",
      "               a",
      "               a",
      "               a",
      "               a",
      "              aa",
      "       `  `    a",
      "       `  `    a",
      "       `))`    a",
      "       `  `    a",
      "       `  `    a",
      "       `  `    a",
      "               a",
      "aaaaaaaaaaaaaaaa"
    ],
    [
      "               a",
      "               a",
      "               a",
      "               a",
      "               a",
      "               a",
      "               a",
      "               a",
      "       `  `    a",
      "       `  `    a",
      "       `  `    a",
      "       `))`    a",
      "       `  `    a",
      "       `  `    a",
      "               a",
      "aaaaaaaaaaaaaaaa"
    ],
    [
      "aaaaaaaaaaaaaaaa",
      "aaaaaaaaaaaaaaaa",
      "aaaaaaaaaaaaaaaa",
      "aaaaaaaaaaaaaaaa",
      "aaaaaaaaaaaaaaaa",
      "aaaaaaaaaaaaaaaa",
      "aaaaaaaaaaaaaaaa",
      "aaaaaaaaaaaaaaaa",
      "aaaaaaaa  aaaaaa",
      "aaaaaaaa  aaaaaa",
      "aaaaaaaa  aaaaaa",
      "aaaaaaaa  aaaaaa",
      "aaaaaaaa))aaaaaa",
      "aaaaaaaaaaaaaaaa",
      "aaaaaaaaaaaaaaaa",
      "aaaaaaaaaaaaaaaa"
    ]
  ]
}