{
  "xsize": 16,
  "zsize": 16,
  "slices": [
    [
      "SQQSSQQSSQQSSQQa",
      "QSSQQSSQQSSQQSSa",
      "QSSQQSSQQSSQQSSa",
      "SQQSSQQSSQQSSQQa",
      "SQQSSQQSSQQSSQQa",
      "QSSQQSSQQSSQQSSa",
      "QSSQQSSQQSSQQSSa",
      "SQQSSQQSSQQSSQQa",
      "SQQSSQQSSQQSSQQa",
      "QSSQQSSQQSSQQSSa",
      "QSSQQSSQQSSQQSSa",
      "SQQSSQQSSQQSSQQa",
      "SQQSSQQSSQQSSQQa",
      "QSSQQSSQQSSQQSSa",
      "QSSQQSSQQSSQQSSa",
      "aaaaaaaaaaaaaaaa"
    ],
    [
      "               a",
      "               a",
      "              aa",
      "              a ",
      "              a ",
      "              a ",
      "              aa",
      "               a",
      "               a",
      "              aa",
      "              a ",
      "              a ",
      "              a ",
      "              aa",
      "  aaaaa  aaaaaaa",
      "aaa   aaaa   aaa"
    ],
    [
      "               a",
      "               a",
      "              aa",
      "              a ",
      "              a ",
      "              a ",
      "              aa",
      "               a",
      "               a",
      "              aa",
      "              a ",
      "              a ",
      "              a ",
      "              aa",
      "  aaaaa  aaaaaaa",
      "aaa   aaaa   aaa"
    ],
    [
      "               a",
      "               a",
      "              aa",
      "              a ",
      "              a ",
      "              a ",
      "             aaa",
      "               a",
      "               a",
      "             aaa",
      "              a ",
      "              a ",
      "              a ",
      "      a  a    aa",
      "  aaaaa  aaaaaaa",
      "aaa   aaaa   aaa"
    ],
    [
      "               a",
      "               a",
      "              aa",
      "              a ",
      "              a ",
      "              a ",
      "              aa",
      "               a",
      "               a",
      "              aa",
      "              a ",
      "              a ",
      "              a ",
      "              aa",
      "  aaaaa  aaaaaaa",
      "aaa   aaaa   aaa"
    ],
    [
      "               a",
      "               a",
      "              aa",
      "              a ",
      "              a ",
      "              a ",
      "              aa",
      "               a",
      "               a",
      "              aa",
      "              a ",
      "              a ",
      "              a ",
      "              aa",
      "  aaaaa  aaaaaaa",
      "aaa   aaaa   aaa"
    ]
  ]
}