{
  "xsize": 16,
  "zsize": 16,
  "slices": [
    [
      "SQQSSQQSSQQSSQQQ",
      "QSSQQSSQQSSQQSSQ",
      "QSSQQSSQQSSQQSSQ",
      "SQQSSQQSSQQSSQQQ",
      "SQQSSQQSSQQSSQQQ",
      "QSSQQSSQQSSQQSSQ",
      "QSSQQSSQQSSQQSSQ",
      "SQQSSQQSSQQSSQQQ",
      "SQQSSQQSSQQSSQQQ",
      "QSSQQSSQQSSQQSSQ",
      "QSSQQSSQQSSQQSSQ",
      "SQQSSQQSSQQSSQQQ",
      "SQQSSQQSSQQSSQQQ",
      "QSSQQSSQQSSQQSSQ",
      "QSSQQSSQQSSQQSSQ",
      "QQQQQQQQQQQQQQQQ"
    ],
    [
      ":              #",
      "               #",
      "               #",
      "               #",
      "               #",
      "               #",
      "               #",
      "               #",
      "       `))`    #",
      "       `  `    #",
      "       `  `    #",
      ":      `  `    #",
      ":      `  `    #",
      ":      `  `    #",
      ":              #",
      "################"
    ],
    [
      "               #",
      "               #",
      "               #",
      "               #",
      "               #",
      "               #",
      "               #",
      "               #",
      "       `  `    #",
      "       `))`    #",
      "       `       #",
      "       `       #",
      "       `       #",
      "       `       #",
      "               #",
      "################"
    ],
    [
      "               a",
      "               #",
      "               a",
      "               a",
      "               #",
      "               a",
      "               a",
      "              a#",
      "       `  `    a",
      "       `  `    a",
      "       `))`    #",
      "       `  `    a",
      "       `  `    a",
      "       `  `    #",
      "       a       #",
      "##aa#aa#aa#aa###"
    ],
    [
      "               #",
      "               #",
      "               #",
      "               #",
      "               #",
      "               #",
      "               #",
      "               #",
      "       `  `    #",
      "       `  `    #",
      "       `  `    #",
      "       `))`    #",
      "       `  `    #",
      "       `  `    #",
      "               #",
      "################"
    ],
    [
      "################",
      "################",
      "################",
      "################",
      "################",
      "################",
      "################",
      "################",
      "########  ######",
      "########  ######",
      "########  ######",
      "########  ######",
      "########))######",
      "################",
      "################",
      "################"
    ]
  ]
}