{
  "xsize": 16,
  "zsize": 16,
  "slices": [
    [
      "QQQQQQQQQQQQQQQQ",
      "QSSQQSSQQSSQQSSQ",
      "QSSQQSSQQSSQQSSQ",
      "QQQSSQQSSQQSSQQQ",
      "QQQSSQQSSQQSSQQQ",
      "QSSQQSSQQSSQQSSQ",
      "QSSQQSSQQSSQQSSQ",
      "QQQSSQQSSQQSSQQQ",
      "QQQSSQQSSQQSSQQQ",
      "QSSQQSSQQSSQQSSQ",
      "QSSQQSSQQSSQQSSQ",
      "QQQSSQQSSQQSSQQQ",
      "QQQSSQQSSQQSSQQQ",
      "QSSQQSSQQSSQQSSQ",
      "QSSQQSSQQSSQQSSQ",
      "QQQSSQQSSQQSSQQQ"
    ],
    [
      "aaaaaaaaaaaaaaaa",
      "a              a",
      "a              a",
      "a              a",
      "a              a",
      "a              a",
      "a              a",
      "a              a",
      "a              a",
      "a              a",
      "a              a",
      "a              a",
      "a              a",
      "a              a",
      "a              a",
      "a              a"
    ],
    [
      "aaaaaaaaaaaaaaaa",
      "a              a",
      "a              a",
      "a              a",
      "a              a",
      "a              a",
      "a              a",
      "a              a",
      "a              a",
      "a              a",
      "a              a",
      "a              a",
      "a              a",
      "a              a",
      "a              a",
      "a              a"
    ],
    [
      "aaaaaaaaaaaaaaaa",
      "a      a       a",
      "a              a",
      "a              a",
      "a              a",
      "a              a",
      "a              a",
      "a              a",
      "a             aa",
      "a              a",
      "a              a",
      "a              a",
      "a              a",
      "a              a",
      "a              a",
      "a              a"
    ],
    [
      "aaaaaaaaaaaaaaaa",
      "a              a",
      "a              a",
      "a              a",
      "a              a",
      "a              a",
      "a              a",
      "a              a",
      "a              a",
      "a              a",
      "a              a",
      "a              a",
      "a              a",
      "a              a",
      "a              a",
      "a              a"
    ],
    [
      "aaaaaaaaaaaaaaaa",
      "aaaaaaaaaaaaaaaa",
      "aaaaaaaaaaaaaaaa",
      "aaaaaaaaaaaaaaaa",
      "aaaaaaaaaaaaaaaa",
      "aaaaaaaaaaaaaaaa",
      "aaaaaaaaaaaaaaaa",
      "aaaaaaaaaaaaaaaa",
      "aaaaaaaaaaaaaaaa",
      "aaaaaaaaaaaaaaaa",
      "aaaaaaaaaaaaaaaa",
      "aaaaaaaaaaaaaaaa",
      "aaaaaaaaaaaaaaaa",
      "aaaaaaaaaaaaaaaa",
      "aaaaaaaaaaaaaaaa",
      "aaaaaaaaaaaaaaaa"
    ]
  ]
}