{
  "meta": [
    {
      "key": "dontconnect",
      "boolean": true
    }
  ],
  "xsize": 16,
  "zsize": 16,
  "slices": [
    [
      "a   aaaa))))aaaa",
      "a   aSSQQSSQQSSQ",
      "a   aQQSSQQSSQQS",
      "a   aQQSSQQSSQQS",
      "a   aSSQQSSQQSSQ",
      "a   aSSQQSSQQSSQ",
      "a   aQQSSQQSSQQS",
      "a   aQQSSQQSSQQS",
      "a   aSSQQSSQQSSQ",
      "a   aSSQQSSQQSSQ",
      "a   aQQSSQQSSQQS",
      "a   aaaaaaaaaaaa",
      "a               ",
      "a               ",
      "a               ",
      "aaaaaaaaaaaaaaaa"
    ],
    [
      "a   :::w    w:::",
      "a   :           ",
      "a   :           ",
      "a   :           ",
      "a   :           ",
      "a   :           ",
      "a   :           ",
      "a   :           ",
      "a   :           ",
      "a   :           ",
      "a   :           ",
      "a   ::::::::::::",
      "a               ",
      "a               ",
      "a               ",
      "aaaaaaaaaaaaaaaa"
    ],
    [
      "a      a    a   ",
      "a               ",
      "a               ",
      "a               ",
      "a               ",
      "a               ",
      "a               ",
      "a               ",
      "a               ",
      "a               ",
      "a               ",
      "a               ",
      "a               ",
      "a               ",
      "a               ",
      "aaaaaaaaaaaaaaaa"
    ],
    [
      "a               ",
      "a               ",
      "a               ",
      "a               ",
      "a               ",
      "a               ",
      "a               ",
      "a               ",
      "a               ",
      "a               ",
      "a               ",
      "a               ",
      "a               ",
      "a               ",
      "a               ",
      "aaaaaaaaaaaaaaaa"
    ],
    [
      "a               ",
      "a               ",
      "a               ",
      "a               ",
      "a               ",
      "a               ",
      "a               ",
      "a               ",
      "a               ",
      "a               ",
      "a               ",
      "a               ",
      "a               ",
      "a               ",
      "a               ",
      "aaaaaaaaaaaaaaaa"
    ],
    [
      "aaaaaaaaaaaaaaaa",
      "aaaaaaaaaaaaaaaa",
      "aaaaaaaaaaaaaaaa",
      "aaaaaaaaaaaaaaaa",
      "aaaaaaaaaaaaaaaa",
      "aaaaaaaaaaaaaaaa",
      "aaaaaaaaaaaaaaaa",
      "aaaaaaaaaaaaaaaa",
      "aaaaaaaaaaaaaaaa",
      "aaaaaaaaaaaaaaaa",
      "aaaaaaaaaaaaaaaa",
      "aaaaaaaaaaaaaaaa",
      "aaaaaaaaaaaaaaaa",
      "aaaaaaaaaaaaaaaa",
      "aaaaaaaaaaaaaaaa",
      "aaaaaaaaaaaaaaaa"
    ]
  ]
}