{
  "meta": [
    {
      "key": "dontconnect",
      "boolean": true
    }
  ],
  "xsize": 16,
  "zsize": 16,
  "slices": [
    [
      "aaa   aaaa   aaa",
      "a aaaaa  aaaaaaa",
      "              aa",
      "              a ",
      "              a ",
      "              a ",
      "              aa",
      "               a",
      "               a",
      "              aa",
      "              a ",
      "              a ",
      "              a ",
      "              aa",
      "               a",
      "               a"
    ],
    [
      "aaa   aaaa   aaa",
      "a aaaaa  aaaaaaa",
      "              aa",
      "              a ",
      "              a ",
      "              a ",
      "              aa",
      "               a",
      "               a",
      "              aa",
      "              a ",
      "              a ",
      "              a ",
      "              aa",
      "               a",
      "               a"
    ],
    [
      "aaa   aaaa   aaa",
      "a aaaaa  aaaaaaa",
      "              aa",
      "              a ",
      "              a ",
      "              a ",
      "              aa",
      "               a",
      "               a",
      "              aa",
      "              a ",
      "              a ",
      "              a ",
      "              aa",
      "               a",
      "               a"
    ],
    [
      "aaa   aaaa   aaa",
      "a aaaaa  aaaaaaa",
      "              aa",
      "              a ",
      "              a ",
      "              a ",
      "              aa",
      "               a",
      "               a",
      "              aa",
      "              a ",
      "              a ",
      "              a ",
      "              aa",
      "               a",
      "               a"
    ],
    [
      "aaa   aaaa   aaa",
      "a aaaaa  aaaaaaa",
      "              aa",
      "              a ",
      "              a ",
      "              a ",
      "              aa",
      "               a",
      "               a",
      "              aa",
      "              a ",
      "              a ",
      "              a ",
      "              aa",
      "               a",
      "               a"
    ],
    [
      "aaaaaaaaaaaaaaaa",
      "aaaaaaaaaaaaaaaa",
      "              aa",
      "              aa",
      "              aa",
      "              aa",
      "              aa",
      "              aa",
      "              aa",
      "              aa",
      "              aa",
      "              aa",
      "              aa",
      "              aa",
      "              aa",
      "              aa"
    ]
  ]
}