{
  "meta": [
    {
      "key": "dontconnect",
      "boolean": true
    }
  ],
  "xsize": 16,
  "zsize": 16,
  "slices": [
    [
      "aaaaaaaaaaaaaaaa",
      "a               ",
      "a               ",
      "a               ",
      "a               ",
      "a               ",
      "a               ",
      "a               ",
      "a               ",
      "a      w    w   ",
      "a      a))))a   ",
      "a               ",
      "a               ",
      "a               ",
      "a               ",
      "a      w    w   "
    ],
    [
      "aaaaaaaaaaaaaaaa",
      "a               ",
      "a               ",
      "a               ",
      "a               ",
      "a               ",
      "a               ",
      "a               ",
      "a               ",
      "a               ",
      "a      w    w   ",
      "a      a))))a   ",
      "a               ",
      "a               ",
      "a               ",
      "a      w    w   "
    ],
    [
      "aaaaaaaaaaaaaaaa",
      "a               ",
      "a               ",
      "a               ",
      "a               ",
      "a               ",
      "a               ",
      "a               ",
      "a               ",
      "a               ",
      "a               ",
      "a      w    w   ",
      "a      a))))a   ",
      "a               ",
      "a               ",
      "a      w    w   "
    ],
    [
      "aaaaaaaaaaaaaaaa",
      "a               ",
      "a               ",
      "a               ",
      "a               ",
      "a               ",
      "a               ",
      "a               ",
      "a               ",
      "a               ",
      "a               ",
      "a               ",
      "a      w    w   ",
      "a      a))))a   ",
      "a               ",
      "a      w    w   "
    ],
    [
      "aaaaaaaaaaaaaaaa",
      "a               ",
      "a               ",
      "a               ",
      "a               ",
      "a               ",
      "a               ",
      "a               ",
      "a               ",
      "a               ",
      "a               ",
      "a               ",
      "a               ",
      "a      w    w   ",
      "a      a))))a   ",
      "a      w    w   "
    ],
    [
      "aaaaaaaaaaaaaaaa",
      "a               ",
      "a               ",
      "a               ",
      "a               ",
      "a               ",
      "a               ",
      "a               ",
      "a               ",
      "a               ",
      "a               ",
      "a               ",
      "a               ",
      "a               ",
      "a      w    w   ",
      "a      a))))a   "
    ]
  ]
}