{
  "meta": [
    {
      "key": "dontconnect",
      "boolean": true
    }
  ],
  "xsize": 16,
  "zsize": 16,
  "slices": [
    [
      "aaa   aaaa   aaa",
      "a aaaaa  aaaaaaa",
      "a             aa",
      "a             a ",
      "a             a ",
      "a             a ",
      "a             aa",
      "a              a",
      "a              a",
      "a             aa",
      "a             a ",
      "a             a ",
      "a             a ",
      "a             aa",
      "a              a",
      "a              a"
    ],
    [
      "aaa   aaaa   aaa",
      "a aaaaa  aaaaaaa",
      "a             aa",
      "a             a ",
      "a             a ",
      "a             a ",
      "a             aa",
      "a              a",
      "a              a",
      "a             aa",
      "a             a ",
      "a             a ",
      "a             a ",
      "a             aa",
      "a              a",
      "a              a"
    ],
    [
      "aaa   aaaa   aaa",
      "a aaaaa  aaaaaaa",
      "a             aa",
      "a             a ",
      "a             a ",
      "a             a ",
      "a             aa",
      "a              a",
      "a              a",
      "a             aa",
      "a             a ",
      "a             a ",
      "a             a ",
      "a             aa",
      "a              a",
      "a              a"
    ],
    [
      "aaa   aaaa   aaa",
      "a aaaaa  aaaaaaa",
      "a             aa",
      "a             a ",
      "a             a ",
      "a             a ",
      "a             aa",
      "a              a",
      "a              a",
      "a             aa",
      "a             a ",
      "a             a ",
      "a             a ",
      "a             aa",
      "a              a",
      "a              a"
    ],
    [
      "aaa   aaaa   aaa",
      "a aaaaa  aaaaaaa",
      "a             aa",
      "a             a ",
      "a             a ",
      "a             a ",
      "a             aa",
      "a              a",
      "a              a",
      "a             aa",
      "a             a ",
      "a             a ",
      "a             a ",
      "a             aa",
      "a              a",
      "a              a"
    ],
    [
      "aaaaaaaaaaaaaaaa",
      "aaaaaaaaaaaaaaaa",
      "a             aa",
      "a             aa",
      "a             aa",
      "a             aa",
      "a             aa",
      "a             aa",
      "a             aa",
      "a             aa",
      "a             aa",
      "a             aa",
      "a             aa",
      "a             aa",
      "a             aa",
      "a             aa"
    ]
  ]
}