{
  "xsize": 16,
  "zsize": 16,
  "slices": [
    [
      "aaaaaaaaaaaaaaaa",
      "aSSQQSSQQSSQQSSQ",
      "aSSQQSSQQSSQQSSQ",
      "aQQSSQQSSQQSSQQS",
      "aQQSSQQSSQQSSQQS",
      "aSSQQSSQQSSQQSSQ",
      "aSSQQSSQQSSQQSSQ",
      "aQQSSQQSSQQSSQQS",
      "aQQSSQQSSQQSSQQS",
      "aSSQQSSQQSSQQSSQ",
      "aSSQQSSQQSSQQSSQ",
      "aQQSSQQSSQQSSQQS",
      "aQQSSQQSSQQSSQQS",
      "aSSQQSSQQSSQQSSQ",
      "aSSQQSSQQSSQQSSQ",
      "aQQSSQQSSQQSSQQS"
    ],
    [
      "aaaaaaaaaaaaaaaa",
      "a               ",
      "a               ",
      "a               ",
      "a               ",
      "a      a))))a   ",
      "a               ",
      "a               ",
      "a               ",
      "a      w    w   ",
      "a               ",
      "a               ",
      "a               ",
      "a               ",
      "a               ",
      "a      w    w   "
    ],
    [
      "aaaaaaaaaaaaaaaa",
      "a               ",
      "a               ",
      "a               ",
      "a               ",
      "a      w    w   ",
      "a     aa))))aa  ",
      "a               ",
      "a               ",
      "a      w    w   ",
      "a               ",
      "a               ",
      "a               ",
      "a               ",
      "a               ",
      "a      w    w   "
    ],
    [
      "aaaaaaaaaaaaaaaa",
      "a               ",
      "a               ",
      "a               ",
      "a               ",
      "a               ",
      "a      w    w   ",
      "a      a))))a   ",
      "a               ",
      "a      w    w   ",
      "a               ",
      "a               ",
      "a               ",
      "a               ",
      "a               ",
      "a      w    w   "
    ],
    [
      "aaaaaaaaaaaaaaaa",
      "a               ",
      "a               ",
      "a               ",
      "a               ",
      "a               ",
      "a               ",
      "a      w    w   ",
      "a      a))))a   ",
      "a      w    w   ",
      "a               ",
      "a               ",
      "a               ",
      "a               ",
      "a               ",
      "a      w    w   "
    ],
    [
      "aaaaaaaaaaaaaaaa",
      "a               ",
      "a               ",
      "a               ",
      "a               ",
      "a               ",
      "a               ",
      "a               ",
      "a      w    w   ",
      "a      a))))a   ",
      "a               ",
      "a               ",
      "a               ",
      "a               ",
      "a               ",
      "a      w    w   "
    ]
  ]
}