{
  "meta": [
    {
      "key": "dontconnect",
      "boolean": true
    }
  ],
  "xsize": 16,
  "zsize": 16,
  "slices": [
    [
      " aaaaaaa))))aaaa",
      " aSQQSSQQSSQQSSQ",
      " aQSSQQSSQQSSQQS",
      " aQSSQQSSQQSSQQS",
      " aSQQSSQQSSQQSSQ",
      " aSQQSSQQSSQQSSQ",
      " aQSSQQSSQQSSQQS",
      " aQSSQQSSQQSSQQS",
      " aSQQSSQQSSQQSSQ",
      " aSQQSSQQSSQQSSQ",
      " aQSSQQSSQQSSQQS",
      " aQSSQQSSQQSSQQS",
      " aSQQSSQQSSQQSSQ",
      " aSQQSSQQSSQQSSQ",
      " aaaaaaaaaaaaaaa",
      "                "
    ],
    [
      " ::::::w    w:::",
      " :              ",
      " :              ",
      " :              ",
      " :              ",
      " :              ",
      " :              ",
      " :              ",
      " :              ",
      " :              ",
      " :              ",
      " :              ",
      " :              ",
      " :              ",
      " w::::::::::::::",
      "                "
    ],
    [
      "       a    a   ",
      "                ",
      "                ",
      "                ",
      "                ",
      "                ",
      "                ",
      "                ",
      "                ",
      "                ",
      "                ",
      "                ",
      "                ",
      "                ",
      " w              ",
      "                "
    ],
    [
      "                ",
      "                ",
      "                ",
      "                ",
      "                ",
      "                ",
      "                ",
      "                ",
      "                ",
      "                ",
      "                ",
      "                ",
      "                ",
      "                ",
      " w              ",
      "                "
    ],
    [
      "                ",
      "                ",
      "                ",
      "                ",
      "                ",
      "                ",
      "                ",
      "                ",
      "                ",
      "                ",
      "                ",
      "                ",
      "                ",
      "                ",
      " a              ",
      "                "
    ],
    [
      "aaaaaaaaaaaaaaaa",
      "aaaaaaaaaaaaaaaa",
      "aaaaaaaaaaaaaaaa",
      "aaaaaaaaaaaaaaaa",
      "aaaaaaaaaaaaaaaa",
      "aaaaaaaaaaaaaaaa",
      "aaaaaaaaaaaaaaaa",
      "aaaaaaaaaaaaaaaa",
      "aaaaaaaaaaaaaaaa",
      "aaaaaaaaaaaaaaaa",
      "aaaaaaaaaaaaaaaa",
      "aaaaaaaaaaaaaaaa",
      "aaaaaaaaaaaaaaaa",
      "aaaaaaaaaaaaaaaa",
      "aaaaaaaaaaaaaaaa",
      "aaaaaaaaaaaaaaaa"
    ]
  ]
}