{
  "xsize": 16,
  "zsize": 16,
  "slices": [
    [
      "aaaaaaaaaaaaaaaa",
      "QSSQQSSQQSSQQSSa",
      "QSSQQSSQQSSQQSSa",
      "SQQSSQQSSQQSSQQa",
      "SQQSSQQSSQQSSQQa",
      "QSSQQSSQQSSQQSSa",
      "QSSQQSSQQSSQQSSa",
      "SQQSSQQSSQQSSQQa",
      "SQQSSQQSSQQSSQQa",
      "QSSQQSSQQSSQQSSa",
      "QSSQQSSQQSSQQSSa",
      "SQQSSQQSSQQSSQQa",
      "SQQSSQQSSQQSSQQa",
      "QSSQQSSQQSSQQSSa",
      "QSSQQSSQQSSQQSSa",
      "SQQSSQQSSQQSSQQa"
    ],
    [
      "aaa   aaaa   aaa",
      "a aaaaa  aaaaaaa",
      "              aa",
      "              a ",
      "              a ",
      "              a ",
      "              aa",
      "               a",
      "               a",
      "              aa",
      "              a ",
      "              a ",
      "              a ",
      "              aa",
      "               a",
      "               a"
    ],
    [
      "aaa   aaaa   aaa",
      "a aaaaa  aaaaaaa",
      "              aa",
      "              a ",
      "              a ",
      "              a ",
      "              aa",
      "               a",
      "               a",
      "              aa",
      "              a ",
      "              a ",
      "              a ",
      "              aa",
      "               a",
      "               a"
    ],
    [
      "aaa   aaaa   aaa",
      "a aaaaa  aaaaaaa",
      "      a  a    aa",
      "              a ",
      "              a ",
      "              a ",
      "             aaa",
      "               a",
      "               a",
      "             aaa",
      "              a ",
      "              a ",
      "              a ",
      "              aa",
      "               a",
      "               a"
    ],
    [
      "aaa   aaaa   aaa",
      "a aaaaa  aaaaaaa",
      "              aa",
      "              a ",
      "              a ",
      "              a ",
      "              aa",
      "               a",
      "               a",
      "              aa",
      "              a ",
      "              a ",
      "              a ",
      "              aa",
      "               a",
      "               a"
    ],
    [
      "aaa   aaaa   aaa",
      "a aaaaa  aaaaaaa",
      "              aa",
      "              a ",
      "              a ",
      "              a ",
      "              aa",
      "               a",
      "               a",
      "              aa",
      "              a ",
      "              a ",
      "              a ",
      "              aa",
      "               a",
      "               a"
    ]
  ]
}