{
  "xsize": 16,
  "zsize": 16,
  "slices": [
    [
      "SQQSSQQSSQQSSQQQ",
      "QSSQQSSQQSSQQSSQ",
      "QSSQQSSQQSSQQSSQ",
      "SQQSSQQSSQQSSQQQ",
      "SQQSSQQSSQQSSQQQ",
      "QSSQQSSQQSSQQSSQ",
      "QSSQQSSQQSSQQSSQ",
      "SQQSSQQSSQQSSQQQ",
      "SQQSSQQSSQQSSQQQ",
      "QSSQQSSQQSSQQSSQ",
      "QSSQQSSQQSSQQSSQ",
      "SQQSSQQSSQQSSQQQ",
      "SQQSSQQSSQQSSQQQ",
      "QSSQQSSQQSSQQSSQ",
      "QSSQQSSQQSSQQSSQ",
      "QQQQQQQQQQQQQQQQ"
    ],
    [
      "a              a",
      "               a",
      "               a",
      "               a",
      "               a",
      "               a",
      "               a",
      "               a",
      "       `))`    a",
      "       `  `    a",
      "       `  `    a",
      "a      `  `    a",
      "a      `  `    a",
      "a      `  `    a",
      "a              a",
      "aaaaaaaaaaaaaaaa"
    ],
    [
      "a              a",
      "               a",
      "               a",
      "               a",
      "               a",
      "               a",
      "               a",
      "               a",
      "       `  `    a",
      "       `))`    a",
      "       `       a",
      "a      `       a",
      "a      `       a",
      "a      `       a",
      "a              a",
      "aaaaaaaaaaaaaaaa"
    ],
    [
      "a              a",
      "               a",
      "               a",
      "               a",
      "               a",
      "               a",
      "               a",
      "              aa",
      "       `  `    a",
      "       `  `    a",
      "       `))`    a",
      "a      `  `    a",
      "a      `  `    a",
      "a      `  `    a",
      "a              a",
      "aaaaaaaaaaaaaaaa"
    ],
    [
      "a              a",
      "               a",
      "               a",
      "               a",
      "               a",
      "               a",
      "               a",
      "               a",
      "       `  `    a",
      "       `  `    a",
      "       `  `    a",
      "a      `))`    a",
      "a      `  `    a",
      "a      `  `    a",
      "a              a",
      "aaaaaaaaaaaaaaaa"
    ],
    [
      "aaaaaaaaaaaaaaaa",
      "aaaaaaaaaaaaaaaa",
      "aaaaaaaaaaaaaaaa",
      "aaaaaaaaaaaaaaaa",
      "aaaaaaaaaaaaaaaa",
      "aaaaaaaaaaaaaaaa",
      "aaaaaaaaaaaaaaaa",
      "aaaaaaaaaaaaaaaa",
      "aaaaaaaa  aaaaaa",
      "aaaaaaaa  aaaaaa",
      "aaaaaaaa  aaaaaa",
      "aaaaaaaa  aaaaaa",
      "aaaaaaaa))aaaaaa",
      "aaaaaaaaaaaaaaaa",
      "aaaaaaaaaaaaaaaa",
      "aaaaaaaaaaaaaaaa"
    ]
  ]
}