{
  "xsize": 16,
  "zsize": 16,
  "slices": [
    [
      "aaaaaaaaaaaaaaaa",
      "QSSQQSSQQSSQQSSa",
      "QSSQQSSQQSSQQSSa",
      "SQQSSQQSSQQSSQQa",
      "SQQSSQQSSQQSSQQa",
      "QSSQQSSQQSSQQSSa",
      "QSSQQSSQQSSQQSSa",
      "SQQSSQQSSQQSSQQa",
      "SQQSSQQSSQQSSQQa",
      "QSSQQSSQQSSQQSSa",
      "QSSQQSSQQSSQQSSa",
      "SQQSSQQSSQQSSQQa",
      "SQQSSQQSSQQSSQQa",
      "QSSQQSSQQSSQQSSa",
      "QSSQQSSQQSSQQSSa",
      "SQQSSQQSSQQSSQQa"
    ],
    [
      "aaaaaaaaaaaaaaaa",
      "               a",
      "               a",
      "               a",
      "               a",
      "               a",
      "               a",
      "               a",
      "               a",
      "               a",
      "               a",
      "               a",
      "               a",
      "               a",
      "               a",
      "               a"
    ],
    [
      "aaaaaaaaaaaaaaaa",
      "               a",
      "               a",
      "               a",
      "               a",
      "               a",
      "               a",
      "               a",
      "               a",
      "               a",
      "               a",
      "               a",
      "               a",
      "               a",
      "               a",
      "               a"
    ],
    [
      "aaaaaaaaaaaaaaaa",
      "       a       a",
      "               a",
      "               a",
      "               a",
      "               a",
      "               a",
      "               a",
      "              aa",
      "               a",
      "               a",
      "               a",
      "               a",
      "               a",
      "               a",
      "               a"
    ],
    [
      "aaaaaaaaaaaaaaaa",
      "               a",
      "               a",
      "               a",
      "               a",
      "               a",
      "               a",
      "               a",
      "               a",
      "               a",
      "               a",
      "               a",
      "               a",
      "               a",
      "               a",
      "               a"
    ],
    [
      "aaaaaaaaaaaaaaaa",
      "aaaaaaaaaaaaaaaa",
      "aaaaaaaaaaaaaaaa",
      "aaaaaaaaaaaaaaaa",
      "aaaaaaaaaaaaaaaa",
      "aaaaaaaaaaaaaaaa",
      "aaaaaaaaaaaaaaaa",
      "aaaaaaaaaaaaaaaa",
      "aaaaaaaaaaaaaaaa",
      "aaaaaaaaaaaaaaaa",
      "aaaaaaaaaaaaaaaa",
      "aaaaaaaaaaaaaaaa",
      "aaaaaaaaaaaaaaaa",
      "aaaaaaaaaaaaaaaa",
      "aaaaaaaaaaaaaaaa",
      "aaaaaaaaaaaaaaaa"
    ]
  ]
}