{
  "xsize": 16,
  "zsize": 16,
  "slices": [
    [
      "aaaaaaaaaaaaaaaa",
      "aSSQQSSQQSSQQSSQ",
      "aSSQQSSQQSSQQSSQ",
      "aQQSSQQSSQQSSQQS",
      "aQQSSQQSSQQSSQQS",
      "aSSQQSSQQSSQQSSQ",
      "aSSQQSSQQSSQQSSQ",
      "aQQSSQQSSQQSSQQS",
      "aQQSSQQSSQQSSQQS",
      "aSSQQSSQQSSQQSSQ",
      "aSSQQSSQQSSQQSSQ",
      "aQQSSQQSSQQSSQQS",
      "aQQSSQQSSQQSSQQS",
      "aSSQQSSQQSSQQSSQ",
      "aSSQQSSQQSSQQSSQ",
      "aQQSSQQSSQQSSQQS"
    ],
    [
      "aaaaaaaaaaaaaaaa",
      "a               ",
      "a               ",
      "a               ",
      "a               ",
      "a               ",
      "a               ",
      "a               ",
      "a               ",
      "a               ",
      "a               ",
      "a               ",
      "a               ",
      "a               ",
      "a               ",
      "a               "
    ],
    [
      "aaaaaaaaaaaaaaaa",
      "a               ",
      "a               ",
      "a               ",
      "a               ",
      "a               ",
      "a               ",
      "a               ",
      "a               ",
      "a               ",
      "a               ",
      "a               ",
      "a               ",
      "a               ",
      "a               ",
      "a               "
    ],
    [
      "aaaaaaaaaaaaaaaa",
      "a               ",
      "a               ",
      "a               ",
      "a               ",
      "a               ",
      "a               ",
      "a               ",
      "a               ",
      "a               ",
      "a               ",
      "a               ",
      "a               ",
      "a               ",
      "a               ",
      "a               "
    ],
    [
      "aaaaaaaaaaaaaaaa",
      "a               ",
      "a               ",
      "a               ",
      "a               ",
      "a               ",
      "a               ",
      "a               ",
      "a               ",
      "a               ",
      "a               ",
      "a               ",
      "a               ",
      "a               ",
      "a               ",
      "a               "
    ],
    [
      "aaaaaaaaaaaaaaaa",
      "aaaaaaaaaaaaaaaa",
      "aaaaaaaaaaaaaaaa",
      "aaaaaaaaaaaaaaaa",
      "aaaaaaaaaaaaaaaa",
      "aaaaaaaaaaaaaaaa",
      "aaaaaaaaaaaaaaaa",
      "aaaaaaaaaaaaaaaa",
      "aaaaaaaaaaaaaaaa",
      "aaaaaaaaaaaaaaaa",
      "aaaaaaaaaaaaaaaa",
      "aaaaaaaaaaaaaaaa",
      "aaaaaaaaaaaaaaaa",
      "aaaaaaaaaaaaaaaa",
      "aaaaaaaaaaaaaaaa",
      "aaaaaaaaaaaaaaaa"
    ]
  ]
}