{
  "xsize": 16,
  "zsize": 16,
  "slices": [
    [
      "aQQSSQQSSQQSSQQS",
      "aSSQQSSQQSSQQSSQ",
      "aSSQQSSQQSSQQSSQ",
      "aQQSSQQSSQQSSQQS",
      "aQQSSQQSSQQSSQQS",
      "aSSQQSSQQSSQQSSQ",
      "aSSQQSSQQSSQQSSQ",
      "aQQSSQQSSQQSSQQS",
      "aQQSSQQSSQQSSQQS",
      "aSSQQSSQQSSQQSSQ",
      "aSSQQSSQQSSQQSSQ",
      "aQQSSQQSSQQSSQQS",
      "aQQSSQQSSQQSSQQS",
      "aSSQQSSQQSSQQSSQ",
      "aSSQQSSQQSSQQSSQ",
      "aaaaaaaaaaaaaaaa"
    ],
    [
      "a               ",
      "a               ",
      "a               ",
      "a               ",
      "a               ",
      "a               ",
      "a               ",
      "a               ",
      "a               ",
      "a               ",
      "a               ",
      "a               ",
      "a               ",
      "a               ",
      "a               ",
      "aaaaaaaaaaaaaaaa"
    ],
    [
      "a               ",
      "a               ",
      "a               ",
      "a               ",
      "a               ",
      "a               ",
      "a               ",
      "a               ",
      "a               ",
      "a               ",
      "a               ",
      "a               ",
      "a               ",
      "a               ",
      "a               ",
      "aaaaaaaaaaaaaaaa"
    ],
    [
      "a               ",
      "a               ",
      "a               ",
      "a               ",
      "a               ",
      "a               ",
      "a               ",
      "a               ",
      "a               ",
      "a               ",
      "a               ",
      "a               ",
      "a               ",
      "a               ",
      "a               ",
      "aaaaaaaaaaaaaaaa"
    ],
    [
      "a               ",
      "a               ",
      "a               ",
      "a               ",
      "a               ",
      "a               ",
      "a               ",
      "a               ",
      "a               ",
      "a               ",
      "a               ",
      "a               ",
      "a               ",
      "a               ",
      "a               ",
      "aaaaaaaaaaaaaaaa"
    ],
    [
      "a               ",
      "a               ",
      "a               ",
      "a               ",
      "a               ",
      "a               ",
      "a               ",
      "a               ",
      "a               ",
      "a               ",
      "a               ",
      "a               ",
      "a               ",
      "a               ",
      "a               ",
      "aaaaaaaaaaaaaaaa"
    ]
  ]
}