{
  "xsize": 16,
  "zsize": 16,
  "slices": [
    [
      "QQQQQQQQQQQQQQQQ",
      "QSSQQSSQQSSQQSSQ",
      "QSSQQSSQQSSQQSSQ",
      "SQQSSQQSSQQSSQQQ",
      "SQQSSQQSSQQSSQQQ",
      "QSSQQSSQQSSQQSSQ",
      "QSSQQSSQQSSQQSSQ",
      "SQQSSQQSSQQSSQQQ",
      "SQQSSQQSSQQSSQQQ",
      "QSSQQSSQQSSQQSSQ",
      "QSSQQSSQQSSQQSSQ",
      "SQQSSQQSSQQSSQQQ",
      "SQQSSQQSSQQSSQQQ",
      "QSSQQSSQQSSQQSSQ",
      "QSSQQSSQQSSQQSSQ",
      "SQQSSQQSSQQSSQQQ"
    ],
    [
      "aaaaaaaaaaaaaaaa",
      ":              a",
      ":              a",
      ":              a",
      ":              a",
      ":              a",
      ":              a",
      ":              a",
      ":              a",
      ":              a",
      ":              a",
      ":              a",
      ":              a",
      ":              a",
      ":              a",
      ":              a"
    ],
    [
      "aaaaaaaaaaaaaaaa",
      "               a",
      "               a",
      "               a",
      "               a",
      "               a",
      "               a",
      "               a",
      "               a",
      "               a",
      "               a",
      "               a",
      "               a",
      "               a",
      "               a",
      "               a"
    ],
    [
      "aaaaaaaaaaaaaaaa",
      "       a       a",
      "               a",
      "               a",
      "               a",
      "               a",
      "               a",
      "               a",
      "              aa",
      "               a",
      "               a",
      "               a",
      "               a",
      "               a",
      "               a",
      "               a"
    ],
    [
      "aaaaaaaaaaaaaaaa",
      "               a",
      "               a",
      "               a",
      "               a",
      "               a",
      "               a",
      "               a",
      "               a",
      "               a",
      "               a",
      "               a",
      "               a",
      "               a",
      "               a",
      "               a"
    ],
    [
      "aaaaaaaaaaaaaaaa",
      "aaaaaaaaaaaaaaaa",
      "aaaaaaaaaaaaaaaa",
      "aaaaaaaaaaaaaaaa",
      "aaaaaaaaaaaaaaaa",
      "aaaaaaaaaaaaaaaa",
      "aaaaaaaaaaaaaaaa",
      "aaaaaaaaaaaaaaaa",
      "aaaaaaaaaaaaaaaa",
      "aaaaaaaaaaaaaaaa",
      "aaaaaaaaaaaaaaaa",
      "aaaaaaaaaaaaaaaa",
      "aaaaaaaaaaaaaaaa",
      "aaaaaaaaaaaaaaaa",
      "aaaaaaaaaaaaaaaa",
      "aaaaaaaaaaaaaaaa"
    ]
  ]
}