{
  "meta": [
    {
      "key": "dontconnect",
      "boolean": true
    }
  ],
  "xsize": 16,
  "zsize": 16,
  "slices": [
    [
      "               a",
      "               a",
      "              aa",
      "              a ",
      "              a ",
      "              a ",
      "              aa",
      "               a",
      "               a",
      "              aa",
      "              a ",
      "              a ",
      "              a ",
      "              aa",
      "  aaaaa  aaaaaaa",
      "aaa   aaaa   aaa"
    ],
    [
      "               a",
      "               a",
      "              aa",
      "              a ",
      "              a ",
      "              a ",
      "              aa",
      "               a",
      "               a",
      "              aa",
      "              a ",
      "              a ",
      "              a ",
      "              aa",
      "  aaaaa  aaaaaaa",
      "aaa   aaaa   aaa"
    ],
    [
      "               a",
      "               a",
      "              aa",
      "              a ",
      "              a ",
      "              a ",
      "              aa",
      "               a",
      "               a",
      "              aa",
      "              a ",
      "              a ",
      "              a ",
      "              aa",
      "  aaaaa  aaaaaaa",
      "aaa   aaaa   aaa"
    ],
    [
      "               a",
      "               a",
      "              aa",
      "              a ",
      "              a ",
      "              a ",
      "              aa",
      "               a",
      "               a",
      "              aa",
      "              a ",
      "              a ",
      "              a ",
      "              aa",
      "  aaaaa  aaaaaaa",
      "aaa   aaaa   aaa"
    ],
    [
      "               a",
      "               a",
      "              aa",
      "              a ",
      "              a ",
      "              a ",
      "              aa",
      "               a",
      "               a",
      "              aa",
      "              a ",
      "              a ",
      "              a ",
      "              aa",
      "  aaaaa  aaaaaaa",
      "aaa   aaaa   aaa"
    ],
    [
      "              aa",
      "              aa",
      "              aa",
      "              aa",
      "              aa",
      "              aa",
      "              aa",
      "              aa",
      "              aa",
      "              aa",
      "              aa",
      "              aa",
      "              aa",
      "              aa",
      "aaaaaaaaaaaaaaaa",
      "aaaaaaaaaaaaaaaa"
    ]
  ]
}