{
  "meta": [
    {
      "key": "dontconnect",
      "boolean": true
    }
  ],
  "xsize": 16,
  "zsize": 16,
  "slices": [
    [
      "aaaaaaaaaaaaaaaa",
      "aSSQQSSQQSSQQSSQ",
      "aSSQQSSQQSSQQSSQ",
      "aQQSSQQSSQQSSQQS",
      "aQQSSQQSSQQSSQQS",
      "aSSQQSSQQSSQQSSQ",
      "aSSQQSSQQSSQQSSQ",
      "aQQSSQQSSQQSSQQS",
      "aQQSSQQSSQQSSQQS",
      "aSSQQSSQQSSQQSSQ",
      "aSSQQSSQQSSQQSSQ",
      "aQQSSQQSSQQSSQQS",
      "aQQSSQQSSQQSSQQS",
      "aSSQQSSQQSSQQSSQ",
      "aSSQQSSQQSSQQSSQ",
      "aQQSSQQSSQQSSQQS"
    ],
    [
      "                ",
      " a              ",
      "                ",
      "                ",
      "                ",
      "       a))))a   ",
      "                ",
      "                ",
      "                ",
      "       w    w   ",
      "                ",
      "                ",
      "                ",
      "                ",
      "                ",
      "       w    w   "
    ],
    [
      "                ",
      " w              ",
      "                ",
      "                ",
      "                ",
      "       w    w   ",
      "      aa))))aa  ",
      "                ",
      "                ",
      "       w    w   ",
      "                ",
      "                ",
      "                ",
      "                ",
      "                ",
      "       w    w   "
    ],
    [
      "                ",
      " w              ",
      "                ",
      "                ",
      "                ",
      "                ",
      "       w    w   ",
      "       a))))a   ",
      "                ",
      "       w    w   ",
      "                ",
      "                ",
      "                ",
      "                ",
      "                ",
      "       w    w   "
    ],
    [
      "                ",
      " w              ",
      "                ",
      "                ",
      "                ",
      "                ",
      "                ",
      "       w    w   ",
      "       a))))a   ",
      "       w    w   ",
      "                ",
      "                ",
      "                ",
      "                ",
      "                ",
      "       w    w   "
    ],
    [
      "                ",
      " w              ",
      "                ",
      "                ",
      "                ",
      "                ",
      "                ",
      "                ",
      "       w    w   ",
      "       a))))a   ",
      "                ",
      "                ",
      "                ",
      "                ",
      "                ",
      "       w    w   "
    ]
  ]
}