{
  "xsize": 16,
  "zsize": 16,
  "slices": [
    [
      "aaaaaaaaaaaaaaaa",
      "aSSQQSSQQSSQQSSa",
      "aSSQQSSQQSSQQSSa",
      "aQQSSQQSSQQSSQQa",
      "aQQSSQQSSQQSSQQa",
      "aSSQQSSQQSSQQSSa",
      "aSSQQSSQQSSQQSSa",
      "aQQSSQQSSQQSSQQa",
      "aQQSSQQSSQQSSQQa",
      "aSSQQSSQQSSQQSSa",
      "aSSQQSSQQSSQQSSa",
      "aQQSSQQSSQQSSQQa",
      "aQQSSQQSSQQSSQQa",
      "aSSQQSSQQSSQQSSa",
      "aSSQQSSQQSSQQSSa",
      "aQQSSQQSSQQSSQQa"
    ],
    [
      "aaa   aaaa   aaa",
      "a aaaaa  aaaaaaa",
      "a             aa",
      "a             a ",
      "a             a ",
      "a             a ",
      "S             aa",
      "               a",
      "               a",
      "S             aa",
      "a             a ",
      "a             a ",
      "a             a ",
      "a             aa",
      "a              a",
      "a              a"
    ],
    [
      "aaa   aaaa   aaa",
      "a aaaaa  aaaaaaa",
      "a     a  a    aa",
      "a             a ",
      "a             a ",
      "a             a ",
      "S            aaa",
      "               a",
      "               a",
      "S            aaa",
      "a             a ",
      "a             a ",
      "a             a ",
      "a             aa",
      "a              a",
      "a              a"
    ],
    [
      "aaa   aaaa   aaa",
      "a aaaaa  aaaaaaa",
      "a             aa",
      "a             a ",
      "a             a ",
      "a             a ",
      "S             aa",
      "S              a",
      "S              a",
      "S             aa",
      "a             a ",
      "a             a ",
      "a             a ",
      "a             aa",
      "a              a",
      "a              a"
    ],
    [
      "aaa   aaaa   aaa",
      "a aaaaa  aaaaaaa",
      "a             aa",
      "a             a ",
      "a             a ",
      "a             a ",
      "a             aa",
      "a              a",
      "a              a",
      "a             aa",
      "a             a ",
      "a             a ",
      "a             a ",
      "a             aa",
      "a              a",
      "a              a"
    ],
    [
      "aaa   aaaa   aaa",
      "a aaaaa  aaaaaaa",
      "a             aa",
      "a             a ",
      "a             a ",
      "a             a ",
      "a             aa",
      "a              a",
      "a              a",
      "a             aa",
      "a             a ",
      "a             a ",
      "a             a ",
      "a             aa",
      "a              a",
      "a              a"
    ]
  ]
}