{
  "meta": [
    {
      "integer": 4,
      "key": "z1"
    },
    {
      "integer": 11,
      "key": "z2"
    }
  ],
  "xsize": 6,
  "zsize": 12,
  "slices": [
    [
      "      ",
      "      ",
      "      ",
      "      ",
      "xxxxxx",
      "xxxxxQ",
      "xxxxxQ",
      "xxxxxQ",
      "xxxxxQ",
      "xxxxxQ",
      "xxxxxQ",
      "xxxxxx"
    ],
    [
      "      ",
      "      ",
      "      ",
      "      ",
      "xxxxxa",
      "xxxxQ ",
      "xxxxQ ",
      "xxxxQ ",
      "xxxxQ ",
      "xxxxQ ",
      "xxxxQ ",
      "xxxxxa"
    ],
    [
      "      ",
      "      ",
      "      ",
      "      ",
      "xxxxa ",
      "xxxQ  ",
      "xxxQ  ",
      "xxxQ  ",
      "xxxQ  ",
      "xxxQ  ",
      "xxxQ  ",
      "xxxxa "
    ],
    [
      "      ",
      "      ",
      "      ",
      "      ",
      "xxxa  ",
      "xxQ   ",
      "xxQ   ",
      "xxQ   ",
      "xxQ   ",
      "xxQ   ",
      "xxQ   ",
      "xxxa  "
    ],
    [
      "      ",
      "      ",
      "      ",
      "      ",
      "xxa   ",
      "xQ    ",
      "xQ    ",
      "xQ    ",
      "xQ    ",
      "xQ    ",
      "xQ    ",
      "xxa   "
    ],
    [
      "      ",
      "      ",
      "      ",
      "      ",
      "xa    ",
      "Q     ",
      "Q     ",
      "Q     ",
      "Q     ",
      "Q     ",
      "Q     ",
      "xa    "
    ],
    [
      "      ",
      "      ",
      "      ",
      "      ",
      "a     ",
      "      ",
      "      ",
      "      ",
      "      ",
      "      ",
      "      ",
      "a     "
    ]
  ]
}