{
  "xsize": 16,
  "zsize": 16,
  "refpalette": "rails",
  "slices": [
    [
      "yyyyyyyyyyyyyyyy",
      "yyyyyyyyyyyyyyyy",
      "yyyyyyyyyyyyyyyy",
      "yyyyyyyyyyyyyyyy",
      "yyyyyyyyyyyyyyyy",
      "yyyyyyyyyyyyyyyy",
      "yyyyyyyyyyyyyyyy",
      "yyyyyyyyyyyyyyyy",
      "yyyyyyyyyyyyyyyy",
      "yyyyyyyyyyyyyyyy",
      "yyyyyyyyyyyyyyyy",
      "yyyyyyyyyyyyyyyy",
      "yyyyyyyyyyyyyyyy",
      "yyyyyyyyyyyyyyyy",
      "yyyyyyyyyyyyyyyy",
      "yyyyyyyyyyyyyyyy"
    ],
    [
      "yyyyyyyyyyyyyyyy",
      "QQQQQQQQQQQQQQQQ",
      "QQQQQQQQQQQQQQQQ",
      "QQQQQQQQQQQQQQQQ",
      "yyyyyyyyyyyyyyyy",
      "eeeeeeefeeeeeeee",
      "yyyyyyygyyyyyyyy",
      "eeeeeeefeeeeeeee",
      "yyyyyyygyyyyyyyy",
      "eeeeeeefeeeeeeee",
      "yyyyyyyyyyyyyyyy",
      "QQQQQQQQQQQQQQQQ",
      "QQQQQQQQQQQQQQQQ",
      "QQQQQQQQQQQQQQQQ",
      "QQQQQQQQQQQQQQQQ",
      "yyyyyyyyyyyyyyyy"
    ],
    [
      "yyyyyyyyyyyyyyyy",
      "~~~~~~~~~~~~~~~~",
      "~~~~~~~~~~~~~~~~",
      "~~~~~~~~~~~~~~~~",
      "~~~~~~~~~~~~~~~~",
      "~~~~~~~~~~~~~~~~",
      "~~~~~~~~~~~~~~~~",
      "~~~~~~~~~~~~~~~~",
      "~~~~~~~~~~~~~~~~",
      "~~~~~~~~~~~~~~~~",
      "~~~~~~~~~~~~~~~~",
      "~~~~~~~~~~~~~~~~",
      "~~~~~yyyyy~~~~~~",
      "~~~~~Qyyyy~~~~~~",
      "~~~~~Qyyyy~~~~~~",
      "yyyyyyyyyyyyyyyy"
    ],
    [
      "yyyyyyyyyyyyyyyy",
      "~~~~~~~~~~~~~~~~",
      "~~~~~~~~~~~~~~~~",
      "~~~~~~~~~~~~~~~~",
      "~~~~~~~~~~~~~~~~",
      "~~~~~~~~~~~~~~~~",
      "~~~~~~~~~~~~~~~~",
      "~~~~~~~~~~~~~~~~",
      "~~~~~~~~~~~~~~~~",
      "~~~~~~~~~~~~~~~~",
      "~~~~~~~~~~~~~~~~",
      "~~~~~~~~~~~~~~~~",
      "~~~~~yyyyy~~~~~~",
      "~~~~~~Qyyy~~~~~~",
      "~~~~~~Qyyy~~~~~~",
      "yyyyyyyyyyyyyyyy"
    ],
    [
      "yyhyyyyyyyyyyhyy",
      "~~~~~~~~~~~~~~~~",
      "~~~~~~~~~~~~~~~~",
      "~~~~~~~~~~~~~~~~",
      "~~~~~~~~~~~~~~~~",
      "~~~~~~~~~~~~~~~~",
      "~~~~~~~~~~~~~~~~",
      "~~~~~~~~~~~~~~~~",
      "~~~~~~~~~~~~~~~~",
      "~~~~~~~~~~~~~~~~",
      "~~~~~~~~~~~~~~~~",
      "~~~~~~~~~~~~~~~~",
      "~~~~~yyyyy~~~~~~",
      "~~~~~~~Qyy~~~~~~",
      "~~~~~~~Qyy~~~~~~",
      "yyhyyyyyyyyyyhyy"
    ],
    [
      "yyyyyyyyyyyyyyyy",
      "yyyyyyyyyyyyyyyy",
      "yyyyyyyyyyyyyyyy",
      "yyyyyyyyyyyyyyyy",
      "yyyyyyyyyyyyyyyy",
      "yyyyyyyyyyyyyyyy",
      "yyyyyyyyyyyyyyyy",
      "yyyyyyyyyyyyyyyy",
      "yyyyyyyyyyyyyyyy",
      "yyyyyyyyyyyyyyyy",
      "yyyyyyyyyyyyyyyy",
      "yyyyyyyyyyyyyyyy",
      "yyyyyyyyyyyyyyyy",
      "yyyy~~~~Qyyyyyyy",
      "yyyy~~~~Qyyyyyyy",
      "yyyyyyyyyyyyyyyy"
    ]
  ]
}