{
  "xsize": 16,
  "zsize": 16,
  "refpalette": "rails",
  "slices": [
    [
      "                ",
      "                ",
      "                ",
      "                ",
      "                ",
      "                ",
      "                ",
      "                ",
      "                ",
      "                ",
      "yyyyyyyyyyy     ",
      "yQQQQQQQQQy     ",
      "yQQQQQQQQQy     ",
      "yQQQ~~~~~Qy     ",
      "yQQQ~~~~~Qy     ",
      "yyyyyyyyyyy     "
    ],
    [
      "                ",
      "                ",
      "                ",
      "                ",
      "                ",
      "                ",
      "                ",
      "                ",
      "                ",
      "                ",
      "y~~~~~~~~~y     ",
      ":~~~~~~~~~~     ",
      ":~~~~~~~~~~     ",
      ":~~~~~~~~~~     ",
      ":~~~~~~~~~~     ",
      "y:::::::::y     "
    ],
    [
      "                ",
      "                ",
      "                ",
      "                ",
      "                ",
      "                ",
      "                ",
      "                ",
      "                ",
      "                ",
      "y~~~~~~~~~y     ",
      ":~~~~~~~~~~     ",
      ":~~~~~~~~~~     ",
      ":~~~~~~~~~~     ",
      ":~~~~~~~~~~     ",
      "y:::::::::y     "
    ],
    [
      "                ",
      "                ",
      "                ",
      "                ",
      "                ",
      "                ",
      "                ",
      "                ",
      "                ",
      "                ",
      "y~~~~~~~~~y     ",
      ":~~~~~~~~~~     ",
      ":~~~~~~~~~~     ",
      ":~~~~~~~~~~     ",
      ":~~~~~~~~~~     ",
      "y:::::::::y     "
    ],
    [
      "                ",
      "                ",
      "                ",
      "                ",
      "                ",
      "                ",
      "                ",
      "                ",
      "                ",
      "                ",
      "aaaaaaaaaaa     ",
      "aaaaaaaaaaa     ",
      "aaaaaaaaaaa     ",
      "aaaaaaaaaaa     ",
      "aaaaaaaaaaa     ",
      "aaaaaaaaaaa     "
    ]
  ]
}