{
  "xsize": 16,
  "zsize": 16,
  "refpalette": "rails",
  "slices": [
    [
      "                ",
      "                ",
      "                ",
      "                ",
      "                ",
      "                ",
      "                ",
      "                ",
      "                ",
      "                ",
      "yyyyyyyyyyy     ",
      "y~~~~~~~~~y     ",
      "y~~~~~~~~~y     ",
      "y~~Q~~~~~~y     ",
      "y~~Q~~~~~~y     ",
      "yyyyyyyyyyy     "
    ],
    [
      "                ",
      "                ",
      "                ",
      "                ",
      "                ",
      "                ",
      "                ",
      "                ",
      "                ",
      "                ",
      "yyyyyyyyyyy     ",
      "y~~~~~~~~~y     ",
      "y~~~~~~~~~y     ",
      "y~~~Q~~~~~y     ",
      "y~~~Q~~~~~y     ",
      "yyyyyyyyyyy     "
    ],
    [
      "                ",
      "                ",
      "                ",
      "                ",
      "                ",
      "                ",
      "                ",
      "                ",
      "                ",
      "                ",
      "yyyyyyyyyyy     ",
      "y~~~~~~~~~y     ",
      "y~~~~~~~~~y     ",
      "y~~~~Q~~~~y     ",
      "y~~~~Q~~~~y     ",
      "yyyyyyyyyyy     "
    ],
    [
      "                ",
      "                ",
      "                ",
      "                ",
      "                ",
      "                ",
      "                ",
      "                ",
      "                ",
      "                ",
      "yyyyyyyyyyy     ",
      "y~~~~a~~~~y     ",
      "y~~~~~~~~~y     ",
      "y~~~~~Q~~~y     ",
      "y~~~~~Q~~~y     ",
      "yyyyyyyyyyy     "
    ],
    [
      "                ",
      "                ",
      "                ",
      "                ",
      "                ",
      "                ",
      "                ",
      "                ",
      "                ",
      "                ",
      "yyyyyyyyyyy     ",
      "y~~~~~~~~~y     ",
      "y~~~~~~~~~y     ",
      "y~~~~~~Q~~y     ",
      "y~~~~~~Q~~y     ",
      "yyyyyyyyyyy     "
    ],
    [
      "                ",
      "                ",
      "                ",
      "                ",
      "                ",
      "                ",
      "                ",
      "                ",
      "                ",
      "                ",
      "yyyyyyyyyyy     ",
      "yQQQQQQQQQy     ",
      "yQQQQQQQQQy     ",
      "yQQQ~~~~QQy     ",
      "yQQQ~~~~QQy     ",
      "yyyyyyyyyyy     "
    ]
  ]
}