{
  "xsize": 16,
  "zsize": 16,
  "slices": [
    [
      "abjjjjjjjjjjjjba",
      "b              b",
      "j              j",
      "j   Q Q        j",
      "j   QQQ   Q    j",
      "j     Q   QQ   j",
      "j     Q        j",
      "j              j",
      "j              j",
      "j              j",
      "j Q     Q Q    j",
      "j Q Q   QQQ    j",
      "jQQQQ   QQ     j",
      "jQQQ    Q   Q Qj",
      "bQQQ        QQQb",
      "abjjjjjjjjjjjjba"
    ],
    [
      "akjjjjjjjjjjjjba",
      "b              k",
      "j              j",
      "j     Q        j",
      "j    m         j",
      "j          m   j",
      "j              j",
      "j              j",
      "j              j",
      "j              j",
      "j              j",
      "j m     Qm     j",
      "jQ             j",
      "j              j",
      "b Q         QmQb",
      "akjjjjjjjjjjjjka"
    ],
    [
      "akjjjjjjjjjjjjka",
      "k              k",
      "j              j",
      "j              j",
      "j              j",
      "j              j",
      "j              j",
      "j              j",
      "j              j",
      "j              j",
      "j              j",
      "j              j",
      "j              j",
      "j              j",
      "k              k",
      "akjjjjjjjjjjjjka"
    ],
    [
      "aaaaaaaaaaaaaaaa",
      "abddddddddddddba",
      "acqqqqqqqqqqqqra",
      "acqbssssssssbqra",
      "acqrjjjjjjjjrqra",
      "acqrjjjjjjjjcqra",
      "acqrjjjjjjjjcqra",
      "acqrjjjjjjjjcqra",
      "acqrjjjjjjjjcqra",
      "acqrjjjjjjjjcqra",
      "acqrjjjjjjjjcqra",
      "acqrjjjjjjjjcqra",
      "acqbddddddddbqra",
      "acqqqqqqqqqqqqra",
      "abssssssssssssba",
      "aaaaaaaaaaaaaaaa"
    ],
    [
      "                ",
      "                ",
      "                ",
      "                ",
      "                ",
      "                ",
      "                ",
      "                ",
      "                ",
      "                ",
      "                ",
      "                ",
      "                ",
      "                ",
      "                ",
      "                "
    ],
    [
      "                ",
      "                ",
      "                ",
      "                ",
      "                ",
      "                ",
      "                ",
      "                ",
      "                ",
      "                ",
      "                ",
      "                ",
      "                ",
      "                ",
      "                ",
      "                "
    ]
  ]
}