{
  "xsize": 16,
  "zsize": 16,
  "slices": [
    [
      "aijjjjjjjjjjjjia",
      "i              i",
      "j              j",
      "j   Q Q        j",
      "j   QQQ   Q    j",
      "j     Q   QQ   j",
      "j     Q        j",
      "j              j",
      "j              j",
      "j              j",
      "j Q     Q Q    j",
      "j Q Q   QQQ    j",
      "jQQQQ   QQ     j",
      "jQQQ    Q   Q Qj",
      "iQQQ        QQQi",
      "aijjjjjjjjjjjjia"
    ],
    [
      "akjjjjjjjjjjjjia",
      "i              k",
      "j              j",
      "j     Q        j",
      "j    m         j",
      "j          m   j",
      "j              j",
      "j              j",
      "j              j",
      "j              j",
      "j              j",
      "j m     Qm     j",
      "jQ             j",
      "j              j",
      "i Q         QmQi",
      "akjjjjjjjjjjjjka"
    ],
    [
      "akjjjjjjjjjjjjka",
      "k              k",
      "j              j",
      "j              j",
      "j              j",
      "j              j",
      "j              j",
      "j              j",
      "j              j",
      "j              j",
      "j              j",
      "j              j",
      "j              j",
      "j              j",
      "k              k",
      "akjjjjjjjjjjjjka"
    ],
    [
      "aaaaaaaaaaaaaaaa",
      "ainnnnnnnnnnnnia",
      "aoqqqqqqqqqqqqra",
      "aoqissssssssiqra",
      "aoqrjjjjjjjjrqra",
      "aoqrjjjjjjjjoqra",
      "aoqrjjjjjjjjoqra",
      "aoqrjjjjjjjjoqra",
      "aoqrjjjjjjjjoqra",
      "aoqrjjjjjjjjoqra",
      "aoqrjjjjjjjjoqra",
      "aoqrjjjjjjjjoqra",
      "aoqinnnnnnnniqra",
      "aoqqqqqqqqqqqqra",
      "aissssssssssssia",
      "aaaaaaaaaaaaaaaa"
    ],
    [
      "                ",
      "                ",
      "                ",
      "                ",
      "                ",
      "                ",
      "                ",
      "                ",
      "                ",
      "                ",
      "                ",
      "                ",
      "                ",
      "                ",
      "                ",
      "                "
    ],
    [
      "                ",
      "                ",
      "                ",
      "                ",
      "                ",
      "                ",
      "                ",
      "                ",
      "                ",
      "                ",
      "                ",
      "                ",
      "                ",
      "                ",
      "                ",
      "                "
    ]
  ]
}