{
  "xsize": 16,
  "zsize": 16,
  "slices": [
    [
      "abddddddddddddba",
      "b              b",
      "d              d",
      "d   Q Q        d",
      "d   QQQ   Q    d",
      "d     Q   QQ   d",
      "d     Q        d",
      "d              d",
      "d              d",
      "d              d",
      "d Q     Q Q    d",
      "d Q Q   QQQ    d",
      "dQQQQ   QQ     d",
      "dQQQ    Q   Q Qd",
      "bQQQ        QQQb",
      "abddddddddddddba"
    ],
    [
      "abddddddddddddba",
      "b              b",
      "d              d",
      "d     Q        d",
      "d    k         d",
      "d          k   d",
      "d              d",
      "d              d",
      "d              d",
      "d              d",
      "d              d",
      "d k     Qk     d",
      "dQ             d",
      "d              d",
      "b Q         QkQb",
      "abddddddddddddba"
    ],
    [
      "abddddddddddddba",
      "b              b",
      "d              d",
      "d              d",
      "d              d",
      "d              d",
      "d              d",
      "d              d",
      "d              d",
      "d              d",
      "d              d",
      "d              d",
      "d              d",
      "d              d",
      "b              b",
      "abddddddddddddba"
    ],
    [
      "aaaaaaaaaaaaaaaa",
      "abddddddddddddba",
      "aciiiiiiiiiiiica",
      "acibddddddddbica",
      "acicddddddddcica",
      "acicddddddddcica",
      "acicddddddddcica",
      "acicddddddddcica",
      "acicddddddddcica",
      "acicddddddddcica",
      "acicddddddddcica",
      "acicddddddddcica",
      "acibddddddddbica",
      "aciiiiiiiiiiiica",
      "abddddddddddddba",
      "aaaaaaaaaaaaaaaa"
    ],
    [
      "                ",
      "                ",
      "                ",
      "                ",
      "                ",
      "                ",
      "                ",
      "                ",
      "                ",
      "                ",
      "                ",
      "                ",
      "                ",
      "                ",
      "                ",
      "                "
    ],
    [
      "                ",
      "                ",
      "                ",
      "                ",
      "                ",
      "                ",
      "                ",
      "                ",
      "                ",
      "                ",
      "                ",
      "                ",
      "                ",
      "                ",
      "                ",
      "                "
    ]
  ]
}