{
  "xsize": 16,
  "zsize": 16,
  "slices": [
    [
      "abddddddddddddba",
      "b              b",
      "d              d",
      "d   j j        d",
      "d   jjj   j    d",
      "d     j   jj   d",
      "d     j        d",
      "d              d",
      "d              d",
      "d              d",
      "d j     j j    d",
      "d j j   jjj    d",
      "djjjj   jj     d",
      "djjj    j   j jd",
      "bjjj        jjjb",
      "abddddddddddddba"
    ],
    [
      "abddddddddddddba",
      "b              b",
      "d              d",
      "d     j        d",
      "d    k         d",
      "d          k   d",
      "d              d",
      "d              d",
      "d              d",
      "d              d",
      "d              d",
      "d k     jk     d",
      "dj             d",
      "d              d",
      "b j         jkjb",
      "abddddddddddddba"
    ],
    [
      "abddddddddddddba",
      "b              b",
      "d              d",
      "d              d",
      "d              d",
      "d              d",
      "d              d",
      "d              d",
      "d              d",
      "d              d",
      "d              d",
      "d              d",
      "d              d",
      "d              d",
      "b              b",
      "abddddddddddddba"
    ],
    [
      "aaaaaaaaaaaaaaaa",
      "abddddddddddddba",
      "aciiiiiiiiiiiica",
      "acibddddddddbica",
      "acicdhhhhhhdcica",
      "acicdhhhhhhdcica",
      "acicdhhhhhhdcica",
      "acicdhhhhhhdcica",
      "acicdhhhhhhdcica",
      "acicdhhhhhhdcica",
      "acicdhhhhhhdcica",
      "acicdhhhhhhdcica",
      "acibddddddddbica",
      "aciiiiiiiiiiiica",
      "abddddddddddddba",
      "aaaaaaaaaaaaaaaa"
    ],
    [
      "                ",
      "                ",
      "                ",
      "                ",
      "                ",
      "                ",
      "                ",
      "                ",
      "                ",
      "                ",
      "                ",
      "                ",
      "                ",
      "                ",
      "                ",
      "                "
    ],
    [
      "                ",
      "                ",
      "                ",
      "                ",
      "                ",
      "                ",
      "                ",
      "                ",
      "                ",
      "                ",
      "                ",
      "                ",
      "                ",
      "                ",
      "                ",
      "                "
    ]
  ]
}