{
  "xsize": 16,
  "zsize": 16,
  "slices": [
    [
      "#ijjjjjjjjjjjji#",
      "i              i",
      "j              j",
      "j   Q Q        j",
      "j   QQQ   Q    j",
      "j     Q   QQ   j",
      "j     Q        j",
      "j              j",
      "j              j",
      "j              j",
      "j Q     Q Q    j",
      "j Q Q   QQQ    j",
      "jQQQQ   QQ     j",
      "jQQQ    Q   Q Qj",
      "iQQQ        QQQi",
      "#ijjjjjjjjjjjji#"
    ],
    [
      "#kjjjjjjjjjjjji#",
      "i              k",
      "j              j",
      "j     Q        j",
      "j    m         j",
      "j          m   j",
      "j              j",
      "j              j",
      "j              j",
      "j              j",
      "j              j",
      "j m     Qm     j",
      "jQ             j",
      "j              j",
      "i Q         QmQi",
      "#kjjjjjjjjjjjjk#"
    ],
    [
      "#kjjjjjjjjjjjjk#",
      "k              k",
      "j              j",
      "j              j",
      "j              j",
      "j              j",
      "j              j",
      "j              j",
      "j              j",
      "j              j",
      "j              j",
      "j              j",
      "j              j",
      "j              j",
      "k              k",
      "#kjjjjjjjjjjjjk#"
    ],
    [
      "################",
      "#innnnnnnnnnnni#",
      "#oqqqqqqqqqqqqr#",
      "#oqissssssssiqr#",
      "#oqrjjjjjjjjrqr#",
      "#oqrjjjjjjjjoqr#",
      "#oqrjjjjjjjjoqr#",
      "#oqrjjjjjjjjoqr#",
      "#oqrjjjjjjjjoqr#",
      "#oqrjjjjjjjjoqr#",
      "#oqrjjjjjjjjoqr#",
      "#oqrjjjjjjjjoqr#",
      "#oqinnnnnnnniqr#",
      "#oqqqqqqqqqqqqr#",
      "#issssssssssssi#",
      "################"
    ],
    [
      "                ",
      "                ",
      "                ",
      "                ",
      "                ",
      "                ",
      "                ",
      "                ",
      "                ",
      "                ",
      "                ",
      "                ",
      "                ",
      "                ",
      "                ",
      "                "
    ],
    [
      "                ",
      "                ",
      "                ",
      "                ",
      "                ",
      "                ",
      "                ",
      "                ",
      "                ",
      "                ",
      "                ",
      "                ",
      "                ",
      "                ",
      "                ",
      "                "
    ]
  ]
}