{
  "xsize": 16,
  "zsize": 16,
  "slices": [
    [
      "aaaaaaaaaaaaaaaa",
      "abddddddddddddba",
      "aciiiiiiiiiiiica",
      "acibddddddddbica",
      "acicaaaaaaaacica",
      "acicaaaaaaaacica",
      "acicaaaoaaoacica",
      "acicaaaaaaaacica",
      "acicaaiiiaaacica",
      "acicaaiyiaoacica",
      "acicaaiiiaaacica",
      "acicaaaaaaaacica",
      "acibddddddddbica",
      "aciiiiiiiiiiiica",
      "abddddddddddddba",
      "aaaaaaaaaaaaaaaa"
    ],
    [
      "abhhhhhhhhhhhhba",
      "b              b",
      "h              h",
      "h   j j        h",
      "h   jjj   j    h",
      "h     j   jj   h",
      "h     j        h",
      "h              h",
      "h              h",
      "h              h",
      "h j     j j    h",
      "h j j   jjj    h",
      "hjjjj   jj     h",
      "hjjj    j   j jh",
      "bjjj        jjjb",
      "abhhhhhhhhhhhhba"
    ],
    [
      "abhhhhhhhhhhhhba",
      "b              b",
      "h              h",
      "h     j        h",
      "h    k         h",
      "h          k   h",
      "h              h",
      "h              h",
      "h              h",
      "h              h",
      "h              h",
      "h k     jk     h",
      "hj             h",
      "h              h",
      "b j         jkjb",
      "abhhhhhhhhhhhhba"
    ],
    [
      "abhhhhhhhhhhhhba",
      "b              b",
      "h              h",
      "h              h",
      "h              h",
      "h              h",
      "h              h",
      "h              h",
      "h              h",
      "h              h",
      "h              h",
      "h              h",
      "h              h",
      "h              h",
      "b              b",
      "abhhhhhhhhhhhhba"
    ],
    [
      "abhhhhhhhhhhhhba",
      "b              b",
      "h              h",
      "h              h",
      "h              h",
      "h              h",
      "h              h",
      "h              h",
      "h              h",
      "h              h",
      "h              h",
      "h              h",
      "h              h",
      "h              h",
      "b              b",
      "abhhhhhhhhhhhhba"
    ],
    [
      "abhhhhhhhhhhhhba",
      "b              b",
      "h              h",
      "h              h",
      "h              h",
      "h              h",
      "h              h",
      "h              h",
      "h              h",
      "h              h",
      "h              h",
      "h              h",
      "h              h",
      "h              h",
      "b              b",
      "abhhhhhhhhhhhhba"
    ],
    [
      "aaaaaaaaaaaaaaaa",
      "abddddddddddddba",
      "aciiiiiiiiiiiica",
      "acibddddddddbica",
      "acichhhhhhhhcica",
      "acichhhhhhhhcica",
      "acichhhhhhhhcica",
      "acichhhhhhhhcica",
      "acichhhhhhhhcica",
      "acichhhhhhhhcica",
      "acichhhhhhhhcica",
      "acichhhhhhhhcica",
      "acibddddddddbica",
      "aciiiiiiiiiiiica",
      "abddddddddddddba",
      "aaaaaaaaaaaaaaaa"
    ]
  ]
}