{
  "xsize": 16,
  "zsize": 16,
  "slices": [
    [
      "aaaaaaaaaaaaaaaa",
      "aaaaaaaaaaaaaaaa",
      "aaaaaaaaaaaaaaaa",
      "aaaaaaaaaaaaaaaa",
      "aaaaaaaaaaaaaaaa",
      "aaaaaaaaaaaaaaaa",
      "aaaaaaaaaaaaaaaa",
      "aaaaaaaaaaaaaaaa",
      "aaaaaaaaaaaaaaaa",
      "aaaaaaaaaaaaaaaa",
      "aaaaaaaaaaaaaaaa",
      "aaaaaaaaaaaaaaaa",
      "aaaaaaaaaaaaaaaa",
      "aaaaaaaaaaaaaaaa",
      "aaaaaaaaaaaaaaaa",
      "aaaaaaaaaaaaaaaa"
    ],
    [
      "aaaaaaaaaaaaaaaa",
      "aDDDDDDDDDDDDDDa",
      "aDGGDDDDDDDDDDDa",
      "aDDDDDDDDDDGDDDa",
      "aDDDDDDDDDDDDDDa",
      "aDDDGDDDDDDDDDDa",
      "aDDDDDDDGDDDDDDa",
      "aDDDDDDDDDDDDDDa",
      "aDDDGDDDDGDDDDDa",
      "aDDDDDDDDDDDDDDa",
      "aDDDDGDDDDDDGDDa",
      "aDDDDDDDDDGDDDDa",
      "aDDDDDGDDDDDDDDa",
      "aDDDDDDDDDGDDDDa",
      "aDDDGDDDDDDDDDDa",
      "aaaaaaaaaaaaaaaa"
    ],
    [
      "            p   ",
      "                ",
      " p    p         ",
      "           p    ",
      "    p           ",
      "         p      ",
      "                ",
      "                ",
      "    p        p  ",
      "                ",
      "                ",
      "        p       ",
      "                ",
      "   p            ",
      "                ",
      "           p    "
    ]
  ]
}