{
  "xsize": 16,
  "zsize": 16,
  "slices": [
    [
      "aaaaaaaaaaaaaaaa",
      "aaaaaaaaaaaaaaaa",
      "aaaaaaaaaaaaaaaa",
      "aaaaaaaaaaaaaaaa",
      "aaaaaaaaaaaaaaaa",
      "aaaaaaaaaaaaaaaa",
      "aaaaaaaaaaaaaaaa",
      "aaaaaaaaaaaaaaaa",
      "aaaaaaaaaaaaaaaa",
      "aaaaaaaaaaaaaaaa",
      "aaaaaaaaaaaaaaaa",
      "aaaaaaaaaaaaaaaa",
      "aaaaaaaaaaaaaaaa",
      "aaaaaaaaaaaaaaaa",
      "aaaaaaaaaaaaaaaa",
      "aaaaaaaaaaaaaaaa"
    ],
    [
      "                ",
      "                ",
      "                ",
      "                ",
      "    aaaaaaa     ",
      "    a     a     ",
      "    a     a     ",
      "          a     ",
      "    a     a     ",
      "    a     a     ",
      "    aaaaaaa     ",
      "                ",
      "                ",
      "                ",
      "                ",
      "                "
    ],
    [
      "                ",
      "                ",
      "                ",
      "                ",
      "    aaaaaaa     ",
      "    a     a     ",
      "    a     a     ",
      "          a     ",
      "    a     a     ",
      "    a     a     ",
      "    aaaaaaa     ",
      "                ",
      "                ",
      "                ",
      "                ",
      "                "
    ],
    [
      "                ",
      "                ",
      "                ",
      "                ",
      "    aaaaaaa     ",
      "    aaaaaaa     ",
      "    aaaaaaa     ",
      "    aaaaaaa     ",
      "    aaaaaaa     ",
      "    aaaaaaa     ",
      "    aaaaaaa     ",
      "                ",
      "                ",
      "                ",
      "                ",
      "                "
    ]
  ]
}