{
  "xsize": 16,
  "zsize": 16,
  "slices": [
    [
      "aaaaaaaaaaaaaaaa",
      "aaaaaaaaaaaaaaaa",
      "aaaaaaaaaaaaaaaa",
      "aaaaaaaaaaaaaaaa",
      "aaaaaaaaaaaaaaaa",
      "aaaaaaaaaaaaaaaa",
      "aaaaaaaaaaaaaaaa",
      "aaaaaaaaaaaaaaaa",
      "aaaaaaaaaaaaaaaa",
      "aaaaaaaaaaaaaaaa",
      "aaaaaaaaaaaaa  a",
      "aaaaaaaaaaaaa  a",
      "aaaaaaaaaaaaa  a",
      "aaaaaaaaaaaaa  a",
      "aaaaaaaaaaaaa))a",
      "aaaaaaaaaaaaaaaa"
    ],
    [
      "wwwwwwwwwwwwwwww",
      "w              w",
      "w              w",
      "w              w",
      "w              w",
      "w              w",
      "w               ",
      "w               ",
      "w               ",
      "w           w  w",
      "w              w",
      "w              w",
      "w              w",
      "w              w",
      "w              w",
      "wwwwwwww    wwww"
    ],
    [
      "                ",
      "                ",
      "                ",
      "                ",
      "                ",
      "                ",
      "                ",
      "                ",
      "                ",
      "            w  w",
      "                ",
      "                ",
      "                ",
      "                ",
      "                ",
      "            w  w"
    ],
    [
      "                ",
      "                ",
      "                ",
      "                ",
      "                ",
      "                ",
      "                ",
      "                ",
      "                ",
      "            aaaa",
      "            aaaa",
      "            aaaa",
      "            aaaa",
      "            aaaa",
      "            aaaa",
      "            aaaa"
    ]
  ]
}