{
  "xsize": 16,
  "zsize": 16,
  "slices": [
    [
      "aaSQSQSQSQSQSQSQ",
      "aaQSQSQSQSQSQSQS",
      ":aSQSQSQSQSQSQSQ",
      ":aQSQSQSQSQSQSQS",
      "aaSQSQSQSQSQSQSQ",
      "aSQSQSQSQSQSQSQS",
      "aQSQSQSQSQSQSQSQ",
      "aSQSQSQSQSQSQSQS",
      "aQSQSQSQSQSQSQSQ",
      "aSQSQSQSQSQSQSQS",
      "aQSQSQSQSQSQSQSQ",
      "aaQSQSQSQSQSQSQS",
      ":aSQSQSQSQSQSQSQ",
      ":aQSQSQSQSQSQSQS",
      "aaaaaQSQSQSaaaaa",
      "aa::aaaaaaaa::aa"
    ],
    [
      "aa              ",
      "aa              ",
      ":a              ",
      ":a              ",
      "aa              ",
      "a               ",
      "a               ",
      "a       a       ",
      "a               ",
      "a               ",
      "a               ",
      "aa              ",
      ":a              ",
      ":a              ",
      "aaaaa      aaaaa",
      "aa::aaaaaaaa::aa"
    ],
    [
      "aa              ",
      "aa              ",
      ":a              ",
      ":a              ",
      "aa              ",
      "a               ",
      "a               ",
      "a               ",
      "a               ",
      "a               ",
      "a               ",
      "aa              ",
      ":a              ",
      ":a              ",
      "aaaaa      aaaaa",
      "aa::aaaaaaaa::aa"
    ],
    [
      "aa              ",
      "aa              ",
      ":a              ",
      ":a              ",
      "aa              ",
      "a               ",
      "a               ",
      "a               ",
      "a               ",
      "a               ",
      "a               ",
      "aa              ",
      ":a              ",
      ":a              ",
      "aaaaa      aaaaa",
      "aa::aaaaaaaa::aa"
    ],
    [
      "aa              ",
      "aa              ",
      ":a              ",
      ":a              ",
      "aa              ",
      "a               ",
      "a               ",
      "a               ",
      "a               ",
      "a               ",
      "a               ",
      "aa              ",
      ":a              ",
      ":a              ",
      "aaaaa      aaaaa",
      "aa::aaaaaaaa::aa"
    ],
    [
      "aaaaaaaaaaaaaaaa",
      "aaaaaaaaaaaaaaaa",
      ":aaaaaaaaaaaaaaa",
      ":aaaaaaaaaaaaaaa",
      "aaaaaaaaaaaaaaaa",
      "aaaaaaaaaaaaaaaa",
      "aaaaaaaaaaaaaaaa",
      "aaaaaaaaaaaaaaaa",
      "aaaaaaaaaaaaaaaa",
      "aaaaaaaaaaaaaaaa",
      "aaaaaaaaaaaaaaaa",
      "aaaaaaaaaaaaaaaa",
      ":aaaaaaaaaaaaaaa",
      ":aaaaaaaaaaaaaaa",
      "aaaaaaaaaaaaaaaa",
      "aa::aaaaaaaa::aa"
    ]
  ]
}