{
  "xsize": 16,
  "zsize": 16,
  "slices": [
    [
      "aaSQSQSQSQSQSQSQ",
      "aSQSQSQSQSQSQSQS",
      "aQSQSQSQSQSQSQSQ",
      "aSQSQSQSQSQSQSQS",
      "aQSQSQSQSQSQSQSQ",
      "aSQSQSQSQSQSQSQS",
      "aQSQSQSQSQSQSQSQ",
      "aSQSQSQSQSQSQSQS",
      "aQSQSQSQSQSQSQSQ",
      "aSQSQSQSQSQSQSQS",
      "aQSQSQSQSQSQSQSQ",
      "aSQSQSQSQSQSQSQS",
      "aQSQSQSQSQSQSQSQ",
      "aSQSQSQSQSQSQSQS",
      "aaSQSQSQSQSQSQSa",
      "aaaaaaaaaaaaaaaa"
    ],
    [
      "aa              ",
      "a               ",
      "a               ",
      "a               ",
      "a               ",
      "a               ",
      "a               ",
      "a       a       ",
      "a               ",
      "a               ",
      "a               ",
      "a               ",
      "a               ",
      "a               ",
      "aa             a",
      "aaaaaaaaaaaaaaaa"
    ],
    [
      "aa              ",
      "a               ",
      "a               ",
      "a               ",
      "a               ",
      "a               ",
      "a               ",
      "a               ",
      "a               ",
      "a               ",
      "a               ",
      "a               ",
      "a               ",
      "a               ",
      "aa             a",
      "aaaaaaaaaaaaaaaa"
    ],
    [
      "aa              ",
      "a               ",
      "a               ",
      "a               ",
      "a               ",
      "a               ",
      "a               ",
      "a               ",
      "a               ",
      "a               ",
      "a               ",
      "a               ",
      "a               ",
      "a               ",
      "aa             a",
      "aaaaaaaaaaaaaaaa"
    ],
    [
      "aa              ",
      "a               ",
      "a               ",
      "a               ",
      "a               ",
      "a               ",
      "a               ",
      "a               ",
      "a               ",
      "a               ",
      "a               ",
      "a               ",
      "a               ",
      "a               ",
      "aa             a",
      "aaaaaaaaaaaaaaaa"
    ],
    [
      "aaaaaaaaaaaaaaaa",
      "aaaaaaaaaaaaaaaa",
      "aaaaaaaaaaaaaaaa",
      "aaaaaaaaaaaaaaaa",
      "aaaaaaaaaaaaaaaa",
      "aaaaaaaaaaaaaaaa",
      "aaaaaaaaaaaaaaaa",
      "aaaaaaaaaaaaaaaa",
      "aaaaaaaaaaaaaaaa",
      "aaaaaaaaaaaaaaaa",
      "aaaaaaaaaaaaaaaa",
      "aaaaaaaaaaaaaaaa",
      "aaaaaaaaaaaaaaaa",
      "aaaaaaaaaaaaaaaa",
      "aaaaaaaaaaaaaaaa",
      "aaaaaaaaaaaaaaaa"
    ]
  ]
}