{
  "xsize": 16,
  "zsize": 16,
  "slices": [
    [
      "aaSQSQSQSQSQSQSQ",
      "aSQSQSQSQSQSQSQS",
      "aQSQSQSQSQSQSQSQ",
      "aSQSQSQSQSQSQSQS",
      "aQSQSQSQSQSQSQSQ",
      "aSQSQSQSQSQSQSQS",
      "aQSQSQSQSQSQSQSQ",
      "aSQSQSQSQSQSQSQS",
      "aQSQSQSQSQSQSQSQ",
      "aSQSQSQSQSQSQSQS",
      "aQSQSQSQSQSQSQSQ",
      "aSQSQSQSQSQSQSQS",
      "aQSQSQSQSQSQSQSQ",
      "aSQSQSQSQSQSQSQS",
      "aaSQSQSQSQSQSQSa",
      "aaaaaaaaaaaaaaaa"
    ],
    [
      "aa              ",
      ":               ",
      ":               ",
      "a               ",
      "a               ",
      "a               ",
      "a               ",
      "a       a       ",
      "a               ",
      "a               ",
      "a               ",
      "a               ",
      ":               ",
      ":               ",
      "aa             a",
      "aa::aaaaaaaaa::a"
    ],
    [
      "aa              ",
      ":               ",
      ":               ",
      "a               ",
      "a               ",
      "a               ",
      "a               ",
      "a               ",
      "a               ",
      "a               ",
      "a               ",
      "a               ",
      ":               ",
      ":               ",
      "aa             a",
      "aa::aaaaaaaaa::a"
    ],
    [
      "aa              ",
      ":               ",
      ":               ",
      "a               ",
      "a               ",
      "a               ",
      "a               ",
      "a               ",
      "a               ",
      "a               ",
      "a               ",
      "a               ",
      ":               ",
      ":               ",
      "aa             a",
      "aa::aaaaaaaaa::a"
    ],
    [
      "aa              ",
      ":               ",
      ":               ",
      "a               ",
      "a               ",
      "a               ",
      "a               ",
      "a               ",
      "a               ",
      "a               ",
      "a               ",
      "a               ",
      ":               ",
      ":               ",
      "aa             a",
      "aa::aaaaaaaaa::a"
    ],
    [
      "aaaaaaaaaaaaaaaa",
      "aaaaaaaaaaaaaaaa",
      "aaaaaaaaaaaaaaaa",
      "aaaaaaaaaaaaaaaa",
      "aaaaaaaaaaaaaaaa",
      "aaaaaaaaaaaaaaaa",
      "aaaaaaaaaaaaaaaa",
      "aaaaaaaaaaaaaaaa",
      "aaaaaaaaaaaaaaaa",
      "aaaaaaaaaaaaaaaa",
      "aaaaaaaaaaaaaaaa",
      "aaaaaaaaaaaaaaaa",
      "aaaaaaaaaaaaaaaa",
      "aaaaaaaaaaaaaaaa",
      "aaaaaaaaaaaaaaaa",
      "aaaaaaaaaaaaaaaa"
    ]
  ]
}