{
  "xsize": 16,
  "zsize": 16,
  "slices": [
    [
      "aaaaaaaaaaaaaaaa",
      "aaQSQSQSQSQSQSQa",
      "aQSQSQSQSQSQSQSQ",
      "aSQSQSQSQSQSQSQS",
      "aQSQSQSQSQSQSQSQ",
      "aSQSQSQSQSQSQSQS",
      "aQSQSQSQSQSQSQSQ",
      "aSQSQSQSQSQSQSQS",
      "aQSQSQSQSQSQSQSQ",
      "aSQSQSQSQSQSQSQS",
      "aQSQSQSQSQSQS  Q",
      "aSQSQSQSQSQSQ  S",
      "aQSQSQSQSQSQS  Q",
      "aSQSQSQSQSQSQ  S",
      "aQSQSQSQSQSQS))Q",
      "aaQSQSQSQSQSQSQS"
    ],
    [
      "aaaaaaaaaaaaaaaa",
      "aa             a",
      "a               ",
      "a               ",
      "a               ",
      "a               ",
      "a               ",
      "a               ",
      "a               ",
      "a            )) ",
      "a           Q  Q",
      "a           Q  Q",
      "a           Q  Q",
      "a           Q  Q",
      "a           Q  Q",
      "aa              "
    ],
    [
      "aaaaaaaaaaaaaaaa",
      "aa             a",
      "a               ",
      "a               ",
      "a               ",
      "a               ",
      "a               ",
      "a               ",
      "a               ",
      "a               ",
      "a           a))a",
      "a           a  a",
      "a           a  a",
      "a           a  a",
      "a           a  a",
      "aa              "
    ],
    [
      "aaaaaaaaaaaaaaaa",
      "aa             a",
      "a               ",
      "a               ",
      "a               ",
      "a               ",
      "a               ",
      "a               ",
      "a               ",
      "a               ",
      "a           a  a",
      "a           a))a",
      "a           a  a",
      "a           a  a",
      "a           a  a",
      "aa              "
    ],
    [
      "aaaaaaaaaaaaaaaa",
      "aa             a",
      "a               ",
      "a               ",
      "a               ",
      "a               ",
      "a               ",
      "a               ",
      "a               ",
      "a               ",
      "a           a  a",
      "a           a  a",
      "a           a))a",
      "a           a  a",
      "a           a  a",
      "aa              "
    ],
    [
      "aaaaaaaaaaaaaaaa",
      "aaaaaaaaaaaaaaaa",
      "aaaaaaaaaaaaaaaa",
      "aaaaaaaaaaaaaaaa",
      "aaaaaaaaaaaaaaaa",
      "aaaaaaaaaaaaaaaa",
      "aaaaaaaaaaaaaaaa",
      "aaaaaaaaaaaaaaaa",
      "aaaaaaaaaaaaaaaa",
      "aaaaaaaaaaaaaaaa",
      "aaaaaaaaaaaaa  a",
      "aaaaaaaaaaaaa  a",
      "aaaaaaaaaaaaa  a",
      "aaaaaaaaaaaaa))a",
      "aaaaaaaaaaaaa  a",
      "aaaaaaaaaaaaaaaa"
    ]
  ]
}