{
  "xsize": 16,
  "zsize": 16,
  "slices": [
    [
      "SQSQSQSQSQSQSQaa",
      "QSQSQSQSQSQSQSaa",
      "SQSQSQSQSQSQSQa:",
      "QSQSQSQSQSQSQSa:",
      "SQSQSQSQSQSQSQaa",
      "QSQSQSQSQSQSQSQa",
      "SQSQSQSQSQSQSQSa",
      "QSQSQSQSQSQSQSQa",
      "SQSQSQSQSQSQSQSa",
      "QSQSQSQSQSQSQSQa",
      "SQSQSQSQSQSQSQSa",
      "QSQSQSQSQSQSQSaa",
      "SQSQSQSQSQSQSQa:",
      "QSQSQSQSQSQSQSa:",
      "aaaaaQSQSQSaaaaa",
      "aa::aaaaaaaa::aa"
    ],
    [
      "              aa",
      "              aa",
      "              a:",
      "              a:",
      "              aa",
      "               a",
      "               a",
      "               a",
      "               a",
      "               a",
      "               a",
      "              aa",
      "              a:",
      "              a:",
      "aaaaa      aaaaa",
      "aa::aaaaaaaa::aa"
    ],
    [
      "              aa",
      "              aa",
      "              a:",
      "              a:",
      "              aa",
      "               a",
      "               a",
      "               a",
      "               a",
      "               a",
      "               a",
      "              aa",
      "              a:",
      "              a:",
      "aaaaa      aaaaa",
      "aa::aaaaaaaa::aa"
    ],
    [
      "              aa",
      "              aa",
      "              a:",
      "              a:",
      "              aa",
      "               a",
      "               a",
      "               a",
      "               a",
      "               a",
      "               a",
      "              aa",
      "              a:",
      "              a:",
      "aaaaa      aaaaa",
      "aa::aaaaaaaa::aa"
    ],
    [
      "              aa",
      "              aa",
      "              a:",
      "              a:",
      "              aa",
      "               a",
      "               a",
      "               a",
      "               a",
      "               a",
      "               a",
      "              aa",
      "              a:",
      "              a:",
      "aaaaa      aaaaa",
      "aa::aaaaaaaa::aa"
    ],
    [
      "aaaaaaaaaaaaaaaa",
      "aaaaaaaaaaaaaaaa",
      "aaaaaaaaaaaaaaa:",
      "aaaaaaaaaaaaaaa:",
      "aaaaaaaaaaaaaaaa",
      "aaaaaaaaaaaaaaaa",
      "aaaaaaaaaaaaaaaa",
      "aaaaaaaaaaaaaaaa",
      "aaaaaaaaaaaaaaaa",
      "aaaaaaaaaaaaaaaa",
      "aaaaaaaaaaaaaaaa",
      "aaaaaaaaaaaaaaaa",
      "aaaaaaaaaaaaaaa:",
      "aaaaaaaaaaaaaaa:",
      "aaaaaaaaaaaaaaaa",
      "aa::aaaaaaaa::aa"
    ]
  ]
}