{
  "xsize": 16,
  "zsize": 16,
  "slices": [
    [
      "                ",
      "                ",
      "                ",
      "                ",
      "                ",
      "                ",
      "                ",
      "                ",
      "                ",
      "                ",
      "                ",
      "                ",
      "                ",
      "                ",
      "                ",
      "                "
    ],
    [
      "                ",
      "                ",
      "   aaaaaaaaaa   ",
      "   a        a   ",
      "   a        a   ",
      "   a  aaaaa a   ",
      "   a  a     a   ",
      "   a  a aaa a   ",
      "   a  a a   a   ",
      "   a  a a   a   ",
      "   a 1a a1  a   ",
      "   aaaa aaaaa   ",
      "                ",
      "                ",
      "                ",
      "                "
    ],
    [
      "                ",
      "                ",
      "   aaaaaaaaaa   ",
      "   a        a   ",
      "   a        a   ",
      "   a  aaaaa a   ",
      "   a  a     a   ",
      "   a  a aaa a   ",
      "   a  a a   a   ",
      "   a  a a   a   ",
      "   a  a a   a   ",
      "   aaaa aaaaa   ",
      "                ",
      "                ",
      "                ",
      "                "
    ],
    [
      "                ",
      "                ",
      "   aaaaaaaaaa   ",
      "   a        a   ",
      "   a        a   ",
      "   a  aaaaa a   ",
      "   a  a     a   ",
      "   a  a aaa a   ",
      "   a  a a   a   ",
      "   a  a a   a   ",
      "   a  a a   a   ",
      "   aaaaaaaaaa   ",
      "                ",
      "                ",
      "                ",
      "                "
    ],
    [
      "                ",
      "                ",
      "   aaaaaaaaaa   ",
      "   a        a   ",
      "   a        a   ",
      "   a  aaaaa a   ",
      "   a  a     a   ",
      "   a  a aaa a   ",
      "   a  a a   a   ",
      "   a  a a   a   ",
      "   a  a a   a   ",
      "   aaaaaaaaaa   ",
      "                ",
      "                ",
      "                ",
      "                "
    ]
  ]
}