{
  "xsize": 16,
  "zsize": 16,
  "slices": [
    [
      "aaaaaaaaaaaaaaaa",
      "aaQSQSQSQSQSQSQa",
      "aQSQSQSQSQSQSQSQ",
      "aSQSQSQSQSQSQSQS",
      "aQSQSQSQSQSQSQSQ",
      "aSQSQSQSQSQSQSQS",
      "aQSQSQSQSQSQSQSQ",
      "aSQSQSQSQSQSQSQS",
      "aQSQSQSQSQSQSQSQ",
      "aSQSQSQSQSQSQSQS",
      "aQSQSQSQSQSQS  Q",
      "aSQSQSQSQSQSQ  S",
      "aQSQSQSQSQSQS  Q",
      "aSQSQSQSQSQSQ  S",
      "aQSQSQSQSQSQS))Q",
      "aaQSQSQSQSQSQSQS"
    ],
    [
      "aa::aaaaaaaaa::a",
      "aa             a",
      ":               ",
      ":               ",
      "a               ",
      "a               ",
      "a               ",
      "a               ",
      "a               ",
      "a            )) ",
      "a           Q  Q",
      "a           Q  Q",
      "a           Q  Q",
      ":           Q  Q",
      ":           Q  Q",
      "aa              "
    ],
    [
      "aa::aaaaaaaaa::a",
      "aa             a",
      ":               ",
      ":               ",
      "a               ",
      "a               ",
      "a               ",
      "a               ",
      "a               ",
      "a               ",
      "a           a))a",
      "a           a  a",
      "a           a  a",
      ":           a  a",
      ":           a  a",
      "aa              "
    ],
    [
      "aa::aaaaaaaaa::a",
      "aa             a",
      ":               ",
      ":               ",
      "a               ",
      "a               ",
      "a               ",
      "a               ",
      "a               ",
      "a               ",
      "a           a  a",
      "a           a))a",
      "a           a  a",
      ":           a  a",
      ":           a  a",
      "aa              "
    ],
    [
      "aa::aaaaaaaaa::a",
      "aa             a",
      ":               ",
      ":               ",
      "a               ",
      "a               ",
      "a               ",
      "a               ",
      "a               ",
      "a               ",
      "a           a  a",
      "a           a  a",
      "a           a))a",
      ":           a  a",
      ":           a  a",
      "aa              "
    ],
    [
      "aaaaaaaaaaaaaaaa",
      "aaaaaaaaaaaaaaaa",
      "aaaaaaaaaaaaaaaa",
      "aaaaaaaaaaaaaaaa",
      "aaaaaaaaaaaaaaaa",
      "aaaaaaaaaaaaaaaa",
      "aaaaaaaaaaaaaaaa",
      "aaaaaaaaaaaaaaaa",
      "aaaaaaaaaaaaaaaa",
      "aaaaaaaaaaaaaaaa",
      "aaaaaaaaaaaaa  a",
      "aaaaaaaaaaaaa  a",
      "aaaaaaaaaaaaa  a",
      "aaaaaaaaaaaaa))a",
      "aaaaaaaaaaaaa  a",
      "aaaaaaaaaaaaaaaa"
    ]
  ]
}