{
  "xsize": 16,
  "zsize": 16,
  "slices": [
    [
      "SQSQSQSQSQSQSQaa",
      "QSQSQSQSQSQSQSQa",
      "SQSQSQSQSQSQSQSa",
      "QSQSQSQSQSQSQSQa",
      "SQSQSQSQSQSQSQSa",
      "QSQSQSQSQSQSQSQa",
      "SQSQSQSQSQSQSQSa",
      "QSQSQSQSQSQSQSQa",
      "SQSQSQSQSQSQSQSa",
      "QSQSQSQSQSQSQSQa",
      "SQSQSQSQSQSQSQSa",
      "QSQSQSQSQSQSQSQa",
      "SQSQSQSQSQSQSQSa",
      "QSQSQSQSQSQSQSQa",
      "aQSQSQSQSQSQSQaa",
      "aaaaaaaaaaaaaaaa"
    ],
    [
      "              aa",
      "               a",
      "               a",
      "               a",
      "               a",
      "               a",
      "               a",
      "               a",
      "               a",
      "               a",
      "               a",
      "               a",
      "               a",
      "               a",
      "a             aa",
      "aaaaaaaaaaaaaaaa"
    ],
    [
      "              aa",
      "               a",
      "               a",
      "               a",
      "               a",
      "               a",
      "               a",
      "               a",
      "               a",
      "               a",
      "               a",
      "               a",
      "               a",
      "               a",
      "a             aa",
      "aaaaaaaaaaaaaaaa"
    ],
    [
      "              aa",
      "               a",
      "               a",
      "               a",
      "               a",
      "               a",
      "               a",
      "               a",
      "               a",
      "               a",
      "               a",
      "               a",
      "               a",
      "               a",
      "a             aa",
      "aaaaaaaaaaaaaaaa"
    ],
    [
      "              aa",
      "               a",
      "               a",
      "               a",
      "               a",
      "               a",
      "               a",
      "               a",
      "               a",
      "               a",
      "               a",
      "               a",
      "               a",
      "               a",
      "a             aa",
      "aaaaaaaaaaaaa:aa"
    ],
    [
      "aaaaaaaaaaaaaaaa",
      "aaaaaaaaaaaaaaaa",
      "aaaaaaaaaaaaaaaa",
      "aaaaaaaaaaaaaaaa",
      "aaaaaaaaaaaaaaaa",
      "aaaaaaaaaaaaaaaa",
      "aaaaaaaaaaaaaaaa",
      "aaaaaaaaaaaaaaaa",
      "aaaaaaaaaaaaaaaa",
      "aaaaaaaaaaaaaaaa",
      "aaaaaaaaaaaaaaaa",
      "aaaaaaaaaaaaaaaa",
      "aaaaaaaaaaaaaaaa",
      "aaaaaaaaaaaaaaaa",
      "aaaaaaaaaaaaaaaa",
      "aaaaaaaaaaaaaaaa"
    ]
  ]
}