{
  "xsize": 16,
  "zsize": 16,
  "slices": [
    [
      "aa::aaaaaaaa::aa",
      "aaaaaSQSQSQaaaaa",
      ":aSQSQSQSQSQSQSQ",
      ":aQSQSQSQSQSQSQS",
      "aaSQSQSQSQSQSQSQ",
      "aSQSQSQSQSQSQSQS",
      "aQSQSQSQSQSQSQSQ",
      "aSQSQSQSQSQSQSQS",
      "aQSQSQSQSQSQSQSQ",
      "aSQSQSQSQSQSQSQS",
      "aQSQSQSQSQSQS  Q",
      "aaQSQSQSQSQSQ  S",
      ":aSQSQSQSQSQS  Q",
      ":aQSQSQSQSQSQ  S",
      "aaSQSQSQSQSQS))Q",
      "aaQSQSQSQSQSQSQS"
    ],
    [
      "aa::aaaaaaaa::aa",
      "aaaaa      aaaaa",
      ":a              ",
      ":a              ",
      "aa              ",
      "a               ",
      "a               ",
      "a               ",
      "a               ",
      "a            )) ",
      "a           Q  Q",
      "aa          Q  Q",
      ":a          Q  Q",
      ":a          Q  Q",
      "aa          Q  Q",
      "aa              "
    ],
    [
      "aa::aaaaaaaa::aa",
      "aaaaa      aaaaa",
      ":a              ",
      ":a              ",
      "aa              ",
      "a               ",
      "a               ",
      "a               ",
      "a               ",
      "a               ",
      "a           a))a",
      "aa          a  a",
      ":a          a  a",
      ":a          a  a",
      "aa          a  a",
      "aa              "
    ],
    [
      "aa::aaaaaaaa::aa",
      "aaaaa      aaaaa",
      ":a              ",
      ":a              ",
      "aa              ",
      "a               ",
      "a               ",
      "a               ",
      "a               ",
      "a               ",
      "a           a  a",
      "aa          a))a",
      ":a          a  a",
      ":a          a  a",
      "aa          a  a",
      "aa              "
    ],
    [
      "aa::aaaaaaaa::aa",
      "aaaaa      aaaaa",
      ":a              ",
      ":a              ",
      "aa              ",
      "a               ",
      "a               ",
      "a               ",
      "a               ",
      "a               ",
      "a           a  a",
      "aa          a  a",
      ":a          a))a",
      ":a          a  a",
      "aa          a  a",
      "aa              "
    ],
    [
      "aa::aaaaaaaa::aa",
      "aaaaaaaaaaaaaaaa",
      ":aaaaaaaaaaaaaaa",
      ":aaaaaaaaaaaaaaa",
      "aaaaaaaaaaaaaaaa",
      "aaaaaaaaaaaaaaaa",
      "aaaaaaaaaaaaaaaa",
      "aaaaaaaaaaaaaaaa",
      "aaaaaaaaaaaaaaaa",
      "aaaaaaaaaaaaaaaa",
      "aaaaaaaaaaaaa  a",
      "aaaaaaaaaaaaa  a",
      ":aaaaaaaaaaaa  a",
      ":aaaaaaaaaaaa))a",
      "aaaaaaaaaaaaa  a",
      "aaaaaaaaaaaaaaaa"
    ]
  ]
}