{
  "xsize": 16,
  "zsize": 16,
  "slices": [
    [
      "aa::aaaaaaaa::aa",
      "aaaaaSQSQSQaaaaa",
      "SQSQSQSQSQSQSQa:",
      "QSQSQSQSQSQSQSa:",
      "SQSQSQSQSQSQSQaa",
      "QSQSQSQSQSQSQSQa",
      "SQSQSQSQSQSQSQSa",
      "QSQSQSQSQSQSQSQa",
      "SQSQSQSQSQSQSQSa",
      "QSQSQSQSQSQSQSQa",
      "SQSQSQSQSQSQSQSa",
      "QSQSQSQSQSQSQSaa",
      "SQSQSQSQSQSQSQa:",
      "QSQSQSQSQSQSQSa:",
      "SQSQSQSQSQSQSQaa",
      "QSQSQSQSQSQSQSaa"
    ],
    [
      "aa::aaaaaaaa::aa",
      "aaaaa      aaaaa",
      "              a:",
      "              a:",
      "              aa",
      "               a",
      "               a",
      "               a",
      "               a",
      "               a",
      "               a",
      "              aa",
      "              a:",
      "              a:",
      "              aa",
      "              aa"
    ],
    [
      "aa::aaaaaaaa::aa",
      "aaaaa      aaaaa",
      "              a:",
      "              a:",
      "              aa",
      "               a",
      "               a",
      "               a",
      "               a",
      "               a",
      "               a",
      "              aa",
      "              a:",
      "              a:",
      "              aa",
      "              aa"
    ],
    [
      "aa::aaaaaaaa::aa",
      "aaaaa      aaaaa",
      "              a:",
      "              a:",
      "              aa",
      "               a",
      "               a",
      "               a",
      "               a",
      "               a",
      "               a",
      "              aa",
      "              a:",
      "              a:",
      "              aa",
      "              aa"
    ],
    [
      "aa::aaaaaaaa::aa",
      "aaaaa      aaaaa",
      "              a:",
      "              a:",
      "              aa",
      "               a",
      "               a",
      "               a",
      "               a",
      "               a",
      "               a",
      "              aa",
      "              a:",
      "              a:",
      "              aa",
      "              aa"
    ],
    [
      "aa::aaaaaaaa::aa",
      "aaaaaaaaaaaaaaaa",
      "aaaaaaaaaaaaaaa:",
      "aaaaaaaaaaaaaaa:",
      "aaaaaaaaaaaaaaaa",
      "aaaaaaaaaaaaaaaa",
      "aaaaaaaaaaaaaaaa",
      "aaaaaaaaaaaaaaaa",
      "aaaaaaaaaaaaaaaa",
      "aaaaaaaaaaaaaaaa",
      "aaaaaaaaaaaaaaaa",
      "aaaaaaaaaaaaaaaa",
      "aaaaaaaaaaaaaaa:",
      "aaaaaaaaaaaaaaa:",
      "aaaaaaaaaaaaaaaa",
      "aaaaaaaaaaaaaaaa"
    ]
  ]
}